Workbook

Sheet Sheet1
A1: NO | B1: =IFERROR(__xludf.DUMMYFUNCTION("QUERY(IMPORTRANGE(""1AzTji2sW29mb6q5i6lLp4OT4kZtfXWmm_A7yA3mApUg"",""Sheet1!B1:S311""), ""SELECT * WHERE Col18 = 'Lunas'"")"),"NAMA") -> NAMA | C1: =IFERROR(__xludf.DUMMYFUNCTION("""COMPUTED_VALUE"""),"NIS") -> NIS | D1: =IFERROR(__xludf.DUMMYFUNCTION("""COMPUTED_VALUE"""),"ASRAMA") -> ASRAMA | E1: =IFERROR(__xludf.DUMMYFUNCTION("""COMPUTED_VALUE"""),"KAMAR") -> KAMAR | F1: =IFERROR(__xludf.DUMMYFUNCTION("""COMPUTED_VALUE"""),"TINGKAT") -> TINGKAT | G1: =IFERROR(__xludf.DUMMYFUNCTION("""COMPUTED_VALUE"""),"MADRASIAH") -> MADRASIAH | H1: =IFERROR(__xludf.DUMMYFUNCTION("""COMPUTED_VALUE"""),"SEKOLAH") -> SEKOLAH | I1: =IFERROR(__xludf.DUMMYFUNCTION("""COMPUTED_VALUE"""),"IBU") -> IBU | J1: =IFERROR(__xludf.DUMMYFUNCTION("""COMPUTED_VALUE"""),"ALAMAT") -> ALAMAT | K1: =IFERROR(__xludf.DUMMYFUNCTION("""COMPUTED_VALUE"""),"WA") -> WA | L1: =IFERROR(__xludf.DUMMYFUNCTION("""COMPUTED_VALUE"""),"JUMLAH SYAHRIYAH") -> JUMLAH SYAHRIYAH | M1: =IFERROR(__xludf.DUMMYFUNCTION("""COMPUTED_VALUE"""),"JUMLAH JARIYAH") -> JUMLAH JARIYAH | N1: =IFERROR(__xludf.DUMMYFUNCTION("""COMPUTED_VALUE"""),"JUMLAH DAFTAR ULANG") -> JUMLAH DAFTAR ULANG | O1: =IFERROR(__xludf.DUMMYFUNCTION("""COMPUTED_VALUE"""),"JUMLAH TOTAL TUNGGAKAN") -> JUMLAH TOTAL TUNGGAKAN | P1: =IFERROR(__xludf.DUMMYFUNCTION("""COMPUTED_VALUE"""),"") | Q1: =IFERROR(__xludf.DUMMYFUNCTION("""COMPUTED_VALUE"""),"") | R1: =IFERROR(__xludf.DUMMYFUNCTION("""COMPUTED_VALUE"""),"") | S1: =IFERROR(__xludf.DUMMYFUNCTION("""COMPUTED_VALUE"""),"STATUS ADMINISTRASI") -> STATUS ADMINISTRASI | T1: TANGGAL | U1: Create PDF
A2: =IF(B2="","",ROW(A2)-1) -> 1 | B2: =IFERROR(__xludf.DUMMYFUNCTION("""COMPUTED_VALUE"""),"ACH. ADITIYA YUGASWARA") -> ACH. ADITIYA YUGASWARA | C2: =IFERROR(__xludf.DUMMYFUNCTION("""COMPUTED_VALUE"""),2.025110681E9) -> 2025110681 | D2: =IFERROR(__xludf.DUMMYFUNCTION("""COMPUTED_VALUE"""),"A") -> A | E2: =IFERROR(__xludf.DUMMYFUNCTION("""COMPUTED_VALUE"""),"A-1") -> A-1 | F2: =IFERROR(__xludf.DUMMYFUNCTION("""COMPUTED_VALUE"""),3.0) -> 3 | G2: =IFERROR(__xludf.DUMMYFUNCTION("""COMPUTED_VALUE"""),"3 ULA A PUTRA") -> 3 ULA A PUTRA | H2: =IFERROR(__xludf.DUMMYFUNCTION("""COMPUTED_VALUE"""),"#N/A") -> #N/A | L2: =IFERROR(__xludf.DUMMYFUNCTION("""COMPUTED_VALUE"""),0.0) -> 0 | M2: =IFERROR(__xludf.DUMMYFUNCTION("""COMPUTED_VALUE"""),0.0) -> 0 | N2: =IFERROR(__xludf.DUMMYFUNCTION("""COMPUTED_VALUE"""),0.0) -> 0 | O2: =IFERROR(__xludf.DUMMYFUNCTION("""COMPUTED_VALUE"""),0.0) -> 0 | S2: =IFERROR(__xludf.DUMMYFUNCTION("""COMPUTED_VALUE"""),"Lunas") -> Lunas | T2: =TODAY() -> 46206 | U2: =IF(ISNA(vlookup(B2,DataExport!$D$2:$D$496,1,false)), "Belum", "Sudah") -> Belum
A3: =IF(B3="","",ROW(A3)-1) -> 2 | B3: =IFERROR(__xludf.DUMMYFUNCTION("""COMPUTED_VALUE"""),"ADELIA ZAHRA ROSYIDAH") -> ADELIA ZAHRA ROSYIDAH | C3: =IFERROR(__xludf.DUMMYFUNCTION("""COMPUTED_VALUE"""),2.024070565E9) -> 2024070565 | D3: =IFERROR(__xludf.DUMMYFUNCTION("""COMPUTED_VALUE"""),"D") -> D | E3: =IFERROR(__xludf.DUMMYFUNCTION("""COMPUTED_VALUE"""),"D-4") -> D-4 | F3: =IFERROR(__xludf.DUMMYFUNCTION("""COMPUTED_VALUE"""),3.0) -> 3 | G3: =IFERROR(__xludf.DUMMYFUNCTION("""COMPUTED_VALUE"""),"3 ULA A PUTRI") -> 3 ULA A PUTRI | H3: =IFERROR(__xludf.DUMMYFUNCTION("""COMPUTED_VALUE"""),"MTS-9 H") -> MTS-9 H | I3: =IFERROR(__xludf.DUMMYFUNCTION("""COMPUTED_VALUE"""),"SUJIATI") -> SUJIATI | J3: =IFERROR(__xludf.DUMMYFUNCTION("""COMPUTED_VALUE"""),"PINGGIRAN SUMBERAGUNG RT 002 RW 003 SUKODADI LAMONGAN") -> PINGGIRAN SUMBERAGUNG RT 002 RW 003 SUKODADI LAMONGAN | K3: =IFERROR(__xludf.DUMMYFUNCTION("""COMPUTED_VALUE"""),"6285733130659") -> 6285733130659 | L3: =IFERROR(__xludf.DUMMYFUNCTION("""COMPUTED_VALUE"""),0.0) -> 0 | M3: =IFERROR(__xludf.DUMMYFUNCTION("""COMPUTED_VALUE"""),0.0) -> 0 | N3: =IFERROR(__xludf.DUMMYFUNCTION("""COMPUTED_VALUE"""),0.0) -> 0 | O3: =IFERROR(__xludf.DUMMYFUNCTION("""COMPUTED_VALUE"""),0.0) -> 0 | S3: =IFERROR(__xludf.DUMMYFUNCTION("""COMPUTED_VALUE"""),"Lunas") -> Lunas | T3: =TODAY() -> 46206 | U3: =IF(ISNA(vlookup(B3,DataExport!$D$2:$D$496,1,false)), "Belum", "Sudah") -> Belum
A4: =IF(B4="","",ROW(A4)-1) -> 3 | B4: =IFERROR(__xludf.DUMMYFUNCTION("""COMPUTED_VALUE"""),"ADINDA KHOIRUN NISWAH") -> ADINDA KHOIRUN NISWAH | C4: =IFERROR(__xludf.DUMMYFUNCTION("""COMPUTED_VALUE"""),2.024070336E9) -> 2024070336 | D4: =IFERROR(__xludf.DUMMYFUNCTION("""COMPUTED_VALUE"""),"D") -> D | E4: =IFERROR(__xludf.DUMMYFUNCTION("""COMPUTED_VALUE"""),"D-6") -> D-6 | F4: =IFERROR(__xludf.DUMMYFUNCTION("""COMPUTED_VALUE"""),3.0) -> 3 | G4: =IFERROR(__xludf.DUMMYFUNCTION("""COMPUTED_VALUE"""),"3 WUSTHO C PUTRI") -> 3 WUSTHO C PUTRI | H4: =IFERROR(__xludf.DUMMYFUNCTION("""COMPUTED_VALUE"""),"MA-XII.11") -> MA-XII.11 | I4: =IFERROR(__xludf.DUMMYFUNCTION("""COMPUTED_VALUE"""),"ANI ROKHMATIN") -> ANI ROKHMATIN | J4: =IFERROR(__xludf.DUMMYFUNCTION("""COMPUTED_VALUE"""),"GRIGIS SUMBERJO RT 3 RW 5 SARIREJO LAMONGAN") -> GRIGIS SUMBERJO RT 3 RW 5 SARIREJO LAMONGAN | K4: =IFERROR(__xludf.DUMMYFUNCTION("""COMPUTED_VALUE"""),"6283833507477") -> 6283833507477 | L4: =IFERROR(__xludf.DUMMYFUNCTION("""COMPUTED_VALUE"""),0.0) -> 0 | M4: =IFERROR(__xludf.DUMMYFUNCTION("""COMPUTED_VALUE"""),0.0) -> 0 | N4: =IFERROR(__xludf.DUMMYFUNCTION("""COMPUTED_VALUE"""),0.0) -> 0 | O4: =IFERROR(__xludf.DUMMYFUNCTION("""COMPUTED_VALUE"""),0.0) -> 0 | S4: =IFERROR(__xludf.DUMMYFUNCTION("""COMPUTED_VALUE"""),"Lunas") -> Lunas | T4: =TODAY() -> 46206 | U4: =IF(ISNA(vlookup(B4,DataExport!$D$2:$D$496,1,false)), "Belum", "Sudah") -> Belum
A5: =IF(B5="","",ROW(A5)-1) -> 4 | B5: =IFERROR(__xludf.DUMMYFUNCTION("""COMPUTED_VALUE"""),"AFANIA AQILATUS SHAFA") -> AFANIA AQILATUS SHAFA | C5: =IFERROR(__xludf.DUMMYFUNCTION("""COMPUTED_VALUE"""),2.02407064E9) -> 2024070640 | D5: =IFERROR(__xludf.DUMMYFUNCTION("""COMPUTED_VALUE"""),"C") -> C | E5: =IFERROR(__xludf.DUMMYFUNCTION("""COMPUTED_VALUE"""),"C-13") -> C-13 | F5: =IFERROR(__xludf.DUMMYFUNCTION("""COMPUTED_VALUE"""),3.0) -> 3 | G5: =IFERROR(__xludf.DUMMYFUNCTION("""COMPUTED_VALUE"""),"3 ULA C PUTRI") -> 3 ULA C PUTRI | H5: =IFERROR(__xludf.DUMMYFUNCTION("""COMPUTED_VALUE"""),"MTS-9 G") -> MTS-9 G | I5: =IFERROR(__xludf.DUMMYFUNCTION("""COMPUTED_VALUE"""),"DWI OKTAFIA NINGSIH") -> DWI OKTAFIA NINGSIH | J5: =IFERROR(__xludf.DUMMYFUNCTION("""COMPUTED_VALUE"""),"PAJANGAN RT 002 RW 002 SUKODADI LAMONGAN") -> PAJANGAN RT 002 RW 002 SUKODADI LAMONGAN | K5: =IFERROR(__xludf.DUMMYFUNCTION("""COMPUTED_VALUE"""),"6285257103018") -> 6285257103018 | L5: =IFERROR(__xludf.DUMMYFUNCTION("""COMPUTED_VALUE"""),0.0) -> 0 | M5: =IFERROR(__xludf.DUMMYFUNCTION("""COMPUTED_VALUE"""),0.0) -> 0 | N5: =IFERROR(__xludf.DUMMYFUNCTION("""COMPUTED_VALUE"""),0.0) -> 0 | O5: =IFERROR(__xludf.DUMMYFUNCTION("""COMPUTED_VALUE"""),0.0) -> 0 | S5: =IFERROR(__xludf.DUMMYFUNCTION("""COMPUTED_VALUE"""),"Lunas") -> Lunas | T5: =TODAY() -> 46206 | U5: =IF(ISNA(vlookup(B5,DataExport!$D$2:$D$496,1,false)), "Belum", "Sudah") -> Belum
A6: =IF(B6="","",ROW(A6)-1) -> 5 | B6: =IFERROR(__xludf.DUMMYFUNCTION("""COMPUTED_VALUE"""),"AFILIA MEGA NURFATMA") -> AFILIA MEGA NURFATMA | C6: =IFERROR(__xludf.DUMMYFUNCTION("""COMPUTED_VALUE"""),2.024070563E9) -> 2024070563 | D6: =IFERROR(__xludf.DUMMYFUNCTION("""COMPUTED_VALUE"""),"B") -> B | E6: =IFERROR(__xludf.DUMMYFUNCTION("""COMPUTED_VALUE"""),"B-10") -> B-10 | F6: =IFERROR(__xludf.DUMMYFUNCTION("""COMPUTED_VALUE"""),3.0) -> 3 | G6: =IFERROR(__xludf.DUMMYFUNCTION("""COMPUTED_VALUE"""),"3 ULA A PUTRI") -> 3 ULA A PUTRI | H6: =IFERROR(__xludf.DUMMYFUNCTION("""COMPUTED_VALUE"""),"MTS-9 A") -> MTS-9 A | I6: =IFERROR(__xludf.DUMMYFUNCTION("""COMPUTED_VALUE"""),"ALIYATUN") -> ALIYATUN | J6: =IFERROR(__xludf.DUMMYFUNCTION("""COMPUTED_VALUE"""),"TENGGULUN RT 003 RW 002 SOLOKURO LAMONGAN") -> TENGGULUN RT 003 RW 002 SOLOKURO LAMONGAN | K6: =IFERROR(__xludf.DUMMYFUNCTION("""COMPUTED_VALUE"""),"6285812446154") -> 6285812446154 | L6: =IFERROR(__xludf.DUMMYFUNCTION("""COMPUTED_VALUE"""),0.0) -> 0 | M6: =IFERROR(__xludf.DUMMYFUNCTION("""COMPUTED_VALUE"""),0.0) -> 0 | N6: =IFERROR(__xludf.DUMMYFUNCTION("""COMPUTED_VALUE"""),0.0) -> 0 | O6: =IFERROR(__xludf.DUMMYFUNCTION("""COMPUTED_VALUE"""),0.0) -> 0 | S6: =IFERROR(__xludf.DUMMYFUNCTION("""COMPUTED_VALUE"""),"Lunas") -> Lunas | T6: =TODAY() -> 46206 | U6: =IF(ISNA(vlookup(B6,DataExport!$D$2:$D$496,1,false)), "Belum", "Sudah") -> Belum
A7: =IF(B7="","",ROW(A7)-1) -> 6 | B7: =IFERROR(__xludf.DUMMYFUNCTION("""COMPUTED_VALUE"""),"AFINA AGUSTIN ROMADHONI") -> AFINA AGUSTIN ROMADHONI | C7: =IFERROR(__xludf.DUMMYFUNCTION("""COMPUTED_VALUE"""),2.024070561E9) -> 2024070561 | D7: =IFERROR(__xludf.DUMMYFUNCTION("""COMPUTED_VALUE"""),"C") -> C | E7: =IFERROR(__xludf.DUMMYFUNCTION("""COMPUTED_VALUE"""),"C-13") -> C-13 | F7: =IFERROR(__xludf.DUMMYFUNCTION("""COMPUTED_VALUE"""),3.0) -> 3 | H7: =IFERROR(__xludf.DUMMYFUNCTION("""COMPUTED_VALUE"""),"MTS-9 G") -> MTS-9 G | I7: =IFERROR(__xludf.DUMMYFUNCTION("""COMPUTED_VALUE"""),"MAZROATUN") -> MAZROATUN | J7: =IFERROR(__xludf.DUMMYFUNCTION("""COMPUTED_VALUE"""),"KEBEN RT 004 RW 002 TURI LAMONGAN") -> KEBEN RT 004 RW 002 TURI LAMONGAN | K7: =IFERROR(__xludf.DUMMYFUNCTION("""COMPUTED_VALUE"""),"6285748099065") -> 6285748099065 | L7: =IFERROR(__xludf.DUMMYFUNCTION("""COMPUTED_VALUE"""),0.0) -> 0 | M7: =IFERROR(__xludf.DUMMYFUNCTION("""COMPUTED_VALUE"""),0.0) -> 0 | N7: =IFERROR(__xludf.DUMMYFUNCTION("""COMPUTED_VALUE"""),0.0) -> 0 | O7: =IFERROR(__xludf.DUMMYFUNCTION("""COMPUTED_VALUE"""),0.0) -> 0 | S7: =IFERROR(__xludf.DUMMYFUNCTION("""COMPUTED_VALUE"""),"Lunas") -> Lunas | T7: =TODAY() -> 46206 | U7: =IF(ISNA(vlookup(B7,DataExport!$D$2:$D$496,1,false)), "Belum", "Sudah") -> Belum
A8: =IF(B8="","",ROW(A8)-1) -> 7 | B8: =IFERROR(__xludf.DUMMYFUNCTION("""COMPUTED_VALUE"""),"AHDA KAISYA BADAATIL MUFIDAH") -> AHDA KAISYA BADAATIL MUFIDAH | C8: =IFERROR(__xludf.DUMMYFUNCTION("""COMPUTED_VALUE"""),2.024070322E9) -> 2024070322 | D8: =IFERROR(__xludf.DUMMYFUNCTION("""COMPUTED_VALUE"""),"C") -> C | E8: =IFERROR(__xludf.DUMMYFUNCTION("""COMPUTED_VALUE"""),"C-9") -> C-9 | F8: =IFERROR(__xludf.DUMMYFUNCTION("""COMPUTED_VALUE"""),3.0) -> 3 | H8: =IFERROR(__xludf.DUMMYFUNCTION("""COMPUTED_VALUE"""),"MA-XII.10") -> MA-XII.10 | I8: =IFERROR(__xludf.DUMMYFUNCTION("""COMPUTED_VALUE"""),"INAYATUL KARIMAH") -> INAYATUL KARIMAH | J8: =IFERROR(__xludf.DUMMYFUNCTION("""COMPUTED_VALUE"""),"KEBET RT 008 RW 002 LAMONGAN LAMONGAN") -> KEBET RT 008 RW 002 LAMONGAN LAMONGAN | K8: =IFERROR(__xludf.DUMMYFUNCTION("""COMPUTED_VALUE"""),"6285895759423") -> 6285895759423 | L8: =IFERROR(__xludf.DUMMYFUNCTION("""COMPUTED_VALUE"""),0.0) -> 0 | M8: =IFERROR(__xludf.DUMMYFUNCTION("""COMPUTED_VALUE"""),0.0) -> 0 | N8: =IFERROR(__xludf.DUMMYFUNCTION("""COMPUTED_VALUE"""),0.0) -> 0 | O8: =IFERROR(__xludf.DUMMYFUNCTION("""COMPUTED_VALUE"""),0.0) -> 0 | S8: =IFERROR(__xludf.DUMMYFUNCTION("""COMPUTED_VALUE"""),"Lunas") -> Lunas | T8: =TODAY() -> 46206 | U8: =IF(ISNA(vlookup(B8,DataExport!$D$2:$D$496,1,false)), "Belum", "Sudah") -> Belum
A9: =IF(B9="","",ROW(A9)-1) -> 8 | B9: =IFERROR(__xludf.DUMMYFUNCTION("""COMPUTED_VALUE"""),"AHMAD AZKA ALFIKRI") -> AHMAD AZKA ALFIKRI | C9: =IFERROR(__xludf.DUMMYFUNCTION("""COMPUTED_VALUE"""),2.024070554E9) -> 2024070554 | D9: =IFERROR(__xludf.DUMMYFUNCTION("""COMPUTED_VALUE"""),"A") -> A | E9: =IFERROR(__xludf.DUMMYFUNCTION("""COMPUTED_VALUE"""),"A-7") -> A-7 | F9: =IFERROR(__xludf.DUMMYFUNCTION("""COMPUTED_VALUE"""),3.0) -> 3 | G9: =IFERROR(__xludf.DUMMYFUNCTION("""COMPUTED_VALUE"""),"3 ULA B PUTRA") -> 3 ULA B PUTRA | H9: =IFERROR(__xludf.DUMMYFUNCTION("""COMPUTED_VALUE"""),"MTS-9 E") -> MTS-9 E | I9: =IFERROR(__xludf.DUMMYFUNCTION("""COMPUTED_VALUE"""),"MASRUAH") -> MASRUAH | J9: =IFERROR(__xludf.DUMMYFUNCTION("""COMPUTED_VALUE"""),"LASEM RT 001 RW 001 SIDAYU GRESIK") -> LASEM RT 001 RW 001 SIDAYU GRESIK | K9: =IFERROR(__xludf.DUMMYFUNCTION("""COMPUTED_VALUE"""),"6285645389910") -> 6285645389910 | L9: =IFERROR(__xludf.DUMMYFUNCTION("""COMPUTED_VALUE"""),0.0) -> 0 | M9: =IFERROR(__xludf.DUMMYFUNCTION("""COMPUTED_VALUE"""),0.0) -> 0 | N9: =IFERROR(__xludf.DUMMYFUNCTION("""COMPUTED_VALUE"""),0.0) -> 0 | O9: =IFERROR(__xludf.DUMMYFUNCTION("""COMPUTED_VALUE"""),0.0) -> 0 | S9: =IFERROR(__xludf.DUMMYFUNCTION("""COMPUTED_VALUE"""),"Lunas") -> Lunas | T9: =TODAY() -> 46206 | U9: =IF(ISNA(vlookup(B9,DataExport!$D$2:$D$496,1,false)), "Belum", "Sudah") -> Belum
A10: =IF(B10="","",ROW(A10)-1) -> 9 | B10: =IFERROR(__xludf.DUMMYFUNCTION("""COMPUTED_VALUE"""),"AHMAD HAFIDZ RIZKI AL ZAMZAMI") -> AHMAD HAFIDZ RIZKI AL ZAMZAMI | C10: =IFERROR(__xludf.DUMMYFUNCTION("""COMPUTED_VALUE"""),2.024070615E9) -> 2024070615 | D10: =IFERROR(__xludf.DUMMYFUNCTION("""COMPUTED_VALUE"""),"A") -> A | E10: =IFERROR(__xludf.DUMMYFUNCTION("""COMPUTED_VALUE"""),"A-7") -> A-7 | F10: =IFERROR(__xludf.DUMMYFUNCTION("""COMPUTED_VALUE"""),3.0) -> 3 | G10: =IFERROR(__xludf.DUMMYFUNCTION("""COMPUTED_VALUE"""),"3 ULA B PUTRA") -> 3 ULA B PUTRA | H10: =IFERROR(__xludf.DUMMYFUNCTION("""COMPUTED_VALUE"""),"MTS-9 E") -> MTS-9 E | I10: =IFERROR(__xludf.DUMMYFUNCTION("""COMPUTED_VALUE"""),"SITI ZUMAROH") -> SITI ZUMAROH | J10: =IFERROR(__xludf.DUMMYFUNCTION("""COMPUTED_VALUE"""),"GLUMO JELAKCATUR RT 003 RW 005 KALITENGAH LAMONGAN") -> GLUMO JELAKCATUR RT 003 RW 005 KALITENGAH LAMONGAN | K10: =IFERROR(__xludf.DUMMYFUNCTION("""COMPUTED_VALUE"""),"6285759930572") -> 6285759930572 | L10: =IFERROR(__xludf.DUMMYFUNCTION("""COMPUTED_VALUE"""),0.0) -> 0 | M10: =IFERROR(__xludf.DUMMYFUNCTION("""COMPUTED_VALUE"""),0.0) -> 0 | N10: =IFERROR(__xludf.DUMMYFUNCTION("""COMPUTED_VALUE"""),0.0) -> 0 | O10: =IFERROR(__xludf.DUMMYFUNCTION("""COMPUTED_VALUE"""),0.0) -> 0 | S10: =IFERROR(__xludf.DUMMYFUNCTION("""COMPUTED_VALUE"""),"Lunas") -> Lunas | T10: =TODAY() -> 46206 | U10: =IF(ISNA(vlookup(B10,DataExport!$D$2:$D$496,1,false)), "Belum", "Sudah") -> Belum
A11: =IF(B11="","",ROW(A11)-1) -> 10 | B11: =IFERROR(__xludf.DUMMYFUNCTION("""COMPUTED_VALUE"""),"AHMAD MANSYAUL HIKAMI") -> AHMAD MANSYAUL HIKAMI | C11: =IFERROR(__xludf.DUMMYFUNCTION("""COMPUTED_VALUE"""),2.024070402E9) -> 2024070402 | D11: =IFERROR(__xludf.DUMMYFUNCTION("""COMPUTED_VALUE"""),"A") -> A | E11: =IFERROR(__xludf.DUMMYFUNCTION("""COMPUTED_VALUE"""),"A-10") -> A-10 | F11: =IFERROR(__xludf.DUMMYFUNCTION("""COMPUTED_VALUE"""),3.0) -> 3 | G11: =IFERROR(__xludf.DUMMYFUNCTION("""COMPUTED_VALUE"""),"3 WUSTHO PUTRA") -> 3 WUSTHO PUTRA | H11: =IFERROR(__xludf.DUMMYFUNCTION("""COMPUTED_VALUE"""),"MA-XII.9") -> MA-XII.9 | I11: =IFERROR(__xludf.DUMMYFUNCTION("""COMPUTED_VALUE"""),"KHOIRIYAH") -> KHOIRIYAH | J11: =IFERROR(__xludf.DUMMYFUNCTION("""COMPUTED_VALUE"""),"MAYONG NGABLAK RT 1 RW 2 KARANGBINANGUN LAMONGAN") -> MAYONG NGABLAK RT 1 RW 2 KARANGBINANGUN LAMONGAN | K11: =IFERROR(__xludf.DUMMYFUNCTION("""COMPUTED_VALUE"""),"6285852940999") -> 6285852940999 | L11: =IFERROR(__xludf.DUMMYFUNCTION("""COMPUTED_VALUE"""),0.0) -> 0 | M11: =IFERROR(__xludf.DUMMYFUNCTION("""COMPUTED_VALUE"""),0.0) -> 0 | N11: =IFERROR(__xludf.DUMMYFUNCTION("""COMPUTED_VALUE"""),0.0) -> 0 | O11: =IFERROR(__xludf.DUMMYFUNCTION("""COMPUTED_VALUE"""),0.0) -> 0 | S11: =IFERROR(__xludf.DUMMYFUNCTION("""COMPUTED_VALUE"""),"Lunas") -> Lunas | T11: =TODAY() -> 46206 | U11: =IF(ISNA(vlookup(B11,DataExport!$D$2:$D$496,1,false)), "Belum", "Sudah") -> Belum
A12: =IF(B12="","",ROW(A12)-1) -> 11 | B12: =IFERROR(__xludf.DUMMYFUNCTION("""COMPUTED_VALUE"""),"AHMAD MUZAKKI") -> AHMAD MUZAKKI | C12: =IFERROR(__xludf.DUMMYFUNCTION("""COMPUTED_VALUE"""),2.024070502E9) -> 2024070502 | D12: =IFERROR(__xludf.DUMMYFUNCTION("""COMPUTED_VALUE"""),"A") -> A | E12: =IFERROR(__xludf.DUMMYFUNCTION("""COMPUTED_VALUE"""),"A-8") -> A-8 | F12: =IFERROR(__xludf.DUMMYFUNCTION("""COMPUTED_VALUE"""),3.0) -> 3 | G12: =IFERROR(__xludf.DUMMYFUNCTION("""COMPUTED_VALUE"""),"3 ULA A PUTRA") -> 3 ULA A PUTRA | H12: =IFERROR(__xludf.DUMMYFUNCTION("""COMPUTED_VALUE"""),"MTS-9 E") -> MTS-9 E | I12: =IFERROR(__xludf.DUMMYFUNCTION("""COMPUTED_VALUE"""),"FITRIATUN NADHIROH") -> FITRIATUN NADHIROH | J12: =IFERROR(__xludf.DUMMYFUNCTION("""COMPUTED_VALUE"""),"JUBAK NGUWOK RT 014 RW 006 MODO LAMONGAN") -> JUBAK NGUWOK RT 014 RW 006 MODO LAMONGAN | K12: =IFERROR(__xludf.DUMMYFUNCTION("""COMPUTED_VALUE"""),"6285230826998") -> 6285230826998 | L12: =IFERROR(__xludf.DUMMYFUNCTION("""COMPUTED_VALUE"""),0.0) -> 0 | M12: =IFERROR(__xludf.DUMMYFUNCTION("""COMPUTED_VALUE"""),0.0) -> 0 | N12: =IFERROR(__xludf.DUMMYFUNCTION("""COMPUTED_VALUE"""),0.0) -> 0 | O12: =IFERROR(__xludf.DUMMYFUNCTION("""COMPUTED_VALUE"""),0.0) -> 0 | S12: =IFERROR(__xludf.DUMMYFUNCTION("""COMPUTED_VALUE"""),"Lunas") -> Lunas | T12: =TODAY() -> 46206 | U12: =IF(ISNA(vlookup(B12,DataExport!$D$2:$D$496,1,false)), "Belum", "Sudah") -> Belum
A13: =IF(B13="","",ROW(A13)-1) -> 12 | B13: =IFERROR(__xludf.DUMMYFUNCTION("""COMPUTED_VALUE"""),"AHMAD NUR FAJAR ROMADHONI") -> AHMAD NUR FAJAR ROMADHONI | C13: =IFERROR(__xludf.DUMMYFUNCTION("""COMPUTED_VALUE"""),2.024070403E9) -> 2024070403 | D13: =IFERROR(__xludf.DUMMYFUNCTION("""COMPUTED_VALUE"""),"A") -> A | E13: =IFERROR(__xludf.DUMMYFUNCTION("""COMPUTED_VALUE"""),"A-2") -> A-2 | F13: =IFERROR(__xludf.DUMMYFUNCTION("""COMPUTED_VALUE"""),3.0) -> 3 | G13: =IFERROR(__xludf.DUMMYFUNCTION("""COMPUTED_VALUE"""),"3 MAK PUTRA") -> 3 MAK PUTRA | H13: =IFERROR(__xludf.DUMMYFUNCTION("""COMPUTED_VALUE"""),"MA-XII.13") -> MA-XII.13 | I13: =IFERROR(__xludf.DUMMYFUNCTION("""COMPUTED_VALUE"""),"SITI ULFAH") -> SITI ULFAH | J13: =IFERROR(__xludf.DUMMYFUNCTION("""COMPUTED_VALUE"""),"GENDONG RT 002 RW 004 LAREN LAMONGAN") -> GENDONG RT 002 RW 004 LAREN LAMONGAN | K13: =IFERROR(__xludf.DUMMYFUNCTION("""COMPUTED_VALUE"""),"685736441139") -> 685736441139 | L13: =IFERROR(__xludf.DUMMYFUNCTION("""COMPUTED_VALUE"""),0.0) -> 0 | M13: =IFERROR(__xludf.DUMMYFUNCTION("""COMPUTED_VALUE"""),0.0) -> 0 | N13: =IFERROR(__xludf.DUMMYFUNCTION("""COMPUTED_VALUE"""),0.0) -> 0 | O13: =IFERROR(__xludf.DUMMYFUNCTION("""COMPUTED_VALUE"""),0.0) -> 0 | S13: =IFERROR(__xludf.DUMMYFUNCTION("""COMPUTED_VALUE"""),"Lunas") -> Lunas | T13: =TODAY() -> 46206 | U13: =IF(ISNA(vlookup(B13,DataExport!$D$2:$D$496,1,false)), "Belum", "Sudah") -> Belum
A14: =IF(B14="","",ROW(A14)-1) -> 13 | B14: =IFERROR(__xludf.DUMMYFUNCTION("""COMPUTED_VALUE"""),"AIKE NESAFA ULIFIA") -> AIKE NESAFA ULIFIA | C14: =IFERROR(__xludf.DUMMYFUNCTION("""COMPUTED_VALUE"""),2.02407045E9) -> 2024070450 | D14: =IFERROR(__xludf.DUMMYFUNCTION("""COMPUTED_VALUE"""),"E") -> E | E14: =IFERROR(__xludf.DUMMYFUNCTION("""COMPUTED_VALUE"""),"E-9") -> E-9 | F14: =IFERROR(__xludf.DUMMYFUNCTION("""COMPUTED_VALUE"""),3.0) -> 3 | G14: =IFERROR(__xludf.DUMMYFUNCTION("""COMPUTED_VALUE"""),"3 ULA B PUTRI") -> 3 ULA B PUTRI | H14: =IFERROR(__xludf.DUMMYFUNCTION("""COMPUTED_VALUE"""),"MTS-9 A") -> MTS-9 A | I14: =IFERROR(__xludf.DUMMYFUNCTION("""COMPUTED_VALUE"""),"MARIA ULFA") -> MARIA ULFA | J14: =IFERROR(__xludf.DUMMYFUNCTION("""COMPUTED_VALUE"""),"KUSUMA BANGSA GG KERTANEGARA TUMENGGUNGAN RT 003 RW 006 LAMONGAN LAMONGAN") -> KUSUMA BANGSA GG KERTANEGARA TUMENGGUNGAN RT 003 RW 006 LAMONGAN LAMONGAN | K14: =IFERROR(__xludf.DUMMYFUNCTION("""COMPUTED_VALUE"""),"6285733946516") -> 6285733946516 | L14: =IFERROR(__xludf.DUMMYFUNCTION("""COMPUTED_VALUE"""),0.0) -> 0 | M14: =IFERROR(__xludf.DUMMYFUNCTION("""COMPUTED_VALUE"""),0.0) -> 0 | N14: =IFERROR(__xludf.DUMMYFUNCTION("""COMPUTED_VALUE"""),0.0) -> 0 | O14: =IFERROR(__xludf.DUMMYFUNCTION("""COMPUTED_VALUE"""),0.0) -> 0 | S14: =IFERROR(__xludf.DUMMYFUNCTION("""COMPUTED_VALUE"""),"Lunas") -> Lunas | T14: =TODAY() -> 46206 | U14: =IF(ISNA(vlookup(B14,DataExport!$D$2:$D$496,1,false)), "Belum", "Sudah") -> Belum
A15: =IF(B15="","",ROW(A15)-1) -> 14 | B15: =IFERROR(__xludf.DUMMYFUNCTION("""COMPUTED_VALUE"""),"AKHMAD FATIKHUL IN`AM") -> AKHMAD FATIKHUL IN`AM | C15: =IFERROR(__xludf.DUMMYFUNCTION("""COMPUTED_VALUE"""),2.024070404E9) -> 2024070404 | D15: =IFERROR(__xludf.DUMMYFUNCTION("""COMPUTED_VALUE"""),"A") -> A | E15: =IFERROR(__xludf.DUMMYFUNCTION("""COMPUTED_VALUE"""),"A-2") -> A-2 | F15: =IFERROR(__xludf.DUMMYFUNCTION("""COMPUTED_VALUE"""),3.0) -> 3 | G15: =IFERROR(__xludf.DUMMYFUNCTION("""COMPUTED_VALUE"""),"3 MAK PUTRA") -> 3 MAK PUTRA | H15: =IFERROR(__xludf.DUMMYFUNCTION("""COMPUTED_VALUE"""),"MA-XII.13") -> MA-XII.13 | I15: =IFERROR(__xludf.DUMMYFUNCTION("""COMPUTED_VALUE"""),"NURUL MUTHOHAROH") -> NURUL MUTHOHAROH | J15: =IFERROR(__xludf.DUMMYFUNCTION("""COMPUTED_VALUE"""),"LUMBER KALIPANG RT 001 RW 001 SUGIO LAMONGAN") -> LUMBER KALIPANG RT 001 RW 001 SUGIO LAMONGAN | K15: =IFERROR(__xludf.DUMMYFUNCTION("""COMPUTED_VALUE"""),"6285645455467") -> 6285645455467 | L15: =IFERROR(__xludf.DUMMYFUNCTION("""COMPUTED_VALUE"""),0.0) -> 0 | M15: =IFERROR(__xludf.DUMMYFUNCTION("""COMPUTED_VALUE"""),0.0) -> 0 | N15: =IFERROR(__xludf.DUMMYFUNCTION("""COMPUTED_VALUE"""),0.0) -> 0 | O15: =IFERROR(__xludf.DUMMYFUNCTION("""COMPUTED_VALUE"""),0.0) -> 0 | S15: =IFERROR(__xludf.DUMMYFUNCTION("""COMPUTED_VALUE"""),"Lunas") -> Lunas | T15: =TODAY() -> 46206 | U15: =IF(ISNA(vlookup(B15,DataExport!$D$2:$D$496,1,false)), "Belum", "Sudah") -> Belum
A16: =IF(B16="","",ROW(A16)-1) -> 15 | B16: =IFERROR(__xludf.DUMMYFUNCTION("""COMPUTED_VALUE"""),"ALIFATUN BINTU KHUMAIROH") -> ALIFATUN BINTU KHUMAIROH | C16: =IFERROR(__xludf.DUMMYFUNCTION("""COMPUTED_VALUE"""),2.024070488E9) -> 2024070488 | D16: =IFERROR(__xludf.DUMMYFUNCTION("""COMPUTED_VALUE"""),"C") -> C | E16: =IFERROR(__xludf.DUMMYFUNCTION("""COMPUTED_VALUE"""),"C-12") -> C-12 | F16: =IFERROR(__xludf.DUMMYFUNCTION("""COMPUTED_VALUE"""),3.0) -> 3 | G16: =IFERROR(__xludf.DUMMYFUNCTION("""COMPUTED_VALUE"""),"3 ULA B PUTRI") -> 3 ULA B PUTRI | H16: =IFERROR(__xludf.DUMMYFUNCTION("""COMPUTED_VALUE"""),"MTS-9 G") -> MTS-9 G | I16: =IFERROR(__xludf.DUMMYFUNCTION("""COMPUTED_VALUE"""),"SRI SULISTYANINGSIH") -> SRI SULISTYANINGSIH | J16: =IFERROR(__xludf.DUMMYFUNCTION("""COMPUTED_VALUE"""),"SIDOBRANTI SIDOMUKTI RT 009 RW 003 KEMBANGBAHU LAMONGAN") -> SIDOBRANTI SIDOMUKTI RT 009 RW 003 KEMBANGBAHU LAMONGAN | K16: =IFERROR(__xludf.DUMMYFUNCTION("""COMPUTED_VALUE"""),"6285704238402") -> 6285704238402 | L16: =IFERROR(__xludf.DUMMYFUNCTION("""COMPUTED_VALUE"""),0.0) -> 0 | M16: =IFERROR(__xludf.DUMMYFUNCTION("""COMPUTED_VALUE"""),0.0) -> 0 | N16: =IFERROR(__xludf.DUMMYFUNCTION("""COMPUTED_VALUE"""),0.0) -> 0 | O16: =IFERROR(__xludf.DUMMYFUNCTION("""COMPUTED_VALUE"""),0.0) -> 0 | S16: =IFERROR(__xludf.DUMMYFUNCTION("""COMPUTED_VALUE"""),"Lunas") -> Lunas | T16: =TODAY() -> 46206 | U16: =IF(ISNA(vlookup(B16,DataExport!$D$2:$D$496,1,false)), "Belum", "Sudah") -> Belum
A17: =IF(B17="","",ROW(A17)-1) -> 16 | B17: =IFERROR(__xludf.DUMMYFUNCTION("""COMPUTED_VALUE"""),"ALYA SHIFA AZZAHRA") -> ALYA SHIFA AZZAHRA | C17: =IFERROR(__xludf.DUMMYFUNCTION("""COMPUTED_VALUE"""),2.024070579E9) -> 2024070579 | D17: =IFERROR(__xludf.DUMMYFUNCTION("""COMPUTED_VALUE"""),"B") -> B | E17: =IFERROR(__xludf.DUMMYFUNCTION("""COMPUTED_VALUE"""),"B-9") -> B-9 | F17: =IFERROR(__xludf.DUMMYFUNCTION("""COMPUTED_VALUE"""),3.0) -> 3 | G17: =IFERROR(__xludf.DUMMYFUNCTION("""COMPUTED_VALUE"""),"3 ULA B PUTRI") -> 3 ULA B PUTRI | H17: =IFERROR(__xludf.DUMMYFUNCTION("""COMPUTED_VALUE"""),"MTS-9 G") -> MTS-9 G | I17: =IFERROR(__xludf.DUMMYFUNCTION("""COMPUTED_VALUE"""),"SULASTRI") -> SULASTRI | J17: =IFERROR(__xludf.DUMMYFUNCTION("""COMPUTED_VALUE"""),"BANJARAN TURI RT 008 RW 002 MADURAN LAMONGAN") -> BANJARAN TURI RT 008 RW 002 MADURAN LAMONGAN | K17: =IFERROR(__xludf.DUMMYFUNCTION("""COMPUTED_VALUE"""),"6285738896773") -> 6285738896773 | L17: =IFERROR(__xludf.DUMMYFUNCTION("""COMPUTED_VALUE"""),0.0) -> 0 | M17: =IFERROR(__xludf.DUMMYFUNCTION("""COMPUTED_VALUE"""),0.0) -> 0 | N17: =IFERROR(__xludf.DUMMYFUNCTION("""COMPUTED_VALUE"""),0.0) -> 0 | O17: =IFERROR(__xludf.DUMMYFUNCTION("""COMPUTED_VALUE"""),0.0) -> 0 | S17: =IFERROR(__xludf.DUMMYFUNCTION("""COMPUTED_VALUE"""),"Lunas") -> Lunas | T17: =TODAY() -> 46206 | U17: =IF(ISNA(vlookup(B17,DataExport!$D$2:$D$496,1,false)), "Belum", "Sudah") -> Belum
A18: =IF(B18="","",ROW(A18)-1) -> 17 | B18: =IFERROR(__xludf.DUMMYFUNCTION("""COMPUTED_VALUE"""),"ASTNA ANIS ADUBA") -> ASTNA ANIS ADUBA | C18: =IFERROR(__xludf.DUMMYFUNCTION("""COMPUTED_VALUE"""),2.024070003E9) -> 2024070003 | D18: =IFERROR(__xludf.DUMMYFUNCTION("""COMPUTED_VALUE"""),"C") -> C | E18: =IFERROR(__xludf.DUMMYFUNCTION("""COMPUTED_VALUE"""),"C-2") -> C-2 | F18: =IFERROR(__xludf.DUMMYFUNCTION("""COMPUTED_VALUE"""),3.0) -> 3 | H18: =IFERROR(__xludf.DUMMYFUNCTION("""COMPUTED_VALUE"""),"MA-XII.1") -> MA-XII.1 | I18: =IFERROR(__xludf.DUMMYFUNCTION("""COMPUTED_VALUE"""),"ZUMROHAH") -> ZUMROHAH | J18: =IFERROR(__xludf.DUMMYFUNCTION("""COMPUTED_VALUE"""),"TAKERHARJO RT 004 RW 002 SOLOKURO LAMONGAN") -> TAKERHARJO RT 004 RW 002 SOLOKURO LAMONGAN | K18: =IFERROR(__xludf.DUMMYFUNCTION("""COMPUTED_VALUE"""),"6285790863008") -> 6285790863008 | L18: =IFERROR(__xludf.DUMMYFUNCTION("""COMPUTED_VALUE"""),0.0) -> 0 | M18: =IFERROR(__xludf.DUMMYFUNCTION("""COMPUTED_VALUE"""),0.0) -> 0 | N18: =IFERROR(__xludf.DUMMYFUNCTION("""COMPUTED_VALUE"""),0.0) -> 0 | O18: =IFERROR(__xludf.DUMMYFUNCTION("""COMPUTED_VALUE"""),0.0) -> 0 | S18: =IFERROR(__xludf.DUMMYFUNCTION("""COMPUTED_VALUE"""),"Lunas") -> Lunas | T18: =TODAY() -> 46206 | U18: =IF(ISNA(vlookup(B18,DataExport!$D$2:$D$496,1,false)), "Belum", "Sudah") -> Belum
A19: =IF(B19="","",ROW(A19)-1) -> 18 | B19: =IFERROR(__xludf.DUMMYFUNCTION("""COMPUTED_VALUE"""),"AUFA NUR LAILI FADHILAH") -> AUFA NUR LAILI FADHILAH | C19: =IFERROR(__xludf.DUMMYFUNCTION("""COMPUTED_VALUE"""),2.024070605E9) -> 2024070605 | D19: =IFERROR(__xludf.DUMMYFUNCTION("""COMPUTED_VALUE"""),"C") -> C | E19: =IFERROR(__xludf.DUMMYFUNCTION("""COMPUTED_VALUE"""),"C-3") -> C-3 | F19: =IFERROR(__xludf.DUMMYFUNCTION("""COMPUTED_VALUE"""),3.0) -> 3 | G19: =IFERROR(__xludf.DUMMYFUNCTION("""COMPUTED_VALUE"""),"3 ULA A PUTRI") -> 3 ULA A PUTRI | H19: =IFERROR(__xludf.DUMMYFUNCTION("""COMPUTED_VALUE"""),"MTS-9 B") -> MTS-9 B | I19: =IFERROR(__xludf.DUMMYFUNCTION("""COMPUTED_VALUE"""),"KUNARTIN") -> KUNARTIN | J19: =IFERROR(__xludf.DUMMYFUNCTION("""COMPUTED_VALUE"""),"CANDITUNGGAL RT 003 RW 002 KALITENGAH LAMONGAN") -> CANDITUNGGAL RT 003 RW 002 KALITENGAH LAMONGAN | K19: =IFERROR(__xludf.DUMMYFUNCTION("""COMPUTED_VALUE"""),"6285815665883") -> 6285815665883 | L19: =IFERROR(__xludf.DUMMYFUNCTION("""COMPUTED_VALUE"""),0.0) -> 0 | M19: =IFERROR(__xludf.DUMMYFUNCTION("""COMPUTED_VALUE"""),0.0) -> 0 | N19: =IFERROR(__xludf.DUMMYFUNCTION("""COMPUTED_VALUE"""),0.0) -> 0 | O19: =IFERROR(__xludf.DUMMYFUNCTION("""COMPUTED_VALUE"""),0.0) -> 0 | S19: =IFERROR(__xludf.DUMMYFUNCTION("""COMPUTED_VALUE"""),"Lunas") -> Lunas | T19: =TODAY() -> 46206 | U19: =IF(ISNA(vlookup(B19,DataExport!$D$2:$D$496,1,false)), "Belum", "Sudah") -> Belum
A20: =IF(B20="","",ROW(A20)-1) -> 19 | B20: =IFERROR(__xludf.DUMMYFUNCTION("""COMPUTED_VALUE"""),"AUFARA DHEA TUNGGA DEWI") -> AUFARA DHEA TUNGGA DEWI | C20: =IFERROR(__xludf.DUMMYFUNCTION("""COMPUTED_VALUE"""),2.02407049E9) -> 2024070490 | D20: =IFERROR(__xludf.DUMMYFUNCTION("""COMPUTED_VALUE"""),"C") -> C | E20: =IFERROR(__xludf.DUMMYFUNCTION("""COMPUTED_VALUE"""),"C-12") -> C-12 | F20: =IFERROR(__xludf.DUMMYFUNCTION("""COMPUTED_VALUE"""),3.0) -> 3 | G20: =IFERROR(__xludf.DUMMYFUNCTION("""COMPUTED_VALUE"""),"3 ULA A PUTRI") -> 3 ULA A PUTRI | H20: =IFERROR(__xludf.DUMMYFUNCTION("""COMPUTED_VALUE"""),"MTS-9 D") -> MTS-9 D | I20: =IFERROR(__xludf.DUMMYFUNCTION("""COMPUTED_VALUE"""),"DEWI UTARI") -> DEWI UTARI | J20: =IFERROR(__xludf.DUMMYFUNCTION("""COMPUTED_VALUE"""),"PRIYOSO WETAN PRIYOSO RT 001 RW 001 KARANGBINANGUN LAMONGAN") -> PRIYOSO WETAN PRIYOSO RT 001 RW 001 KARANGBINANGUN LAMONGAN | K20: =IFERROR(__xludf.DUMMYFUNCTION("""COMPUTED_VALUE"""),"6281334198484") -> 6281334198484 | L20: =IFERROR(__xludf.DUMMYFUNCTION("""COMPUTED_VALUE"""),0.0) -> 0 | M20: =IFERROR(__xludf.DUMMYFUNCTION("""COMPUTED_VALUE"""),0.0) -> 0 | N20: =IFERROR(__xludf.DUMMYFUNCTION("""COMPUTED_VALUE"""),0.0) -> 0 | O20: =IFERROR(__xludf.DUMMYFUNCTION("""COMPUTED_VALUE"""),0.0) -> 0 | S20: =IFERROR(__xludf.DUMMYFUNCTION("""COMPUTED_VALUE"""),"Lunas") -> Lunas | T20: =TODAY() -> 46206 | U20: =IF(ISNA(vlookup(B20,DataExport!$D$2:$D$496,1,false)), "Belum", "Sudah") -> Belum
A21: =IF(B21="","",ROW(A21)-1) -> 20 | B21: =IFERROR(__xludf.DUMMYFUNCTION("""COMPUTED_VALUE"""),"AULIYAH SYIFA WINARNI") -> AULIYAH SYIFA WINARNI | C21: =IFERROR(__xludf.DUMMYFUNCTION("""COMPUTED_VALUE"""),2.024070188E9) -> 2024070188 | D21: =IFERROR(__xludf.DUMMYFUNCTION("""COMPUTED_VALUE"""),"E") -> E | E21: =IFERROR(__xludf.DUMMYFUNCTION("""COMPUTED_VALUE"""),"E-3") -> E-3 | F21: =IFERROR(__xludf.DUMMYFUNCTION("""COMPUTED_VALUE"""),3.0) -> 3 | G21: =IFERROR(__xludf.DUMMYFUNCTION("""COMPUTED_VALUE"""),"3 WUSTHO C PUTRI") -> 3 WUSTHO C PUTRI | H21: =IFERROR(__xludf.DUMMYFUNCTION("""COMPUTED_VALUE"""),"MA-XII.5") -> MA-XII.5 | I21: =IFERROR(__xludf.DUMMYFUNCTION("""COMPUTED_VALUE"""),"RULLY SYAMSI WINARNI") -> RULLY SYAMSI WINARNI | J21: =IFERROR(__xludf.DUMMYFUNCTION("""COMPUTED_VALUE"""),"JL. PEMUDA KLOOFKAMP GURABESI RT 001 RW 005 JAYAPURA UTARA JAYAPURA") -> JL. PEMUDA KLOOFKAMP GURABESI RT 001 RW 005 JAYAPURA UTARA JAYAPURA | K21: =IFERROR(__xludf.DUMMYFUNCTION("""COMPUTED_VALUE"""),"6282248415765") -> 6282248415765 | L21: =IFERROR(__xludf.DUMMYFUNCTION("""COMPUTED_VALUE"""),0.0) -> 0 | M21: =IFERROR(__xludf.DUMMYFUNCTION("""COMPUTED_VALUE"""),0.0) -> 0 | N21: =IFERROR(__xludf.DUMMYFUNCTION("""COMPUTED_VALUE"""),0.0) -> 0 | O21: =IFERROR(__xludf.DUMMYFUNCTION("""COMPUTED_VALUE"""),0.0) -> 0 | S21: =IFERROR(__xludf.DUMMYFUNCTION("""COMPUTED_VALUE"""),"Lunas") -> Lunas | T21: =TODAY() -> 46206 | U21: =IF(ISNA(vlookup(B21,DataExport!$D$2:$D$496,1,false)), "Belum", "Sudah") -> Belum
A22: =IF(B22="","",ROW(A22)-1) -> 21 | B22: =IFERROR(__xludf.DUMMYFUNCTION("""COMPUTED_VALUE"""),"AUREL NUR HABIBATUL LATHIFAH") -> AUREL NUR HABIBATUL LATHIFAH | C22: =IFERROR(__xludf.DUMMYFUNCTION("""COMPUTED_VALUE"""),2.024070498E9) -> 2024070498 | D22: =IFERROR(__xludf.DUMMYFUNCTION("""COMPUTED_VALUE"""),"D") -> D | E22: =IFERROR(__xludf.DUMMYFUNCTION("""COMPUTED_VALUE"""),"D-4") -> D-4 | F22: =IFERROR(__xludf.DUMMYFUNCTION("""COMPUTED_VALUE"""),3.0) -> 3 | H22: =IFERROR(__xludf.DUMMYFUNCTION("""COMPUTED_VALUE"""),"MTS-9 C") -> MTS-9 C | I22: =IFERROR(__xludf.DUMMYFUNCTION("""COMPUTED_VALUE"""),"IMROATUL KHASANAH") -> IMROATUL KHASANAH | J22: =IFERROR(__xludf.DUMMYFUNCTION("""COMPUTED_VALUE"""),"BANJARMADU RT 001 RW 003 KARANGGENENG LAMONGAN") -> BANJARMADU RT 001 RW 003 KARANGGENENG LAMONGAN | K22: =IFERROR(__xludf.DUMMYFUNCTION("""COMPUTED_VALUE"""),"6281226713566") -> 6281226713566 | L22: =IFERROR(__xludf.DUMMYFUNCTION("""COMPUTED_VALUE"""),0.0) -> 0 | M22: =IFERROR(__xludf.DUMMYFUNCTION("""COMPUTED_VALUE"""),0.0) -> 0 | N22: =IFERROR(__xludf.DUMMYFUNCTION("""COMPUTED_VALUE"""),0.0) -> 0 | O22: =IFERROR(__xludf.DUMMYFUNCTION("""COMPUTED_VALUE"""),0.0) -> 0 | S22: =IFERROR(__xludf.DUMMYFUNCTION("""COMPUTED_VALUE"""),"Lunas") -> Lunas | T22: =TODAY() -> 46206 | U22: =IF(ISNA(vlookup(B22,DataExport!$D$2:$D$496,1,false)), "Belum", "Sudah") -> Belum
A23: =IF(B23="","",ROW(A23)-1) -> 22 | B23: =IFERROR(__xludf.DUMMYFUNCTION("""COMPUTED_VALUE"""),"AUVA HILYA LUBABAH") -> AUVA HILYA LUBABAH | C23: =IFERROR(__xludf.DUMMYFUNCTION("""COMPUTED_VALUE"""),2.024070414E9) -> 2024070414 | D23: =IFERROR(__xludf.DUMMYFUNCTION("""COMPUTED_VALUE"""),"C") -> C | E23: =IFERROR(__xludf.DUMMYFUNCTION("""COMPUTED_VALUE"""),"C-7") -> C-7 | F23: =IFERROR(__xludf.DUMMYFUNCTION("""COMPUTED_VALUE"""),3.0) -> 3 | G23: =IFERROR(__xludf.DUMMYFUNCTION("""COMPUTED_VALUE"""),"3 MAK PUTRI") -> 3 MAK PUTRI | H23: =IFERROR(__xludf.DUMMYFUNCTION("""COMPUTED_VALUE"""),"MA-XII.13") -> MA-XII.13 | I23: =IFERROR(__xludf.DUMMYFUNCTION("""COMPUTED_VALUE"""),"RODHIATUN") -> RODHIATUN | J23: =IFERROR(__xludf.DUMMYFUNCTION("""COMPUTED_VALUE"""),"GEDONG GEDONGBOYOUNTUNG RT 001 RW 001 TURI LAMONGAN") -> GEDONG GEDONGBOYOUNTUNG RT 001 RW 001 TURI LAMONGAN | K23: =IFERROR(__xludf.DUMMYFUNCTION("""COMPUTED_VALUE"""),"6285608051421") -> 6285608051421 | L23: =IFERROR(__xludf.DUMMYFUNCTION("""COMPUTED_VALUE"""),0.0) -> 0 | M23: =IFERROR(__xludf.DUMMYFUNCTION("""COMPUTED_VALUE"""),0.0) -> 0 | N23: =IFERROR(__xludf.DUMMYFUNCTION("""COMPUTED_VALUE"""),0.0) -> 0 | O23: =IFERROR(__xludf.DUMMYFUNCTION("""COMPUTED_VALUE"""),0.0) -> 0 | S23: =IFERROR(__xludf.DUMMYFUNCTION("""COMPUTED_VALUE"""),"Lunas") -> Lunas | T23: =TODAY() -> 46206 | U23: =IF(ISNA(vlookup(B23,DataExport!$D$2:$D$496,1,false)), "Belum", "Sudah") -> Belum
A24: =IF(B24="","",ROW(A24)-1) -> 23 | B24: =IFERROR(__xludf.DUMMYFUNCTION("""COMPUTED_VALUE"""),"AYU YOVA NAYLA FAZA") -> AYU YOVA NAYLA FAZA | C24: =IFERROR(__xludf.DUMMYFUNCTION("""COMPUTED_VALUE"""),2.024070039E9) -> 2024070039 | D24: =IFERROR(__xludf.DUMMYFUNCTION("""COMPUTED_VALUE"""),"C") -> C | E24: =IFERROR(__xludf.DUMMYFUNCTION("""COMPUTED_VALUE"""),"C-8") -> C-8 | F24: =IFERROR(__xludf.DUMMYFUNCTION("""COMPUTED_VALUE"""),3.0) -> 3 | G24: =IFERROR(__xludf.DUMMYFUNCTION("""COMPUTED_VALUE"""),"3 WUSTHO A PUTRI") -> 3 WUSTHO A PUTRI | H24: =IFERROR(__xludf.DUMMYFUNCTION("""COMPUTED_VALUE"""),"MA-XII.2") -> MA-XII.2 | I24: =IFERROR(__xludf.DUMMYFUNCTION("""COMPUTED_VALUE"""),"HANIK ASYRIFAH") -> HANIK ASYRIFAH | J24: =IFERROR(__xludf.DUMMYFUNCTION("""COMPUTED_VALUE"""),"DAGAN RT 002 RW 003 SOLOKURO LAMONGAN") -> DAGAN RT 002 RW 003 SOLOKURO LAMONGAN | K24: =IFERROR(__xludf.DUMMYFUNCTION("""COMPUTED_VALUE"""),"6285856022187") -> 6285856022187 | L24: =IFERROR(__xludf.DUMMYFUNCTION("""COMPUTED_VALUE"""),0.0) -> 0 | M24: =IFERROR(__xludf.DUMMYFUNCTION("""COMPUTED_VALUE"""),0.0) -> 0 | N24: =IFERROR(__xludf.DUMMYFUNCTION("""COMPUTED_VALUE"""),0.0) -> 0 | O24: =IFERROR(__xludf.DUMMYFUNCTION("""COMPUTED_VALUE"""),0.0) -> 0 | S24: =IFERROR(__xludf.DUMMYFUNCTION("""COMPUTED_VALUE"""),"Lunas") -> Lunas | T24: =TODAY() -> 46206 | U24: =IF(ISNA(vlookup(B24,DataExport!$D$2:$D$496,1,false)), "Belum", "Sudah") -> Belum
A25: =IF(B25="","",ROW(A25)-1) -> 24 | B25: =IFERROR(__xludf.DUMMYFUNCTION("""COMPUTED_VALUE"""),"AZKA YAFIS FIRMANSYAH") -> AZKA YAFIS FIRMANSYAH | C25: =IFERROR(__xludf.DUMMYFUNCTION("""COMPUTED_VALUE"""),2.024070306E9) -> 2024070306 | D25: =IFERROR(__xludf.DUMMYFUNCTION("""COMPUTED_VALUE"""),"A") -> A | E25: =IFERROR(__xludf.DUMMYFUNCTION("""COMPUTED_VALUE"""),"A-10") -> A-10 | F25: =IFERROR(__xludf.DUMMYFUNCTION("""COMPUTED_VALUE"""),3.0) -> 3 | G25: =IFERROR(__xludf.DUMMYFUNCTION("""COMPUTED_VALUE"""),"3 WUSTHO PUTRA") -> 3 WUSTHO PUTRA | H25: =IFERROR(__xludf.DUMMYFUNCTION("""COMPUTED_VALUE"""),"MA-XII.10") -> MA-XII.10 | I25: =IFERROR(__xludf.DUMMYFUNCTION("""COMPUTED_VALUE"""),"ISWATI") -> ISWATI | J25: =IFERROR(__xludf.DUMMYFUNCTION("""COMPUTED_VALUE"""),"WIDHE SENDANGHARJO RT 006 RW 001 BRONDONG LAMONGAN") -> WIDHE SENDANGHARJO RT 006 RW 001 BRONDONG LAMONGAN | K25: =IFERROR(__xludf.DUMMYFUNCTION("""COMPUTED_VALUE"""),"628585028102") -> 628585028102 | L25: =IFERROR(__xludf.DUMMYFUNCTION("""COMPUTED_VALUE"""),0.0) -> 0 | M25: =IFERROR(__xludf.DUMMYFUNCTION("""COMPUTED_VALUE"""),0.0) -> 0 | N25: =IFERROR(__xludf.DUMMYFUNCTION("""COMPUTED_VALUE"""),0.0) -> 0 | O25: =IFERROR(__xludf.DUMMYFUNCTION("""COMPUTED_VALUE"""),0.0) -> 0 | S25: =IFERROR(__xludf.DUMMYFUNCTION("""COMPUTED_VALUE"""),"Lunas") -> Lunas | T25: =TODAY() -> 46206 | U25: =IF(ISNA(vlookup(B25,DataExport!$D$2:$D$496,1,false)), "Belum", "Sudah") -> Belum
A26: =IF(B26="","",ROW(A26)-1) -> 25 | B26: =IFERROR(__xludf.DUMMYFUNCTION("""COMPUTED_VALUE"""),"CALLYSTA QOWIM AZ-ZAHRA") -> CALLYSTA QOWIM AZ-ZAHRA | C26: =IFERROR(__xludf.DUMMYFUNCTION("""COMPUTED_VALUE"""),2.024070489E9) -> 2024070489 | D26: =IFERROR(__xludf.DUMMYFUNCTION("""COMPUTED_VALUE"""),"C") -> C | E26: =IFERROR(__xludf.DUMMYFUNCTION("""COMPUTED_VALUE"""),"C-13") -> C-13 | F26: =IFERROR(__xludf.DUMMYFUNCTION("""COMPUTED_VALUE"""),3.0) -> 3 | G26: =IFERROR(__xludf.DUMMYFUNCTION("""COMPUTED_VALUE"""),"3 ULA A PUTRI") -> 3 ULA A PUTRI | H26: =IFERROR(__xludf.DUMMYFUNCTION("""COMPUTED_VALUE"""),"MTS-9 G") -> MTS-9 G | I26: =IFERROR(__xludf.DUMMYFUNCTION("""COMPUTED_VALUE"""),"NUR HIDAYATI") -> NUR HIDAYATI | J26: =IFERROR(__xludf.DUMMYFUNCTION("""COMPUTED_VALUE"""),"PAJI RT 002 RW 005 PUCUK LAMONGAN") -> PAJI RT 002 RW 005 PUCUK LAMONGAN | K26: =IFERROR(__xludf.DUMMYFUNCTION("""COMPUTED_VALUE"""),"2682131710998") -> 2682131710998 | L26: =IFERROR(__xludf.DUMMYFUNCTION("""COMPUTED_VALUE"""),0.0) -> 0 | M26: =IFERROR(__xludf.DUMMYFUNCTION("""COMPUTED_VALUE"""),0.0) -> 0 | N26: =IFERROR(__xludf.DUMMYFUNCTION("""COMPUTED_VALUE"""),0.0) -> 0 | O26: =IFERROR(__xludf.DUMMYFUNCTION("""COMPUTED_VALUE"""),0.0) -> 0 | S26: =IFERROR(__xludf.DUMMYFUNCTION("""COMPUTED_VALUE"""),"Lunas") -> Lunas | T26: =TODAY() -> 46206 | U26: =IF(ISNA(vlookup(B26,DataExport!$D$2:$D$496,1,false)), "Belum", "Sudah") -> Belum
A27: =IF(B27="","",ROW(A27)-1) -> 26 | B27: =IFERROR(__xludf.DUMMYFUNCTION("""COMPUTED_VALUE"""),"CANTIKA ASSYARIFIYAH") -> CANTIKA ASSYARIFIYAH | C27: =IFERROR(__xludf.DUMMYFUNCTION("""COMPUTED_VALUE"""),2.024070069E9) -> 2024070069 | D27: =IFERROR(__xludf.DUMMYFUNCTION("""COMPUTED_VALUE"""),"D") -> D | E27: =IFERROR(__xludf.DUMMYFUNCTION("""COMPUTED_VALUE"""),"D-6") -> D-6 | F27: =IFERROR(__xludf.DUMMYFUNCTION("""COMPUTED_VALUE"""),3.0) -> 3 | G27: =IFERROR(__xludf.DUMMYFUNCTION("""COMPUTED_VALUE"""),"3 WUSTHO C PUTRI") -> 3 WUSTHO C PUTRI | H27: =IFERROR(__xludf.DUMMYFUNCTION("""COMPUTED_VALUE"""),"MA-XII.3") -> MA-XII.3 | I27: =IFERROR(__xludf.DUMMYFUNCTION("""COMPUTED_VALUE"""),"SITI MARWIYA") -> SITI MARWIYA | J27: =IFERROR(__xludf.DUMMYFUNCTION("""COMPUTED_VALUE"""),"NGAMBEG RT 1 RW 1 PUCUK LAMONGAN") -> NGAMBEG RT 1 RW 1 PUCUK LAMONGAN | K27: =IFERROR(__xludf.DUMMYFUNCTION("""COMPUTED_VALUE"""),"6285706485182") -> 6285706485182 | L27: =IFERROR(__xludf.DUMMYFUNCTION("""COMPUTED_VALUE"""),0.0) -> 0 | M27: =IFERROR(__xludf.DUMMYFUNCTION("""COMPUTED_VALUE"""),0.0) -> 0 | N27: =IFERROR(__xludf.DUMMYFUNCTION("""COMPUTED_VALUE"""),0.0) -> 0 | O27: =IFERROR(__xludf.DUMMYFUNCTION("""COMPUTED_VALUE"""),0.0) -> 0 | S27: =IFERROR(__xludf.DUMMYFUNCTION("""COMPUTED_VALUE"""),"Lunas") -> Lunas | T27: =TODAY() -> 46206 | U27: =IF(ISNA(vlookup(B27,DataExport!$D$2:$D$496,1,false)), "Belum", "Sudah") -> Belum
A28: =IF(B28="","",ROW(A28)-1) -> 27 | B28: =IFERROR(__xludf.DUMMYFUNCTION("""COMPUTED_VALUE"""),"CELENA FEBRIANA") -> CELENA FEBRIANA | C28: =IFERROR(__xludf.DUMMYFUNCTION("""COMPUTED_VALUE"""),2.024070471E9) -> 2024070471 | D28: =IFERROR(__xludf.DUMMYFUNCTION("""COMPUTED_VALUE"""),"D") -> D | E28: =IFERROR(__xludf.DUMMYFUNCTION("""COMPUTED_VALUE"""),"D-4") -> D-4 | F28: =IFERROR(__xludf.DUMMYFUNCTION("""COMPUTED_VALUE"""),3.0) -> 3 | G28: =IFERROR(__xludf.DUMMYFUNCTION("""COMPUTED_VALUE"""),"3 ULA A PUTRI") -> 3 ULA A PUTRI | H28: =IFERROR(__xludf.DUMMYFUNCTION("""COMPUTED_VALUE"""),"MTS-9 C") -> MTS-9 C | I28: =IFERROR(__xludf.DUMMYFUNCTION("""COMPUTED_VALUE"""),"EKA FITRIANA") -> EKA FITRIANA | J28: =IFERROR(__xludf.DUMMYFUNCTION("""COMPUTED_VALUE"""),"KEBUN MANGGA TANGGUNGAN RT 003 RW 006 PUCUK LAMONGAN") -> KEBUN MANGGA TANGGUNGAN RT 003 RW 006 PUCUK LAMONGAN | K28: =IFERROR(__xludf.DUMMYFUNCTION("""COMPUTED_VALUE"""),"6285843744198") -> 6285843744198 | L28: =IFERROR(__xludf.DUMMYFUNCTION("""COMPUTED_VALUE"""),0.0) -> 0 | M28: =IFERROR(__xludf.DUMMYFUNCTION("""COMPUTED_VALUE"""),0.0) -> 0 | N28: =IFERROR(__xludf.DUMMYFUNCTION("""COMPUTED_VALUE"""),0.0) -> 0 | O28: =IFERROR(__xludf.DUMMYFUNCTION("""COMPUTED_VALUE"""),0.0) -> 0 | S28: =IFERROR(__xludf.DUMMYFUNCTION("""COMPUTED_VALUE"""),"Lunas") -> Lunas | T28: =TODAY() -> 46206 | U28: =IF(ISNA(vlookup(B28,DataExport!$D$2:$D$496,1,false)), "Belum", "Sudah") -> Belum
A29: =IF(B29="","",ROW(A29)-1) -> 28 | B29: =IFERROR(__xludf.DUMMYFUNCTION("""COMPUTED_VALUE"""),"CERLITA VANIA NUGRAHENI") -> CERLITA VANIA NUGRAHENI | C29: =IFERROR(__xludf.DUMMYFUNCTION("""COMPUTED_VALUE"""),2.024070107E9) -> 2024070107 | D29: =IFERROR(__xludf.DUMMYFUNCTION("""COMPUTED_VALUE"""),"C") -> C | E29: =IFERROR(__xludf.DUMMYFUNCTION("""COMPUTED_VALUE"""),"C-9") -> C-9 | F29: =IFERROR(__xludf.DUMMYFUNCTION("""COMPUTED_VALUE"""),3.0) -> 3 | H29: =IFERROR(__xludf.DUMMYFUNCTION("""COMPUTED_VALUE"""),"MA-XII.4") -> MA-XII.4 | I29: =IFERROR(__xludf.DUMMYFUNCTION("""COMPUTED_VALUE"""),"LILIS SUJIATI") -> LILIS SUJIATI | J29: =IFERROR(__xludf.DUMMYFUNCTION("""COMPUTED_VALUE"""),"KULURAN RT 004 RW 002 KALITENGAH LAMONGAN") -> KULURAN RT 004 RW 002 KALITENGAH LAMONGAN | K29: =IFERROR(__xludf.DUMMYFUNCTION("""COMPUTED_VALUE"""),"628563025554") -> 628563025554 | L29: =IFERROR(__xludf.DUMMYFUNCTION("""COMPUTED_VALUE"""),0.0) -> 0 | M29: =IFERROR(__xludf.DUMMYFUNCTION("""COMPUTED_VALUE"""),0.0) -> 0 | N29: =IFERROR(__xludf.DUMMYFUNCTION("""COMPUTED_VALUE"""),0.0) -> 0 | O29: =IFERROR(__xludf.DUMMYFUNCTION("""COMPUTED_VALUE"""),0.0) -> 0 | S29: =IFERROR(__xludf.DUMMYFUNCTION("""COMPUTED_VALUE"""),"Lunas") -> Lunas | T29: =TODAY() -> 46206 | U29: =IF(ISNA(vlookup(B29,DataExport!$D$2:$D$496,1,false)), "Belum", "Sudah") -> Belum
A30: =IF(B30="","",ROW(A30)-1) -> 29 | B30: =IFERROR(__xludf.DUMMYFUNCTION("""COMPUTED_VALUE"""),"CHARISA WANIDYA UTAMA HARTONO") -> CHARISA WANIDYA UTAMA HARTONO | C30: =IFERROR(__xludf.DUMMYFUNCTION("""COMPUTED_VALUE"""),2.024070476E9) -> 2024070476 | D30: =IFERROR(__xludf.DUMMYFUNCTION("""COMPUTED_VALUE"""),"E") -> E | E30: =IFERROR(__xludf.DUMMYFUNCTION("""COMPUTED_VALUE"""),"E-9") -> E-9 | F30: =IFERROR(__xludf.DUMMYFUNCTION("""COMPUTED_VALUE"""),3.0) -> 3 | G30: =IFERROR(__xludf.DUMMYFUNCTION("""COMPUTED_VALUE"""),"3 ULA A PUTRI") -> 3 ULA A PUTRI | H30: =IFERROR(__xludf.DUMMYFUNCTION("""COMPUTED_VALUE"""),"MTS-9 A") -> MTS-9 A | I30: =IFERROR(__xludf.DUMMYFUNCTION("""COMPUTED_VALUE"""),"AINUL ISNAENI") -> AINUL ISNAENI | J30: =IFERROR(__xludf.DUMMYFUNCTION("""COMPUTED_VALUE"""),"MULUNG KARANGTINGGIL RT 002 RW 001 PUCUK LAMONGAN") -> MULUNG KARANGTINGGIL RT 002 RW 001 PUCUK LAMONGAN | K30: =IFERROR(__xludf.DUMMYFUNCTION("""COMPUTED_VALUE"""),"6282234537281") -> 6282234537281 | L30: =IFERROR(__xludf.DUMMYFUNCTION("""COMPUTED_VALUE"""),0.0) -> 0 | M30: =IFERROR(__xludf.DUMMYFUNCTION("""COMPUTED_VALUE"""),0.0) -> 0 | N30: =IFERROR(__xludf.DUMMYFUNCTION("""COMPUTED_VALUE"""),0.0) -> 0 | O30: =IFERROR(__xludf.DUMMYFUNCTION("""COMPUTED_VALUE"""),0.0) -> 0 | S30: =IFERROR(__xludf.DUMMYFUNCTION("""COMPUTED_VALUE"""),"Lunas") -> Lunas | T30: =TODAY() -> 46206 | U30: =IF(ISNA(vlookup(B30,DataExport!$D$2:$D$496,1,false)), "Belum", "Sudah") -> Belum
A31: =IF(B31="","",ROW(A31)-1) -> 30 | B31: =IFERROR(__xludf.DUMMYFUNCTION("""COMPUTED_VALUE"""),"DIMAS ALFIAN SAPUTRA") -> DIMAS ALFIAN SAPUTRA | C31: =IFERROR(__xludf.DUMMYFUNCTION("""COMPUTED_VALUE"""),2.024070655E9) -> 2024070655 | D31: =IFERROR(__xludf.DUMMYFUNCTION("""COMPUTED_VALUE"""),"A") -> A | E31: =IFERROR(__xludf.DUMMYFUNCTION("""COMPUTED_VALUE"""),"A-7") -> A-7 | F31: =IFERROR(__xludf.DUMMYFUNCTION("""COMPUTED_VALUE"""),3.0) -> 3 | G31: =IFERROR(__xludf.DUMMYFUNCTION("""COMPUTED_VALUE"""),"3 ULA A PUTRA") -> 3 ULA A PUTRA | H31: =IFERROR(__xludf.DUMMYFUNCTION("""COMPUTED_VALUE"""),"MTS-9 F") -> MTS-9 F | I31: =IFERROR(__xludf.DUMMYFUNCTION("""COMPUTED_VALUE"""),"MAHZUMAH") -> MAHZUMAH | J31: =IFERROR(__xludf.DUMMYFUNCTION("""COMPUTED_VALUE"""),"WEDENG SUKOREJO RT 001 RW 002 KARANGBINANGUN LAMONGAN") -> WEDENG SUKOREJO RT 001 RW 002 KARANGBINANGUN LAMONGAN | K31: =IFERROR(__xludf.DUMMYFUNCTION("""COMPUTED_VALUE"""),"6285855732030") -> 6285855732030 | L31: =IFERROR(__xludf.DUMMYFUNCTION("""COMPUTED_VALUE"""),0.0) -> 0 | M31: =IFERROR(__xludf.DUMMYFUNCTION("""COMPUTED_VALUE"""),0.0) -> 0 | N31: =IFERROR(__xludf.DUMMYFUNCTION("""COMPUTED_VALUE"""),0.0) -> 0 | O31: =IFERROR(__xludf.DUMMYFUNCTION("""COMPUTED_VALUE"""),0.0) -> 0 | S31: =IFERROR(__xludf.DUMMYFUNCTION("""COMPUTED_VALUE"""),"Lunas") -> Lunas | T31: =TODAY() -> 46206 | U31: =IF(ISNA(vlookup(B31,DataExport!$D$2:$D$496,1,false)), "Belum", "Sudah") -> Belum
A32: =IF(B32="","",ROW(A32)-1) -> 31 | B32: =IFERROR(__xludf.DUMMYFUNCTION("""COMPUTED_VALUE"""),"DIMAS PRATAMA ARIYANTO") -> DIMAS PRATAMA ARIYANTO | C32: =IFERROR(__xludf.DUMMYFUNCTION("""COMPUTED_VALUE"""),2.024070444E9) -> 2024070444 | D32: =IFERROR(__xludf.DUMMYFUNCTION("""COMPUTED_VALUE"""),"A") -> A | E32: =IFERROR(__xludf.DUMMYFUNCTION("""COMPUTED_VALUE"""),"A-8") -> A-8 | F32: =IFERROR(__xludf.DUMMYFUNCTION("""COMPUTED_VALUE"""),3.0) -> 3 | G32: =IFERROR(__xludf.DUMMYFUNCTION("""COMPUTED_VALUE"""),"3 ULA A PUTRA") -> 3 ULA A PUTRA | H32: =IFERROR(__xludf.DUMMYFUNCTION("""COMPUTED_VALUE"""),"MTS-9 E") -> MTS-9 E | I32: =IFERROR(__xludf.DUMMYFUNCTION("""COMPUTED_VALUE"""),"YAYUK ERNAWATI") -> YAYUK ERNAWATI | J32: =IFERROR(__xludf.DUMMYFUNCTION("""COMPUTED_VALUE"""),"SUKOWATI SUKOSONGO RT 017 RW 008 KEMBANGBAHU LAMONGAN") -> SUKOWATI SUKOSONGO RT 017 RW 008 KEMBANGBAHU LAMONGAN | K32: =IFERROR(__xludf.DUMMYFUNCTION("""COMPUTED_VALUE"""),"6281515026997") -> 6281515026997 | L32: =IFERROR(__xludf.DUMMYFUNCTION("""COMPUTED_VALUE"""),0.0) -> 0 | M32: =IFERROR(__xludf.DUMMYFUNCTION("""COMPUTED_VALUE"""),0.0) -> 0 | N32: =IFERROR(__xludf.DUMMYFUNCTION("""COMPUTED_VALUE"""),0.0) -> 0 | O32: =IFERROR(__xludf.DUMMYFUNCTION("""COMPUTED_VALUE"""),0.0) -> 0 | S32: =IFERROR(__xludf.DUMMYFUNCTION("""COMPUTED_VALUE"""),"Lunas") -> Lunas | T32: =TODAY() -> 46206 | U32: =IF(ISNA(vlookup(B32,DataExport!$D$2:$D$496,1,false)), "Belum", "Sudah") -> Belum
A33: =IF(B33="","",ROW(A33)-1) -> 32 | B33: =IFERROR(__xludf.DUMMYFUNCTION("""COMPUTED_VALUE"""),"DINDA FAIZIRAH ZAHROTUS SITA") -> DINDA FAIZIRAH ZAHROTUS SITA | C33: =IFERROR(__xludf.DUMMYFUNCTION("""COMPUTED_VALUE"""),2.024070005E9) -> 2024070005 | D33: =IFERROR(__xludf.DUMMYFUNCTION("""COMPUTED_VALUE"""),"D") -> D | E33: =IFERROR(__xludf.DUMMYFUNCTION("""COMPUTED_VALUE"""),"D-7") -> D-7 | F33: =IFERROR(__xludf.DUMMYFUNCTION("""COMPUTED_VALUE"""),3.0) -> 3 | H33: =IFERROR(__xludf.DUMMYFUNCTION("""COMPUTED_VALUE"""),"MA-XII.1") -> MA-XII.1 | I33: =IFERROR(__xludf.DUMMYFUNCTION("""COMPUTED_VALUE"""),"WIWIN WINARTIN") -> WIWIN WINARTIN | J33: =IFERROR(__xludf.DUMMYFUNCTION("""COMPUTED_VALUE"""),"SUNGELEBAK RT 5 RW 2 KARANGGENENG LAMONGAN") -> SUNGELEBAK RT 5 RW 2 KARANGGENENG LAMONGAN | K33: =IFERROR(__xludf.DUMMYFUNCTION("""COMPUTED_VALUE"""),"628563468694") -> 628563468694 | L33: =IFERROR(__xludf.DUMMYFUNCTION("""COMPUTED_VALUE"""),0.0) -> 0 | M33: =IFERROR(__xludf.DUMMYFUNCTION("""COMPUTED_VALUE"""),0.0) -> 0 | N33: =IFERROR(__xludf.DUMMYFUNCTION("""COMPUTED_VALUE"""),0.0) -> 0 | O33: =IFERROR(__xludf.DUMMYFUNCTION("""COMPUTED_VALUE"""),0.0) -> 0 | S33: =IFERROR(__xludf.DUMMYFUNCTION("""COMPUTED_VALUE"""),"Lunas") -> Lunas | T33: =TODAY() -> 46206 | U33: =IF(ISNA(vlookup(B33,DataExport!$D$2:$D$496,1,false)), "Belum", "Sudah") -> Belum
A34: =IF(B34="","",ROW(A34)-1) -> 33 | B34: =IFERROR(__xludf.DUMMYFUNCTION("""COMPUTED_VALUE"""),"DZUN NUHA MAHMUDAH") -> DZUN NUHA MAHMUDAH | C34: =IFERROR(__xludf.DUMMYFUNCTION("""COMPUTED_VALUE"""),2.024070042E9) -> 2024070042 | D34: =IFERROR(__xludf.DUMMYFUNCTION("""COMPUTED_VALUE"""),"B") -> B | F34: =IFERROR(__xludf.DUMMYFUNCTION("""COMPUTED_VALUE"""),3.0) -> 3 | G34: =IFERROR(__xludf.DUMMYFUNCTION("""COMPUTED_VALUE"""),"3 WUSTHO B PUTRI") -> 3 WUSTHO B PUTRI | H34: =IFERROR(__xludf.DUMMYFUNCTION("""COMPUTED_VALUE"""),"MA-XII.2") -> MA-XII.2 | I34: =IFERROR(__xludf.DUMMYFUNCTION("""COMPUTED_VALUE"""),"SRIATUN") -> SRIATUN | J34: =IFERROR(__xludf.DUMMYFUNCTION("""COMPUTED_VALUE"""),"MENGAI SUKOREJO RT 2 RW 5 KARANGBINANGUN LAMONGAN") -> MENGAI SUKOREJO RT 2 RW 5 KARANGBINANGUN LAMONGAN | K34: =IFERROR(__xludf.DUMMYFUNCTION("""COMPUTED_VALUE"""),"6285604191924") -> 6285604191924 | L34: =IFERROR(__xludf.DUMMYFUNCTION("""COMPUTED_VALUE"""),0.0) -> 0 | M34: =IFERROR(__xludf.DUMMYFUNCTION("""COMPUTED_VALUE"""),0.0) -> 0 | N34: =IFERROR(__xludf.DUMMYFUNCTION("""COMPUTED_VALUE"""),0.0) -> 0 | O34: =IFERROR(__xludf.DUMMYFUNCTION("""COMPUTED_VALUE"""),0.0) -> 0 | S34: =IFERROR(__xludf.DUMMYFUNCTION("""COMPUTED_VALUE"""),"Lunas") -> Lunas | T34: =TODAY() -> 46206 | U34: =IF(ISNA(vlookup(B34,DataExport!$D$2:$D$496,1,false)), "Belum", "Sudah") -> Belum
A35: =IF(B35="","",ROW(A35)-1) -> 34 | B35: =IFERROR(__xludf.DUMMYFUNCTION("""COMPUTED_VALUE"""),"ELZA AMELIA FIRDA") -> ELZA AMELIA FIRDA | C35: =IFERROR(__xludf.DUMMYFUNCTION("""COMPUTED_VALUE"""),2.024071523E9) -> 2024071523 | D35: =IFERROR(__xludf.DUMMYFUNCTION("""COMPUTED_VALUE"""),"D") -> D | E35: =IFERROR(__xludf.DUMMYFUNCTION("""COMPUTED_VALUE"""),"D-7") -> D-7 | F35: =IFERROR(__xludf.DUMMYFUNCTION("""COMPUTED_VALUE"""),3.0) -> 3 | G35: =IFERROR(__xludf.DUMMYFUNCTION("""COMPUTED_VALUE"""),"3 ULA C PUTRI") -> 3 ULA C PUTRI | H35: =IFERROR(__xludf.DUMMYFUNCTION("""COMPUTED_VALUE"""),"MTS-9 A") -> MTS-9 A | I35: =IFERROR(__xludf.DUMMYFUNCTION("""COMPUTED_VALUE"""),"RUKAMAH") -> RUKAMAH | J35: =IFERROR(__xludf.DUMMYFUNCTION("""COMPUTED_VALUE"""),"SUNGELEBAK RT 014 RW 004 KARANGGENENG LAMONGAN") -> SUNGELEBAK RT 014 RW 004 KARANGGENENG LAMONGAN | K35: =IFERROR(__xludf.DUMMYFUNCTION("""COMPUTED_VALUE"""),"6285749766177") -> 6285749766177 | L35: =IFERROR(__xludf.DUMMYFUNCTION("""COMPUTED_VALUE"""),0.0) -> 0 | M35: =IFERROR(__xludf.DUMMYFUNCTION("""COMPUTED_VALUE"""),0.0) -> 0 | N35: =IFERROR(__xludf.DUMMYFUNCTION("""COMPUTED_VALUE"""),0.0) -> 0 | O35: =IFERROR(__xludf.DUMMYFUNCTION("""COMPUTED_VALUE"""),0.0) -> 0 | S35: =IFERROR(__xludf.DUMMYFUNCTION("""COMPUTED_VALUE"""),"Lunas") -> Lunas | T35: =TODAY() -> 46206 | U35: =IF(ISNA(vlookup(B35,DataExport!$D$2:$D$496,1,false)), "Belum", "Sudah") -> Belum
A36: =IF(B36="","",ROW(A36)-1) -> 35 | B36: =IFERROR(__xludf.DUMMYFUNCTION("""COMPUTED_VALUE"""),"EZZAR RADITYA PUTRA RAMADHAN") -> EZZAR RADITYA PUTRA RAMADHAN | C36: =IFERROR(__xludf.DUMMYFUNCTION("""COMPUTED_VALUE"""),2.024070639E9) -> 2024070639 | D36: =IFERROR(__xludf.DUMMYFUNCTION("""COMPUTED_VALUE"""),"A") -> A | E36: =IFERROR(__xludf.DUMMYFUNCTION("""COMPUTED_VALUE"""),"A-8") -> A-8 | F36: =IFERROR(__xludf.DUMMYFUNCTION("""COMPUTED_VALUE"""),3.0) -> 3 | G36: =IFERROR(__xludf.DUMMYFUNCTION("""COMPUTED_VALUE"""),"3 ULA A PUTRA") -> 3 ULA A PUTRA | H36: =IFERROR(__xludf.DUMMYFUNCTION("""COMPUTED_VALUE"""),"MTS-9 B") -> MTS-9 B | I36: =IFERROR(__xludf.DUMMYFUNCTION("""COMPUTED_VALUE"""),"NUR AINI") -> NUR AINI | J36: =IFERROR(__xludf.DUMMYFUNCTION("""COMPUTED_VALUE"""),"PUCANGRO RT 002 RW 001 KALITENGAH LAMONGAN") -> PUCANGRO RT 002 RW 001 KALITENGAH LAMONGAN | K36: =IFERROR(__xludf.DUMMYFUNCTION("""COMPUTED_VALUE"""),"6285707124359") -> 6285707124359 | L36: =IFERROR(__xludf.DUMMYFUNCTION("""COMPUTED_VALUE"""),0.0) -> 0 | M36: =IFERROR(__xludf.DUMMYFUNCTION("""COMPUTED_VALUE"""),0.0) -> 0 | N36: =IFERROR(__xludf.DUMMYFUNCTION("""COMPUTED_VALUE"""),0.0) -> 0 | O36: =IFERROR(__xludf.DUMMYFUNCTION("""COMPUTED_VALUE"""),0.0) -> 0 | S36: =IFERROR(__xludf.DUMMYFUNCTION("""COMPUTED_VALUE"""),"Lunas") -> Lunas | T36: =TODAY() -> 46206 | U36: =IF(ISNA(vlookup(B36,DataExport!$D$2:$D$496,1,false)), "Belum", "Sudah") -> Belum
A37: =IF(B37="","",ROW(A37)-1) -> 36 | B37: =IFERROR(__xludf.DUMMYFUNCTION("""COMPUTED_VALUE"""),"FAHDINA ZAHRA RAMADHANI") -> FAHDINA ZAHRA RAMADHANI | C37: =IFERROR(__xludf.DUMMYFUNCTION("""COMPUTED_VALUE"""),2.024070514E9) -> 2024070514 | D37: =IFERROR(__xludf.DUMMYFUNCTION("""COMPUTED_VALUE"""),"B") -> B | E37: =IFERROR(__xludf.DUMMYFUNCTION("""COMPUTED_VALUE"""),"B-9") -> B-9 | F37: =IFERROR(__xludf.DUMMYFUNCTION("""COMPUTED_VALUE"""),3.0) -> 3 | G37: =IFERROR(__xludf.DUMMYFUNCTION("""COMPUTED_VALUE"""),"3 ULA B PUTRI") -> 3 ULA B PUTRI | H37: =IFERROR(__xludf.DUMMYFUNCTION("""COMPUTED_VALUE"""),"MTS-9 C") -> MTS-9 C | I37: =IFERROR(__xludf.DUMMYFUNCTION("""COMPUTED_VALUE"""),"DEFI NUR CHUSAINI") -> DEFI NUR CHUSAINI | J37: =IFERROR(__xludf.DUMMYFUNCTION("""COMPUTED_VALUE"""),"SIDOMULYO RT 004 RW 003 DEKET LAMONGAN") -> SIDOMULYO RT 004 RW 003 DEKET LAMONGAN | K37: =IFERROR(__xludf.DUMMYFUNCTION("""COMPUTED_VALUE"""),"6285748441057") -> 6285748441057 | L37: =IFERROR(__xludf.DUMMYFUNCTION("""COMPUTED_VALUE"""),0.0) -> 0 | M37: =IFERROR(__xludf.DUMMYFUNCTION("""COMPUTED_VALUE"""),0.0) -> 0 | N37: =IFERROR(__xludf.DUMMYFUNCTION("""COMPUTED_VALUE"""),0.0) -> 0 | O37: =IFERROR(__xludf.DUMMYFUNCTION("""COMPUTED_VALUE"""),0.0) -> 0 | S37: =IFERROR(__xludf.DUMMYFUNCTION("""COMPUTED_VALUE"""),"Lunas") -> Lunas | T37: =TODAY() -> 46206 | U37: =IF(ISNA(vlookup(B37,DataExport!$D$2:$D$496,1,false)), "Belum", "Sudah") -> Belum
A38: =IF(B38="","",ROW(A38)-1) -> 37 | B38: =IFERROR(__xludf.DUMMYFUNCTION("""COMPUTED_VALUE"""),"FARIKHTA RAMADHANI RIDWAN") -> FARIKHTA RAMADHANI RIDWAN | C38: =IFERROR(__xludf.DUMMYFUNCTION("""COMPUTED_VALUE"""),2.024070043E9) -> 2024070043 | D38: =IFERROR(__xludf.DUMMYFUNCTION("""COMPUTED_VALUE"""),"C") -> C | E38: =IFERROR(__xludf.DUMMYFUNCTION("""COMPUTED_VALUE"""),"C-8") -> C-8 | F38: =IFERROR(__xludf.DUMMYFUNCTION("""COMPUTED_VALUE"""),3.0) -> 3 | H38: =IFERROR(__xludf.DUMMYFUNCTION("""COMPUTED_VALUE"""),"MA-XII.2") -> MA-XII.2 | I38: =IFERROR(__xludf.DUMMYFUNCTION("""COMPUTED_VALUE"""),"YENI KHUSNIYAH") -> YENI KHUSNIYAH | J38: =IFERROR(__xludf.DUMMYFUNCTION("""COMPUTED_VALUE"""),"PEGANDEN PALACE PEGANDEN RT 3 RW 7 MANYAR GRESIK") -> PEGANDEN PALACE PEGANDEN RT 3 RW 7 MANYAR GRESIK | K38: =IFERROR(__xludf.DUMMYFUNCTION("""COMPUTED_VALUE"""),"6283856686322") -> 6283856686322 | L38: =IFERROR(__xludf.DUMMYFUNCTION("""COMPUTED_VALUE"""),0.0) -> 0 | M38: =IFERROR(__xludf.DUMMYFUNCTION("""COMPUTED_VALUE"""),0.0) -> 0 | N38: =IFERROR(__xludf.DUMMYFUNCTION("""COMPUTED_VALUE"""),0.0) -> 0 | O38: =IFERROR(__xludf.DUMMYFUNCTION("""COMPUTED_VALUE"""),0.0) -> 0 | S38: =IFERROR(__xludf.DUMMYFUNCTION("""COMPUTED_VALUE"""),"Lunas") -> Lunas | T38: =TODAY() -> 46206 | U38: =IF(ISNA(vlookup(B38,DataExport!$D$2:$D$496,1,false)), "Belum", "Sudah") -> Belum
A39: =IF(B39="","",ROW(A39)-1) -> 38 | B39: =IFERROR(__xludf.DUMMYFUNCTION("""COMPUTED_VALUE"""),"FATHIMAH ANNAJWA") -> FATHIMAH ANNAJWA | C39: =IFERROR(__xludf.DUMMYFUNCTION("""COMPUTED_VALUE"""),2.02407042E9) -> 2024070420 | D39: =IFERROR(__xludf.DUMMYFUNCTION("""COMPUTED_VALUE"""),"C") -> C | E39: =IFERROR(__xludf.DUMMYFUNCTION("""COMPUTED_VALUE"""),"C-7") -> C-7 | F39: =IFERROR(__xludf.DUMMYFUNCTION("""COMPUTED_VALUE"""),3.0) -> 3 | G39: =IFERROR(__xludf.DUMMYFUNCTION("""COMPUTED_VALUE"""),"3 MAK PUTRI") -> 3 MAK PUTRI | H39: =IFERROR(__xludf.DUMMYFUNCTION("""COMPUTED_VALUE"""),"MA-XII.13") -> MA-XII.13 | I39: =IFERROR(__xludf.DUMMYFUNCTION("""COMPUTED_VALUE"""),"MARIYATUL QIBTIYAH") -> MARIYATUL QIBTIYAH | J39: =IFERROR(__xludf.DUMMYFUNCTION("""COMPUTED_VALUE"""),"TAMBAKREJO RT 005 RW 001 DUDUK SAMPEYAN GRESIK") -> TAMBAKREJO RT 005 RW 001 DUDUK SAMPEYAN GRESIK | K39: =IFERROR(__xludf.DUMMYFUNCTION("""COMPUTED_VALUE"""),"6282132397918") -> 6282132397918 | L39: =IFERROR(__xludf.DUMMYFUNCTION("""COMPUTED_VALUE"""),0.0) -> 0 | M39: =IFERROR(__xludf.DUMMYFUNCTION("""COMPUTED_VALUE"""),0.0) -> 0 | N39: =IFERROR(__xludf.DUMMYFUNCTION("""COMPUTED_VALUE"""),0.0) -> 0 | O39: =IFERROR(__xludf.DUMMYFUNCTION("""COMPUTED_VALUE"""),0.0) -> 0 | S39: =IFERROR(__xludf.DUMMYFUNCTION("""COMPUTED_VALUE"""),"Lunas") -> Lunas | T39: =TODAY() -> 46206 | U39: =IF(ISNA(vlookup(B39,DataExport!$D$2:$D$496,1,false)), "Belum", "Sudah") -> Belum
A40: =IF(B40="","",ROW(A40)-1) -> 39 | B40: =IFERROR(__xludf.DUMMYFUNCTION("""COMPUTED_VALUE"""),"FITHRIYATUL MAULIDAH") -> FITHRIYATUL MAULIDAH | C40: =IFERROR(__xludf.DUMMYFUNCTION("""COMPUTED_VALUE"""),2.024070546E9) -> 2024070546 | D40: =IFERROR(__xludf.DUMMYFUNCTION("""COMPUTED_VALUE"""),"E") -> E | E40: =IFERROR(__xludf.DUMMYFUNCTION("""COMPUTED_VALUE"""),"E-3") -> E-3 | F40: =IFERROR(__xludf.DUMMYFUNCTION("""COMPUTED_VALUE"""),3.0) -> 3 | G40: =IFERROR(__xludf.DUMMYFUNCTION("""COMPUTED_VALUE"""),"3 ULA B PUTRI") -> 3 ULA B PUTRI | H40: =IFERROR(__xludf.DUMMYFUNCTION("""COMPUTED_VALUE"""),"MTS-9 H") -> MTS-9 H | I40: =IFERROR(__xludf.DUMMYFUNCTION("""COMPUTED_VALUE"""),"MAHWIYAH") -> MAHWIYAH | J40: =IFERROR(__xludf.DUMMYFUNCTION("""COMPUTED_VALUE"""),"KALIREJO RT 003 RW 002 DUKUN GRESIK") -> KALIREJO RT 003 RW 002 DUKUN GRESIK | K40: =IFERROR(__xludf.DUMMYFUNCTION("""COMPUTED_VALUE"""),"6282257167881") -> 6282257167881 | L40: =IFERROR(__xludf.DUMMYFUNCTION("""COMPUTED_VALUE"""),0.0) -> 0 | M40: =IFERROR(__xludf.DUMMYFUNCTION("""COMPUTED_VALUE"""),0.0) -> 0 | N40: =IFERROR(__xludf.DUMMYFUNCTION("""COMPUTED_VALUE"""),0.0) -> 0 | O40: =IFERROR(__xludf.DUMMYFUNCTION("""COMPUTED_VALUE"""),0.0) -> 0 | S40: =IFERROR(__xludf.DUMMYFUNCTION("""COMPUTED_VALUE"""),"Lunas") -> Lunas | T40: =TODAY() -> 46206 | U40: =IF(ISNA(vlookup(B40,DataExport!$D$2:$D$496,1,false)), "Belum", "Sudah") -> Belum
...

Sheet TemplateWABulk
A1: No | B1: ID | C1: Link | D1: Hiperlink | E1: Timestamp | F1: Whatsapp
A2: =IF(B2="","",ROW(A2)-1) | F2: =iferror(vlookup(D2,Sheet1!$B$2:$K$500,10,false),"") | G2: =IF(ISNA(vlookup(D2,DataExport!$D$2:$D$481,1,false)), "Belum", "Sudah") -> Belum
A3: =IF(B3="","",ROW(A3)-1) | F3: =iferror(vlookup(D3,Sheet1!$B$2:$K$500,10,false),"") | G3: =IF(ISNA(vlookup(D3,DataExport!$D$2:$D$481,1,false)), "Belum", "Sudah") -> Belum
A4: =IF(B4="","",ROW(A4)-1) | F4: =iferror(vlookup(D4,Sheet1!$B$2:$K$500,10,false),"") | G4: =IF(ISNA(vlookup(D4,DataExport!$D$2:$D$481,1,false)), "Belum", "Sudah") -> Belum
A5: =IF(B5="","",ROW(A5)-1) | F5: =iferror(vlookup(D5,Sheet1!$B$2:$K$500,10,false),"") | G5: =IF(ISNA(vlookup(D5,DataExport!$D$2:$D$481,1,false)), "Belum", "Sudah") -> Belum
A6: =IF(B6="","",ROW(A6)-1) | F6: =iferror(vlookup(D6,Sheet1!$B$2:$K$500,10,false),"") | G6: =IF(ISNA(vlookup(D6,DataExport!$D$2:$D$481,1,false)), "Belum", "Sudah") -> Belum
A7: =IF(B7="","",ROW(A7)-1) | F7: =iferror(vlookup(D7,Sheet1!$B$2:$K$500,10,false),"") | G7: =IF(ISNA(vlookup(D7,DataExport!$D$2:$D$481,1,false)), "Belum", "Sudah") -> Belum
A8: =IF(B8="","",ROW(A8)-1) | F8: =iferror(vlookup(D8,Sheet1!$B$2:$K$500,10,false),"") | G8: =IF(ISNA(vlookup(D8,DataExport!$D$2:$D$481,1,false)), "Belum", "Sudah") -> Belum
A9: =IF(B9="","",ROW(A9)-1) | F9: =iferror(vlookup(D9,Sheet1!$B$2:$K$500,10,false),"") | G9: =IF(ISNA(vlookup(D9,DataExport!$D$2:$D$481,1,false)), "Belum", "Sudah") -> Belum
A10: =IF(B10="","",ROW(A10)-1) | F10: =iferror(vlookup(D10,Sheet1!$B$2:$K$500,10,false),"") | G10: =IF(ISNA(vlookup(D10,DataExport!$D$2:$D$481,1,false)), "Belum", "Sudah") -> Belum
A11: =IF(B11="","",ROW(A11)-1) | F11: =iferror(vlookup(D11,Sheet1!$B$2:$K$500,10,false),"") | G11: =IF(ISNA(vlookup(D11,DataExport!$D$2:$D$481,1,false)), "Belum", "Sudah") -> Belum
A12: =IF(B12="","",ROW(A12)-1) | F12: =iferror(vlookup(D12,Sheet1!$B$2:$K$500,10,false),"") | G12: =IF(ISNA(vlookup(D12,DataExport!$D$2:$D$481,1,false)), "Belum", "Sudah") -> Belum
A13: =IF(B13="","",ROW(A13)-1) | F13: =iferror(vlookup(D13,Sheet1!$B$2:$K$500,10,false),"") | G13: =IF(ISNA(vlookup(D13,DataExport!$D$2:$D$481,1,false)), "Belum", "Sudah") -> Belum
... A511: =IF(B511="","",ROW(A511)-1) | F511: =iferror(vlookup(D511,Sheet1!$B$2:$K$500,10,false),"") | G511: =IF(ISNA(vlookup(D511,DataExport!$D$2:$D$481,1,false)), "Belum", "Sudah") -> Belum

Sheet DataExport
A1: No | B1: ID | C1: Link | D1: Hiperlink | E1: Timestamp | F1: Whatsapp
A2: =IF(B2="","",ROW(A2)-1) | F2: =iferror(vlookup(D2,Sheet1!$B$2:$K$500,10,false),"")
A3: =IF(B3="","",ROW(A3)-1) | F3: =iferror(vlookup(D3,Sheet1!$B$2:$K$500,10,false),"")
A4: =IF(B4="","",ROW(A4)-1) | F4: =iferror(vlookup(D4,Sheet1!$B$2:$K$500,10,false),"")
A5: =IF(B5="","",ROW(A5)-1) | F5: =iferror(vlookup(D5,Sheet1!$B$2:$K$500,10,false),"")
A6: =IF(B6="","",ROW(A6)-1) | F6: =iferror(vlookup(D6,Sheet1!$B$2:$K$500,10,false),"")
A7: =IF(B7="","",ROW(A7)-1) | F7: =iferror(vlookup(D7,Sheet1!$B$2:$K$500,10,false),"")
A8: =IF(B8="","",ROW(A8)-1) | F8: =iferror(vlookup(D8,Sheet1!$B$2:$K$500,10,false),"")
A9: =IF(B9="","",ROW(A9)-1) | F9: =iferror(vlookup(D9,Sheet1!$B$2:$K$500,10,false),"")
