Workbook

Sheet Sheet1
A1: NO | B1: =IFERROR(__xludf.DUMMYFUNCTION("QUERY(IMPORTRANGE(""1AzTji2sW29mb6q5i6lLp4OT4kZtfXWmm_A7yA3mApUg"",""Sheet1!B1:S750""), ""SELECT * WHERE Col18 = 'Belum Lunas'ORDER BY Col14 ASC"")"),"NAMA") -> NAMA | C1: =IFERROR(__xludf.DUMMYFUNCTION("""COMPUTED_VALUE"""),"NIS") -> NIS | D1: =IFERROR(__xludf.DUMMYFUNCTION("""COMPUTED_VALUE"""),"ASRAMA") -> ASRAMA | E1: =IFERROR(__xludf.DUMMYFUNCTION("""COMPUTED_VALUE"""),"KAMAR") -> KAMAR | F1: =IFERROR(__xludf.DUMMYFUNCTION("""COMPUTED_VALUE"""),"TINGKAT") -> TINGKAT | G1: =IFERROR(__xludf.DUMMYFUNCTION("""COMPUTED_VALUE"""),"MADRASIAH") -> MADRASIAH | H1: =IFERROR(__xludf.DUMMYFUNCTION("""COMPUTED_VALUE"""),"SEKOLAH") -> SEKOLAH | I1: =IFERROR(__xludf.DUMMYFUNCTION("""COMPUTED_VALUE"""),"IBU") -> IBU | J1: =IFERROR(__xludf.DUMMYFUNCTION("""COMPUTED_VALUE"""),"ALAMAT") -> ALAMAT | K1: =IFERROR(__xludf.DUMMYFUNCTION("""COMPUTED_VALUE"""),"WA") -> WA | L1: =IFERROR(__xludf.DUMMYFUNCTION("""COMPUTED_VALUE"""),"JUMLAH SYAHRIYAH") -> JUMLAH SYAHRIYAH | M1: =IFERROR(__xludf.DUMMYFUNCTION("""COMPUTED_VALUE"""),"JUMLAH JARIYAH") -> JUMLAH JARIYAH | N1: =IFERROR(__xludf.DUMMYFUNCTION("""COMPUTED_VALUE"""),"JUMLAH DAFTAR ULANG") -> JUMLAH DAFTAR ULANG | O1: =IFERROR(__xludf.DUMMYFUNCTION("""COMPUTED_VALUE"""),"JUMLAH TOTAL TUNGGAKAN") -> JUMLAH TOTAL TUNGGAKAN | P1: =IFERROR(__xludf.DUMMYFUNCTION("""COMPUTED_VALUE"""),"") | Q1: =IFERROR(__xludf.DUMMYFUNCTION("""COMPUTED_VALUE"""),"") | R1: =IFERROR(__xludf.DUMMYFUNCTION("""COMPUTED_VALUE"""),"") | S1: =IFERROR(__xludf.DUMMYFUNCTION("""COMPUTED_VALUE"""),"STATUS ADMINISTRASI") -> STATUS ADMINISTRASI
A2: =IF(B2="","",ROW(A2)-1) -> 1 | B2: =IFERROR(__xludf.DUMMYFUNCTION("""COMPUTED_VALUE"""),"DWI MAULIDIYAH") -> DWI MAULIDIYAH | C2: =IFERROR(__xludf.DUMMYFUNCTION("""COMPUTED_VALUE"""),2.024070596E9) -> 2024070596 | D2: =IFERROR(__xludf.DUMMYFUNCTION("""COMPUTED_VALUE"""),"E") -> E | E2: =IFERROR(__xludf.DUMMYFUNCTION("""COMPUTED_VALUE"""),"E-9") -> E-9 | F2: =IFERROR(__xludf.DUMMYFUNCTION("""COMPUTED_VALUE"""),3.0) -> 3 | G2: =IFERROR(__xludf.DUMMYFUNCTION("""COMPUTED_VALUE"""),"3 ULA B PUTRI") -> 3 ULA B PUTRI | H2: =IFERROR(__xludf.DUMMYFUNCTION("""COMPUTED_VALUE"""),"MTS-9 A") -> MTS-9 A | I2: =IFERROR(__xludf.DUMMYFUNCTION("""COMPUTED_VALUE"""),"ISLAMIYAH") -> ISLAMIYAH | J2: =IFERROR(__xludf.DUMMYFUNCTION("""COMPUTED_VALUE"""),"KARANGTAPEN KARANGLANGIT RT 001 RW 003 LAMONGAN LAMONGAN") -> KARANGTAPEN KARANGLANGIT RT 001 RW 003 LAMONGAN LAMONGAN | K2: =IFERROR(__xludf.DUMMYFUNCTION("""COMPUTED_VALUE"""),"6285853420436") -> 6285853420436 | L2: =IFERROR(__xludf.DUMMYFUNCTION("""COMPUTED_VALUE"""),270000.0) -> 270000 | M2: =IFERROR(__xludf.DUMMYFUNCTION("""COMPUTED_VALUE"""),0.0) -> 0 | N2: =IFERROR(__xludf.DUMMYFUNCTION("""COMPUTED_VALUE"""),0.0) -> 0 | O2: =IFERROR(__xludf.DUMMYFUNCTION("""COMPUTED_VALUE"""),270000.0) -> 270000 | S2: =IFERROR(__xludf.DUMMYFUNCTION("""COMPUTED_VALUE"""),"Belum Lunas") -> Belum Lunas
A3: =IF(B3="","",ROW(A3)-1) -> 2 | B3: =IFERROR(__xludf.DUMMYFUNCTION("""COMPUTED_VALUE"""),"M. FAHMI ALFIYAN NURIL HAQ") -> M. FAHMI ALFIYAN NURIL HAQ | C3: =IFERROR(__xludf.DUMMYFUNCTION("""COMPUTED_VALUE"""),2.024070718E9) -> 2024070718 | D3: =IFERROR(__xludf.DUMMYFUNCTION("""COMPUTED_VALUE"""),"A") -> A | E3: =IFERROR(__xludf.DUMMYFUNCTION("""COMPUTED_VALUE"""),"A-13") -> A-13 | F3: =IFERROR(__xludf.DUMMYFUNCTION("""COMPUTED_VALUE"""),3.0) -> 3 | H3: =IFERROR(__xludf.DUMMYFUNCTION("""COMPUTED_VALUE"""),"SMK-XII DKV") -> SMK-XII DKV | I3: =IFERROR(__xludf.DUMMYFUNCTION("""COMPUTED_VALUE"""),"SUKARTI") -> SUKARTI | J3: =IFERROR(__xludf.DUMMYFUNCTION("""COMPUTED_VALUE"""),"PLAKARAN SOMOSARI RT 3 RW 2 KALITENGAH LAMONGAN") -> PLAKARAN SOMOSARI RT 3 RW 2 KALITENGAH LAMONGAN | K3: =IFERROR(__xludf.DUMMYFUNCTION("""COMPUTED_VALUE"""),"6289677807375") -> 6289677807375 | L3: =IFERROR(__xludf.DUMMYFUNCTION("""COMPUTED_VALUE"""),410000.0) -> 410000 | M3: =IFERROR(__xludf.DUMMYFUNCTION("""COMPUTED_VALUE"""),0.0) -> 0 | N3: =IFERROR(__xludf.DUMMYFUNCTION("""COMPUTED_VALUE"""),0.0) -> 0 | O3: =IFERROR(__xludf.DUMMYFUNCTION("""COMPUTED_VALUE"""),410000.0) -> 410000 | S3: =IFERROR(__xludf.DUMMYFUNCTION("""COMPUTED_VALUE"""),"Belum Lunas") -> Belum Lunas
A4: =IF(B4="","",ROW(A4)-1) -> 3 | B4: =IFERROR(__xludf.DUMMYFUNCTION("""COMPUTED_VALUE"""),"MIRZA ATHA HIBATULLAH") -> MIRZA ATHA HIBATULLAH | C4: =IFERROR(__xludf.DUMMYFUNCTION("""COMPUTED_VALUE"""),2.0240706E9) -> 2024070600 | D4: =IFERROR(__xludf.DUMMYFUNCTION("""COMPUTED_VALUE"""),"A") -> A | E4: =IFERROR(__xludf.DUMMYFUNCTION("""COMPUTED_VALUE"""),"A-13") -> A-13 | F4: =IFERROR(__xludf.DUMMYFUNCTION("""COMPUTED_VALUE"""),3.0) -> 3 | H4: =IFERROR(__xludf.DUMMYFUNCTION("""COMPUTED_VALUE"""),"MTS-9 E") -> MTS-9 E | I4: =IFERROR(__xludf.DUMMYFUNCTION("""COMPUTED_VALUE"""),"HARWATI, S,SOS I") -> HARWATI, S,SOS I | J4: =IFERROR(__xludf.DUMMYFUNCTION("""COMPUTED_VALUE"""),"BADAN BOGOBABADAN RT 001 RW 004 KARANGBINANGUN LAMONGAN") -> BADAN BOGOBABADAN RT 001 RW 004 KARANGBINANGUN LAMONGAN | K4: =IFERROR(__xludf.DUMMYFUNCTION("""COMPUTED_VALUE"""),"6285731205500") -> 6285731205500 | L4: =IFERROR(__xludf.DUMMYFUNCTION("""COMPUTED_VALUE"""),410000.0) -> 410000 | M4: =IFERROR(__xludf.DUMMYFUNCTION("""COMPUTED_VALUE"""),0.0) -> 0 | N4: =IFERROR(__xludf.DUMMYFUNCTION("""COMPUTED_VALUE"""),0.0) -> 0 | O4: =IFERROR(__xludf.DUMMYFUNCTION("""COMPUTED_VALUE"""),410000.0) -> 410000 | S4: =IFERROR(__xludf.DUMMYFUNCTION("""COMPUTED_VALUE"""),"Belum Lunas") -> Belum Lunas
A5: =IF(B5="","",ROW(A5)-1) -> 4 | B5: =IFERROR(__xludf.DUMMYFUNCTION("""COMPUTED_VALUE"""),"ABIDAH OKTA SALSABILA") -> ABIDAH OKTA SALSABILA | C5: =IFERROR(__xludf.DUMMYFUNCTION("""COMPUTED_VALUE"""),2.024070146E9) -> 2024070146 | D5: =IFERROR(__xludf.DUMMYFUNCTION("""COMPUTED_VALUE"""),"C") -> C | E5: =IFERROR(__xludf.DUMMYFUNCTION("""COMPUTED_VALUE"""),"C-9") -> C-9 | F5: =IFERROR(__xludf.DUMMYFUNCTION("""COMPUTED_VALUE"""),3.0) -> 3 | G5: =IFERROR(__xludf.DUMMYFUNCTION("""COMPUTED_VALUE"""),"3 WUSTHO B PUTRI") -> 3 WUSTHO B PUTRI | H5: =IFERROR(__xludf.DUMMYFUNCTION("""COMPUTED_VALUE"""),"MA-XII.5") -> MA-XII.5 | I5: =IFERROR(__xludf.DUMMYFUNCTION("""COMPUTED_VALUE"""),"CICIK LUTFIANAH") -> CICIK LUTFIANAH | J5: =IFERROR(__xludf.DUMMYFUNCTION("""COMPUTED_VALUE"""),"RANDEKAN RT 001 RW 001 KEMBANGBAHU LAMONGAN") -> RANDEKAN RT 001 RW 001 KEMBANGBAHU LAMONGAN | K5: =IFERROR(__xludf.DUMMYFUNCTION("""COMPUTED_VALUE"""),"6285649525237") -> 6285649525237 | L5: =IFERROR(__xludf.DUMMYFUNCTION("""COMPUTED_VALUE"""),450000.0) -> 450000 | M5: =IFERROR(__xludf.DUMMYFUNCTION("""COMPUTED_VALUE"""),0.0) -> 0 | N5: =IFERROR(__xludf.DUMMYFUNCTION("""COMPUTED_VALUE"""),0.0) -> 0 | O5: =IFERROR(__xludf.DUMMYFUNCTION("""COMPUTED_VALUE"""),450000.0) -> 450000 | S5: =IFERROR(__xludf.DUMMYFUNCTION("""COMPUTED_VALUE"""),"Belum Lunas") -> Belum Lunas
A6: =IF(B6="","",ROW(A6)-1) -> 5 | B6: =IFERROR(__xludf.DUMMYFUNCTION("""COMPUTED_VALUE"""),"AHMAD SUSETO ANGGA SUKMA") -> AHMAD SUSETO ANGGA SUKMA | C6: =IFERROR(__xludf.DUMMYFUNCTION("""COMPUTED_VALUE"""),2.024070601E9) -> 2024070601 | D6: =IFERROR(__xludf.DUMMYFUNCTION("""COMPUTED_VALUE"""),"A") -> A | E6: =IFERROR(__xludf.DUMMYFUNCTION("""COMPUTED_VALUE"""),"A-7") -> A-7 | F6: =IFERROR(__xludf.DUMMYFUNCTION("""COMPUTED_VALUE"""),3.0) -> 3 | G6: =IFERROR(__xludf.DUMMYFUNCTION("""COMPUTED_VALUE"""),"3 ULA B PUTRA") -> 3 ULA B PUTRA | H6: =IFERROR(__xludf.DUMMYFUNCTION("""COMPUTED_VALUE"""),"MTS-9 E") -> MTS-9 E | I6: =IFERROR(__xludf.DUMMYFUNCTION("""COMPUTED_VALUE"""),"MUSYAFAAH") -> MUSYAFAAH | J6: =IFERROR(__xludf.DUMMYFUNCTION("""COMPUTED_VALUE"""),"WEDENG SUKOREJO RT 001 RW 003 KARANGBINANGUN LAMONGAN") -> WEDENG SUKOREJO RT 001 RW 003 KARANGBINANGUN LAMONGAN | K6: =IFERROR(__xludf.DUMMYFUNCTION("""COMPUTED_VALUE"""),"6281330117049") -> 6281330117049 | L6: =IFERROR(__xludf.DUMMYFUNCTION("""COMPUTED_VALUE"""),450000.0) -> 450000 | M6: =IFERROR(__xludf.DUMMYFUNCTION("""COMPUTED_VALUE"""),0.0) -> 0 | N6: =IFERROR(__xludf.DUMMYFUNCTION("""COMPUTED_VALUE"""),0.0) -> 0 | O6: =IFERROR(__xludf.DUMMYFUNCTION("""COMPUTED_VALUE"""),450000.0) -> 450000 | S6: =IFERROR(__xludf.DUMMYFUNCTION("""COMPUTED_VALUE"""),"Belum Lunas") -> Belum Lunas
A7: =IF(B7="","",ROW(A7)-1) -> 6 | B7: =IFERROR(__xludf.DUMMYFUNCTION("""COMPUTED_VALUE"""),"ALFA FALAJ SALSABILA") -> ALFA FALAJ SALSABILA | C7: =IFERROR(__xludf.DUMMYFUNCTION("""COMPUTED_VALUE"""),2.024070611E9) -> 2024070611 | D7: =IFERROR(__xludf.DUMMYFUNCTION("""COMPUTED_VALUE"""),"C") -> C | E7: =IFERROR(__xludf.DUMMYFUNCTION("""COMPUTED_VALUE"""),"C-3") -> C-3 | F7: =IFERROR(__xludf.DUMMYFUNCTION("""COMPUTED_VALUE"""),3.0) -> 3 | G7: =IFERROR(__xludf.DUMMYFUNCTION("""COMPUTED_VALUE"""),"3 ULA C PUTRI") -> 3 ULA C PUTRI | H7: =IFERROR(__xludf.DUMMYFUNCTION("""COMPUTED_VALUE"""),"MTS-9 A") -> MTS-9 A | I7: =IFERROR(__xludf.DUMMYFUNCTION("""COMPUTED_VALUE"""),"SUMIANAH") -> SUMIANAH | J7: =IFERROR(__xludf.DUMMYFUNCTION("""COMPUTED_VALUE"""),"KULURAN RT 005 RW 001 KALITENGAH LAMONGAN") -> KULURAN RT 005 RW 001 KALITENGAH LAMONGAN | K7: =IFERROR(__xludf.DUMMYFUNCTION("""COMPUTED_VALUE"""),"6285859539394") -> 6285859539394 | L7: =IFERROR(__xludf.DUMMYFUNCTION("""COMPUTED_VALUE"""),450000.0) -> 450000 | M7: =IFERROR(__xludf.DUMMYFUNCTION("""COMPUTED_VALUE"""),0.0) -> 0 | N7: =IFERROR(__xludf.DUMMYFUNCTION("""COMPUTED_VALUE"""),0.0) -> 0 | O7: =IFERROR(__xludf.DUMMYFUNCTION("""COMPUTED_VALUE"""),450000.0) -> 450000 | S7: =IFERROR(__xludf.DUMMYFUNCTION("""COMPUTED_VALUE"""),"Belum Lunas") -> Belum Lunas
A8: =IF(B8="","",ROW(A8)-1) -> 7 | B8: =IFERROR(__xludf.DUMMYFUNCTION("""COMPUTED_VALUE"""),"AZZA IBNU ARJUN") -> AZZA IBNU ARJUN | C8: =IFERROR(__xludf.DUMMYFUNCTION("""COMPUTED_VALUE"""),2.024090771E9) -> 2024090771 | D8: =IFERROR(__xludf.DUMMYFUNCTION("""COMPUTED_VALUE"""),"A") -> A | E8: =IFERROR(__xludf.DUMMYFUNCTION("""COMPUTED_VALUE"""),"A-8") -> A-8 | F8: =IFERROR(__xludf.DUMMYFUNCTION("""COMPUTED_VALUE"""),3.0) -> 3 | G8: =IFERROR(__xludf.DUMMYFUNCTION("""COMPUTED_VALUE"""),"3 ULA A PUTRA") -> 3 ULA A PUTRA | H8: =IFERROR(__xludf.DUMMYFUNCTION("""COMPUTED_VALUE"""),"SMP-IX A") -> SMP-IX A | I8: =IFERROR(__xludf.DUMMYFUNCTION("""COMPUTED_VALUE"""),"IKA NUR KHOLIFAH") -> IKA NUR KHOLIFAH | J8: =IFERROR(__xludf.DUMMYFUNCTION("""COMPUTED_VALUE"""),"MALINAU HULU RT 009 RW 000 MALINAU KOTA MALINAU") -> MALINAU HULU RT 009 RW 000 MALINAU KOTA MALINAU | K8: =IFERROR(__xludf.DUMMYFUNCTION("""COMPUTED_VALUE"""),"6282234721856") -> 6282234721856 | L8: =IFERROR(__xludf.DUMMYFUNCTION("""COMPUTED_VALUE"""),450000.0) -> 450000 | M8: =IFERROR(__xludf.DUMMYFUNCTION("""COMPUTED_VALUE"""),0.0) -> 0 | N8: =IFERROR(__xludf.DUMMYFUNCTION("""COMPUTED_VALUE"""),0.0) -> 0 | O8: =IFERROR(__xludf.DUMMYFUNCTION("""COMPUTED_VALUE"""),450000.0) -> 450000 | S8: =IFERROR(__xludf.DUMMYFUNCTION("""COMPUTED_VALUE"""),"Belum Lunas") -> Belum Lunas
A9: =IF(B9="","",ROW(A9)-1) -> 8 | B9: =IFERROR(__xludf.DUMMYFUNCTION("""COMPUTED_VALUE"""),"BINTANG FARSYA HUSBANA") -> BINTANG FARSYA HUSBANA | C9: =IFERROR(__xludf.DUMMYFUNCTION("""COMPUTED_VALUE"""),2.024070646E9) -> 2024070646 | D9: =IFERROR(__xludf.DUMMYFUNCTION("""COMPUTED_VALUE"""),"A") -> A | E9: =IFERROR(__xludf.DUMMYFUNCTION("""COMPUTED_VALUE"""),"A-7") -> A-7 | F9: =IFERROR(__xludf.DUMMYFUNCTION("""COMPUTED_VALUE"""),3.0) -> 3 | G9: =IFERROR(__xludf.DUMMYFUNCTION("""COMPUTED_VALUE"""),"3 ULA A PUTRA") -> 3 ULA A PUTRA | H9: =IFERROR(__xludf.DUMMYFUNCTION("""COMPUTED_VALUE"""),"MTS-9 F") -> MTS-9 F | I9: =IFERROR(__xludf.DUMMYFUNCTION("""COMPUTED_VALUE"""),"SITI MUNFARIDA") -> SITI MUNFARIDA | J9: =IFERROR(__xludf.DUMMYFUNCTION("""COMPUTED_VALUE"""),"SEREN JATIPANDAK RT 007 RW 003 SAMBENG LAMONGAN") -> SEREN JATIPANDAK RT 007 RW 003 SAMBENG LAMONGAN | K9: =IFERROR(__xludf.DUMMYFUNCTION("""COMPUTED_VALUE"""),"6285851833747") -> 6285851833747 | L9: =IFERROR(__xludf.DUMMYFUNCTION("""COMPUTED_VALUE"""),450000.0) -> 450000 | M9: =IFERROR(__xludf.DUMMYFUNCTION("""COMPUTED_VALUE"""),0.0) -> 0 | N9: =IFERROR(__xludf.DUMMYFUNCTION("""COMPUTED_VALUE"""),0.0) -> 0 | O9: =IFERROR(__xludf.DUMMYFUNCTION("""COMPUTED_VALUE"""),450000.0) -> 450000 | S9: =IFERROR(__xludf.DUMMYFUNCTION("""COMPUTED_VALUE"""),"Belum Lunas") -> Belum Lunas
A10: =IF(B10="","",ROW(A10)-1) -> 9 | B10: =IFERROR(__xludf.DUMMYFUNCTION("""COMPUTED_VALUE"""),"DILLA AGUSTIAWATI PUTRI") -> DILLA AGUSTIAWATI PUTRI | C10: =IFERROR(__xludf.DUMMYFUNCTION("""COMPUTED_VALUE"""),2.024070532E9) -> 2024070532 | D10: =IFERROR(__xludf.DUMMYFUNCTION("""COMPUTED_VALUE"""),"C") -> C | E10: =IFERROR(__xludf.DUMMYFUNCTION("""COMPUTED_VALUE"""),"C-13") -> C-13 | F10: =IFERROR(__xludf.DUMMYFUNCTION("""COMPUTED_VALUE"""),3.0) -> 3 | G10: =IFERROR(__xludf.DUMMYFUNCTION("""COMPUTED_VALUE"""),"3 ULA C PUTRI") -> 3 ULA C PUTRI | H10: =IFERROR(__xludf.DUMMYFUNCTION("""COMPUTED_VALUE"""),"MTS-9 D") -> MTS-9 D | I10: =IFERROR(__xludf.DUMMYFUNCTION("""COMPUTED_VALUE"""),"IRA RAHMATUS SAADA") -> IRA RAHMATUS SAADA | J10: =IFERROR(__xludf.DUMMYFUNCTION("""COMPUTED_VALUE"""),"SEPAT TAMBAKMENJANGAN RT 001 RW 007 SARIREJO LAMONGAN") -> SEPAT TAMBAKMENJANGAN RT 001 RW 007 SARIREJO LAMONGAN | K10: =IFERROR(__xludf.DUMMYFUNCTION("""COMPUTED_VALUE"""),"6285808407652") -> 6285808407652 | L10: =IFERROR(__xludf.DUMMYFUNCTION("""COMPUTED_VALUE"""),450000.0) -> 450000 | M10: =IFERROR(__xludf.DUMMYFUNCTION("""COMPUTED_VALUE"""),0.0) -> 0 | N10: =IFERROR(__xludf.DUMMYFUNCTION("""COMPUTED_VALUE"""),0.0) -> 0 | O10: =IFERROR(__xludf.DUMMYFUNCTION("""COMPUTED_VALUE"""),450000.0) -> 450000 | S10: =IFERROR(__xludf.DUMMYFUNCTION("""COMPUTED_VALUE"""),"Belum Lunas") -> Belum Lunas
A11: =IF(B11="","",ROW(A11)-1) -> 10 | B11: =IFERROR(__xludf.DUMMYFUNCTION("""COMPUTED_VALUE"""),"FATMA NAJWA ZAHIRA") -> FATMA NAJWA ZAHIRA | C11: =IFERROR(__xludf.DUMMYFUNCTION("""COMPUTED_VALUE"""),2.024070497E9) -> 2024070497 | D11: =IFERROR(__xludf.DUMMYFUNCTION("""COMPUTED_VALUE"""),"C") -> C | E11: =IFERROR(__xludf.DUMMYFUNCTION("""COMPUTED_VALUE"""),"C-12") -> C-12 | F11: =IFERROR(__xludf.DUMMYFUNCTION("""COMPUTED_VALUE"""),3.0) -> 3 | G11: =IFERROR(__xludf.DUMMYFUNCTION("""COMPUTED_VALUE"""),"3 ULA B PUTRI") -> 3 ULA B PUTRI | H11: =IFERROR(__xludf.DUMMYFUNCTION("""COMPUTED_VALUE"""),"MTS-9 D") -> MTS-9 D | I11: =IFERROR(__xludf.DUMMYFUNCTION("""COMPUTED_VALUE"""),"SITI NURIYAH") -> SITI NURIYAH | J11: =IFERROR(__xludf.DUMMYFUNCTION("""COMPUTED_VALUE"""),"NGUWOK RT 004 RW 002 MODO LAMONGAN") -> NGUWOK RT 004 RW 002 MODO LAMONGAN | K11: =IFERROR(__xludf.DUMMYFUNCTION("""COMPUTED_VALUE"""),"6282337956113") -> 6282337956113 | L11: =IFERROR(__xludf.DUMMYFUNCTION("""COMPUTED_VALUE"""),450000.0) -> 450000 | M11: =IFERROR(__xludf.DUMMYFUNCTION("""COMPUTED_VALUE"""),0.0) -> 0 | N11: =IFERROR(__xludf.DUMMYFUNCTION("""COMPUTED_VALUE"""),0.0) -> 0 | O11: =IFERROR(__xludf.DUMMYFUNCTION("""COMPUTED_VALUE"""),450000.0) -> 450000 | S11: =IFERROR(__xludf.DUMMYFUNCTION("""COMPUTED_VALUE"""),"Belum Lunas") -> Belum Lunas
A12: =IF(B12="","",ROW(A12)-1) -> 11 | B12: =IFERROR(__xludf.DUMMYFUNCTION("""COMPUTED_VALUE"""),"LABIB AZAM") -> LABIB AZAM | C12: =IFERROR(__xludf.DUMMYFUNCTION("""COMPUTED_VALUE"""),2.024070756E9) -> 2024070756 | D12: =IFERROR(__xludf.DUMMYFUNCTION("""COMPUTED_VALUE"""),"A") -> A | E12: =IFERROR(__xludf.DUMMYFUNCTION("""COMPUTED_VALUE"""),"A-7") -> A-7 | F12: =IFERROR(__xludf.DUMMYFUNCTION("""COMPUTED_VALUE"""),3.0) -> 3 | G12: =IFERROR(__xludf.DUMMYFUNCTION("""COMPUTED_VALUE"""),"3 ULA A PUTRA") -> 3 ULA A PUTRA | H12: =IFERROR(__xludf.DUMMYFUNCTION("""COMPUTED_VALUE"""),"SMP-IX B") -> SMP-IX B | I12: =IFERROR(__xludf.DUMMYFUNCTION("""COMPUTED_VALUE"""),"EVA YUNIARTI") -> EVA YUNIARTI | J12: =IFERROR(__xludf.DUMMYFUNCTION("""COMPUTED_VALUE"""),"TENGGER RAYA 1 KANDANGAN RT 007 RW 002 BENOWO SURABAYA") -> TENGGER RAYA 1 KANDANGAN RT 007 RW 002 BENOWO SURABAYA | K12: =IFERROR(__xludf.DUMMYFUNCTION("""COMPUTED_VALUE"""),"6282333086607") -> 6282333086607 | L12: =IFERROR(__xludf.DUMMYFUNCTION("""COMPUTED_VALUE"""),450000.0) -> 450000 | M12: =IFERROR(__xludf.DUMMYFUNCTION("""COMPUTED_VALUE"""),0.0) -> 0 | N12: =IFERROR(__xludf.DUMMYFUNCTION("""COMPUTED_VALUE"""),0.0) -> 0 | O12: =IFERROR(__xludf.DUMMYFUNCTION("""COMPUTED_VALUE"""),450000.0) -> 450000 | S12: =IFERROR(__xludf.DUMMYFUNCTION("""COMPUTED_VALUE"""),"Belum Lunas") -> Belum Lunas
A13: =IF(B13="","",ROW(A13)-1) -> 12 | B13: =IFERROR(__xludf.DUMMYFUNCTION("""COMPUTED_VALUE"""),"M. SATRIA PUTRA AMILINA") -> M. SATRIA PUTRA AMILINA | C13: =IFERROR(__xludf.DUMMYFUNCTION("""COMPUTED_VALUE"""),2.024070092E9) -> 2024070092 | D13: =IFERROR(__xludf.DUMMYFUNCTION("""COMPUTED_VALUE"""),"A") -> A | E13: =IFERROR(__xludf.DUMMYFUNCTION("""COMPUTED_VALUE"""),"A-10") -> A-10 | F13: =IFERROR(__xludf.DUMMYFUNCTION("""COMPUTED_VALUE"""),3.0) -> 3 | G13: =IFERROR(__xludf.DUMMYFUNCTION("""COMPUTED_VALUE"""),"3 WUSTHO PUTRA") -> 3 WUSTHO PUTRA | H13: =IFERROR(__xludf.DUMMYFUNCTION("""COMPUTED_VALUE"""),"MA-XII.4") -> MA-XII.4 | I13: =IFERROR(__xludf.DUMMYFUNCTION("""COMPUTED_VALUE"""),"LINA ANGGRAINI") -> LINA ANGGRAINI | J13: =IFERROR(__xludf.DUMMYFUNCTION("""COMPUTED_VALUE"""),"TALUN RT 4 RW 1 SUMBERREJO BOJONEGORO") -> TALUN RT 4 RW 1 SUMBERREJO BOJONEGORO | K13: =IFERROR(__xludf.DUMMYFUNCTION("""COMPUTED_VALUE"""),"628568406710") -> 628568406710 | L13: =IFERROR(__xludf.DUMMYFUNCTION("""COMPUTED_VALUE"""),450000.0) -> 450000 | M13: =IFERROR(__xludf.DUMMYFUNCTION("""COMPUTED_VALUE"""),0.0) -> 0 | N13: =IFERROR(__xludf.DUMMYFUNCTION("""COMPUTED_VALUE"""),0.0) -> 0 | O13: =IFERROR(__xludf.DUMMYFUNCTION("""COMPUTED_VALUE"""),450000.0) -> 450000 | S13: =IFERROR(__xludf.DUMMYFUNCTION("""COMPUTED_VALUE"""),"Belum Lunas") -> Belum Lunas
A14: =IF(B14="","",ROW(A14)-1) -> 13 | B14: =IFERROR(__xludf.DUMMYFUNCTION("""COMPUTED_VALUE"""),"MAHATMA SATYA GRAHA") -> MAHATMA SATYA GRAHA | C14: =IFERROR(__xludf.DUMMYFUNCTION("""COMPUTED_VALUE"""),2.024070407E9) -> 2024070407 | D14: =IFERROR(__xludf.DUMMYFUNCTION("""COMPUTED_VALUE"""),"A") -> A | E14: =IFERROR(__xludf.DUMMYFUNCTION("""COMPUTED_VALUE"""),"A-10") -> A-10 | F14: =IFERROR(__xludf.DUMMYFUNCTION("""COMPUTED_VALUE"""),3.0) -> 3 | G14: =IFERROR(__xludf.DUMMYFUNCTION("""COMPUTED_VALUE"""),"3 WUSTHO PUTRA") -> 3 WUSTHO PUTRA | H14: =IFERROR(__xludf.DUMMYFUNCTION("""COMPUTED_VALUE"""),"MA-XII.9") -> MA-XII.9 | I14: =IFERROR(__xludf.DUMMYFUNCTION("""COMPUTED_VALUE"""),"AIYINATUL JAMILAH") -> AIYINATUL JAMILAH | J14: =IFERROR(__xludf.DUMMYFUNCTION("""COMPUTED_VALUE"""),"JELAK JELAKCATUR RT 001 RW 004 KALITENGAH LAMONGAN") -> JELAK JELAKCATUR RT 001 RW 004 KALITENGAH LAMONGAN | K14: =IFERROR(__xludf.DUMMYFUNCTION("""COMPUTED_VALUE"""),"628557692330") -> 628557692330 | L14: =IFERROR(__xludf.DUMMYFUNCTION("""COMPUTED_VALUE"""),450000.0) -> 450000 | M14: =IFERROR(__xludf.DUMMYFUNCTION("""COMPUTED_VALUE"""),0.0) -> 0 | N14: =IFERROR(__xludf.DUMMYFUNCTION("""COMPUTED_VALUE"""),0.0) -> 0 | O14: =IFERROR(__xludf.DUMMYFUNCTION("""COMPUTED_VALUE"""),450000.0) -> 450000 | S14: =IFERROR(__xludf.DUMMYFUNCTION("""COMPUTED_VALUE"""),"Belum Lunas") -> Belum Lunas
A15: =IF(B15="","",ROW(A15)-1) -> 14 | B15: =IFERROR(__xludf.DUMMYFUNCTION("""COMPUTED_VALUE"""),"MOCHAMMAD NEIZTAHUL HUDA") -> MOCHAMMAD NEIZTAHUL HUDA | C15: =IFERROR(__xludf.DUMMYFUNCTION("""COMPUTED_VALUE"""),2.024070626E9) -> 2024070626 | D15: =IFERROR(__xludf.DUMMYFUNCTION("""COMPUTED_VALUE"""),"A") -> A | E15: =IFERROR(__xludf.DUMMYFUNCTION("""COMPUTED_VALUE"""),"A-8") -> A-8 | F15: =IFERROR(__xludf.DUMMYFUNCTION("""COMPUTED_VALUE"""),3.0) -> 3 | G15: =IFERROR(__xludf.DUMMYFUNCTION("""COMPUTED_VALUE"""),"3 ULA B PUTRA") -> 3 ULA B PUTRA | H15: =IFERROR(__xludf.DUMMYFUNCTION("""COMPUTED_VALUE"""),"MTS-9 B") -> MTS-9 B | I15: =IFERROR(__xludf.DUMMYFUNCTION("""COMPUTED_VALUE"""),"RIYAYUK") -> RIYAYUK | J15: =IFERROR(__xludf.DUMMYFUNCTION("""COMPUTED_VALUE"""),"NGAYUNG RT 007 RW 002 MADURAN LAMONGAN") -> NGAYUNG RT 007 RW 002 MADURAN LAMONGAN | K15: =IFERROR(__xludf.DUMMYFUNCTION("""COMPUTED_VALUE"""),"6282237520701") -> 6282237520701 | L15: =IFERROR(__xludf.DUMMYFUNCTION("""COMPUTED_VALUE"""),450000.0) -> 450000 | M15: =IFERROR(__xludf.DUMMYFUNCTION("""COMPUTED_VALUE"""),0.0) -> 0 | N15: =IFERROR(__xludf.DUMMYFUNCTION("""COMPUTED_VALUE"""),0.0) -> 0 | O15: =IFERROR(__xludf.DUMMYFUNCTION("""COMPUTED_VALUE"""),450000.0) -> 450000 | S15: =IFERROR(__xludf.DUMMYFUNCTION("""COMPUTED_VALUE"""),"Belum Lunas") -> Belum Lunas
A16: =IF(B16="","",ROW(A16)-1) -> 15 | B16: =IFERROR(__xludf.DUMMYFUNCTION("""COMPUTED_VALUE"""),"MUHAMMAD ALAM FIRMANSYAH") -> MUHAMMAD ALAM FIRMANSYAH | C16: =IFERROR(__xludf.DUMMYFUNCTION("""COMPUTED_VALUE"""),2.024070506E9) -> 2024070506 | D16: =IFERROR(__xludf.DUMMYFUNCTION("""COMPUTED_VALUE"""),"A") -> A | E16: =IFERROR(__xludf.DUMMYFUNCTION("""COMPUTED_VALUE"""),"A-8") -> A-8 | F16: =IFERROR(__xludf.DUMMYFUNCTION("""COMPUTED_VALUE"""),3.0) -> 3 | G16: =IFERROR(__xludf.DUMMYFUNCTION("""COMPUTED_VALUE"""),"3 ULA A PUTRA") -> 3 ULA A PUTRA | H16: =IFERROR(__xludf.DUMMYFUNCTION("""COMPUTED_VALUE"""),"MTS-9 F") -> MTS-9 F | I16: =IFERROR(__xludf.DUMMYFUNCTION("""COMPUTED_VALUE"""),"MUFA ROKAH") -> MUFA ROKAH | J16: =IFERROR(__xludf.DUMMYFUNCTION("""COMPUTED_VALUE"""),"KAMAL RT 004 RW 000 KAIRATU BARAT SERAM BAGIAN BARAT") -> KAMAL RT 004 RW 000 KAIRATU BARAT SERAM BAGIAN BARAT | K16: =IFERROR(__xludf.DUMMYFUNCTION("""COMPUTED_VALUE"""),"6282199817002") -> 6282199817002 | L16: =IFERROR(__xludf.DUMMYFUNCTION("""COMPUTED_VALUE"""),450000.0) -> 450000 | M16: =IFERROR(__xludf.DUMMYFUNCTION("""COMPUTED_VALUE"""),0.0) -> 0 | N16: =IFERROR(__xludf.DUMMYFUNCTION("""COMPUTED_VALUE"""),0.0) -> 0 | O16: =IFERROR(__xludf.DUMMYFUNCTION("""COMPUTED_VALUE"""),450000.0) -> 450000 | S16: =IFERROR(__xludf.DUMMYFUNCTION("""COMPUTED_VALUE"""),"Belum Lunas") -> Belum Lunas
A17: =IF(B17="","",ROW(A17)-1) -> 16 | B17: =IFERROR(__xludf.DUMMYFUNCTION("""COMPUTED_VALUE"""),"MUHAMMAD SYA`DANA") -> MUHAMMAD SYA`DANA | C17: =IFERROR(__xludf.DUMMYFUNCTION("""COMPUTED_VALUE"""),2.024070715E9) -> 2024070715 | D17: =IFERROR(__xludf.DUMMYFUNCTION("""COMPUTED_VALUE"""),"A") -> A | E17: =IFERROR(__xludf.DUMMYFUNCTION("""COMPUTED_VALUE"""),"A-10") -> A-10 | F17: =IFERROR(__xludf.DUMMYFUNCTION("""COMPUTED_VALUE"""),3.0) -> 3 | G17: =IFERROR(__xludf.DUMMYFUNCTION("""COMPUTED_VALUE"""),"3 WUSTHO PUTRA") -> 3 WUSTHO PUTRA | H17: =IFERROR(__xludf.DUMMYFUNCTION("""COMPUTED_VALUE"""),"SMK-XII TKJ 2") -> SMK-XII TKJ 2 | I17: =IFERROR(__xludf.DUMMYFUNCTION("""COMPUTED_VALUE"""),"FATMAWATI") -> FATMAWATI | J17: =IFERROR(__xludf.DUMMYFUNCTION("""COMPUTED_VALUE"""),"PARENGAN RT 4 RW 3 MADURAN LAMONGAN") -> PARENGAN RT 4 RW 3 MADURAN LAMONGAN | K17: =IFERROR(__xludf.DUMMYFUNCTION("""COMPUTED_VALUE"""),"6281216068509") -> 6281216068509 | L17: =IFERROR(__xludf.DUMMYFUNCTION("""COMPUTED_VALUE"""),450000.0) -> 450000 | M17: =IFERROR(__xludf.DUMMYFUNCTION("""COMPUTED_VALUE"""),0.0) -> 0 | N17: =IFERROR(__xludf.DUMMYFUNCTION("""COMPUTED_VALUE"""),0.0) -> 0 | O17: =IFERROR(__xludf.DUMMYFUNCTION("""COMPUTED_VALUE"""),450000.0) -> 450000 | S17: =IFERROR(__xludf.DUMMYFUNCTION("""COMPUTED_VALUE"""),"Belum Lunas") -> Belum Lunas
A18: =IF(B18="","",ROW(A18)-1) -> 17 | B18: =IFERROR(__xludf.DUMMYFUNCTION("""COMPUTED_VALUE"""),"AHMAD BAHRUL FITRONI") -> AHMAD BAHRUL FITRONI | C18: =IFERROR(__xludf.DUMMYFUNCTION("""COMPUTED_VALUE"""),2.024070534E9) -> 2024070534 | D18: =IFERROR(__xludf.DUMMYFUNCTION("""COMPUTED_VALUE"""),"A") -> A | E18: =IFERROR(__xludf.DUMMYFUNCTION("""COMPUTED_VALUE"""),"A-8") -> A-8 | F18: =IFERROR(__xludf.DUMMYFUNCTION("""COMPUTED_VALUE"""),3.0) -> 3 | G18: =IFERROR(__xludf.DUMMYFUNCTION("""COMPUTED_VALUE"""),"3 ULA B PUTRA") -> 3 ULA B PUTRA | H18: =IFERROR(__xludf.DUMMYFUNCTION("""COMPUTED_VALUE"""),"MTS-9 E") -> MTS-9 E | I18: =IFERROR(__xludf.DUMMYFUNCTION("""COMPUTED_VALUE"""),"SRI MULYATI") -> SRI MULYATI | J18: =IFERROR(__xludf.DUMMYFUNCTION("""COMPUTED_VALUE"""),"KEBET RT 005 RW 001 LAMONGAN LAMONGAN") -> KEBET RT 005 RW 001 LAMONGAN LAMONGAN | K18: =IFERROR(__xludf.DUMMYFUNCTION("""COMPUTED_VALUE"""),"6285812677937") -> 6285812677937 | L18: =IFERROR(__xludf.DUMMYFUNCTION("""COMPUTED_VALUE"""),0.0) -> 0 | M18: =IFERROR(__xludf.DUMMYFUNCTION("""COMPUTED_VALUE"""),500000.0) -> 500000 | N18: =IFERROR(__xludf.DUMMYFUNCTION("""COMPUTED_VALUE"""),0.0) -> 0 | O18: =IFERROR(__xludf.DUMMYFUNCTION("""COMPUTED_VALUE"""),500000.0) -> 500000 | S18: =IFERROR(__xludf.DUMMYFUNCTION("""COMPUTED_VALUE"""),"Belum Lunas") -> Belum Lunas
A19: =IF(B19="","",ROW(A19)-1) -> 18 | B19: =IFERROR(__xludf.DUMMYFUNCTION("""COMPUTED_VALUE"""),"AIDZILA DHEA ANANTA") -> AIDZILA DHEA ANANTA | C19: =IFERROR(__xludf.DUMMYFUNCTION("""COMPUTED_VALUE"""),2.024070495E9) -> 2024070495 | D19: =IFERROR(__xludf.DUMMYFUNCTION("""COMPUTED_VALUE"""),"C") -> C | E19: =IFERROR(__xludf.DUMMYFUNCTION("""COMPUTED_VALUE"""),"C-12") -> C-12 | F19: =IFERROR(__xludf.DUMMYFUNCTION("""COMPUTED_VALUE"""),3.0) -> 3 | G19: =IFERROR(__xludf.DUMMYFUNCTION("""COMPUTED_VALUE"""),"3 ULA C PUTRI") -> 3 ULA C PUTRI | H19: =IFERROR(__xludf.DUMMYFUNCTION("""COMPUTED_VALUE"""),"MTS-9 D") -> MTS-9 D | I19: =IFERROR(__xludf.DUMMYFUNCTION("""COMPUTED_VALUE"""),"MARATUS SHOLICHAH") -> MARATUS SHOLICHAH | J19: =IFERROR(__xludf.DUMMYFUNCTION("""COMPUTED_VALUE"""),"NGUWOK RT 004 RW 002 MODO LAMONGAN") -> NGUWOK RT 004 RW 002 MODO LAMONGAN | K19: =IFERROR(__xludf.DUMMYFUNCTION("""COMPUTED_VALUE"""),"6281559586998") -> 6281559586998 | L19: =IFERROR(__xludf.DUMMYFUNCTION("""COMPUTED_VALUE"""),0.0) -> 0 | M19: =IFERROR(__xludf.DUMMYFUNCTION("""COMPUTED_VALUE"""),500000.0) -> 500000 | N19: =IFERROR(__xludf.DUMMYFUNCTION("""COMPUTED_VALUE"""),0.0) -> 0 | O19: =IFERROR(__xludf.DUMMYFUNCTION("""COMPUTED_VALUE"""),500000.0) -> 500000 | S19: =IFERROR(__xludf.DUMMYFUNCTION("""COMPUTED_VALUE"""),"Belum Lunas") -> Belum Lunas
A20: =IF(B20="","",ROW(A20)-1) -> 19 | B20: =IFERROR(__xludf.DUMMYFUNCTION("""COMPUTED_VALUE"""),"ATHIIYAH AULIYA`UL MUSHOFAROH") -> ATHIIYAH AULIYA`UL MUSHOFAROH | C20: =IFERROR(__xludf.DUMMYFUNCTION("""COMPUTED_VALUE"""),2.024070631E9) -> 2024070631 | D20: =IFERROR(__xludf.DUMMYFUNCTION("""COMPUTED_VALUE"""),"C") -> C | E20: =IFERROR(__xludf.DUMMYFUNCTION("""COMPUTED_VALUE"""),"C-3") -> C-3 | F20: =IFERROR(__xludf.DUMMYFUNCTION("""COMPUTED_VALUE"""),3.0) -> 3 | H20: =IFERROR(__xludf.DUMMYFUNCTION("""COMPUTED_VALUE"""),"MTS-9 A") -> MTS-9 A | I20: =IFERROR(__xludf.DUMMYFUNCTION("""COMPUTED_VALUE"""),"NUR KHOMSATUN FINARIYAH") -> NUR KHOMSATUN FINARIYAH | J20: =IFERROR(__xludf.DUMMYFUNCTION("""COMPUTED_VALUE"""),"KEDIREN RT 003 RW 001 KALITENGAH LAMONGAN") -> KEDIREN RT 003 RW 001 KALITENGAH LAMONGAN | K20: =IFERROR(__xludf.DUMMYFUNCTION("""COMPUTED_VALUE"""),"6285731317533") -> 6285731317533 | L20: =IFERROR(__xludf.DUMMYFUNCTION("""COMPUTED_VALUE"""),0.0) -> 0 | M20: =IFERROR(__xludf.DUMMYFUNCTION("""COMPUTED_VALUE"""),500000.0) -> 500000 | N20: =IFERROR(__xludf.DUMMYFUNCTION("""COMPUTED_VALUE"""),0.0) -> 0 | O20: =IFERROR(__xludf.DUMMYFUNCTION("""COMPUTED_VALUE"""),500000.0) -> 500000 | S20: =IFERROR(__xludf.DUMMYFUNCTION("""COMPUTED_VALUE"""),"Belum Lunas") -> Belum Lunas
A21: =IF(B21="","",ROW(A21)-1) -> 20 | B21: =IFERROR(__xludf.DUMMYFUNCTION("""COMPUTED_VALUE"""),"ATINA AZKAL FUADAH") -> ATINA AZKAL FUADAH | C21: =IFERROR(__xludf.DUMMYFUNCTION("""COMPUTED_VALUE"""),2.024070474E9) -> 2024070474 | D21: =IFERROR(__xludf.DUMMYFUNCTION("""COMPUTED_VALUE"""),"E") -> E | E21: =IFERROR(__xludf.DUMMYFUNCTION("""COMPUTED_VALUE"""),"E-3") -> E-3 | F21: =IFERROR(__xludf.DUMMYFUNCTION("""COMPUTED_VALUE"""),3.0) -> 3 | G21: =IFERROR(__xludf.DUMMYFUNCTION("""COMPUTED_VALUE"""),"3 ULA B PUTRI") -> 3 ULA B PUTRI | H21: =IFERROR(__xludf.DUMMYFUNCTION("""COMPUTED_VALUE"""),"MTS-9 B") -> MTS-9 B | I21: =IFERROR(__xludf.DUMMYFUNCTION("""COMPUTED_VALUE"""),"KHAULA ANIS") -> KHAULA ANIS | J21: =IFERROR(__xludf.DUMMYFUNCTION("""COMPUTED_VALUE"""),"NGAYUNG RT 006 RW 002 MADURAN LAMONGAN") -> NGAYUNG RT 006 RW 002 MADURAN LAMONGAN | K21: =IFERROR(__xludf.DUMMYFUNCTION("""COMPUTED_VALUE"""),"6281554492983") -> 6281554492983 | L21: =IFERROR(__xludf.DUMMYFUNCTION("""COMPUTED_VALUE"""),500000.0) -> 500000 | M21: =IFERROR(__xludf.DUMMYFUNCTION("""COMPUTED_VALUE"""),0.0) -> 0 | N21: =IFERROR(__xludf.DUMMYFUNCTION("""COMPUTED_VALUE"""),0.0) -> 0 | O21: =IFERROR(__xludf.DUMMYFUNCTION("""COMPUTED_VALUE"""),500000.0) -> 500000 | S21: =IFERROR(__xludf.DUMMYFUNCTION("""COMPUTED_VALUE"""),"Belum Lunas") -> Belum Lunas
A22: =IF(B22="","",ROW(A22)-1) -> 21 | B22: =IFERROR(__xludf.DUMMYFUNCTION("""COMPUTED_VALUE"""),"AZZAM ABDILLAH SAPTA") -> AZZAM ABDILLAH SAPTA | C22: =IFERROR(__xludf.DUMMYFUNCTION("""COMPUTED_VALUE"""),2.02407059E9) -> 2024070590 | D22: =IFERROR(__xludf.DUMMYFUNCTION("""COMPUTED_VALUE"""),"A") -> A | E22: =IFERROR(__xludf.DUMMYFUNCTION("""COMPUTED_VALUE"""),"A-8") -> A-8 | F22: =IFERROR(__xludf.DUMMYFUNCTION("""COMPUTED_VALUE"""),3.0) -> 3 | G22: =IFERROR(__xludf.DUMMYFUNCTION("""COMPUTED_VALUE"""),"3 ULA B PUTRA") -> 3 ULA B PUTRA | H22: =IFERROR(__xludf.DUMMYFUNCTION("""COMPUTED_VALUE"""),"MTS-9 D") -> MTS-9 D | I22: =IFERROR(__xludf.DUMMYFUNCTION("""COMPUTED_VALUE"""),"MUIYATI") -> MUIYATI | J22: =IFERROR(__xludf.DUMMYFUNCTION("""COMPUTED_VALUE"""),"NGAYUNG RT 005 RW 002 MADURAN LAMONGAN") -> NGAYUNG RT 005 RW 002 MADURAN LAMONGAN | K22: =IFERROR(__xludf.DUMMYFUNCTION("""COMPUTED_VALUE"""),"6282143068892") -> 6282143068892 | L22: =IFERROR(__xludf.DUMMYFUNCTION("""COMPUTED_VALUE"""),0.0) -> 0 | M22: =IFERROR(__xludf.DUMMYFUNCTION("""COMPUTED_VALUE"""),500000.0) -> 500000 | N22: =IFERROR(__xludf.DUMMYFUNCTION("""COMPUTED_VALUE"""),0.0) -> 0 | O22: =IFERROR(__xludf.DUMMYFUNCTION("""COMPUTED_VALUE"""),500000.0) -> 500000 | S22: =IFERROR(__xludf.DUMMYFUNCTION("""COMPUTED_VALUE"""),"Belum Lunas") -> Belum Lunas
A23: =IF(B23="","",ROW(A23)-1) -> 22 | B23: =IFERROR(__xludf.DUMMYFUNCTION("""COMPUTED_VALUE"""),"BAGAS KHOIRUL AZAM") -> BAGAS KHOIRUL AZAM | C23: =IFERROR(__xludf.DUMMYFUNCTION("""COMPUTED_VALUE"""),2.024070452E9) -> 2024070452 | D23: =IFERROR(__xludf.DUMMYFUNCTION("""COMPUTED_VALUE"""),"A") -> A | E23: =IFERROR(__xludf.DUMMYFUNCTION("""COMPUTED_VALUE"""),"A-8") -> A-8 | F23: =IFERROR(__xludf.DUMMYFUNCTION("""COMPUTED_VALUE"""),3.0) -> 3 | G23: =IFERROR(__xludf.DUMMYFUNCTION("""COMPUTED_VALUE"""),"3 ULA A PUTRA") -> 3 ULA A PUTRA | H23: =IFERROR(__xludf.DUMMYFUNCTION("""COMPUTED_VALUE"""),"MTS-9 D") -> MTS-9 D | I23: =IFERROR(__xludf.DUMMYFUNCTION("""COMPUTED_VALUE"""),"SUKANI") -> SUKANI | J23: =IFERROR(__xludf.DUMMYFUNCTION("""COMPUTED_VALUE"""),"WONOSARI MULYO 5/37 WONOKUSUMO RT 017 RW 007 SEMAMPIR SURABAYA") -> WONOSARI MULYO 5/37 WONOKUSUMO RT 017 RW 007 SEMAMPIR SURABAYA | K23: =IFERROR(__xludf.DUMMYFUNCTION("""COMPUTED_VALUE"""),"6285738565150") -> 6285738565150 | L23: =IFERROR(__xludf.DUMMYFUNCTION("""COMPUTED_VALUE"""),0.0) -> 0 | M23: =IFERROR(__xludf.DUMMYFUNCTION("""COMPUTED_VALUE"""),500000.0) -> 500000 | N23: =IFERROR(__xludf.DUMMYFUNCTION("""COMPUTED_VALUE"""),0.0) -> 0 | O23: =IFERROR(__xludf.DUMMYFUNCTION("""COMPUTED_VALUE"""),500000.0) -> 500000 | S23: =IFERROR(__xludf.DUMMYFUNCTION("""COMPUTED_VALUE"""),"Belum Lunas") -> Belum Lunas
A24: =IF(B24="","",ROW(A24)-1) -> 23 | B24: =IFERROR(__xludf.DUMMYFUNCTION("""COMPUTED_VALUE"""),"BATRISYIA ALFILZAH") -> BATRISYIA ALFILZAH | C24: =IFERROR(__xludf.DUMMYFUNCTION("""COMPUTED_VALUE"""),2.024070634E9) -> 2024070634 | D24: =IFERROR(__xludf.DUMMYFUNCTION("""COMPUTED_VALUE"""),"E") -> E | E24: =IFERROR(__xludf.DUMMYFUNCTION("""COMPUTED_VALUE"""),"E-2") -> E-2 | F24: =IFERROR(__xludf.DUMMYFUNCTION("""COMPUTED_VALUE"""),3.0) -> 3 | G24: =IFERROR(__xludf.DUMMYFUNCTION("""COMPUTED_VALUE"""),"3 ULA A PUTRI") -> 3 ULA A PUTRI | H24: =IFERROR(__xludf.DUMMYFUNCTION("""COMPUTED_VALUE"""),"MTS-9 H") -> MTS-9 H | I24: =IFERROR(__xludf.DUMMYFUNCTION("""COMPUTED_VALUE"""),"LILIS") -> LILIS | J24: =IFERROR(__xludf.DUMMYFUNCTION("""COMPUTED_VALUE"""),"KAWISTOLEGI RT 001 RW 001 KARANGGENENG LAMONGAN") -> KAWISTOLEGI RT 001 RW 001 KARANGGENENG LAMONGAN | K24: =IFERROR(__xludf.DUMMYFUNCTION("""COMPUTED_VALUE"""),"62895801050384") -> 62895801050384 | L24: =IFERROR(__xludf.DUMMYFUNCTION("""COMPUTED_VALUE"""),500000.0) -> 500000 | M24: =IFERROR(__xludf.DUMMYFUNCTION("""COMPUTED_VALUE"""),0.0) -> 0 | N24: =IFERROR(__xludf.DUMMYFUNCTION("""COMPUTED_VALUE"""),0.0) -> 0 | O24: =IFERROR(__xludf.DUMMYFUNCTION("""COMPUTED_VALUE"""),500000.0) -> 500000 | S24: =IFERROR(__xludf.DUMMYFUNCTION("""COMPUTED_VALUE"""),"Belum Lunas") -> Belum Lunas
A25: =IF(B25="","",ROW(A25)-1) -> 24 | B25: =IFERROR(__xludf.DUMMYFUNCTION("""COMPUTED_VALUE"""),"DEWI LAILA ANISAH SHOFIYAH") -> DEWI LAILA ANISAH SHOFIYAH | C25: =IFERROR(__xludf.DUMMYFUNCTION("""COMPUTED_VALUE"""),2.024070373E9) -> 2024070373 | D25: =IFERROR(__xludf.DUMMYFUNCTION("""COMPUTED_VALUE"""),"C") -> C | E25: =IFERROR(__xludf.DUMMYFUNCTION("""COMPUTED_VALUE"""),"C-9") -> C-9 | F25: =IFERROR(__xludf.DUMMYFUNCTION("""COMPUTED_VALUE"""),3.0) -> 3 | G25: =IFERROR(__xludf.DUMMYFUNCTION("""COMPUTED_VALUE"""),"3 WUSTHO A PUTRI") -> 3 WUSTHO A PUTRI | H25: =IFERROR(__xludf.DUMMYFUNCTION("""COMPUTED_VALUE"""),"MA-XII.12") -> MA-XII.12 | I25: =IFERROR(__xludf.DUMMYFUNCTION("""COMPUTED_VALUE"""),"SITI ROKANI") -> SITI ROKANI | J25: =IFERROR(__xludf.DUMMYFUNCTION("""COMPUTED_VALUE"""),"KADUNG KADUNGREMBUG RT 001 RW 005 SUKODADI LAMONGAN") -> KADUNG KADUNGREMBUG RT 001 RW 005 SUKODADI LAMONGAN | K25: =IFERROR(__xludf.DUMMYFUNCTION("""COMPUTED_VALUE"""),"6285748023154") -> 6285748023154 | L25: =IFERROR(__xludf.DUMMYFUNCTION("""COMPUTED_VALUE"""),0.0) -> 0 | M25: =IFERROR(__xludf.DUMMYFUNCTION("""COMPUTED_VALUE"""),500000.0) -> 500000 | N25: =IFERROR(__xludf.DUMMYFUNCTION("""COMPUTED_VALUE"""),0.0) -> 0 | O25: =IFERROR(__xludf.DUMMYFUNCTION("""COMPUTED_VALUE"""),500000.0) -> 500000 | S25: =IFERROR(__xludf.DUMMYFUNCTION("""COMPUTED_VALUE"""),"Belum Lunas") -> Belum Lunas
A26: =IF(B26="","",ROW(A26)-1) -> 25 | B26: =IFERROR(__xludf.DUMMYFUNCTION("""COMPUTED_VALUE"""),"DINI WAHYU NINGTYAS") -> DINI WAHYU NINGTYAS | C26: =IFERROR(__xludf.DUMMYFUNCTION("""COMPUTED_VALUE"""),2.024070688E9) -> 2024070688 | D26: =IFERROR(__xludf.DUMMYFUNCTION("""COMPUTED_VALUE"""),"B") -> B | E26: =IFERROR(__xludf.DUMMYFUNCTION("""COMPUTED_VALUE"""),"B-4") -> B-4 | F26: =IFERROR(__xludf.DUMMYFUNCTION("""COMPUTED_VALUE"""),3.0) -> 3 | G26: =IFERROR(__xludf.DUMMYFUNCTION("""COMPUTED_VALUE"""),"3 WUSTHO C PUTRI") -> 3 WUSTHO C PUTRI | H26: =IFERROR(__xludf.DUMMYFUNCTION("""COMPUTED_VALUE"""),"SMK-XII DKV") -> SMK-XII DKV | I26: =IFERROR(__xludf.DUMMYFUNCTION("""COMPUTED_VALUE"""),"YA ANTI") -> YA ANTI | J26: =IFERROR(__xludf.DUMMYFUNCTION("""COMPUTED_VALUE"""),"TIRTA MULIA BATU MERANTI RT 011 RW 005 SUNGAILOBAN TANAH BUMBU") -> TIRTA MULIA BATU MERANTI RT 011 RW 005 SUNGAILOBAN TANAH BUMBU | K26: =IFERROR(__xludf.DUMMYFUNCTION("""COMPUTED_VALUE"""),"6281255133458") -> 6281255133458 | L26: =IFERROR(__xludf.DUMMYFUNCTION("""COMPUTED_VALUE"""),0.0) -> 0 | M26: =IFERROR(__xludf.DUMMYFUNCTION("""COMPUTED_VALUE"""),500000.0) -> 500000 | N26: =IFERROR(__xludf.DUMMYFUNCTION("""COMPUTED_VALUE"""),0.0) -> 0 | O26: =IFERROR(__xludf.DUMMYFUNCTION("""COMPUTED_VALUE"""),500000.0) -> 500000 | S26: =IFERROR(__xludf.DUMMYFUNCTION("""COMPUTED_VALUE"""),"Belum Lunas") -> Belum Lunas
A27: =IF(B27="","",ROW(A27)-1) -> 26 | B27: =IFERROR(__xludf.DUMMYFUNCTION("""COMPUTED_VALUE"""),"DIVA APRILIA SHOLIKHA") -> DIVA APRILIA SHOLIKHA | C27: =IFERROR(__xludf.DUMMYFUNCTION("""COMPUTED_VALUE"""),2.024070223E9) -> 2024070223 | D27: =IFERROR(__xludf.DUMMYFUNCTION("""COMPUTED_VALUE"""),"C") -> C | E27: =IFERROR(__xludf.DUMMYFUNCTION("""COMPUTED_VALUE"""),"C-8") -> C-8 | F27: =IFERROR(__xludf.DUMMYFUNCTION("""COMPUTED_VALUE"""),3.0) -> 3 | G27: =IFERROR(__xludf.DUMMYFUNCTION("""COMPUTED_VALUE"""),"3 WUSTHO A PUTRI") -> 3 WUSTHO A PUTRI | H27: =IFERROR(__xludf.DUMMYFUNCTION("""COMPUTED_VALUE"""),"MA-XII.6") -> MA-XII.6 | I27: =IFERROR(__xludf.DUMMYFUNCTION("""COMPUTED_VALUE"""),"KHOTIM SUNARIYAH") -> KHOTIM SUNARIYAH | J27: =IFERROR(__xludf.DUMMYFUNCTION("""COMPUTED_VALUE"""),"KARANGCANGKRING RT 7 RW 3 DUKUN GRESIK") -> KARANGCANGKRING RT 7 RW 3 DUKUN GRESIK | K27: =IFERROR(__xludf.DUMMYFUNCTION("""COMPUTED_VALUE"""),"6281553483950") -> 6281553483950 | L27: =IFERROR(__xludf.DUMMYFUNCTION("""COMPUTED_VALUE"""),0.0) -> 0 | M27: =IFERROR(__xludf.DUMMYFUNCTION("""COMPUTED_VALUE"""),500000.0) -> 500000 | N27: =IFERROR(__xludf.DUMMYFUNCTION("""COMPUTED_VALUE"""),0.0) -> 0 | O27: =IFERROR(__xludf.DUMMYFUNCTION("""COMPUTED_VALUE"""),500000.0) -> 500000 | S27: =IFERROR(__xludf.DUMMYFUNCTION("""COMPUTED_VALUE"""),"Belum Lunas") -> Belum Lunas
A28: =IF(B28="","",ROW(A28)-1) -> 27 | B28: =IFERROR(__xludf.DUMMYFUNCTION("""COMPUTED_VALUE"""),"ELSA LAILATUN NIHAYAH") -> ELSA LAILATUN NIHAYAH | C28: =IFERROR(__xludf.DUMMYFUNCTION("""COMPUTED_VALUE"""),2.024070112E9) -> 2024070112 | D28: =IFERROR(__xludf.DUMMYFUNCTION("""COMPUTED_VALUE"""),"C") -> C | E28: =IFERROR(__xludf.DUMMYFUNCTION("""COMPUTED_VALUE"""),"C-9") -> C-9 | F28: =IFERROR(__xludf.DUMMYFUNCTION("""COMPUTED_VALUE"""),3.0) -> 3 | G28: =IFERROR(__xludf.DUMMYFUNCTION("""COMPUTED_VALUE"""),"3 WUSTHO B PUTRI") -> 3 WUSTHO B PUTRI | H28: =IFERROR(__xludf.DUMMYFUNCTION("""COMPUTED_VALUE"""),"MA-XII.4") -> MA-XII.4 | I28: =IFERROR(__xludf.DUMMYFUNCTION("""COMPUTED_VALUE"""),"KARMU") -> KARMU | J28: =IFERROR(__xludf.DUMMYFUNCTION("""COMPUTED_VALUE"""),"CLURING RT 002 RW 002 KALITENGAH LAMONGAN") -> CLURING RT 002 RW 002 KALITENGAH LAMONGAN | K28: =IFERROR(__xludf.DUMMYFUNCTION("""COMPUTED_VALUE"""),"6287794103025") -> 6287794103025 | L28: =IFERROR(__xludf.DUMMYFUNCTION("""COMPUTED_VALUE"""),0.0) -> 0 | M28: =IFERROR(__xludf.DUMMYFUNCTION("""COMPUTED_VALUE"""),500000.0) -> 500000 | N28: =IFERROR(__xludf.DUMMYFUNCTION("""COMPUTED_VALUE"""),0.0) -> 0 | O28: =IFERROR(__xludf.DUMMYFUNCTION("""COMPUTED_VALUE"""),500000.0) -> 500000 | S28: =IFERROR(__xludf.DUMMYFUNCTION("""COMPUTED_VALUE"""),"Belum Lunas") -> Belum Lunas
A29: =IF(B29="","",ROW(A29)-1) -> 28 | B29: =IFERROR(__xludf.DUMMYFUNCTION("""COMPUTED_VALUE"""),"ERIN MAULIDIAH") -> ERIN MAULIDIAH | C29: =IFERROR(__xludf.DUMMYFUNCTION("""COMPUTED_VALUE"""),2.024070475E9) -> 2024070475 | D29: =IFERROR(__xludf.DUMMYFUNCTION("""COMPUTED_VALUE"""),"E") -> E | E29: =IFERROR(__xludf.DUMMYFUNCTION("""COMPUTED_VALUE"""),"E-3") -> E-3 | F29: =IFERROR(__xludf.DUMMYFUNCTION("""COMPUTED_VALUE"""),3.0) -> 3 | G29: =IFERROR(__xludf.DUMMYFUNCTION("""COMPUTED_VALUE"""),"3 ULA B PUTRI") -> 3 ULA B PUTRI | H29: =IFERROR(__xludf.DUMMYFUNCTION("""COMPUTED_VALUE"""),"MTS-9 B") -> MTS-9 B | I29: =IFERROR(__xludf.DUMMYFUNCTION("""COMPUTED_VALUE"""),"ASMAUS SHOFIYANAH") -> ASMAUS SHOFIYANAH | J29: =IFERROR(__xludf.DUMMYFUNCTION("""COMPUTED_VALUE"""),"NGAYUNG RT 005 RW 002 MADURAN LAMONGAN") -> NGAYUNG RT 005 RW 002 MADURAN LAMONGAN | K29: =IFERROR(__xludf.DUMMYFUNCTION("""COMPUTED_VALUE"""),"6282233810314") -> 6282233810314 | L29: =IFERROR(__xludf.DUMMYFUNCTION("""COMPUTED_VALUE"""),0.0) -> 0 | M29: =IFERROR(__xludf.DUMMYFUNCTION("""COMPUTED_VALUE"""),500000.0) -> 500000 | N29: =IFERROR(__xludf.DUMMYFUNCTION("""COMPUTED_VALUE"""),0.0) -> 0 | O29: =IFERROR(__xludf.DUMMYFUNCTION("""COMPUTED_VALUE"""),500000.0) -> 500000 | S29: =IFERROR(__xludf.DUMMYFUNCTION("""COMPUTED_VALUE"""),"Belum Lunas") -> Belum Lunas
A30: =IF(B30="","",ROW(A30)-1) -> 29 | B30: =IFERROR(__xludf.DUMMYFUNCTION("""COMPUTED_VALUE"""),"FAIQOTUR RIFDAH AL ABIDAH") -> FAIQOTUR RIFDAH AL ABIDAH | C30: =IFERROR(__xludf.DUMMYFUNCTION("""COMPUTED_VALUE"""),2.024070487E9) -> 2024070487 | D30: =IFERROR(__xludf.DUMMYFUNCTION("""COMPUTED_VALUE"""),"E") -> E | E30: =IFERROR(__xludf.DUMMYFUNCTION("""COMPUTED_VALUE"""),"E-2") -> E-2 | F30: =IFERROR(__xludf.DUMMYFUNCTION("""COMPUTED_VALUE"""),3.0) -> 3 | G30: =IFERROR(__xludf.DUMMYFUNCTION("""COMPUTED_VALUE"""),"3 ULA B PUTRI") -> 3 ULA B PUTRI | H30: =IFERROR(__xludf.DUMMYFUNCTION("""COMPUTED_VALUE"""),"MTS-9 C") -> MTS-9 C | I30: =IFERROR(__xludf.DUMMYFUNCTION("""COMPUTED_VALUE"""),"CHAMIMAH") -> CHAMIMAH | J30: =IFERROR(__xludf.DUMMYFUNCTION("""COMPUTED_VALUE"""),"PLOSOSETRO RT 008 RW 002 PUCUK LAMONGAN") -> PLOSOSETRO RT 008 RW 002 PUCUK LAMONGAN | K30: =IFERROR(__xludf.DUMMYFUNCTION("""COMPUTED_VALUE"""),"6285791612653") -> 6285791612653 | L30: =IFERROR(__xludf.DUMMYFUNCTION("""COMPUTED_VALUE"""),0.0) -> 0 | M30: =IFERROR(__xludf.DUMMYFUNCTION("""COMPUTED_VALUE"""),500000.0) -> 500000 | N30: =IFERROR(__xludf.DUMMYFUNCTION("""COMPUTED_VALUE"""),0.0) -> 0 | O30: =IFERROR(__xludf.DUMMYFUNCTION("""COMPUTED_VALUE"""),500000.0) -> 500000 | S30: =IFERROR(__xludf.DUMMYFUNCTION("""COMPUTED_VALUE"""),"Belum Lunas") -> Belum Lunas
A31: =IF(B31="","",ROW(A31)-1) -> 30 | B31: =IFERROR(__xludf.DUMMYFUNCTION("""COMPUTED_VALUE"""),"FAIRUZZABADI WAHYU MAHFUL") -> FAIRUZZABADI WAHYU MAHFUL | C31: =IFERROR(__xludf.DUMMYFUNCTION("""COMPUTED_VALUE"""),2.024070458E9) -> 2024070458 | D31: =IFERROR(__xludf.DUMMYFUNCTION("""COMPUTED_VALUE"""),"A") -> A | E31: =IFERROR(__xludf.DUMMYFUNCTION("""COMPUTED_VALUE"""),"A-7") -> A-7 | F31: =IFERROR(__xludf.DUMMYFUNCTION("""COMPUTED_VALUE"""),3.0) -> 3 | G31: =IFERROR(__xludf.DUMMYFUNCTION("""COMPUTED_VALUE"""),"3 ULA A PUTRA") -> 3 ULA A PUTRA | H31: =IFERROR(__xludf.DUMMYFUNCTION("""COMPUTED_VALUE"""),"MTS-9 E") -> MTS-9 E | I31: =IFERROR(__xludf.DUMMYFUNCTION("""COMPUTED_VALUE"""),"TRI UTAMI") -> TRI UTAMI | J31: =IFERROR(__xludf.DUMMYFUNCTION("""COMPUTED_VALUE"""),"PAJANGAN RT 001 RW 002 SUKODADI LAMONGAN") -> PAJANGAN RT 001 RW 002 SUKODADI LAMONGAN | K31: =IFERROR(__xludf.DUMMYFUNCTION("""COMPUTED_VALUE"""),"6285730482785") -> 6285730482785 | L31: =IFERROR(__xludf.DUMMYFUNCTION("""COMPUTED_VALUE"""),0.0) -> 0 | M31: =IFERROR(__xludf.DUMMYFUNCTION("""COMPUTED_VALUE"""),500000.0) -> 500000 | N31: =IFERROR(__xludf.DUMMYFUNCTION("""COMPUTED_VALUE"""),0.0) -> 0 | O31: =IFERROR(__xludf.DUMMYFUNCTION("""COMPUTED_VALUE"""),500000.0) -> 500000 | S31: =IFERROR(__xludf.DUMMYFUNCTION("""COMPUTED_VALUE"""),"Belum Lunas") -> Belum Lunas
A32: =IF(B32="","",ROW(A32)-1) -> 31 | B32: =IFERROR(__xludf.DUMMYFUNCTION("""COMPUTED_VALUE"""),"FARAH OKTARIAN SYAHPUTRI") -> FARAH OKTARIAN SYAHPUTRI | C32: =IFERROR(__xludf.DUMMYFUNCTION("""COMPUTED_VALUE"""),2.024070466E9) -> 2024070466 | D32: =IFERROR(__xludf.DUMMYFUNCTION("""COMPUTED_VALUE"""),"E") -> E | E32: =IFERROR(__xludf.DUMMYFUNCTION("""COMPUTED_VALUE"""),"E-9") -> E-9 | F32: =IFERROR(__xludf.DUMMYFUNCTION("""COMPUTED_VALUE"""),3.0) -> 3 | G32: =IFERROR(__xludf.DUMMYFUNCTION("""COMPUTED_VALUE"""),"3 ULA C PUTRI") -> 3 ULA C PUTRI | H32: =IFERROR(__xludf.DUMMYFUNCTION("""COMPUTED_VALUE"""),"MTS-9 A") -> MTS-9 A | I32: =IFERROR(__xludf.DUMMYFUNCTION("""COMPUTED_VALUE"""),"HUSNUL MUSTAFIDAH") -> HUSNUL MUSTAFIDAH | J32: =IFERROR(__xludf.DUMMYFUNCTION("""COMPUTED_VALUE"""),"JL. RAYA SUGIO NO. 53 KEBET RT 004 RW 001 LAMONGAN LAMONGAN") -> JL. RAYA SUGIO NO. 53 KEBET RT 004 RW 001 LAMONGAN LAMONGAN | K32: =IFERROR(__xludf.DUMMYFUNCTION("""COMPUTED_VALUE"""),"6281332772930") -> 6281332772930 | L32: =IFERROR(__xludf.DUMMYFUNCTION("""COMPUTED_VALUE"""),0.0) -> 0 | M32: =IFERROR(__xludf.DUMMYFUNCTION("""COMPUTED_VALUE"""),500000.0) -> 500000 | N32: =IFERROR(__xludf.DUMMYFUNCTION("""COMPUTED_VALUE"""),0.0) -> 0 | O32: =IFERROR(__xludf.DUMMYFUNCTION("""COMPUTED_VALUE"""),500000.0) -> 500000 | S32: =IFERROR(__xludf.DUMMYFUNCTION("""COMPUTED_VALUE"""),"Belum Lunas") -> Belum Lunas
A33: =IF(B33="","",ROW(A33)-1) -> 32 | B33: =IFERROR(__xludf.DUMMYFUNCTION("""COMPUTED_VALUE"""),"FARIKHA AULIA SALSABILLAH") -> FARIKHA AULIA SALSABILLAH | C33: =IFERROR(__xludf.DUMMYFUNCTION("""COMPUTED_VALUE"""),2.024070074E9) -> 2024070074 | D33: =IFERROR(__xludf.DUMMYFUNCTION("""COMPUTED_VALUE"""),"C") -> C | E33: =IFERROR(__xludf.DUMMYFUNCTION("""COMPUTED_VALUE"""),"C-4") -> C-4 | F33: =IFERROR(__xludf.DUMMYFUNCTION("""COMPUTED_VALUE"""),3.0) -> 3 | G33: =IFERROR(__xludf.DUMMYFUNCTION("""COMPUTED_VALUE"""),"3 WUSTHO B PUTRI") -> 3 WUSTHO B PUTRI | H33: =IFERROR(__xludf.DUMMYFUNCTION("""COMPUTED_VALUE"""),"MA-XII.3") -> MA-XII.3 | I33: =IFERROR(__xludf.DUMMYFUNCTION("""COMPUTED_VALUE"""),"SUNARTI") -> SUNARTI | J33: =IFERROR(__xludf.DUMMYFUNCTION("""COMPUTED_VALUE"""),"WEDENG SUKOREJO RT 001 RW 003 KARANGBINANGUN LAMONGAN") -> WEDENG SUKOREJO RT 001 RW 003 KARANGBINANGUN LAMONGAN | K33: =IFERROR(__xludf.DUMMYFUNCTION("""COMPUTED_VALUE"""),"6285645468404") -> 6285645468404 | L33: =IFERROR(__xludf.DUMMYFUNCTION("""COMPUTED_VALUE"""),0.0) -> 0 | M33: =IFERROR(__xludf.DUMMYFUNCTION("""COMPUTED_VALUE"""),500000.0) -> 500000 | N33: =IFERROR(__xludf.DUMMYFUNCTION("""COMPUTED_VALUE"""),0.0) -> 0 | O33: =IFERROR(__xludf.DUMMYFUNCTION("""COMPUTED_VALUE"""),500000.0) -> 500000 | S33: =IFERROR(__xludf.DUMMYFUNCTION("""COMPUTED_VALUE"""),"Belum Lunas") -> Belum Lunas
A34: =IF(B34="","",ROW(A34)-1) -> 33 | B34: =IFERROR(__xludf.DUMMYFUNCTION("""COMPUTED_VALUE"""),"FATIMAH AZ-ZAHRAH") -> FATIMAH AZ-ZAHRAH | C34: =IFERROR(__xludf.DUMMYFUNCTION("""COMPUTED_VALUE"""),2.024070507E9) -> 2024070507 | D34: =IFERROR(__xludf.DUMMYFUNCTION("""COMPUTED_VALUE"""),"B") -> B | E34: =IFERROR(__xludf.DUMMYFUNCTION("""COMPUTED_VALUE"""),"B-9") -> B-9 | F34: =IFERROR(__xludf.DUMMYFUNCTION("""COMPUTED_VALUE"""),3.0) -> 3 | G34: =IFERROR(__xludf.DUMMYFUNCTION("""COMPUTED_VALUE"""),"3 ULA B PUTRI") -> 3 ULA B PUTRI | H34: =IFERROR(__xludf.DUMMYFUNCTION("""COMPUTED_VALUE"""),"MTS-9 H") -> MTS-9 H | I34: =IFERROR(__xludf.DUMMYFUNCTION("""COMPUTED_VALUE"""),"SITI LUTHFIYAH") -> SITI LUTHFIYAH | J34: =IFERROR(__xludf.DUMMYFUNCTION("""COMPUTED_VALUE"""),"SONGO SUKOSONGO RT 013 RW 006 KEMBANGBAHU LAMONGAN") -> SONGO SUKOSONGO RT 013 RW 006 KEMBANGBAHU LAMONGAN | K34: =IFERROR(__xludf.DUMMYFUNCTION("""COMPUTED_VALUE"""),"6285706056735") -> 6285706056735 | L34: =IFERROR(__xludf.DUMMYFUNCTION("""COMPUTED_VALUE"""),0.0) -> 0 | M34: =IFERROR(__xludf.DUMMYFUNCTION("""COMPUTED_VALUE"""),500000.0) -> 500000 | N34: =IFERROR(__xludf.DUMMYFUNCTION("""COMPUTED_VALUE"""),0.0) -> 0 | O34: =IFERROR(__xludf.DUMMYFUNCTION("""COMPUTED_VALUE"""),500000.0) -> 500000 | S34: =IFERROR(__xludf.DUMMYFUNCTION("""COMPUTED_VALUE"""),"Belum Lunas") -> Belum Lunas
A35: =IF(B35="","",ROW(A35)-1) -> 34 | B35: =IFERROR(__xludf.DUMMYFUNCTION("""COMPUTED_VALUE"""),"GALANG SAPUTRA") -> GALANG SAPUTRA | C35: =IFERROR(__xludf.DUMMYFUNCTION("""COMPUTED_VALUE"""),2.02407073E9) -> 2024070730 | D35: =IFERROR(__xludf.DUMMYFUNCTION("""COMPUTED_VALUE"""),"A") -> A | E35: =IFERROR(__xludf.DUMMYFUNCTION("""COMPUTED_VALUE"""),"A-8") -> A-8 | F35: =IFERROR(__xludf.DUMMYFUNCTION("""COMPUTED_VALUE"""),3.0) -> 3 | G35: =IFERROR(__xludf.DUMMYFUNCTION("""COMPUTED_VALUE"""),"3 ULA A PUTRA") -> 3 ULA A PUTRA | H35: =IFERROR(__xludf.DUMMYFUNCTION("""COMPUTED_VALUE"""),"SMP-IX A") -> SMP-IX A | I35: =IFERROR(__xludf.DUMMYFUNCTION("""COMPUTED_VALUE"""),"SULIYATI") -> SULIYATI | J35: =IFERROR(__xludf.DUMMYFUNCTION("""COMPUTED_VALUE"""),"DORO KARANGWEDORO RT 009 RW 003 TURI LAMONGAN") -> DORO KARANGWEDORO RT 009 RW 003 TURI LAMONGAN | K35: =IFERROR(__xludf.DUMMYFUNCTION("""COMPUTED_VALUE"""),"6285756513128") -> 6285756513128 | L35: =IFERROR(__xludf.DUMMYFUNCTION("""COMPUTED_VALUE"""),0.0) -> 0 | M35: =IFERROR(__xludf.DUMMYFUNCTION("""COMPUTED_VALUE"""),500000.0) -> 500000 | N35: =IFERROR(__xludf.DUMMYFUNCTION("""COMPUTED_VALUE"""),0.0) -> 0 | O35: =IFERROR(__xludf.DUMMYFUNCTION("""COMPUTED_VALUE"""),500000.0) -> 500000 | S35: =IFERROR(__xludf.DUMMYFUNCTION("""COMPUTED_VALUE"""),"Belum Lunas") -> Belum Lunas
A36: =IF(B36="","",ROW(A36)-1) -> 35 | B36: =IFERROR(__xludf.DUMMYFUNCTION("""COMPUTED_VALUE"""),"GHITA RAINA AZZAHRA PRIYANTO") -> GHITA RAINA AZZAHRA PRIYANTO | C36: =IFERROR(__xludf.DUMMYFUNCTION("""COMPUTED_VALUE"""),2.024070636E9) -> 2024070636 | D36: =IFERROR(__xludf.DUMMYFUNCTION("""COMPUTED_VALUE"""),"C") -> C | E36: =IFERROR(__xludf.DUMMYFUNCTION("""COMPUTED_VALUE"""),"C-12") -> C-12 | F36: =IFERROR(__xludf.DUMMYFUNCTION("""COMPUTED_VALUE"""),3.0) -> 3 | G36: =IFERROR(__xludf.DUMMYFUNCTION("""COMPUTED_VALUE"""),"3 ULA C PUTRI") -> 3 ULA C PUTRI | H36: =IFERROR(__xludf.DUMMYFUNCTION("""COMPUTED_VALUE"""),"MTS-9 H") -> MTS-9 H | I36: =IFERROR(__xludf.DUMMYFUNCTION("""COMPUTED_VALUE"""),"ANIS ROHMAWATI") -> ANIS ROHMAWATI | J36: =IFERROR(__xludf.DUMMYFUNCTION("""COMPUTED_VALUE"""),"TULUNG WANAR RT 004 RW 005 PUCUK LAMONGAN") -> TULUNG WANAR RT 004 RW 005 PUCUK LAMONGAN | K36: =IFERROR(__xludf.DUMMYFUNCTION("""COMPUTED_VALUE"""),"6281260170147") -> 6281260170147 | L36: =IFERROR(__xludf.DUMMYFUNCTION("""COMPUTED_VALUE"""),0.0) -> 0 | M36: =IFERROR(__xludf.DUMMYFUNCTION("""COMPUTED_VALUE"""),500000.0) -> 500000 | N36: =IFERROR(__xludf.DUMMYFUNCTION("""COMPUTED_VALUE"""),0.0) -> 0 | O36: =IFERROR(__xludf.DUMMYFUNCTION("""COMPUTED_VALUE"""),500000.0) -> 500000 | S36: =IFERROR(__xludf.DUMMYFUNCTION("""COMPUTED_VALUE"""),"Belum Lunas") -> Belum Lunas
A37: =IF(B37="","",ROW(A37)-1) -> 36 | B37: =IFERROR(__xludf.DUMMYFUNCTION("""COMPUTED_VALUE"""),"HAMDAN ALIEF") -> HAMDAN ALIEF | C37: =IFERROR(__xludf.DUMMYFUNCTION("""COMPUTED_VALUE"""),2.024070663E9) -> 2024070663 | D37: =IFERROR(__xludf.DUMMYFUNCTION("""COMPUTED_VALUE"""),"A") -> A | E37: =IFERROR(__xludf.DUMMYFUNCTION("""COMPUTED_VALUE"""),"A-7") -> A-7 | F37: =IFERROR(__xludf.DUMMYFUNCTION("""COMPUTED_VALUE"""),3.0) -> 3 | G37: =IFERROR(__xludf.DUMMYFUNCTION("""COMPUTED_VALUE"""),"3 ULA A PUTRA") -> 3 ULA A PUTRA | H37: =IFERROR(__xludf.DUMMYFUNCTION("""COMPUTED_VALUE"""),"MTS-9 D") -> MTS-9 D | I37: =IFERROR(__xludf.DUMMYFUNCTION("""COMPUTED_VALUE"""),"NUR AMALAH") -> NUR AMALAH | J37: =IFERROR(__xludf.DUMMYFUNCTION("""COMPUTED_VALUE"""),"SEMOLOWARU UTARA 1/31 RT 005 RW 001 SUKOLILO SURABAYA") -> SEMOLOWARU UTARA 1/31 RT 005 RW 001 SUKOLILO SURABAYA | K37: =IFERROR(__xludf.DUMMYFUNCTION("""COMPUTED_VALUE"""),"6281216694589") -> 6281216694589 | L37: =IFERROR(__xludf.DUMMYFUNCTION("""COMPUTED_VALUE"""),0.0) -> 0 | M37: =IFERROR(__xludf.DUMMYFUNCTION("""COMPUTED_VALUE"""),500000.0) -> 500000 | N37: =IFERROR(__xludf.DUMMYFUNCTION("""COMPUTED_VALUE"""),0.0) -> 0 | O37: =IFERROR(__xludf.DUMMYFUNCTION("""COMPUTED_VALUE"""),500000.0) -> 500000 | S37: =IFERROR(__xludf.DUMMYFUNCTION("""COMPUTED_VALUE"""),"Belum Lunas") -> Belum Lunas
A38: =IF(B38="","",ROW(A38)-1) -> 37 | B38: =IFERROR(__xludf.DUMMYFUNCTION("""COMPUTED_VALUE"""),"HILDA AFRILLIA SALSA FUNNY") -> HILDA AFRILLIA SALSA FUNNY | C38: =IFERROR(__xludf.DUMMYFUNCTION("""COMPUTED_VALUE"""),2.024070609E9) -> 2024070609 | D38: =IFERROR(__xludf.DUMMYFUNCTION("""COMPUTED_VALUE"""),"C") -> C | E38: =IFERROR(__xludf.DUMMYFUNCTION("""COMPUTED_VALUE"""),"C-12") -> C-12 | F38: =IFERROR(__xludf.DUMMYFUNCTION("""COMPUTED_VALUE"""),3.0) -> 3 | G38: =IFERROR(__xludf.DUMMYFUNCTION("""COMPUTED_VALUE"""),"3 ULA C PUTRI") -> 3 ULA C PUTRI | H38: =IFERROR(__xludf.DUMMYFUNCTION("""COMPUTED_VALUE"""),"MTS-9 D") -> MTS-9 D | I38: =IFERROR(__xludf.DUMMYFUNCTION("""COMPUTED_VALUE"""),"SUNTIANAH") -> SUNTIANAH | J38: =IFERROR(__xludf.DUMMYFUNCTION("""COMPUTED_VALUE"""),"KULURAN RT 004 RW 003 KALITENGAH LAMONGAN") -> KULURAN RT 004 RW 003 KALITENGAH LAMONGAN | K38: =IFERROR(__xludf.DUMMYFUNCTION("""COMPUTED_VALUE"""),"628570216013") -> 628570216013 | L38: =IFERROR(__xludf.DUMMYFUNCTION("""COMPUTED_VALUE"""),0.0) -> 0 | M38: =IFERROR(__xludf.DUMMYFUNCTION("""COMPUTED_VALUE"""),500000.0) -> 500000 | N38: =IFERROR(__xludf.DUMMYFUNCTION("""COMPUTED_VALUE"""),0.0) -> 0 | O38: =IFERROR(__xludf.DUMMYFUNCTION("""COMPUTED_VALUE"""),500000.0) -> 500000 | S38: =IFERROR(__xludf.DUMMYFUNCTION("""COMPUTED_VALUE"""),"Belum Lunas") -> Belum Lunas
A39: =IF(B39="","",ROW(A39)-1) -> 38 | B39: =IFERROR(__xludf.DUMMYFUNCTION("""COMPUTED_VALUE"""),"KEYSHA BRILLYAN FEBIANA") -> KEYSHA BRILLYAN FEBIANA | C39: =IFERROR(__xludf.DUMMYFUNCTION("""COMPUTED_VALUE"""),2.024070513E9) -> 2024070513 | D39: =IFERROR(__xludf.DUMMYFUNCTION("""COMPUTED_VALUE"""),"E") -> E | E39: =IFERROR(__xludf.DUMMYFUNCTION("""COMPUTED_VALUE"""),"E-3") -> E-3 | F39: =IFERROR(__xludf.DUMMYFUNCTION("""COMPUTED_VALUE"""),3.0) -> 3 | G39: =IFERROR(__xludf.DUMMYFUNCTION("""COMPUTED_VALUE"""),"3 ULA C PUTRI") -> 3 ULA C PUTRI | H39: =IFERROR(__xludf.DUMMYFUNCTION("""COMPUTED_VALUE"""),"MTS-9 G") -> MTS-9 G | I39: =IFERROR(__xludf.DUMMYFUNCTION("""COMPUTED_VALUE"""),"SISKA APRILIA") -> SISKA APRILIA | J39: =IFERROR(__xludf.DUMMYFUNCTION("""COMPUTED_VALUE"""),"PENGANGSALAN RT 001 RW 001 KALITENGAH LAMONGAN") -> PENGANGSALAN RT 001 RW 001 KALITENGAH LAMONGAN | K39: =IFERROR(__xludf.DUMMYFUNCTION("""COMPUTED_VALUE"""),"628564039966") -> 628564039966 | L39: =IFERROR(__xludf.DUMMYFUNCTION("""COMPUTED_VALUE"""),0.0) -> 0 | M39: =IFERROR(__xludf.DUMMYFUNCTION("""COMPUTED_VALUE"""),500000.0) -> 500000 | N39: =IFERROR(__xludf.DUMMYFUNCTION("""COMPUTED_VALUE"""),0.0) -> 0 | O39: =IFERROR(__xludf.DUMMYFUNCTION("""COMPUTED_VALUE"""),500000.0) -> 500000 | S39: =IFERROR(__xludf.DUMMYFUNCTION("""COMPUTED_VALUE"""),"Belum Lunas") -> Belum Lunas
A40: =IF(B40="","",ROW(A40)-1) -> 39 | B40: =IFERROR(__xludf.DUMMYFUNCTION("""COMPUTED_VALUE"""),"LALUNA NAYRA KAMILA") -> LALUNA NAYRA KAMILA | C40: =IFERROR(__xludf.DUMMYFUNCTION("""COMPUTED_VALUE"""),2.025070425E9) -> 2025070425 | D40: =IFERROR(__xludf.DUMMYFUNCTION("""COMPUTED_VALUE"""),"D") -> D | E40: =IFERROR(__xludf.DUMMYFUNCTION("""COMPUTED_VALUE"""),"D-6") -> D-6 | F40: =IFERROR(__xludf.DUMMYFUNCTION("""COMPUTED_VALUE"""),3.0) -> 3 | G40: =IFERROR(__xludf.DUMMYFUNCTION("""COMPUTED_VALUE"""),"3 WUSTHO C PUTRI") -> 3 WUSTHO C PUTRI | H40: =IFERROR(__xludf.DUMMYFUNCTION("""COMPUTED_VALUE"""),"MA-XII.12") -> MA-XII.12 | I40: =IFERROR(__xludf.DUMMYFUNCTION("""COMPUTED_VALUE"""),"ISTIADATUR RIZA") -> ISTIADATUR RIZA | J40: =IFERROR(__xludf.DUMMYFUNCTION("""COMPUTED_VALUE"""),"NGILANG RT 002 RW 001 KALEN KEDUNGPRING LAMONGAN") -> NGILANG RT 002 RW 001 KALEN KEDUNGPRING LAMONGAN | K40: =IFERROR(__xludf.DUMMYFUNCTION("""COMPUTED_VALUE"""),"6281331012600") -> 6281331012600 | L40: =IFERROR(__xludf.DUMMYFUNCTION("""COMPUTED_VALUE"""),0.0) -> 0 | M40: =IFERROR(__xludf.DUMMYFUNCTION("""COMPUTED_VALUE"""),500000.0) -> 500000 | N40: =IFERROR(__xludf.DUMMYFUNCTION("""COMPUTED_VALUE"""),0.0) -> 0 | O40: =IFERROR(__xludf.DUMMYFUNCTION("""COMPUTED_VALUE"""),500000.0) -> 500000 | S40: =IFERROR(__xludf.DUMMYFUNCTION("""COMPUTED_VALUE"""),"Belum Lunas") -> Belum Lunas
...

Sheet textvalue
A1: NO | B1: NAMA | C1: NIS | D1: ASRAMA | E1: KAMAR | F1: TINGKAT | G1: MADRASIAH | H1: HP | I1: JUMLAH SYAHRIYAH | J1: JUMLAH JARIYAH | K1: JUMLAH DAFTAR ULANG | L1: JUMLAH TOTAL TUNGGAKAN | M1: Syahriyah | N1: Jariyah | O1: Daftar Ulang | P1: Total | Q1: Rincian & Total
A2: =IF(B2="","",ROW(A2)-1) -> 1 | B2: =IFERROR(__xludf.DUMMYFUNCTION("SORT(QUERY(Sheet1!B2:W750,""Select Col1,Col2,Col3,Col4,Col5,Col6,Col10,Col11,Col12,Col13,Col14 Where Col3 IS NOT NULL "",""""),11,2)"),"DWI MAULIDIYAH") -> DWI MAULIDIYAH | C2: =IFERROR(__xludf.DUMMYFUNCTION("""COMPUTED_VALUE"""),2.024070596E9) -> 2024070596 | D2: =IFERROR(__xludf.DUMMYFUNCTION("""COMPUTED_VALUE"""),"E") -> E | E2: =IFERROR(__xludf.DUMMYFUNCTION("""COMPUTED_VALUE"""),"E-9") -> E-9 | F2: =IFERROR(__xludf.DUMMYFUNCTION("""COMPUTED_VALUE"""),3.0) -> 3 | G2: =IFERROR(__xludf.DUMMYFUNCTION("""COMPUTED_VALUE"""),"3 ULA B PUTRI") -> 3 ULA B PUTRI | H2: =IFERROR(__xludf.DUMMYFUNCTION("""COMPUTED_VALUE"""),"6285853420436") -> 6285853420436 | I2: =IFERROR(__xludf.DUMMYFUNCTION("""COMPUTED_VALUE"""),270000.0) -> 270000 | J2: =IFERROR(__xludf.DUMMYFUNCTION("""COMPUTED_VALUE"""),0.0) -> 0 | K2: =IFERROR(__xludf.DUMMYFUNCTION("""COMPUTED_VALUE"""),0.0) -> 0 | L2: =IFERROR(__xludf.DUMMYFUNCTION("""COMPUTED_VALUE"""),270000.0) -> 270000 | M2: =text(I2,"Rp #,##0") -> Rp 270.000 | N2: =text(J2,"Rp #,##0") -> Rp 0 | O2: =text(K2,"Rp #,##0") -> Rp 0 | P2: =text(L2,"Rp #,##0") -> Rp 270.000 | Q2: =$M$1&" = "&M2&" "&$N$1&" = "&N2&" "&$O$1&" = "&O2&" "&$P$1&" = "&P2&" ______________________"&R2&" ID : "&C2 -> Syahriyah = Rp 270.000 Jariyah = Rp 0 Daftar Ulang = Rp 0 Total = Rp 270.000 ______________________ ID : 2024070596
A3: =IF(B3="","",ROW(A3)-1) -> 2 | B3: =IFERROR(__xludf.DUMMYFUNCTION("""COMPUTED_VALUE"""),"M. FAHMI ALFIYAN NURIL HAQ") -> M. FAHMI ALFIYAN NURIL HAQ | C3: =IFERROR(__xludf.DUMMYFUNCTION("""COMPUTED_VALUE"""),2.024070718E9) -> 2024070718 | D3: =IFERROR(__xludf.DUMMYFUNCTION("""COMPUTED_VALUE"""),"A") -> A | E3: =IFERROR(__xludf.DUMMYFUNCTION("""COMPUTED_VALUE"""),"A-13") -> A-13 | F3: =IFERROR(__xludf.DUMMYFUNCTION("""COMPUTED_VALUE"""),3.0) -> 3 | H3: =IFERROR(__xludf.DUMMYFUNCTION("""COMPUTED_VALUE"""),"6289677807375") -> 6289677807375 | I3: =IFERROR(__xludf.DUMMYFUNCTION("""COMPUTED_VALUE"""),410000.0) -> 410000 | J3: =IFERROR(__xludf.DUMMYFUNCTION("""COMPUTED_VALUE"""),0.0) -> 0 | K3: =IFERROR(__xludf.DUMMYFUNCTION("""COMPUTED_VALUE"""),0.0) -> 0 | L3: =IFERROR(__xludf.DUMMYFUNCTION("""COMPUTED_VALUE"""),410000.0) -> 410000 | M3: =text(I3,"Rp #,##0") -> Rp 410.000 | N3: =text(J3,"Rp #,##0") -> Rp 0 | O3: =text(K3,"Rp #,##0") -> Rp 0 | P3: =text(L3,"Rp #,##0") -> Rp 410.000 | Q3: =$M$1&" = "&M3&" "&$N$1&" = "&N3&" "&$O$1&" = "&O3&" "&$P$1&" = "&P3&" ______________________"&R3&" ID : "&C3 -> Syahriyah = Rp 410.000 Jariyah = Rp 0 Daftar Ulang = Rp 0 Total = Rp 410.000 ______________________ ID : 2024070718
A4: =IF(B4="","",ROW(A4)-1) -> 3 | B4: =IFERROR(__xludf.DUMMYFUNCTION("""COMPUTED_VALUE"""),"MIRZA ATHA HIBATULLAH") -> MIRZA ATHA HIBATULLAH | C4: =IFERROR(__xludf.DUMMYFUNCTION("""COMPUTED_VALUE"""),2.0240706E9) -> 2024070600 | D4: =IFERROR(__xludf.DUMMYFUNCTION("""COMPUTED_VALUE"""),"A") -> A | E4: =IFERROR(__xludf.DUMMYFUNCTION("""COMPUTED_VALUE"""),"A-13") -> A-13 | F4: =IFERROR(__xludf.DUMMYFUNCTION("""COMPUTED_VALUE"""),3.0) -> 3 | H4: =IFERROR(__xludf.DUMMYFUNCTION("""COMPUTED_VALUE"""),"6285731205500") -> 6285731205500 | I4: =IFERROR(__xludf.DUMMYFUNCTION("""COMPUTED_VALUE"""),410000.0) -> 410000 | J4: =IFERROR(__xludf.DUMMYFUNCTION("""COMPUTED_VALUE"""),0.0) -> 0 | K4: =IFERROR(__xludf.DUMMYFUNCTION("""COMPUTED_VALUE"""),0.0) -> 0 | L4: =IFERROR(__xludf.DUMMYFUNCTION("""COMPUTED_VALUE"""),410000.0) -> 410000 | M4: =text(I4,"Rp #,##0") -> Rp 410.000 | N4: =text(J4,"Rp #,##0") -> Rp 0 | O4: =text(K4,"Rp #,##0") -> Rp 0 | P4: =text(L4,"Rp #,##0") -> Rp 410.000 | Q4: =$M$1&" = "&M4&" "&$N$1&" = "&N4&" "&$O$1&" = "&O4&" "&$P$1&" = "&P4&" ______________________"&R4&" ID : "&C4 -> Syahriyah = Rp 410.000 Jariyah = Rp 0 Daftar Ulang = Rp 0 Total = Rp 410.000 ______________________ ID : 2024070600
A5: =IF(B5="","",ROW(A5)-1) -> 4 | B5: =IFERROR(__xludf.DUMMYFUNCTION("""COMPUTED_VALUE"""),"ABIDAH OKTA SALSABILA") -> ABIDAH OKTA SALSABILA | C5: =IFERROR(__xludf.DUMMYFUNCTION("""COMPUTED_VALUE"""),2.024070146E9) -> 2024070146 | D5: =IFERROR(__xludf.DUMMYFUNCTION("""COMPUTED_VALUE"""),"C") -> C | E5: =IFERROR(__xludf.DUMMYFUNCTION("""COMPUTED_VALUE"""),"C-9") -> C-9 | F5: =IFERROR(__xludf.DUMMYFUNCTION("""COMPUTED_VALUE"""),3.0) -> 3 | G5: =IFERROR(__xludf.DUMMYFUNCTION("""COMPUTED_VALUE"""),"3 WUSTHO B PUTRI") -> 3 WUSTHO B PUTRI | H5: =IFERROR(__xludf.DUMMYFUNCTION("""COMPUTED_VALUE"""),"6285649525237") -> 6285649525237 | I5: =IFERROR(__xludf.DUMMYFUNCTION("""COMPUTED_VALUE"""),450000.0) -> 450000 | J5: =IFERROR(__xludf.DUMMYFUNCTION("""COMPUTED_VALUE"""),0.0) -> 0 | K5: =IFERROR(__xludf.DUMMYFUNCTION("""COMPUTED_VALUE"""),0.0) -> 0 | L5: =IFERROR(__xludf.DUMMYFUNCTION("""COMPUTED_VALUE"""),450000.0) -> 450000 | M5: =text(I5,"Rp #,##0") -> Rp 450.000 | N5: =text(J5,"Rp #,##0") -> Rp 0 | O5: =text(K5,"Rp #,##0") -> Rp 0 | P5: =text(L5,"Rp #,##0") -> Rp 450.000 | Q5: =$M$1&" = "&M5&" "&$N$1&" = "&N5&" "&$O$1&" = "&O5&" "&$P$1&" = "&P5&" ______________________"&R5&" ID : "&C5 -> Syahriyah = Rp 450.000 Jariyah = Rp 0 Daftar Ulang = Rp 0 Total = Rp 450.000 ______________________ ID : 2024070146
