Workbook

Sheet REPORT
B1: HIGHLIGHTS
B2: =TODAY() -> 46206
B4: SANTRI MATHOLI`UL ANWAR TAHUN TADRIS 2026/2027
B5: =A!S2+B!S2+'C'!S2+D!S2+E!S2+F!S2 -> 722
B8: ASRAMA A | AR8: TOTAL TUNGGAKAN SANTRI PER ASRAMA | AT8: KOTAK KOTAK, DIBAWAHNYA DI BERI RINCIAN TINGKATNYA DAN TOTALNYA
B9: =A!S2 -> 219
B10: =A!T3&" : "&A!S3 -> I : 0 | C10: =A!T4&" : "&A!S4 -> II : 112 | D10: =A!T5&" : "&A!S5 -> III : 107 | F10: CHART TUNGGAKAN
B11: LUNAS | D11: =A!$S$6 -> 331 | F11: ="1. "&A!$S$13 &" Syahriyah : "&text(A!$T$13,"Rp #,##0") &" Jariyah : "&text(A!$U$13,"Rp #,##0") &" Daftar Ulang : "&text(A!$V$13,"Rp #,##0") &" Total : "&text(A!$W$13,"Rp #,##0") -> 1. MUHAMMAD IQBAL MAULANA PUTRA Syahriyah : Rp 8.100.000 Jariyah : Rp 1.600.000 Daftar Ulang : Rp 0 Total : Rp 9.700.000 | G11: ="3. "&A!$S$15 &" Syahriyah : "&text(A!$T$15,"Rp #,##0") &" Jariyah : "&text(A!$U$15,"Rp #,##0") &" Daftar Ulang : "&text(A!$V$15,"Rp #,##0") &" Total : "&text(A!$W$15,"Rp #,##0") -> 3. ABI DZAR AL GHIFARI Syahriyah : Rp 4.500.000 Jariyah : Rp 1.600.000 Daftar Ulang : Rp 0 Total : Rp 6.100.000 | H11: ="5. "&A!$S$17 &" Syahriyah : "&text(A!$T$17,"Rp #,##0") &" Jariyah : "&text(A!$U$17,"Rp #,##0") &" Daftar Ulang : "&text(A!$V$17,"Rp #,##0") &" Total : "&text(A!$W$17,"Rp #,##0") -> 5. MOCH. DANISH IRFAN NUSHFIANTO WAHID Syahriyah : Rp 4.950.000 Jariyah : Rp 1.000.000 Daftar Ulang : Rp 0 Total : Rp 5.950.000 | I11: ="7. "&A!$S$19 &" Syahriyah : "&text(A!$T$19,"Rp #,##0") &" Jariyah : "&text(A!$U$19,"Rp #,##0") &" Daftar Ulang : "&text(A!$V$19,"Rp #,##0") &" Total : "&text(A!$W$19,"Rp #,##0") -> 7. AHMAD BAKER ADLAN Syahriyah : Rp 4.950.000 Jariyah : Rp 1.000.000 Daftar Ulang : Rp 0 Total : Rp 5.950.000 | J11: ="9. "&A!$S$21 &" Syahriyah : "&text(A!$T$21,"Rp #,##0") &" Jariyah : "&text(A!$U$21,"Rp #,##0") &" Daftar Ulang : "&text(A!$V$21,"Rp #,##0") &" Total : "&text(A!$W$21,"Rp #,##0") -> 9. MOHAMAD NOVAL JALALUDIN Syahriyah : Rp 4.950.000 Jariyah : Rp 1.000.000 Daftar Ulang : Rp 0 Total : Rp 5.950.000
B12: BELUM | D12: =A!$S$7 -> 2 | F12: ="2. "&A!$S$14 &" Syahriyah : "&text(A!$T$14,"Rp #,##0") &" Jariyah : "&text(A!$U$14,"Rp #,##0") &" Daftar Ulang : "&text(A!$V$14,"Rp #,##0") &" Total : "&text(A!$W$14,"Rp #,##0") -> 2. AHMAD GUTI JAELANI Syahriyah : Rp 6.750.000 Jariyah : Rp 0 Daftar Ulang : Rp 0 Total : Rp 6.750.000 | G12: ="4. "&A!$S$16 &" Syahriyah : "&text(A!$T$16,"Rp #,##0") &" Jariyah :"&text(A!$U$16,"Rp #,##0") &" Daftar Ulang : "&text(A!$V$16,"Rp #,##0") &" Total : "&text(A!$W$16,"Rp #,##0") -> 4. AHMAD LAIQLABI ASROFI Syahriyah : Rp 4.950.000 Jariyah :Rp 1.000.000 Daftar Ulang : Rp 0 Total : Rp 5.950.000 | H12: ="6. "&A!$S$18 &" Syahriyah : "&text(A!$T$18,"Rp #,##0") &" Jariyah : "&text(A!$U$18,"Rp #,##0") &" Daftar Ulang : "&text(A!$V$18,"Rp #,##0") &" Total : "&text(A!$W$18,"Rp #,##0") -> 6. MUHAMMAD RAFFA NUR RAMADHAN Syahriyah : Rp 4.950.000 Jariyah : Rp 1.000.000 Daftar Ulang : Rp 0 Total : Rp 5.950.000 | I12: ="8. "&A!$S$20 &" Syahriyah : "&text(A!$T$20,"Rp #,##0") &" Jariyah : "&text(A!$U$20,"Rp #,##0") &" Daftar Ulang : "&text(A!$V$20,"Rp #,##0") &" Total : "&text(A!$W$20,"Rp #,##0") -> 8. ANDIKA CAHYO BUDI LAKSONO Syahriyah : Rp 4.950.000 Jariyah : Rp 1.000.000 Daftar Ulang : Rp 0 Total : Rp 5.950.000 | J12: ="10. "&A!$S$22 &" Syahriyah : "&text(A!$T$22,"Rp #,##0") &" Jariyah : "&text(A!$U$22,"Rp #,##0") &" Daftar Ulang : "&text(A!$V$22,"Rp #,##0") &" Total : "&text(A!$W$22,"Rp #,##0") -> 10. AHMAD HABIBUR RAHMAN Syahriyah : Rp 4.050.000 Jariyah : Rp 1.600.000 Daftar Ulang : Rp 0 Total : Rp 5.650.000
B13: DANA KEGIATAN
B17: ASRAMA B
B18: =B!S2 -> 92
B19: =B!T3&" : "&B!S3 -> I : 0 | C19: =B!T4&" : "&B!S4 -> II : 57 | D19: =B!T5&" : "&B!S5 -> III : 35 | F19: CHART TUNGGAKAN
B20: LUNAS | D20: =B!$S$6 -> 134 | F20: ="1. "&B!$S$13 &" Syahriyah : "&text(B!$T$13,"Rp #,##0") &" Jariyah : "&text(B!$U$13,"Rp #,##0") &" Daftar Ulang : "&text(B!$V$13,"Rp #,##0") &" Total : "&text(B!$W$13,"Rp #,##0") -> 1. AYUNDA KIRANA QURROTUL ISHAQIYYAH Syahriyah : Rp 9.000.000 Jariyah : Rp 1.000.000 Daftar Ulang : Rp 0 Total : Rp 10.000.000 | G20: ="3. "&B!$S$15 &" Syahriyah : "&text(B!$T$15,"Rp #,##0") &" Jariyah : "&text(B!$U$15,"Rp #,##0") &" Daftar Ulang : "&text(B!$V$15,"Rp #,##0") &" Total : "&text(B!$W$15,"Rp #,##0") -> 3. PARAMITA ANGGRAINI Syahriyah : Rp 7.650.000 Jariyah : Rp 1.000.000 Daftar Ulang : Rp 350.000 Total : Rp 9.000.000 | H20: ="5. "&B!$S$17 &" Syahriyah : "&text(B!$T$17,"Rp #,##0") &" Jariyah : "&text(B!$U$17,"Rp #,##0") &" Daftar Ulang : "&text(B!$V$17,"Rp #,##0") &" Total : "&text(B!$W$17,"Rp #,##0") -> 5. HILYATUL FAIRAH Syahriyah : Rp 4.950.000 Jariyah : Rp 1.600.000 Daftar Ulang : Rp 0 Total : Rp 6.550.000 | I20: ="7. "&B!$S$19 &" Syahriyah : "&text(B!$T$19,"Rp #,##0") &" Jariyah : "&text(B!$U$19,"Rp #,##0") &" Daftar Ulang : "&text(B!$V$19,"Rp #,##0") &" Total : "&text(B!$W$19,"Rp #,##0") -> 7. CITRA MULYA SARI Syahriyah : Rp 4.950.000 Jariyah : Rp 0 Daftar Ulang : Rp 0 Total : Rp 4.950.000 | J20: ="9. "&B!$S$21 &" Syahriyah : "&text(B!$T$21,"Rp #,##0") &" Jariyah : "&text(B!$U$21,"Rp #,##0") &" Daftar Ulang : "&text(B!$V$21,"Rp #,##0") &" Total : "&text(B!$W$21,"Rp #,##0") -> 9. SHAFA KIRANA KAMALAT AZIZAH Syahriyah : Rp 3.150.000 Jariyah : Rp 1.000.000 Daftar Ulang : Rp 0 Total : Rp 4.150.000
B21: BELUM | D21: =B!$S$7 -> 3 | F21: ="2. "&B!$S$14 &" Syahriyah : "&text(B!$T$14,"Rp #,##0") &" Jariyah : "&text(B!$U$14,"Rp #,##0") &" Daftar Ulang : "&text(B!$V$14,"Rp #,##0") &" Total : "&text(B!$W$14,"Rp #,##0") -> 2. KHUMAIRO FAUZIA Syahriyah : Rp 8.100.000 Jariyah : Rp 1.000.000 Daftar Ulang : Rp 350.000 Total : Rp 9.450.000 | G21: ="4. "&B!$S$16 &" Syahriyah : "&text(B!$T$16,"Rp #,##0") &" Jariyah :"&text(B!$U$16,"Rp #,##0") &" Daftar Ulang : "&text(B!$V$16,"Rp #,##0") &" Total : "&text(B!$W$16,"Rp #,##0") -> 4. FARIH FIRDAUSI NUZULA Syahriyah : Rp 5.400.000 Jariyah :Rp 1.600.000 Daftar Ulang : Rp 0 Total : Rp 7.000.000 | H21: ="6. "&B!$S$18 &" Syahriyah : "&text(B!$T$18,"Rp #,##0") &" Jariyah : "&text(B!$U$18,"Rp #,##0") &" Daftar Ulang : "&text(B!$V$18,"Rp #,##0") &" Total : "&text(B!$W$18,"Rp #,##0") -> 6. ZAHRIATUL MUHIMATUN NISA` Syahriyah : Rp 5.400.000 Jariyah : Rp 0 Daftar Ulang : Rp 0 Total : Rp 5.400.000 | I21: ="8. "&B!$S$20 &" Syahriyah : "&text(B!$T$20,"Rp #,##0") &" Jariyah : "&text(B!$U$20,"Rp #,##0") &" Daftar Ulang : "&text(B!$V$20,"Rp #,##0") &" Total : "&text(B!$W$20,"Rp #,##0") -> 8. SEVANI CHINTIA ANGELIA Syahriyah : Rp 3.150.000 Jariyah : Rp 1.000.000 Daftar Ulang : Rp 0 Total : Rp 4.150.000 | J21: ="10. "&B!$S$22 &" Syahriyah : "&text(B!$T$22,"Rp #,##0") &" Jariyah : "&text(B!$U$22,"Rp #,##0") &" Daftar Ulang : "&text(B!$V$22,"Rp #,##0") &" Total : "&text(B!$W$22,"Rp #,##0") -> 10. LAESYTAH AGGUSTINA RAMADHANI Syahriyah : Rp 2.700.000 Jariyah : Rp 1.000.000 Daftar Ulang : Rp 0 Total : Rp 3.700.000
B22: DANA KEGIATAN
B26: ASRAMA C
B27: ='C'!S2 -> 241
B28: ='C'!T3&" : "&'C'!S3 -> I : 0 | C28: ='C'!T4&" : "&'C'!S4 -> II : 120 | D28: ='C'!T5&" : "&'C'!S5 -> III : 121 | F28: CHART TUNGGAKAN
B29: LUNAS | D29: ='C'!$S$6 -> 321 | F29: ="1. "&'C'!$S$13 &" Syahriyah : "&text('C'!$T$13,"Rp #,##0") &" Jariyah : "&text('C'!$U$13,"Rp #,##0") &" Daftar Ulang : "&text('C'!$V$13,"Rp #,##0") &" Total : "&text('C'!$W$13,"Rp #,##0") -> 1. NIA KRISNAWATI Syahriyah : Rp 7.650.000 Jariyah : Rp 1.000.000 Daftar Ulang : Rp 350.000 Total : Rp 9.000.000 | G29: ="3. "&'C'!$S$15 &" Syahriyah : "&text('C'!$T$15,"Rp #,##0") &" Jariyah : "&text('C'!$U$15,"Rp #,##0") &" Daftar Ulang : "&text('C'!$V$15,"Rp #,##0") &" Total : "&text('C'!$W$15,"Rp #,##0") -> 3. NEYLA MARITSA AZ ZAHRA Syahriyah : Rp 4.500.000 Jariyah : Rp 1.600.000 Daftar Ulang : Rp 0 Total : Rp 6.100.000 | H29: ="5. "&'C'!$S$17 &" Syahriyah : "&text('C'!$T$17,"Rp #,##0") &" Jariyah : "&text('C'!$U$17,"Rp #,##0") &" Daftar Ulang : "&text('C'!$V$17,"Rp #,##0") &" Total : "&text('C'!$W$17,"Rp #,##0") -> 5. FIRNANDA KHOLAGUL HIDAYATUS MUAWIYAH Syahriyah : Rp 3.600.000 Jariyah : Rp 1.600.000 Daftar Ulang : Rp 0 Total : Rp 5.200.000 | I29: ="7. "&'C'!$S$19 &" Syahriyah : "&text('C'!$T$19,"Rp #,##0") &" Jariyah : "&text('C'!$U$19,"Rp #,##0") &" Daftar Ulang : "&text('C'!$V$19,"Rp #,##0") &" Total : "&text('C'!$W$19,"Rp #,##0") -> 7. SYA`BANIA ROHMA RISQIYAH WULANDARI Syahriyah : Rp 3.150.000 Jariyah : Rp 1.000.000 Daftar Ulang : Rp 0 Total : Rp 4.150.000 | J29: ="9. "&'C'!$S$21 &" Syahriyah : "&text('C'!$T$21,"Rp #,##0") &" Jariyah : "&text('C'!$U$21,"Rp #,##0") &" Daftar Ulang : "&text('C'!$V$21,"Rp #,##0") &" Total : "&text('C'!$W$21,"Rp #,##0") -> 9. SITI MUZAROTUS SHOBUROH Syahriyah : Rp 2.600.000 Jariyah : Rp 1.000.000 Daftar Ulang : Rp 350.000 Total : Rp 3.950.000
B30: BELUM | D30: ='C'!$S$7 -> 2 | F30: ="2. "&'C'!$S$14 &" Syahriyah : "&text('C'!$T$14,"Rp #,##0") &" Jariyah : "&text('C'!$U$14,"Rp #,##0") &" Daftar Ulang : "&text('C'!$V$14,"Rp #,##0") &" Total : "&text('C'!$W$14,"Rp #,##0") -> 2. EKA FADHILATUN NAFSI Syahriyah : Rp 5.400.000 Jariyah : Rp 1.600.000 Daftar Ulang : Rp 0 Total : Rp 7.000.000 | G30: ="4. "&'C'!$S$16 &" Syahriyah : "&text('C'!$T$16,"Rp #,##0") &" Jariyah :"&text('C'!$U$16,"Rp #,##0") &" Daftar Ulang : "&text('C'!$V$16,"Rp #,##0") &" Total : "&text('C'!$W$16,"Rp #,##0") -> 4. RAVAUL ZAHIDAH Syahriyah : Rp 4.500.000 Jariyah :Rp 1.000.000 Daftar Ulang : Rp 0 Total : Rp 5.500.000 | H30: ="6. "&'C'!$S$18 &" Syahriyah : "&text('C'!$T$18,"Rp #,##0") &" Jariyah : "&text('C'!$U$18,"Rp #,##0") &" Daftar Ulang : "&text('C'!$V$18,"Rp #,##0") &" Total : "&text('C'!$W$18,"Rp #,##0") -> 6. MEISYA JUWITA SARI Syahriyah : Rp 2.700.000 Jariyah : Rp 1.600.000 Daftar Ulang : Rp 0 Total : Rp 4.300.000 | I30: ="8. "&'C'!$S$20 &" Syahriyah : "&text('C'!$T$20,"Rp #,##0") &" Jariyah : "&text('C'!$U$20,"Rp #,##0") &" Daftar Ulang : "&text('C'!$V$20,"Rp #,##0") &" Total : "&text('C'!$W$20,"Rp #,##0") -> 8. HIMMATU ZAWA ARRIFA Syahriyah : Rp 3.150.000 Jariyah : Rp 1.000.000 Daftar Ulang : Rp 0 Total : Rp 4.150.000 | J30: ="10. "&'C'!$S$22 &" Syahriyah : "&text('C'!$T$22,"Rp #,##0") &" Jariyah : "&text('C'!$U$22,"Rp #,##0") &" Daftar Ulang : "&text('C'!$V$22,"Rp #,##0") &" Total : "&text('C'!$W$22,"Rp #,##0") -> 10. FARAH ALTHAFUN NISA` Syahriyah : Rp 2.250.000 Jariyah : Rp 1.000.000 Daftar Ulang : Rp 0 Total : Rp 3.250.000
B31: DANA KEGIATAN
B35: ASRAMA D
B36: =D!S2 -> 78
B37: =D!T3&" : "&D!S3 -> I : 0 | C37: =D!T4&" : "&D!S4 -> II : 29 | D37: =D!T5&" : "&D!S5 -> III : 49 | F37: CHART TUNGGAKAN
B38: LUNAS | D38: =D!$S$6 -> 107 | F38: ="1. "&D!$S$13 &" Syahriyah : "&text(D!$T$13,"Rp #,##0") &" Jariyah : "&text(D!$U$13,"Rp #,##0") &" Daftar Ulang : "&text(D!$V$13,"Rp #,##0") &" Total : "&text(D!$W$13,"Rp #,##0") -> 1. FIKA ANJANI CAMELIA AL AJEMAIN Syahriyah : Rp 10.800.000 Jariyah : Rp 1.600.000 Daftar Ulang : Rp 0 Total : Rp 12.400.000 | G38: ="3. "&D!$S$15 &" Syahriyah : "&text(D!$T$15,"Rp #,##0") &" Jariyah : "&text(D!$U$15,"Rp #,##0") &" Daftar Ulang : "&text(D!$V$15,"Rp #,##0") &" Total : "&text(D!$W$15,"Rp #,##0") -> 3. ISTHOFI NADA MILLAH Syahriyah : Rp 10.800.000 Jariyah : Rp 0 Daftar Ulang : Rp 350.000 Total : Rp 11.150.000 | H38: ="5. "&D!$S$17 &" Syahriyah : "&text(D!$T$17,"Rp #,##0") &" Jariyah : "&text(D!$U$17,"Rp #,##0") &" Daftar Ulang : "&text(D!$V$17,"Rp #,##0") &" Total : "&text(D!$W$17,"Rp #,##0") -> 5. KAYLA SABRINA ANGGRAINI Syahriyah : Rp 6.750.000 Jariyah : Rp 1.600.000 Daftar Ulang : Rp 0 Total : Rp 8.350.000 | I38: ="7. "&D!$S$19 &" Syahriyah : "&text(D!$T$19,"Rp #,##0") &" Jariyah : "&text(D!$U$19,"Rp #,##0") &" Daftar Ulang : "&text(D!$V$19,"Rp #,##0") &" Total : "&text(D!$W$19,"Rp #,##0") -> 7. HALIMATUS SA`DIYYAH Syahriyah : Rp 5.400.000 Jariyah : Rp 0 Daftar Ulang : Rp 0 Total : Rp 5.400.000 | J38: ="9. "&D!$S$21 &" Syahriyah : "&text(D!$T$21,"Rp #,##0") &" Jariyah : "&text(D!$U$21,"Rp #,##0") &" Daftar Ulang : "&text(D!$V$21,"Rp #,##0") &" Total : "&text(D!$W$21,"Rp #,##0") -> 9. SELENA SHERIN MARGARET Syahriyah : Rp 3.150.000 Jariyah : Rp 1.600.000 Daftar Ulang : Rp 0 Total : Rp 4.750.000
B39: BELUM | D39: =D!$S$7 -> 3 | F39: ="2. "&D!$S$14 &" Syahriyah : "&text(D!$T$14,"Rp #,##0") &" Jariyah : "&text(D!$U$14,"Rp #,##0") &" Daftar Ulang : "&text(D!$V$14,"Rp #,##0") &" Total : "&text(D!$W$14,"Rp #,##0") -> 2. ANGEL CYNTYA DEWI MAULIDAH Syahriyah : Rp 9.900.000 Jariyah : Rp 1.600.000 Daftar Ulang : Rp 0 Total : Rp 11.500.000 | G39: ="4. "&D!$S$16 &" Syahriyah : "&text(D!$T$16,"Rp #,##0") &" Jariyah :"&text(D!$U$16,"Rp #,##0") &" Daftar Ulang : "&text(D!$V$16,"Rp #,##0") &" Total : "&text(D!$W$16,"Rp #,##0") -> 4. DEWI ZAIDATUL RAHMA Syahriyah : Rp 8.100.000 Jariyah :Rp 0 Daftar Ulang : Rp 350.000 Total : Rp 8.450.000 | H39: ="6. "&D!$S$18 &" Syahriyah : "&text(D!$T$18,"Rp #,##0") &" Jariyah : "&text(D!$U$18,"Rp #,##0") &" Daftar Ulang : "&text(D!$V$18,"Rp #,##0") &" Total : "&text(D!$W$18,"Rp #,##0") -> 6. DZAKIRAH THALITA ZAHRA Syahriyah : Rp 6.300.000 Jariyah : Rp 1.000.000 Daftar Ulang : Rp 350.000 Total : Rp 7.650.000 | I39: ="8. "&D!$S$20 &" Syahriyah : "&text(D!$T$20,"Rp #,##0") &" Jariyah : "&text(D!$U$20,"Rp #,##0") &" Daftar Ulang : "&text(D!$V$20,"Rp #,##0") &" Total : "&text(D!$W$20,"Rp #,##0") -> 8. SHOHIFAH Syahriyah : Rp 3.600.000 Jariyah : Rp 1.600.000 Daftar Ulang : Rp 0 Total : Rp 5.200.000 | J39: ="10. "&D!$S$22 &" Syahriyah : "&text(D!$T$22,"Rp #,##0") &" Jariyah : "&text(D!$U$22,"Rp #,##0") &" Daftar Ulang : "&text(D!$V$22,"Rp #,##0") &" Total : "&text(D!$W$22,"Rp #,##0") -> 10. LATHIFATUL FATIHAH ALMASYRIFAH Syahriyah : Rp 4.500.000 Jariyah : Rp 0 Daftar Ulang : Rp 0 Total : Rp 4.500.000
B40: DANA KEGIATAN
B44: ASRAMA E
B45: =E!S2 -> 82
B46: =E!T3&" : "&E!S3 -> I : 0 | C46: =E!T4&" : "&E!S4 -> II : 37 | D46: =E!T5&" : "&E!S5 -> III : 45 | F46: CHART TUNGGAKAN
B47: LUNAS | D47: =E!$S$6 -> 128 | F47: ="1. "&E!$S$13 &" Syahriyah : "&text(E!$T$13,"Rp #,##0") &" Jariyah : "&text(E!$U$13,"Rp #,##0") &" Daftar Ulang : "&text(E!$V$13,"Rp #,##0") &" Total : "&text(E!$W$13,"Rp #,##0") -> 1. ZASKIA MAHARANI PUTRI Syahriyah : Rp 7.500.000 Jariyah : Rp 1.600.000 Daftar Ulang : Rp 350.000 Total : Rp 9.450.000 | G47: ="3. "&E!$S$15 &" Syahriyah : "&text(E!$T$15,"Rp #,##0") &" Jariyah : "&text(E!$U$15,"Rp #,##0") &" Daftar Ulang : "&text(E!$V$15,"Rp #,##0") &" Total : "&text(E!$W$15,"Rp #,##0") -> 3. USWAH EL FAHRUSAZZAM ZAMI Syahriyah : Rp 3.500.000 Jariyah : Rp 1.000.000 Daftar Ulang : Rp 350.000 Total : Rp 4.850.000 | H47: ="5. "&E!$S$17 &" Syahriyah : "&text(E!$T$17,"Rp #,##0") &" Jariyah : "&text(E!$U$17,"Rp #,##0") &" Daftar Ulang : "&text(E!$V$17,"Rp #,##0") &" Total : "&text(E!$W$17,"Rp #,##0") -> 5. ZAHIRA JULIA SAIDAH Syahriyah : Rp 3.500.000 Jariyah : Rp 0 Daftar Ulang : Rp 0 Total : Rp 3.500.000 | I47: ="7. "&E!$S$19 &" Syahriyah : "&text(E!$T$19,"Rp #,##0") &" Jariyah : "&text(E!$U$19,"Rp #,##0") &" Daftar Ulang : "&text(E!$V$19,"Rp #,##0") &" Total : "&text(E!$W$19,"Rp #,##0") -> 7. KHARISYAH NADYATUR ROHMAH Syahriyah : Rp 3.000.000 Jariyah : Rp 0 Daftar Ulang : Rp 0 Total : Rp 3.000.000 | J47: ="9. "&E!$S$21 &" Syahriyah : "&text(E!$T$21,"Rp #,##0") &" Jariyah : "&text(E!$U$21,"Rp #,##0") &" Daftar Ulang : "&text(E!$V$21,"Rp #,##0") &" Total : "&text(E!$W$21,"Rp #,##0") -> 9. DAVINA NANGSYA AZZAHRAH Syahriyah : Rp 2.160.000 Jariyah : Rp 0 Daftar Ulang : Rp 350.000 Total : Rp 2.510.000
B48: BELUM | D48: =E!$S$7 -> 4 | F48: ="2. "&E!$S$14 &" Syahriyah : "&text(E!$T$14,"Rp #,##0") &" Jariyah : "&text(E!$U$14,"Rp #,##0") &" Daftar Ulang : "&text(E!$V$14,"Rp #,##0") &" Total : "&text(E!$W$14,"Rp #,##0") -> 2. FATIMAH Syahriyah : Rp 6.210.000 Jariyah : Rp 0 Daftar Ulang : Rp 350.000 Total : Rp 6.560.000 | G48: ="4. "&E!$S$16 &" Syahriyah : "&text(E!$T$16,"Rp #,##0") &" Jariyah :"&text(E!$U$16,"Rp #,##0") &" Daftar Ulang : "&text(E!$V$16,"Rp #,##0") &" Total : "&text(E!$W$16,"Rp #,##0") -> 4. ANGELINA KIBRIYAH SAFITRI Syahriyah : Rp 3.000.000 Jariyah :Rp 500.000 Daftar Ulang : Rp 0 Total : Rp 3.500.000 | H48: ="6. "&E!$S$18 &" Syahriyah : "&text(E!$T$18,"Rp #,##0") &" Jariyah : "&text(E!$U$18,"Rp #,##0") &" Daftar Ulang : "&text(E!$V$18,"Rp #,##0") &" Total : "&text(E!$W$18,"Rp #,##0") -> 6. AZURO SABILA FAZZA MAULIDAH Syahriyah : Rp 2.000.000 Jariyah : Rp 1.000.000 Daftar Ulang : Rp 0 Total : Rp 3.000.000 | I48: ="8. "&E!$S$20 &" Syahriyah : "&text(E!$T$20,"Rp #,##0") &" Jariyah : "&text(E!$U$20,"Rp #,##0") &" Daftar Ulang : "&text(E!$V$20,"Rp #,##0") &" Total : "&text(E!$W$20,"Rp #,##0") -> 8. ASYIFATUR RAHMAH AL AZZA Syahriyah : Rp 3.000.000 Jariyah : Rp 0 Daftar Ulang : Rp 0 Total : Rp 3.000.000 | J48: ="10. "&E!$S$22 &" Syahriyah : "&text(E!$T$22,"Rp #,##0") &" Jariyah : "&text(E!$U$22,"Rp #,##0") &" Daftar Ulang : "&text(E!$V$22,"Rp #,##0") &" Total : "&text(E!$W$22,"Rp #,##0") -> 10. ILHAFAH ARYA NOVRYANI Syahriyah : Rp 1.500.000 Jariyah : Rp 1.000.000 Daftar Ulang : Rp 0 Total : Rp 2.500.000
B49: DANA KEGIATAN
B53: ASRAMA F
B54: =F!S2 -> 10
B55: =F!T3&" : "&F!S3 -> I : 0 | C55: =F!T4&" : "&F!S4 -> II : 10 | D55: =F!T5&" : "&F!S5 -> III : 0 | F55: CHART TUNGGAKAN
B56: LUNAS | D56: =F!$S$6 -> 19 | F56: ="1. "&F!$S$13 &" Syahriyah : "&text(F!$T$13,"Rp #,##0") &" Jariyah : "&text(F!$U$13,"Rp #,##0") &" Daftar Ulang : "&text(F!$V$13,"Rp #,##0") &" Total : "&text(F!$W$13,"Rp #,##0") -> 1. RATIH RAHMAH YUNITA Syahriyah : Rp 0 Jariyah : Rp 1.600.000 Daftar Ulang : Rp 0 Total : Rp 1.600.000 | G56: ="3. "&F!$S$15 &" Syahriyah : "&text(F!$T$15,"Rp #,##0") &" Jariyah : "&text(F!$U$15,"Rp #,##0") &" Daftar Ulang : "&text(F!$V$15,"Rp #,##0") &" Total : "&text(F!$W$15,"Rp #,##0") -> 3. SAFAWATI NURUL AFIQAH Syahriyah : Rp 0 Jariyah : Rp 1.000.000 Daftar Ulang : Rp 0 Total : Rp 1.000.000 | H56: ="5. "&F!$S$17 &" Syahriyah : "&text(F!$T$17,"Rp #,##0") &" Jariyah : "&text(F!$U$17,"Rp #,##0") &" Daftar Ulang : "&text(F!$V$17,"Rp #,##0") &" Total : "&text(F!$W$17,"Rp #,##0") -> 5. MIRANTI PUSPITA DEWI Syahriyah : Rp 0 Jariyah : Rp 500.000 Daftar Ulang : Rp 0 Total : Rp 500.000 | I56: ="7. "&F!$S$19 &" Syahriyah : "&text(F!$T$19,"Rp #,##0") &" Jariyah : "&text(F!$U$19,"Rp #,##0") &" Daftar Ulang : "&text(F!$V$19,"Rp #,##0") &" Total : "&text(F!$W$19,"Rp #,##0") -> 7. NAFISAH AZ-ZAHRAH Syahriyah : Rp 0 Jariyah : Rp 0 Daftar Ulang : Rp 0 Total : Rp 0 | J56: ="9. "&F!$S$21 &" Syahriyah : "&text(F!$T$21,"Rp #,##0") &" Jariyah : "&text(F!$U$21,"Rp #,##0") &" Daftar Ulang : "&text(F!$V$21,"Rp #,##0") &" Total : "&text(F!$W$21,"Rp #,##0") -> 9. TIFLAH HANIFAH ARSITA Syahriyah : Rp 0 Jariyah : Rp 0 Daftar Ulang : Rp 0 Total : Rp 0
B57: BELUM | D57: =F!$S$7 -> 0 | F57: ="2. "&F!$S$14 &" Syahriyah : "&text(F!$T$14,"Rp #,##0") &" Jariyah : "&text(F!$U$14,"Rp #,##0") &" Daftar Ulang : "&text(F!$V$14,"Rp #,##0") &" Total : "&text(F!$W$14,"Rp #,##0") -> 2. CAHAYA ROSANA AIRA KURNIA CANTIK Syahriyah : Rp 0 Jariyah : Rp 1.000.000 Daftar Ulang : Rp 0 Total : Rp 1.000.000 | G57: ="4. "&F!$S$16 &" Syahriyah : "&text(F!$T$16,"Rp #,##0") &" Jariyah :"&text(F!$U$16,"Rp #,##0") &" Daftar Ulang : "&text(F!$V$16,"Rp #,##0") &" Total : "&text(F!$W$16,"Rp #,##0") -> 4. NAILAH MAULIDAH ISNAH Syahriyah : Rp 900.000 Jariyah :Rp 0 Daftar Ulang : Rp 0 Total : Rp 900.000 | H57: ="6. "&F!$S$18 &" Syahriyah : "&text(F!$T$18,"Rp #,##0") &" Jariyah : "&text(F!$U$18,"Rp #,##0") &" Daftar Ulang : "&text(F!$V$18,"Rp #,##0") &" Total : "&text(F!$W$18,"Rp #,##0") -> 6. SALWA WARDATUL MISKIYAH Syahriyah : Rp 450.000 Jariyah : Rp 0 Daftar Ulang : Rp 0 Total : Rp 450.000 | I57: ="8. "&F!$S$20 &" Syahriyah : "&text(F!$T$20,"Rp #,##0") &" Jariyah : "&text(F!$U$20,"Rp #,##0") &" Daftar Ulang : "&text(F!$V$20,"Rp #,##0") &" Total : "&text(F!$W$20,"Rp #,##0") -> 8. SAFINA NUR AULIA WAHIDA Syahriyah : Rp 0 Jariyah : Rp 0 Daftar Ulang : Rp 0 Total : Rp 0 | J57: ="10. "&F!$S$22 &" Syahriyah : "&text(F!$T$22,"Rp #,##0") &" Jariyah : "&text(F!$U$22,"Rp #,##0") &" Daftar Ulang : "&text(F!$V$22,"Rp #,##0") &" Total : "&text(F!$W$22,"Rp #,##0") -> #N/A
B58: DANA KEGIATAN

Sheet I
A1: =IFERROR(__xludf.DUMMYFUNCTION("IMPORTRANGE(""1r--qa2i5jCx8YeQ_mLlUrqLRTQh7y-fik2wTdRKBimk/edit?gid=214218921#gid=214218921"",""KELAS I!A2:BF750"")"),"NO") -> NO | B1: =IFERROR(__xludf.DUMMYFUNCTION("""COMPUTED_VALUE"""),"NAMA") -> NAMA | C1: =IFERROR(__xludf.DUMMYFUNCTION("""COMPUTED_VALUE"""),"NIS") -> NIS | D1: =IFERROR(__xludf.DUMMYFUNCTION("""COMPUTED_VALUE"""),"AYAH") -> AYAH | E1: =IFERROR(__xludf.DUMMYFUNCTION("""COMPUTED_VALUE"""),"IBU") -> IBU | F1: =IFERROR(__xludf.DUMMYFUNCTION("""COMPUTED_VALUE"""),"ALAMAT") -> ALAMAT | G1: =IFERROR(__xludf.DUMMYFUNCTION("""COMPUTED_VALUE"""),"SEKOLAH") -> SEKOLAH | H1: =IFERROR(__xludf.DUMMYFUNCTION("""COMPUTED_VALUE"""),"ASRAMA") -> ASRAMA | I1: =IFERROR(__xludf.DUMMYFUNCTION("""COMPUTED_VALUE"""),"KAMAR") -> KAMAR | J1: =IFERROR(__xludf.DUMMYFUNCTION("""COMPUTED_VALUE"""),"TINGKAT") -> TINGKAT | K1: =IFERROR(__xludf.DUMMYFUNCTION("""COMPUTED_VALUE"""),"MADRASIAH") -> MADRASIAH | L1: =IFERROR(__xludf.DUMMYFUNCTION("""COMPUTED_VALUE"""),"HP") -> HP | M1: =IFERROR(__xludf.DUMMYFUNCTION("""COMPUTED_VALUE"""),"JARIYAH I") -> JARIYAH I | N1: =IFERROR(__xludf.DUMMYFUNCTION("""COMPUTED_VALUE"""),"DANA KEGIATAN") -> DANA KEGIATAN | O1: =IFERROR(__xludf.DUMMYFUNCTION("""COMPUTED_VALUE"""),7.0) -> 7 | P1: =IFERROR(__xludf.DUMMYFUNCTION("""COMPUTED_VALUE"""),8.0) -> 8 | Q1: =IFERROR(__xludf.DUMMYFUNCTION("""COMPUTED_VALUE"""),9.0) -> 9 | R1: =IFERROR(__xludf.DUMMYFUNCTION("""COMPUTED_VALUE"""),10.0) -> 10 | S1: =IFERROR(__xludf.DUMMYFUNCTION("""COMPUTED_VALUE"""),11.0) -> 11 | T1: =IFERROR(__xludf.DUMMYFUNCTION("""COMPUTED_VALUE"""),12.0) -> 12 | U1: =IFERROR(__xludf.DUMMYFUNCTION("""COMPUTED_VALUE"""),1.0) -> 1 | V1: =IFERROR(__xludf.DUMMYFUNCTION("""COMPUTED_VALUE"""),2.0) -> 2 | W1: =IFERROR(__xludf.DUMMYFUNCTION("""COMPUTED_VALUE"""),3.0) -> 3 | X1: =IFERROR(__xludf.DUMMYFUNCTION("""COMPUTED_VALUE"""),4.0) -> 4 | Y1: =IFERROR(__xludf.DUMMYFUNCTION("""COMPUTED_VALUE"""),5.0) -> 5 | Z1: =IFERROR(__xludf.DUMMYFUNCTION("""COMPUTED_VALUE"""),6.0) -> 6 | AA1: =IFERROR(__xludf.DUMMYFUNCTION("""COMPUTED_VALUE"""),"DAFTAR ULANG KELAS II") -> DAFTAR ULANG KELAS II | AB1: =IFERROR(__xludf.DUMMYFUNCTION("""COMPUTED_VALUE"""),"JARIYAH II") -> JARIYAH II | AC1: =IFERROR(__xludf.DUMMYFUNCTION("""COMPUTED_VALUE"""),7.0) -> 7 | AD1: =IFERROR(__xludf.DUMMYFUNCTION("""COMPUTED_VALUE"""),8.0) -> 8 | AE1: =IFERROR(__xludf.DUMMYFUNCTION("""COMPUTED_VALUE"""),9.0) -> 9 | AF1: =IFERROR(__xludf.DUMMYFUNCTION("""COMPUTED_VALUE"""),10.0) -> 10 | AG1: =IFERROR(__xludf.DUMMYFUNCTION("""COMPUTED_VALUE"""),11.0) -> 11 | AH1: =IFERROR(__xludf.DUMMYFUNCTION("""COMPUTED_VALUE"""),12.0) -> 12 | AI1: =IFERROR(__xludf.DUMMYFUNCTION("""COMPUTED_VALUE"""),1.0) -> 1 | AJ1: =IFERROR(__xludf.DUMMYFUNCTION("""COMPUTED_VALUE"""),2.0) -> 2 | AK1: =IFERROR(__xludf.DUMMYFUNCTION("""COMPUTED_VALUE"""),3.0) -> 3 | AL1: =IFERROR(__xludf.DUMMYFUNCTION("""COMPUTED_VALUE"""),4.0) -> 4 | AM1: =IFERROR(__xludf.DUMMYFUNCTION("""COMPUTED_VALUE"""),5.0) -> 5 | AN1: =IFERROR(__xludf.DUMMYFUNCTION("""COMPUTED_VALUE"""),6.0) -> 6 | AO1: =IFERROR(__xludf.DUMMYFUNCTION("""COMPUTED_VALUE"""),"DAFTAR ULANG KELAS III") -> DAFTAR ULANG KELAS III | AP1: =IFERROR(__xludf.DUMMYFUNCTION("""COMPUTED_VALUE"""),"JARIYAH III") -> JARIYAH III | AQ1: =IFERROR(__xludf.DUMMYFUNCTION("""COMPUTED_VALUE"""),7.0) -> 7 | AR1: =IFERROR(__xludf.DUMMYFUNCTION("""COMPUTED_VALUE"""),8.0) -> 8 | AS1: =IFERROR(__xludf.DUMMYFUNCTION("""COMPUTED_VALUE"""),9.0) -> 9 | AT1: =IFERROR(__xludf.DUMMYFUNCTION("""COMPUTED_VALUE"""),10.0) -> 10 | AU1: =IFERROR(__xludf.DUMMYFUNCTION("""COMPUTED_VALUE"""),11.0) -> 11 | AV1: =IFERROR(__xludf.DUMMYFUNCTION("""COMPUTED_VALUE"""),12.0) -> 12 | AW1: =IFERROR(__xludf.DUMMYFUNCTION("""COMPUTED_VALUE"""),1.0) -> 1 | AX1: =IFERROR(__xludf.DUMMYFUNCTION("""COMPUTED_VALUE"""),2.0) -> 2 | AY1: =IFERROR(__xludf.DUMMYFUNCTION("""COMPUTED_VALUE"""),3.0) -> 3 | AZ1: =IFERROR(__xludf.DUMMYFUNCTION("""COMPUTED_VALUE"""),4.0) -> 4 | BA1: =IFERROR(__xludf.DUMMYFUNCTION("""COMPUTED_VALUE"""),5.0) -> 5 | BB1: =IFERROR(__xludf.DUMMYFUNCTION("""COMPUTED_VALUE"""),6.0) -> 6 | BC1: =IFERROR(__xludf.DUMMYFUNCTION("""COMPUTED_VALUE"""),"JUMLAH SYAHRIYAH") -> JUMLAH SYAHRIYAH | BD1: =IFERROR(__xludf.DUMMYFUNCTION("""COMPUTED_VALUE"""),"JUMLAH JARIYAH") -> JUMLAH JARIYAH | BE1: =IFERROR(__xludf.DUMMYFUNCTION("""COMPUTED_VALUE"""),"JUMLAH DAFTAR ULANG") -> JUMLAH DAFTAR ULANG | BF1: =IFERROR(__xludf.DUMMYFUNCTION("""COMPUTED_VALUE"""),"JUMLAH TOTAL TUNGGAKAN") -> JUMLAH TOTAL TUNGGAKAN
A2: =IFERROR(__xludf.DUMMYFUNCTION("""COMPUTED_VALUE"""),"") | BC2: =IFERROR(__xludf.DUMMYFUNCTION("""COMPUTED_VALUE"""),0.0) -> 0 | BD2: =IFERROR(__xludf.DUMMYFUNCTION("""COMPUTED_VALUE"""),0.0) -> 0 | BE2: =IFERROR(__xludf.DUMMYFUNCTION("""COMPUTED_VALUE"""),0.0) -> 0 | BF2: =IFERROR(__xludf.DUMMYFUNCTION("""COMPUTED_VALUE"""),0.0) -> 0
A3: =IFERROR(__xludf.DUMMYFUNCTION("""COMPUTED_VALUE"""),"") | BC3: =IFERROR(__xludf.DUMMYFUNCTION("""COMPUTED_VALUE"""),0.0) -> 0 | BD3: =IFERROR(__xludf.DUMMYFUNCTION("""COMPUTED_VALUE"""),0.0) -> 0 | BE3: =IFERROR(__xludf.DUMMYFUNCTION("""COMPUTED_VALUE"""),0.0) -> 0 | BF3: =IFERROR(__xludf.DUMMYFUNCTION("""COMPUTED_VALUE"""),0.0) -> 0
A4: =IFERROR(__xludf.DUMMYFUNCTION("""COMPUTED_VALUE"""),"") | BC4: =IFERROR(__xludf.DUMMYFUNCTION("""COMPUTED_VALUE"""),0.0) -> 0 | BD4: =IFERROR(__xludf.DUMMYFUNCTION("""COMPUTED_VALUE"""),0.0) -> 0 | BE4: =IFERROR(__xludf.DUMMYFUNCTION("""COMPUTED_VALUE"""),0.0) -> 0 | BF4: =IFERROR(__xludf.DUMMYFUNCTION("""COMPUTED_VALUE"""),0.0) -> 0
A5: =IFERROR(__xludf.DUMMYFUNCTION("""COMPUTED_VALUE"""),"") | BC5: =IFERROR(__xludf.DUMMYFUNCTION("""COMPUTED_VALUE"""),0.0) -> 0 | BD5: =IFERROR(__xludf.DUMMYFUNCTION("""COMPUTED_VALUE"""),0.0) -> 0 | BE5: =IFERROR(__xludf.DUMMYFUNCTION("""COMPUTED_VALUE"""),0.0) -> 0 | BF5: =IFERROR(__xludf.DUMMYFUNCTION("""COMPUTED_VALUE"""),0.0) -> 0
A6: =IFERROR(__xludf.DUMMYFUNCTION("""COMPUTED_VALUE"""),"") | BC6: =IFERROR(__xludf.DUMMYFUNCTION("""COMPUTED_VALUE"""),0.0) -> 0 | BD6: =IFERROR(__xludf.DUMMYFUNCTION("""COMPUTED_VALUE"""),0.0) -> 0 | BE6: =IFERROR(__xludf.DUMMYFUNCTION("""COMPUTED_VALUE"""),0.0) -> 0 | BF6: =IFERROR(__xludf.DUMMYFUNCTION("""COMPUTED_VALUE"""),0.0) -> 0
A7: =IFERROR(__xludf.DUMMYFUNCTION("""COMPUTED_VALUE"""),"") | BC7: =IFERROR(__xludf.DUMMYFUNCTION("""COMPUTED_VALUE"""),0.0) -> 0 | BD7: =IFERROR(__xludf.DUMMYFUNCTION("""COMPUTED_VALUE"""),0.0) -> 0 | BE7: =IFERROR(__xludf.DUMMYFUNCTION("""COMPUTED_VALUE"""),0.0) -> 0 | BF7: =IFERROR(__xludf.DUMMYFUNCTION("""COMPUTED_VALUE"""),0.0) -> 0
A8: =IFERROR(__xludf.DUMMYFUNCTION("""COMPUTED_VALUE"""),"") | BC8: =IFERROR(__xludf.DUMMYFUNCTION("""COMPUTED_VALUE"""),0.0) -> 0 | BD8: =IFERROR(__xludf.DUMMYFUNCTION("""COMPUTED_VALUE"""),0.0) -> 0 | BE8: =IFERROR(__xludf.DUMMYFUNCTION("""COMPUTED_VALUE"""),0.0) -> 0 | BF8: =IFERROR(__xludf.DUMMYFUNCTION("""COMPUTED_VALUE"""),0.0) -> 0
A9: =IFERROR(__xludf.DUMMYFUNCTION("""COMPUTED_VALUE"""),"") | BC9: =IFERROR(__xludf.DUMMYFUNCTION("""COMPUTED_VALUE"""),0.0) -> 0 | BD9: =IFERROR(__xludf.DUMMYFUNCTION("""COMPUTED_VALUE"""),0.0) -> 0 | BE9: =IFERROR(__xludf.DUMMYFUNCTION("""COMPUTED_VALUE"""),0.0) -> 0 | BF9: =IFERROR(__xludf.DUMMYFUNCTION("""COMPUTED_VALUE"""),0.0) -> 0
A10: =IFERROR(__xludf.DUMMYFUNCTION("""COMPUTED_VALUE"""),"") | BC10: =IFERROR(__xludf.DUMMYFUNCTION("""COMPUTED_VALUE"""),0.0) -> 0 | BD10: =IFERROR(__xludf.DUMMYFUNCTION("""COMPUTED_VALUE"""),0.0) -> 0 | BE10: =IFERROR(__xludf.DUMMYFUNCTION("""COMPUTED_VALUE"""),0.0) -> 0 | BF10: =IFERROR(__xludf.DUMMYFUNCTION("""COMPUTED_VALUE"""),0.0) -> 0
A11: =IFERROR(__xludf.DUMMYFUNCTION("""COMPUTED_VALUE"""),"") | BC11: =IFERROR(__xludf.DUMMYFUNCTION("""COMPUTED_VALUE"""),0.0) -> 0 | BD11: =IFERROR(__xludf.DUMMYFUNCTION("""COMPUTED_VALUE"""),0.0) -> 0 | BE11: =IFERROR(__xludf.DUMMYFUNCTION("""COMPUTED_VALUE"""),0.0) -> 0 | BF11: =IFERROR(__xludf.DUMMYFUNCTION("""COMPUTED_VALUE"""),0.0) -> 0
A12: =IFERROR(__xludf.DUMMYFUNCTION("""COMPUTED_VALUE"""),"") | BC12: =IFERROR(__xludf.DUMMYFUNCTION("""COMPUTED_VALUE"""),0.0) -> 0 | BD12: =IFERROR(__xludf.DUMMYFUNCTION("""COMPUTED_VALUE"""),0.0) -> 0 | BE12: =IFERROR(__xludf.DUMMYFUNCTION("""COMPUTED_VALUE"""),0.0) -> 0 | BF12: =IFERROR(__xludf.DUMMYFUNCTION("""COMPUTED_VALUE"""),0.0) -> 0
A13: =IFERROR(__xludf.DUMMYFUNCTION("""COMPUTED_VALUE"""),"") | BC13: =IFERROR(__xludf.DUMMYFUNCTION("""COMPUTED_VALUE"""),0.0) -> 0 | BD13: =IFERROR(__xludf.DUMMYFUNCTION("""COMPUTED_VALUE"""),0.0) -> 0 | BE13: =IFERROR(__xludf.DUMMYFUNCTION("""COMPUTED_VALUE"""),0.0) -> 0 | BF13: =IFERROR(__xludf.DUMMYFUNCTION("""COMPUTED_VALUE"""),0.0) -> 0
... A370: =IFERROR(__xludf.DUMMYFUNCTION("""COMPUTED_VALUE"""),"") | BC370: =IFERROR(__xludf.DUMMYFUNCTION("""COMPUTED_VALUE"""),0.0) -> 0 | BD370: =IFERROR(__xludf.DUMMYFUNCTION("""COMPUTED_VALUE"""),0.0) -> 0 | BE370: =IFERROR(__xludf.DUMMYFUNCTION("""COMPUTED_VALUE"""),0.0) -> 0 | BF370: =IFERROR(__xludf.DUMMYFUNCTION("""COMPUTED_VALUE"""),0.0) -> 0
A371: =IFERROR(__xludf.DUMMYFUNCTION("""COMPUTED_VALUE"""),"")
A372: =IFERROR(__xludf.DUMMYFUNCTION("""COMPUTED_VALUE"""),"")
A373: =IFERROR(__xludf.DUMMYFUNCTION("""COMPUTED_VALUE"""),"")
A374: =IFERROR(__xludf.DUMMYFUNCTION("""COMPUTED_VALUE"""),"")
A375: =IFERROR(__xludf.DUMMYFUNCTION("""COMPUTED_VALUE"""),"")
A376: =IFERROR(__xludf.DUMMYFUNCTION("""COMPUTED_VALUE"""),"")
A377: =IFERROR(__xludf.DUMMYFUNCTION("""COMPUTED_VALUE"""),"")
A378: =IFERROR(__xludf.DUMMYFUNCTION("""COMPUTED_VALUE"""),"")
A379: =IFERROR(__xludf.DUMMYFUNCTION("""COMPUTED_VALUE"""),"")
A380: =IFERROR(__xludf.DUMMYFUNCTION("""COMPUTED_VALUE"""),"")
A381: =IFERROR(__xludf.DUMMYFUNCTION("""COMPUTED_VALUE"""),"")
A382: =IFERROR(__xludf.DUMMYFUNCTION("""COMPUTED_VALUE"""),"")
... A711: =IFERROR(__xludf.DUMMYFUNCTION("""COMPUTED_VALUE"""),"")

Sheet II
A1: =IFERROR(__xludf.DUMMYFUNCTION("IMPORTRANGE(""1r--qa2i5jCx8YeQ_mLlUrqLRTQh7y-fik2wTdRKBimk/edit?gid=675166745#gid=675166745"",""KELAS II!A2:BF750"")"),"NO") -> NO | B1: =IFERROR(__xludf.DUMMYFUNCTION("""COMPUTED_VALUE"""),"NAMA") -> NAMA | C1: =IFERROR(__xludf.DUMMYFUNCTION("""COMPUTED_VALUE"""),"NIS") -> NIS | D1: =IFERROR(__xludf.DUMMYFUNCTION("""COMPUTED_VALUE"""),"AYAH") -> AYAH | E1: =IFERROR(__xludf.DUMMYFUNCTION("""COMPUTED_VALUE"""),"IBU") -> IBU | F1: =IFERROR(__xludf.DUMMYFUNCTION("""COMPUTED_VALUE"""),"ALAMAT") -> ALAMAT | G1: =IFERROR(__xludf.DUMMYFUNCTION("""COMPUTED_VALUE"""),"SEKOLAH") -> SEKOLAH | H1: =IFERROR(__xludf.DUMMYFUNCTION("""COMPUTED_VALUE"""),"ASRAMA") -> ASRAMA | I1: =IFERROR(__xludf.DUMMYFUNCTION("""COMPUTED_VALUE"""),"KAMAR") -> KAMAR | J1: =IFERROR(__xludf.DUMMYFUNCTION("""COMPUTED_VALUE"""),"TINGKAT") -> TINGKAT | K1: =IFERROR(__xludf.DUMMYFUNCTION("""COMPUTED_VALUE"""),"MADRASIAH") -> MADRASIAH | L1: =IFERROR(__xludf.DUMMYFUNCTION("""COMPUTED_VALUE"""),"HP") -> HP | M1: =IFERROR(__xludf.DUMMYFUNCTION("""COMPUTED_VALUE"""),"JARIYAH I") -> JARIYAH I | N1: =IFERROR(__xludf.DUMMYFUNCTION("""COMPUTED_VALUE"""),"DANA KEGIATAN") -> DANA KEGIATAN | O1: =IFERROR(__xludf.DUMMYFUNCTION("""COMPUTED_VALUE"""),7.0) -> 7 | P1: =IFERROR(__xludf.DUMMYFUNCTION("""COMPUTED_VALUE"""),8.0) -> 8 | Q1: =IFERROR(__xludf.DUMMYFUNCTION("""COMPUTED_VALUE"""),9.0) -> 9 | R1: =IFERROR(__xludf.DUMMYFUNCTION("""COMPUTED_VALUE"""),10.0) -> 10 | S1: =IFERROR(__xludf.DUMMYFUNCTION("""COMPUTED_VALUE"""),11.0) -> 11 | T1: =IFERROR(__xludf.DUMMYFUNCTION("""COMPUTED_VALUE"""),12.0) -> 12 | U1: =IFERROR(__xludf.DUMMYFUNCTION("""COMPUTED_VALUE"""),1.0) -> 1 | V1: =IFERROR(__xludf.DUMMYFUNCTION("""COMPUTED_VALUE"""),2.0) -> 2 | W1: =IFERROR(__xludf.DUMMYFUNCTION("""COMPUTED_VALUE"""),3.0) -> 3 | X1: =IFERROR(__xludf.DUMMYFUNCTION("""COMPUTED_VALUE"""),4.0) -> 4 | Y1: =IFERROR(__xludf.DUMMYFUNCTION("""COMPUTED_VALUE"""),5.0) -> 5 | Z1: =IFERROR(__xludf.DUMMYFUNCTION("""COMPUTED_VALUE"""),6.0) -> 6 | AA1: =IFERROR(__xludf.DUMMYFUNCTION("""COMPUTED_VALUE"""),"DAFTAR ULANG KELAS II") -> DAFTAR ULANG KELAS II | AB1: =IFERROR(__xludf.DUMMYFUNCTION("""COMPUTED_VALUE"""),"JARIYAH II") -> JARIYAH II | AC1: =IFERROR(__xludf.DUMMYFUNCTION("""COMPUTED_VALUE"""),7.0) -> 7 | AD1: =IFERROR(__xludf.DUMMYFUNCTION("""COMPUTED_VALUE"""),8.0) -> 8 | AE1: =IFERROR(__xludf.DUMMYFUNCTION("""COMPUTED_VALUE"""),9.0) -> 9 | AF1: =IFERROR(__xludf.DUMMYFUNCTION("""COMPUTED_VALUE"""),10.0) -> 10 | AG1: =IFERROR(__xludf.DUMMYFUNCTION("""COMPUTED_VALUE"""),11.0) -> 11 | AH1: =IFERROR(__xludf.DUMMYFUNCTION("""COMPUTED_VALUE"""),12.0) -> 12 | AI1: =IFERROR(__xludf.DUMMYFUNCTION("""COMPUTED_VALUE"""),1.0) -> 1 | AJ1: =IFERROR(__xludf.DUMMYFUNCTION("""COMPUTED_VALUE"""),2.0) -> 2 | AK1: =IFERROR(__xludf.DUMMYFUNCTION("""COMPUTED_VALUE"""),3.0) -> 3 | AL1: =IFERROR(__xludf.DUMMYFUNCTION("""COMPUTED_VALUE"""),4.0) -> 4 | AM1: =IFERROR(__xludf.DUMMYFUNCTION("""COMPUTED_VALUE"""),5.0) -> 5 | AN1: =IFERROR(__xludf.DUMMYFUNCTION("""COMPUTED_VALUE"""),6.0) -> 6 | AO1: =IFERROR(__xludf.DUMMYFUNCTION("""COMPUTED_VALUE"""),"DAFTAR ULANG KELAS III") -> DAFTAR ULANG KELAS III | AP1: =IFERROR(__xludf.DUMMYFUNCTION("""COMPUTED_VALUE"""),"JARIYAH III") -> JARIYAH III | AQ1: =IFERROR(__xludf.DUMMYFUNCTION("""COMPUTED_VALUE"""),7.0) -> 7 | AR1: =IFERROR(__xludf.DUMMYFUNCTION("""COMPUTED_VALUE"""),8.0) -> 8 | AS1: =IFERROR(__xludf.DUMMYFUNCTION("""COMPUTED_VALUE"""),9.0) -> 9 | AT1: =IFERROR(__xludf.DUMMYFUNCTION("""COMPUTED_VALUE"""),10.0) -> 10 | AU1: =IFERROR(__xludf.DUMMYFUNCTION("""COMPUTED_VALUE"""),11.0) -> 11 | AV1: =IFERROR(__xludf.DUMMYFUNCTION("""COMPUTED_VALUE"""),12.0) -> 12 | AW1: =IFERROR(__xludf.DUMMYFUNCTION("""COMPUTED_VALUE"""),1.0) -> 1 | AX1: =IFERROR(__xludf.DUMMYFUNCTION("""COMPUTED_VALUE"""),2.0) -> 2 | AY1: =IFERROR(__xludf.DUMMYFUNCTION("""COMPUTED_VALUE"""),3.0) -> 3 | AZ1: =IFERROR(__xludf.DUMMYFUNCTION("""COMPUTED_VALUE"""),4.0) -> 4 | BA1: =IFERROR(__xludf.DUMMYFUNCTION("""COMPUTED_VALUE"""),5.0) -> 5 | BB1: =IFERROR(__xludf.DUMMYFUNCTION("""COMPUTED_VALUE"""),6.0) -> 6 | BC1: =IFERROR(__xludf.DUMMYFUNCTION("""COMPUTED_VALUE"""),"JUMLAH SYAHRIYAH") -> JUMLAH SYAHRIYAH | BD1: =IFERROR(__xludf.DUMMYFUNCTION("""COMPUTED_VALUE"""),"JUMLAH JARIYAH") -> JUMLAH JARIYAH | BE1: =IFERROR(__xludf.DUMMYFUNCTION("""COMPUTED_VALUE"""),"JUMLAH DAFTAR ULANG") -> JUMLAH DAFTAR ULANG | BF1: =IFERROR(__xludf.DUMMYFUNCTION("""COMPUTED_VALUE"""),"JUMLAH TOTAL TUNGGAKAN") -> JUMLAH TOTAL TUNGGAKAN
A2: =IFERROR(__xludf.DUMMYFUNCTION("""COMPUTED_VALUE"""),1.0) -> 1 | B2: =IFERROR(__xludf.DUMMYFUNCTION("""COMPUTED_VALUE"""),"ABD. RO`UF WISNU WARDANA") -> ABD. RO`UF WISNU WARDANA | C2: =IFERROR(__xludf.DUMMYFUNCTION("""COMPUTED_VALUE"""),2.025070115E9) -> 2025070115 | D2: =IFERROR(__xludf.DUMMYFUNCTION("""COMPUTED_VALUE"""),"ABDUL MUKHIT") -> ABDUL MUKHIT | E2: =IFERROR(__xludf.DUMMYFUNCTION("""COMPUTED_VALUE"""),"NUR LAYLI ROHMAWATI") -> NUR LAYLI ROHMAWATI | F2: =IFERROR(__xludf.DUMMYFUNCTION("""COMPUTED_VALUE"""),"KLATING TAKERANKLATING RT 005 RW 001 TIKUNG LAMONGAN") -> KLATING TAKERANKLATING RT 005 RW 001 TIKUNG LAMONGAN | G2: =IFERROR(__xludf.DUMMYFUNCTION("""COMPUTED_VALUE"""),"MA-XI.13") -> MA-XI.13 | H2: =IFERROR(__xludf.DUMMYFUNCTION("""COMPUTED_VALUE"""),"A") -> A | I2: =IFERROR(__xludf.DUMMYFUNCTION("""COMPUTED_VALUE"""),"A-4") -> A-4 | J2: =IFERROR(__xludf.DUMMYFUNCTION("""COMPUTED_VALUE"""),2.0) -> 2 | K2: =IFERROR(__xludf.DUMMYFUNCTION("""COMPUTED_VALUE"""),"2 MAK PUTRA") -> 2 MAK PUTRA | L2: =IFERROR(__xludf.DUMMYFUNCTION("""COMPUTED_VALUE"""),"6285707284833") -> 6285707284833 | AB2: =IFERROR(__xludf.DUMMYFUNCTION("""COMPUTED_VALUE"""),500000.0) -> 500000 | AP2: =IFERROR(__xludf.DUMMYFUNCTION("""COMPUTED_VALUE"""),500000.0) -> 500000 | BC2: =IFERROR(__xludf.DUMMYFUNCTION("""COMPUTED_VALUE"""),0.0) -> 0 | BD2: =IFERROR(__xludf.DUMMYFUNCTION("""COMPUTED_VALUE"""),1000000.0) -> 1000000 | BE2: =IFERROR(__xludf.DUMMYFUNCTION("""COMPUTED_VALUE"""),0.0) -> 0 | BF2: =IFERROR(__xludf.DUMMYFUNCTION("""COMPUTED_VALUE"""),1000000.0) -> 1000000
A3: =IFERROR(__xludf.DUMMYFUNCTION("""COMPUTED_VALUE"""),2.0) -> 2 | B3: =IFERROR(__xludf.DUMMYFUNCTION("""COMPUTED_VALUE"""),"ABDUL AZIZ") -> ABDUL AZIZ | C3: =IFERROR(__xludf.DUMMYFUNCTION("""COMPUTED_VALUE"""),2.025070596E9) -> 2025070596 | D3: =IFERROR(__xludf.DUMMYFUNCTION("""COMPUTED_VALUE"""),"ABDUL ROHIM") -> ABDUL ROHIM | E3: =IFERROR(__xludf.DUMMYFUNCTION("""COMPUTED_VALUE"""),"MAHWIYAH") -> MAHWIYAH | F3: =IFERROR(__xludf.DUMMYFUNCTION("""COMPUTED_VALUE"""),"KALIREJO RT 003 RW 002 DUKUN GRESIK") -> KALIREJO RT 003 RW 002 DUKUN GRESIK | G3: =IFERROR(__xludf.DUMMYFUNCTION("""COMPUTED_VALUE"""),"MTS-8 C") -> MTS-8 C | H3: =IFERROR(__xludf.DUMMYFUNCTION("""COMPUTED_VALUE"""),"A") -> A | I3: =IFERROR(__xludf.DUMMYFUNCTION("""COMPUTED_VALUE"""),"A-1") -> A-1 | J3: =IFERROR(__xludf.DUMMYFUNCTION("""COMPUTED_VALUE"""),2.0) -> 2 | K3: =IFERROR(__xludf.DUMMYFUNCTION("""COMPUTED_VALUE"""),"2 ULA A PUTRA") -> 2 ULA A PUTRA | L3: =IFERROR(__xludf.DUMMYFUNCTION("""COMPUTED_VALUE"""),"6285784330109") -> 6285784330109 | AP3: =IFERROR(__xludf.DUMMYFUNCTION("""COMPUTED_VALUE"""),500000.0) -> 500000 | BC3: =IFERROR(__xludf.DUMMYFUNCTION("""COMPUTED_VALUE"""),0.0) -> 0 | BD3: =IFERROR(__xludf.DUMMYFUNCTION("""COMPUTED_VALUE"""),500000.0) -> 500000 | BE3: =IFERROR(__xludf.DUMMYFUNCTION("""COMPUTED_VALUE"""),0.0) -> 0 | BF3: =IFERROR(__xludf.DUMMYFUNCTION("""COMPUTED_VALUE"""),500000.0) -> 500000
A4: =IFERROR(__xludf.DUMMYFUNCTION("""COMPUTED_VALUE"""),3.0) -> 3 | B4: =IFERROR(__xludf.DUMMYFUNCTION("""COMPUTED_VALUE"""),"ABDUL MALIK ARIF DAULAY") -> ABDUL MALIK ARIF DAULAY | C4: =IFERROR(__xludf.DUMMYFUNCTION("""COMPUTED_VALUE"""),2.025070299E9) -> 2025070299 | D4: =IFERROR(__xludf.DUMMYFUNCTION("""COMPUTED_VALUE"""),"HARI MAULIADI DAULAY") -> HARI MAULIADI DAULAY | E4: =IFERROR(__xludf.DUMMYFUNCTION("""COMPUTED_VALUE"""),"SITI NURAFIYAH") -> SITI NURAFIYAH | F4: =IFERROR(__xludf.DUMMYFUNCTION("""COMPUTED_VALUE"""),"GENDONG RT 002 RW 004 LAREN LAMONGAN") -> GENDONG RT 002 RW 004 LAREN LAMONGAN | G4: =IFERROR(__xludf.DUMMYFUNCTION("""COMPUTED_VALUE"""),"MA-XI.13") -> MA-XI.13 | H4: =IFERROR(__xludf.DUMMYFUNCTION("""COMPUTED_VALUE"""),"A") -> A | I4: =IFERROR(__xludf.DUMMYFUNCTION("""COMPUTED_VALUE"""),"A-2") -> A-2 | J4: =IFERROR(__xludf.DUMMYFUNCTION("""COMPUTED_VALUE"""),2.0) -> 2 | K4: =IFERROR(__xludf.DUMMYFUNCTION("""COMPUTED_VALUE"""),"2 MAK PUTRA") -> 2 MAK PUTRA | L4: =IFERROR(__xludf.DUMMYFUNCTION("""COMPUTED_VALUE"""),"6285646321062") -> 6285646321062 | AP4: =IFERROR(__xludf.DUMMYFUNCTION("""COMPUTED_VALUE"""),500000.0) -> 500000 | BC4: =IFERROR(__xludf.DUMMYFUNCTION("""COMPUTED_VALUE"""),0.0) -> 0 | BD4: =IFERROR(__xludf.DUMMYFUNCTION("""COMPUTED_VALUE"""),500000.0) -> 500000 | BE4: =IFERROR(__xludf.DUMMYFUNCTION("""COMPUTED_VALUE"""),0.0) -> 0 | BF4: =IFERROR(__xludf.DUMMYFUNCTION("""COMPUTED_VALUE"""),500000.0) -> 500000
A5: =IFERROR(__xludf.DUMMYFUNCTION("""COMPUTED_VALUE"""),4.0) -> 4 | B5: =IFERROR(__xludf.DUMMYFUNCTION("""COMPUTED_VALUE"""),"ABDUL MUIZ SALAM") -> ABDUL MUIZ SALAM | C5: =IFERROR(__xludf.DUMMYFUNCTION("""COMPUTED_VALUE"""),2.025070224E9) -> 2025070224 | D5: =IFERROR(__xludf.DUMMYFUNCTION("""COMPUTED_VALUE"""),"SUHARTOYO") -> SUHARTOYO | E5: =IFERROR(__xludf.DUMMYFUNCTION("""COMPUTED_VALUE"""),"KASMUNTIK") -> KASMUNTIK | F5: =IFERROR(__xludf.DUMMYFUNCTION("""COMPUTED_VALUE"""),"KEPATIHAN SUKOREJO RT 007 RW 002 TURI LAMONGAN") -> KEPATIHAN SUKOREJO RT 007 RW 002 TURI LAMONGAN | G5: =IFERROR(__xludf.DUMMYFUNCTION("""COMPUTED_VALUE"""),"MA-XI.13") -> MA-XI.13 | H5: =IFERROR(__xludf.DUMMYFUNCTION("""COMPUTED_VALUE"""),"A") -> A | I5: =IFERROR(__xludf.DUMMYFUNCTION("""COMPUTED_VALUE"""),"A-4") -> A-4 | J5: =IFERROR(__xludf.DUMMYFUNCTION("""COMPUTED_VALUE"""),2.0) -> 2 | K5: =IFERROR(__xludf.DUMMYFUNCTION("""COMPUTED_VALUE"""),"2 MAK PUTRA") -> 2 MAK PUTRA | L5: =IFERROR(__xludf.DUMMYFUNCTION("""COMPUTED_VALUE"""),"6285731779996") -> 6285731779996 | AB5: =IFERROR(__xludf.DUMMYFUNCTION("""COMPUTED_VALUE"""),500000.0) -> 500000 | AP5: =IFERROR(__xludf.DUMMYFUNCTION("""COMPUTED_VALUE"""),500000.0) -> 500000 | BC5: =IFERROR(__xludf.DUMMYFUNCTION("""COMPUTED_VALUE"""),0.0) -> 0 | BD5: =IFERROR(__xludf.DUMMYFUNCTION("""COMPUTED_VALUE"""),1000000.0) -> 1000000 | BE5: =IFERROR(__xludf.DUMMYFUNCTION("""COMPUTED_VALUE"""),0.0) -> 0 | BF5: =IFERROR(__xludf.DUMMYFUNCTION("""COMPUTED_VALUE"""),1000000.0) -> 1000000
A6: =IFERROR(__xludf.DUMMYFUNCTION("""COMPUTED_VALUE"""),5.0) -> 5 | B6: =IFERROR(__xludf.DUMMYFUNCTION("""COMPUTED_VALUE"""),"ABDUL QODIR AL JAILANI") -> ABDUL QODIR AL JAILANI | C6: =IFERROR(__xludf.DUMMYFUNCTION("""COMPUTED_VALUE"""),2.025070418E9) -> 2025070418 | D6: =IFERROR(__xludf.DUMMYFUNCTION("""COMPUTED_VALUE"""),"SHOLEHODDIN") -> SHOLEHODDIN | E6: =IFERROR(__xludf.DUMMYFUNCTION("""COMPUTED_VALUE"""),"MUNIROH") -> MUNIROH | F6: =IFERROR(__xludf.DUMMYFUNCTION("""COMPUTED_VALUE"""),"BERLANTONG PANDIYANGAN RT 000 RW 000 ROBATAL SAMPANG") -> BERLANTONG PANDIYANGAN RT 000 RW 000 ROBATAL SAMPANG | G6: =IFERROR(__xludf.DUMMYFUNCTION("""COMPUTED_VALUE"""),"MA-XI.13") -> MA-XI.13 | H6: =IFERROR(__xludf.DUMMYFUNCTION("""COMPUTED_VALUE"""),"A") -> A | I6: =IFERROR(__xludf.DUMMYFUNCTION("""COMPUTED_VALUE"""),"A-2") -> A-2 | J6: =IFERROR(__xludf.DUMMYFUNCTION("""COMPUTED_VALUE"""),2.0) -> 2 | K6: =IFERROR(__xludf.DUMMYFUNCTION("""COMPUTED_VALUE"""),"2 MAK PUTRA") -> 2 MAK PUTRA | L6: =IFERROR(__xludf.DUMMYFUNCTION("""COMPUTED_VALUE"""),"6282334141174") -> 6282334141174 | N6: =IFERROR(__xludf.DUMMYFUNCTION("""COMPUTED_VALUE""")," ") | Z6: =IFERROR(__xludf.DUMMYFUNCTION("""COMPUTED_VALUE"""),450000.0) -> 450000 | BC6: =IFERROR(__xludf.DUMMYFUNCTION("""COMPUTED_VALUE"""),450000.0) -> 450000 | BD6: =IFERROR(__xludf.DUMMYFUNCTION("""COMPUTED_VALUE"""),0.0) -> 0 | BE6: =IFERROR(__xludf.DUMMYFUNCTION("""COMPUTED_VALUE"""),0.0) -> 0 | BF6: =IFERROR(__xludf.DUMMYFUNCTION("""COMPUTED_VALUE"""),450000.0) -> 450000
A7: =IFERROR(__xludf.DUMMYFUNCTION("""COMPUTED_VALUE"""),6.0) -> 6 | B7: =IFERROR(__xludf.DUMMYFUNCTION("""COMPUTED_VALUE"""),"ABI DZAR AL GHIFARI") -> ABI DZAR AL GHIFARI | C7: =IFERROR(__xludf.DUMMYFUNCTION("""COMPUTED_VALUE"""),2.025070493E9) -> 2025070493 | D7: =IFERROR(__xludf.DUMMYFUNCTION("""COMPUTED_VALUE"""),"MOH. ROHMAN") -> MOH. ROHMAN | E7: =IFERROR(__xludf.DUMMYFUNCTION("""COMPUTED_VALUE"""),"SITI WAHYUNI") -> SITI WAHYUNI | F7: =IFERROR(__xludf.DUMMYFUNCTION("""COMPUTED_VALUE"""),"GLUMO JELAKCATUR RT 001 RW 005 KALITENGAH LAMONGAN") -> GLUMO JELAKCATUR RT 001 RW 005 KALITENGAH LAMONGAN | G7: =IFERROR(__xludf.DUMMYFUNCTION("""COMPUTED_VALUE"""),"SMP-VIII C") -> SMP-VIII C | H7: =IFERROR(__xludf.DUMMYFUNCTION("""COMPUTED_VALUE"""),"A") -> A | I7: =IFERROR(__xludf.DUMMYFUNCTION("""COMPUTED_VALUE"""),"A-1") -> A-1 | J7: =IFERROR(__xludf.DUMMYFUNCTION("""COMPUTED_VALUE"""),2.0) -> 2 | K7: =IFERROR(__xludf.DUMMYFUNCTION("""COMPUTED_VALUE"""),"2 ULA A PUTRA") -> 2 ULA A PUTRA | L7: =IFERROR(__xludf.DUMMYFUNCTION("""COMPUTED_VALUE"""),"6285855722817") -> 6285855722817 | M7: =IFERROR(__xludf.DUMMYFUNCTION("""COMPUTED_VALUE"""),600000.0) -> 600000 | Q7: =IFERROR(__xludf.DUMMYFUNCTION("""COMPUTED_VALUE"""),450000.0) -> 450000 | R7: =IFERROR(__xludf.DUMMYFUNCTION("""COMPUTED_VALUE"""),450000.0) -> 450000 | S7: =IFERROR(__xludf.DUMMYFUNCTION("""COMPUTED_VALUE"""),450000.0) -> 450000 | T7: =IFERROR(__xludf.DUMMYFUNCTION("""COMPUTED_VALUE"""),450000.0) -> 450000 | U7: =IFERROR(__xludf.DUMMYFUNCTION("""COMPUTED_VALUE"""),450000.0) -> 450000 | V7: =IFERROR(__xludf.DUMMYFUNCTION("""COMPUTED_VALUE"""),450000.0) -> 450000 | W7: =IFERROR(__xludf.DUMMYFUNCTION("""COMPUTED_VALUE"""),450000.0) -> 450000 | X7: =IFERROR(__xludf.DUMMYFUNCTION("""COMPUTED_VALUE"""),450000.0) -> 450000 | ... Z7: =IFERROR(__xludf.DUMMYFUNCTION("""COMPUTED_VALUE"""),450000.0) -> 450000 | AB7: =IFERROR(__xludf.DUMMYFUNCTION("""COMPUTED_VALUE"""),500000.0) -> 500000 | AP7: =IFERROR(__xludf.DUMMYFUNCTION("""COMPUTED_VALUE"""),500000.0) -> 500000 | BC7: =IFERROR(__xludf.DUMMYFUNCTION("""COMPUTED_VALUE"""),4500000.0) -> 4500000 | BD7: =IFERROR(__xludf.DUMMYFUNCTION("""COMPUTED_VALUE"""),1600000.0) -> 1600000 | BE7: =IFERROR(__xludf.DUMMYFUNCTION("""COMPUTED_VALUE"""),0.0) -> 0 | BF7: =IFERROR(__xludf.DUMMYFUNCTION("""COMPUTED_VALUE"""),6100000.0) -> 6100000
A8: =IFERROR(__xludf.DUMMYFUNCTION("""COMPUTED_VALUE"""),7.0) -> 7 | B8: =IFERROR(__xludf.DUMMYFUNCTION("""COMPUTED_VALUE"""),"ACHMAD MIFTAHUL AN-NURIL HUDA") -> ACHMAD MIFTAHUL AN-NURIL HUDA | C8: =IFERROR(__xludf.DUMMYFUNCTION("""COMPUTED_VALUE"""),2.025070328E9) -> 2025070328 | D8: =IFERROR(__xludf.DUMMYFUNCTION("""COMPUTED_VALUE"""),"MUHAMMAD ROQIB") -> MUHAMMAD ROQIB | E8: =IFERROR(__xludf.DUMMYFUNCTION("""COMPUTED_VALUE"""),"QOMAI EFTIKA") -> QOMAI EFTIKA | F8: =IFERROR(__xludf.DUMMYFUNCTION("""COMPUTED_VALUE"""),"SUKOLILO RT 002 RW 003 SUKODADI LAMONGAN") -> SUKOLILO RT 002 RW 003 SUKODADI LAMONGAN | G8: =IFERROR(__xludf.DUMMYFUNCTION("""COMPUTED_VALUE"""),"MA-XI.13") -> MA-XI.13 | H8: =IFERROR(__xludf.DUMMYFUNCTION("""COMPUTED_VALUE"""),"A") -> A | I8: =IFERROR(__xludf.DUMMYFUNCTION("""COMPUTED_VALUE"""),"A-2") -> A-2 | J8: =IFERROR(__xludf.DUMMYFUNCTION("""COMPUTED_VALUE"""),2.0) -> 2 | K8: =IFERROR(__xludf.DUMMYFUNCTION("""COMPUTED_VALUE"""),"2 MAK PUTRA") -> 2 MAK PUTRA | L8: =IFERROR(__xludf.DUMMYFUNCTION("""COMPUTED_VALUE"""),"62895420477717") -> 62895420477717 | N8: =IFERROR(__xludf.DUMMYFUNCTION("""COMPUTED_VALUE"""),200000.0) -> 200000 | X8: =IFERROR(__xludf.DUMMYFUNCTION("""COMPUTED_VALUE"""),450000.0) -> 450000 | Y8: =IFERROR(__xludf.DUMMYFUNCTION("""COMPUTED_VALUE"""),450000.0) -> 450000 | Z8: =IFERROR(__xludf.DUMMYFUNCTION("""COMPUTED_VALUE"""),450000.0) -> 450000 | BC8: =IFERROR(__xludf.DUMMYFUNCTION("""COMPUTED_VALUE"""),1350000.0) -> 1350000 | BD8: =IFERROR(__xludf.DUMMYFUNCTION("""COMPUTED_VALUE"""),0.0) -> 0 | BE8: =IFERROR(__xludf.DUMMYFUNCTION("""COMPUTED_VALUE"""),0.0) -> 0 | BF8: =IFERROR(__xludf.DUMMYFUNCTION("""COMPUTED_VALUE"""),1350000.0) -> 1350000
A9: =IFERROR(__xludf.DUMMYFUNCTION("""COMPUTED_VALUE"""),8.0) -> 8 | B9: =IFERROR(__xludf.DUMMYFUNCTION("""COMPUTED_VALUE"""),"ACHMAD SIDDIQ") -> ACHMAD SIDDIQ | C9: =IFERROR(__xludf.DUMMYFUNCTION("""COMPUTED_VALUE"""),2.025070306E9) -> 2025070306 | D9: =IFERROR(__xludf.DUMMYFUNCTION("""COMPUTED_VALUE"""),"ZAENAL MUSTOFA") -> ZAENAL MUSTOFA | E9: =IFERROR(__xludf.DUMMYFUNCTION("""COMPUTED_VALUE"""),"KUSENAH") -> KUSENAH | F9: =IFERROR(__xludf.DUMMYFUNCTION("""COMPUTED_VALUE"""),"BANYUBANG RT 011 RW 003 SOLOKURO LAMONGAN") -> BANYUBANG RT 011 RW 003 SOLOKURO LAMONGAN | G9: =IFERROR(__xludf.DUMMYFUNCTION("""COMPUTED_VALUE"""),"MA-XI.13") -> MA-XI.13 | H9: =IFERROR(__xludf.DUMMYFUNCTION("""COMPUTED_VALUE"""),"A") -> A | I9: =IFERROR(__xludf.DUMMYFUNCTION("""COMPUTED_VALUE"""),"A-4") -> A-4 | J9: =IFERROR(__xludf.DUMMYFUNCTION("""COMPUTED_VALUE"""),2.0) -> 2 | K9: =IFERROR(__xludf.DUMMYFUNCTION("""COMPUTED_VALUE"""),"2 MAK PUTRA") -> 2 MAK PUTRA | L9: =IFERROR(__xludf.DUMMYFUNCTION("""COMPUTED_VALUE"""),"6282214993212") -> 6282214993212 | AB9: =IFERROR(__xludf.DUMMYFUNCTION("""COMPUTED_VALUE"""),500000.0) -> 500000 | AP9: =IFERROR(__xludf.DUMMYFUNCTION("""COMPUTED_VALUE"""),500000.0) -> 500000 | BC9: =IFERROR(__xludf.DUMMYFUNCTION("""COMPUTED_VALUE"""),0.0) -> 0 | BD9: =IFERROR(__xludf.DUMMYFUNCTION("""COMPUTED_VALUE"""),1000000.0) -> 1000000 | BE9: =IFERROR(__xludf.DUMMYFUNCTION("""COMPUTED_VALUE"""),0.0) -> 0 | BF9: =IFERROR(__xludf.DUMMYFUNCTION("""COMPUTED_VALUE"""),1000000.0) -> 1000000
A10: =IFERROR(__xludf.DUMMYFUNCTION("""COMPUTED_VALUE"""),9.0) -> 9 | B10: =IFERROR(__xludf.DUMMYFUNCTION("""COMPUTED_VALUE"""),"ACHMAD SYAHRUL DZAKIE AL KAUTSAR") -> ACHMAD SYAHRUL DZAKIE AL KAUTSAR | C10: =IFERROR(__xludf.DUMMYFUNCTION("""COMPUTED_VALUE"""),2.025070523E9) -> 2025070523 | D10: =IFERROR(__xludf.DUMMYFUNCTION("""COMPUTED_VALUE"""),"MOH. SYAIFUL ANSHOR") -> MOH. SYAIFUL ANSHOR | E10: =IFERROR(__xludf.DUMMYFUNCTION("""COMPUTED_VALUE"""),"SHOLIHATUL MUFIDAH") -> SHOLIHATUL MUFIDAH | F10: =IFERROR(__xludf.DUMMYFUNCTION("""COMPUTED_VALUE"""),"JL AMBARAWA PETUNG RT 010 RW 004 PANCENG BABAT") -> JL AMBARAWA PETUNG RT 010 RW 004 PANCENG BABAT | G10: =IFERROR(__xludf.DUMMYFUNCTION("""COMPUTED_VALUE"""),"MTS-8 F") -> MTS-8 F | H10: =IFERROR(__xludf.DUMMYFUNCTION("""COMPUTED_VALUE"""),"A") -> A | I10: =IFERROR(__xludf.DUMMYFUNCTION("""COMPUTED_VALUE"""),"A-3") -> A-3 | J10: =IFERROR(__xludf.DUMMYFUNCTION("""COMPUTED_VALUE"""),2.0) -> 2 | K10: =IFERROR(__xludf.DUMMYFUNCTION("""COMPUTED_VALUE"""),"2 ULA A PUTRA") -> 2 ULA A PUTRA | L10: =IFERROR(__xludf.DUMMYFUNCTION("""COMPUTED_VALUE"""),"62881027793394") -> 62881027793394 | AB10: =IFERROR(__xludf.DUMMYFUNCTION("""COMPUTED_VALUE"""),500000.0) -> 500000 | AP10: =IFERROR(__xludf.DUMMYFUNCTION("""COMPUTED_VALUE"""),500000.0) -> 500000 | BC10: =IFERROR(__xludf.DUMMYFUNCTION("""COMPUTED_VALUE"""),0.0) -> 0 | BD10: =IFERROR(__xludf.DUMMYFUNCTION("""COMPUTED_VALUE"""),1000000.0) -> 1000000 | BE10: =IFERROR(__xludf.DUMMYFUNCTION("""COMPUTED_VALUE"""),0.0) -> 0 | BF10: =IFERROR(__xludf.DUMMYFUNCTION("""COMPUTED_VALUE"""),1000000.0) -> 1000000
A11: =IFERROR(__xludf.DUMMYFUNCTION("""COMPUTED_VALUE"""),10.0) -> 10 | B11: =IFERROR(__xludf.DUMMYFUNCTION("""COMPUTED_VALUE"""),"ADHIAN SAKANI ZADDA") -> ADHIAN SAKANI ZADDA | C11: =IFERROR(__xludf.DUMMYFUNCTION("""COMPUTED_VALUE"""),2.025070582E9) -> 2025070582 | D11: =IFERROR(__xludf.DUMMYFUNCTION("""COMPUTED_VALUE"""),"KUSNUL SAKIN") -> KUSNUL SAKIN | E11: =IFERROR(__xludf.DUMMYFUNCTION("""COMPUTED_VALUE"""),"MARKUTIK") -> MARKUTIK | F11: =IFERROR(__xludf.DUMMYFUNCTION("""COMPUTED_VALUE"""),"SUGIHAN RT 012 RW 002 SOLOKURO LAMONGAN") -> SUGIHAN RT 012 RW 002 SOLOKURO LAMONGAN | G11: =IFERROR(__xludf.DUMMYFUNCTION("""COMPUTED_VALUE"""),"MTS-8 G") -> MTS-8 G | H11: =IFERROR(__xludf.DUMMYFUNCTION("""COMPUTED_VALUE"""),"A") -> A | I11: =IFERROR(__xludf.DUMMYFUNCTION("""COMPUTED_VALUE"""),"A-3") -> A-3 | J11: =IFERROR(__xludf.DUMMYFUNCTION("""COMPUTED_VALUE"""),2.0) -> 2 | K11: =IFERROR(__xludf.DUMMYFUNCTION("""COMPUTED_VALUE"""),"2 ULA A PUTRA") -> 2 ULA A PUTRA | L11: =IFERROR(__xludf.DUMMYFUNCTION("""COMPUTED_VALUE"""),"628563276002") -> 628563276002 | AB11: =IFERROR(__xludf.DUMMYFUNCTION("""COMPUTED_VALUE"""),500000.0) -> 500000 | AP11: =IFERROR(__xludf.DUMMYFUNCTION("""COMPUTED_VALUE"""),500000.0) -> 500000 | BC11: =IFERROR(__xludf.DUMMYFUNCTION("""COMPUTED_VALUE"""),0.0) -> 0 | BD11: =IFERROR(__xludf.DUMMYFUNCTION("""COMPUTED_VALUE"""),1000000.0) -> 1000000 | BE11: =IFERROR(__xludf.DUMMYFUNCTION("""COMPUTED_VALUE"""),0.0) -> 0 | BF11: =IFERROR(__xludf.DUMMYFUNCTION("""COMPUTED_VALUE"""),1000000.0) -> 1000000
A12: =IFERROR(__xludf.DUMMYFUNCTION("""COMPUTED_VALUE"""),11.0) -> 11 | B12: =IFERROR(__xludf.DUMMYFUNCTION("""COMPUTED_VALUE"""),"ADI FAJAR MUAYYAD") -> ADI FAJAR MUAYYAD | C12: =IFERROR(__xludf.DUMMYFUNCTION("""COMPUTED_VALUE"""),2.025070642E9) -> 2025070642 | D12: =IFERROR(__xludf.DUMMYFUNCTION("""COMPUTED_VALUE"""),"SRIMAT") -> SRIMAT | E12: =IFERROR(__xludf.DUMMYFUNCTION("""COMPUTED_VALUE"""),"UMMUL HASANAH") -> UMMUL HASANAH | F12: =IFERROR(__xludf.DUMMYFUNCTION("""COMPUTED_VALUE"""),"KARANGTAWAR RT 002 RW 001 LAREN LAMONGAN") -> KARANGTAWAR RT 002 RW 001 LAREN LAMONGAN | G12: =IFERROR(__xludf.DUMMYFUNCTION("""COMPUTED_VALUE"""),"MTS-8 B") -> MTS-8 B | H12: =IFERROR(__xludf.DUMMYFUNCTION("""COMPUTED_VALUE"""),"A") -> A | I12: =IFERROR(__xludf.DUMMYFUNCTION("""COMPUTED_VALUE"""),"A-1") -> A-1 | J12: =IFERROR(__xludf.DUMMYFUNCTION("""COMPUTED_VALUE"""),2.0) -> 2 | K12: =IFERROR(__xludf.DUMMYFUNCTION("""COMPUTED_VALUE"""),"2 ULA A PUTRA") -> 2 ULA A PUTRA | L12: =IFERROR(__xludf.DUMMYFUNCTION("""COMPUTED_VALUE"""),"6285739097145") -> 6285739097145 | BC12: =IFERROR(__xludf.DUMMYFUNCTION("""COMPUTED_VALUE"""),0.0) -> 0 | BD12: =IFERROR(__xludf.DUMMYFUNCTION("""COMPUTED_VALUE"""),0.0) -> 0 | BE12: =IFERROR(__xludf.DUMMYFUNCTION("""COMPUTED_VALUE"""),0.0) -> 0 | BF12: =IFERROR(__xludf.DUMMYFUNCTION("""COMPUTED_VALUE"""),0.0) -> 0
A13: =IFERROR(__xludf.DUMMYFUNCTION("""COMPUTED_VALUE"""),12.0) -> 12 | B13: =IFERROR(__xludf.DUMMYFUNCTION("""COMPUTED_VALUE"""),"ADITYA FERYANSYAH") -> ADITYA FERYANSYAH | C13: =IFERROR(__xludf.DUMMYFUNCTION("""COMPUTED_VALUE"""),2.02507046E9) -> 2025070460 | D13: =IFERROR(__xludf.DUMMYFUNCTION("""COMPUTED_VALUE"""),"ZAENAL ARIFIN W") -> ZAENAL ARIFIN W | E13: =IFERROR(__xludf.DUMMYFUNCTION("""COMPUTED_VALUE"""),"ASLAMIYAH") -> ASLAMIYAH | F13: =IFERROR(__xludf.DUMMYFUNCTION("""COMPUTED_VALUE"""),"JL. DEMAK JAYA GG 8 NO 9 TEMBOK DUKUH RT 012 RW 010 BUBUTAN SURABAYA") -> JL. DEMAK JAYA GG 8 NO 9 TEMBOK DUKUH RT 012 RW 010 BUBUTAN SURABAYA | G13: =IFERROR(__xludf.DUMMYFUNCTION("""COMPUTED_VALUE"""),"SMK-XI TSM") -> SMK-XI TSM | H13: =IFERROR(__xludf.DUMMYFUNCTION("""COMPUTED_VALUE"""),"A") -> A | I13: =IFERROR(__xludf.DUMMYFUNCTION("""COMPUTED_VALUE"""),"A-4") -> A-4 | J13: =IFERROR(__xludf.DUMMYFUNCTION("""COMPUTED_VALUE"""),2.0) -> 2 | K13: =IFERROR(__xludf.DUMMYFUNCTION("""COMPUTED_VALUE"""),"2 WUSTHO A PUTRA") -> 2 WUSTHO A PUTRA | L13: =IFERROR(__xludf.DUMMYFUNCTION("""COMPUTED_VALUE"""),"6283857988668") -> 6283857988668 | AB13: =IFERROR(__xludf.DUMMYFUNCTION("""COMPUTED_VALUE"""),500000.0) -> 500000 | AP13: =IFERROR(__xludf.DUMMYFUNCTION("""COMPUTED_VALUE"""),500000.0) -> 500000 | BC13: =IFERROR(__xludf.DUMMYFUNCTION("""COMPUTED_VALUE"""),0.0) -> 0 | BD13: =IFERROR(__xludf.DUMMYFUNCTION("""COMPUTED_VALUE"""),1000000.0) -> 1000000 | BE13: =IFERROR(__xludf.DUMMYFUNCTION("""COMPUTED_VALUE"""),0.0) -> 0 | BF13: =IFERROR(__xludf.DUMMYFUNCTION("""COMPUTED_VALUE"""),1000000.0) -> 1000000
A14: =IFERROR(__xludf.DUMMYFUNCTION("""COMPUTED_VALUE"""),13.0) -> 13 | B14: =IFERROR(__xludf.DUMMYFUNCTION("""COMPUTED_VALUE"""),"ADJIE PANGESTU NURZAINI") -> ADJIE PANGESTU NURZAINI | C14: =IFERROR(__xludf.DUMMYFUNCTION("""COMPUTED_VALUE"""),2.02507061E9) -> 2025070610 | D14: =IFERROR(__xludf.DUMMYFUNCTION("""COMPUTED_VALUE"""),"AHKMAD ZAINUDDIN") -> AHKMAD ZAINUDDIN | E14: =IFERROR(__xludf.DUMMYFUNCTION("""COMPUTED_VALUE"""),"YUNI HARIATI NINGSIH") -> YUNI HARIATI NINGSIH | F14: =IFERROR(__xludf.DUMMYFUNCTION("""COMPUTED_VALUE"""),"GERMAN RT 002 RW 004 SUGIO LAMONGAN") -> GERMAN RT 002 RW 004 SUGIO LAMONGAN | G14: =IFERROR(__xludf.DUMMYFUNCTION("""COMPUTED_VALUE"""),"MTS-8 C") -> MTS-8 C | H14: =IFERROR(__xludf.DUMMYFUNCTION("""COMPUTED_VALUE"""),"A") -> A | I14: =IFERROR(__xludf.DUMMYFUNCTION("""COMPUTED_VALUE"""),"A-1") -> A-1 | J14: =IFERROR(__xludf.DUMMYFUNCTION("""COMPUTED_VALUE"""),2.0) -> 2 | K14: =IFERROR(__xludf.DUMMYFUNCTION("""COMPUTED_VALUE"""),"2 ULA A PUTRA") -> 2 ULA A PUTRA | L14: =IFERROR(__xludf.DUMMYFUNCTION("""COMPUTED_VALUE"""),"6282132209162") -> 6282132209162 | Y14: =IFERROR(__xludf.DUMMYFUNCTION("""COMPUTED_VALUE"""),450000.0) -> 450000 | Z14: =IFERROR(__xludf.DUMMYFUNCTION("""COMPUTED_VALUE"""),450000.0) -> 450000 | AP14: =IFERROR(__xludf.DUMMYFUNCTION("""COMPUTED_VALUE"""),500000.0) -> 500000 | BC14: =IFERROR(__xludf.DUMMYFUNCTION("""COMPUTED_VALUE"""),900000.0) -> 900000 | BD14: =IFERROR(__xludf.DUMMYFUNCTION("""COMPUTED_VALUE"""),500000.0) -> 500000 | BE14: =IFERROR(__xludf.DUMMYFUNCTION("""COMPUTED_VALUE"""),0.0) -> 0 | BF14: =IFERROR(__xludf.DUMMYFUNCTION("""COMPUTED_VALUE"""),1400000.0) -> 1400000
A15: =IFERROR(__xludf.DUMMYFUNCTION("""COMPUTED_VALUE"""),14.0) -> 14 | B15: =IFERROR(__xludf.DUMMYFUNCTION("""COMPUTED_VALUE"""),"AFDHOL MUSYAFA") -> AFDHOL MUSYAFA | C15: =IFERROR(__xludf.DUMMYFUNCTION("""COMPUTED_VALUE"""),2.025070436E9) -> 2025070436 | D15: =IFERROR(__xludf.DUMMYFUNCTION("""COMPUTED_VALUE"""),"IRWAN") -> IRWAN | E15: =IFERROR(__xludf.DUMMYFUNCTION("""COMPUTED_VALUE"""),"MAISAROH") -> MAISAROH | F15: =IFERROR(__xludf.DUMMYFUNCTION("""COMPUTED_VALUE"""),"JL. KAPAL SELAM LOK TUAN RT 018 RW 000 BONTANG UTARA BONTANG") -> JL. KAPAL SELAM LOK TUAN RT 018 RW 000 BONTANG UTARA BONTANG | G15: =IFERROR(__xludf.DUMMYFUNCTION("""COMPUTED_VALUE"""),"SMK-XI TKJ 1") -> SMK-XI TKJ 1 | H15: =IFERROR(__xludf.DUMMYFUNCTION("""COMPUTED_VALUE"""),"A") -> A | I15: =IFERROR(__xludf.DUMMYFUNCTION("""COMPUTED_VALUE"""),"A-9") -> A-9 | J15: =IFERROR(__xludf.DUMMYFUNCTION("""COMPUTED_VALUE"""),2.0) -> 2 | K15: =IFERROR(__xludf.DUMMYFUNCTION("""COMPUTED_VALUE"""),"2 WUSTHO A PUTRA") -> 2 WUSTHO A PUTRA | L15: =IFERROR(__xludf.DUMMYFUNCTION("""COMPUTED_VALUE"""),"6282240716916") -> 6282240716916 | BC15: =IFERROR(__xludf.DUMMYFUNCTION("""COMPUTED_VALUE"""),0.0) -> 0 | BD15: =IFERROR(__xludf.DUMMYFUNCTION("""COMPUTED_VALUE"""),0.0) -> 0 | BE15: =IFERROR(__xludf.DUMMYFUNCTION("""COMPUTED_VALUE"""),0.0) -> 0 | BF15: =IFERROR(__xludf.DUMMYFUNCTION("""COMPUTED_VALUE"""),0.0) -> 0
A16: =IFERROR(__xludf.DUMMYFUNCTION("""COMPUTED_VALUE"""),15.0) -> 15 | B16: =IFERROR(__xludf.DUMMYFUNCTION("""COMPUTED_VALUE"""),"AHMAD AUFAR SHOLAHAN HIRZI") -> AHMAD AUFAR SHOLAHAN HIRZI | C16: =IFERROR(__xludf.DUMMYFUNCTION("""COMPUTED_VALUE"""),2.025070632E9) -> 2025070632 | D16: =IFERROR(__xludf.DUMMYFUNCTION("""COMPUTED_VALUE"""),"MOHAMAD NURUL IHSAN") -> MOHAMAD NURUL IHSAN | E16: =IFERROR(__xludf.DUMMYFUNCTION("""COMPUTED_VALUE"""),"SHOFIYATUN") -> SHOFIYATUN | F16: =IFERROR(__xludf.DUMMYFUNCTION("""COMPUTED_VALUE"""),"PUCANGRO RT 004 RW 001 KALITENGAH LAMONGAN") -> PUCANGRO RT 004 RW 001 KALITENGAH LAMONGAN | G16: =IFERROR(__xludf.DUMMYFUNCTION("""COMPUTED_VALUE"""),"MTS-8 C") -> MTS-8 C | H16: =IFERROR(__xludf.DUMMYFUNCTION("""COMPUTED_VALUE"""),"A") -> A | I16: =IFERROR(__xludf.DUMMYFUNCTION("""COMPUTED_VALUE"""),"A-3") -> A-3 | J16: =IFERROR(__xludf.DUMMYFUNCTION("""COMPUTED_VALUE"""),2.0) -> 2 | K16: =IFERROR(__xludf.DUMMYFUNCTION("""COMPUTED_VALUE"""),"2 ULA A PUTRA") -> 2 ULA A PUTRA | L16: =IFERROR(__xludf.DUMMYFUNCTION("""COMPUTED_VALUE"""),"6285707398701") -> 6285707398701 | AB16: =IFERROR(__xludf.DUMMYFUNCTION("""COMPUTED_VALUE"""),500000.0) -> 500000 | AP16: =IFERROR(__xludf.DUMMYFUNCTION("""COMPUTED_VALUE"""),500000.0) -> 500000 | BC16: =IFERROR(__xludf.DUMMYFUNCTION("""COMPUTED_VALUE"""),0.0) -> 0 | BD16: =IFERROR(__xludf.DUMMYFUNCTION("""COMPUTED_VALUE"""),1000000.0) -> 1000000 | BE16: =IFERROR(__xludf.DUMMYFUNCTION("""COMPUTED_VALUE"""),0.0) -> 0 | BF16: =IFERROR(__xludf.DUMMYFUNCTION("""COMPUTED_VALUE"""),1000000.0) -> 1000000
A17: =IFERROR(__xludf.DUMMYFUNCTION("""COMPUTED_VALUE"""),16.0) -> 16 | B17: =IFERROR(__xludf.DUMMYFUNCTION("""COMPUTED_VALUE"""),"AHMAD AVICENNA AHZA") -> AHMAD AVICENNA AHZA | C17: =IFERROR(__xludf.DUMMYFUNCTION("""COMPUTED_VALUE"""),2.025070625E9) -> 2025070625 | D17: =IFERROR(__xludf.DUMMYFUNCTION("""COMPUTED_VALUE"""),"ILHAM") -> ILHAM | E17: =IFERROR(__xludf.DUMMYFUNCTION("""COMPUTED_VALUE"""),"ARKANI") -> ARKANI | F17: =IFERROR(__xludf.DUMMYFUNCTION("""COMPUTED_VALUE"""),"PADENGANPLOSO RT 005 RW 001 PUCUK LAMONGAN") -> PADENGANPLOSO RT 005 RW 001 PUCUK LAMONGAN | G17: =IFERROR(__xludf.DUMMYFUNCTION("""COMPUTED_VALUE"""),"MTS-8 E") -> MTS-8 E | H17: =IFERROR(__xludf.DUMMYFUNCTION("""COMPUTED_VALUE"""),"A") -> A | I17: =IFERROR(__xludf.DUMMYFUNCTION("""COMPUTED_VALUE"""),"A-3") -> A-3 | J17: =IFERROR(__xludf.DUMMYFUNCTION("""COMPUTED_VALUE"""),2.0) -> 2 | K17: =IFERROR(__xludf.DUMMYFUNCTION("""COMPUTED_VALUE"""),"2 ULA A PUTRA") -> 2 ULA A PUTRA | L17: =IFERROR(__xludf.DUMMYFUNCTION("""COMPUTED_VALUE"""),"6285231952815") -> 6285231952815 | AB17: =IFERROR(__xludf.DUMMYFUNCTION("""COMPUTED_VALUE"""),500000.0) -> 500000 | AP17: =IFERROR(__xludf.DUMMYFUNCTION("""COMPUTED_VALUE"""),500000.0) -> 500000 | BC17: =IFERROR(__xludf.DUMMYFUNCTION("""COMPUTED_VALUE"""),0.0) -> 0 | BD17: =IFERROR(__xludf.DUMMYFUNCTION("""COMPUTED_VALUE"""),1000000.0) -> 1000000 | BE17: =IFERROR(__xludf.DUMMYFUNCTION("""COMPUTED_VALUE"""),0.0) -> 0 | BF17: =IFERROR(__xludf.DUMMYFUNCTION("""COMPUTED_VALUE"""),1000000.0) -> 1000000
