Workbook

Sheet import1
A1: =IFERROR(__xludf.DUMMYFUNCTION("IMPORTRANGE(""1r--qa2i5jCx8YeQ_mLlUrqLRTQh7y-fik2wTdRKBimk/edit?gid=214218921#gid=214218921"",""KELAS I!A2:BF750"")"),"NO") -> NO | B1: =IFERROR(__xludf.DUMMYFUNCTION("""COMPUTED_VALUE"""),"NAMA") -> NAMA | C1: =IFERROR(__xludf.DUMMYFUNCTION("""COMPUTED_VALUE"""),"NIS") -> NIS | D1: =IFERROR(__xludf.DUMMYFUNCTION("""COMPUTED_VALUE"""),"AYAH") -> AYAH | E1: =IFERROR(__xludf.DUMMYFUNCTION("""COMPUTED_VALUE"""),"IBU") -> IBU | F1: =IFERROR(__xludf.DUMMYFUNCTION("""COMPUTED_VALUE"""),"ALAMAT") -> ALAMAT | G1: =IFERROR(__xludf.DUMMYFUNCTION("""COMPUTED_VALUE"""),"SEKOLAH") -> SEKOLAH | H1: =IFERROR(__xludf.DUMMYFUNCTION("""COMPUTED_VALUE"""),"ASRAMA") -> ASRAMA | I1: =IFERROR(__xludf.DUMMYFUNCTION("""COMPUTED_VALUE"""),"KAMAR") -> KAMAR | J1: =IFERROR(__xludf.DUMMYFUNCTION("""COMPUTED_VALUE"""),"TINGKAT") -> TINGKAT | K1: =IFERROR(__xludf.DUMMYFUNCTION("""COMPUTED_VALUE"""),"MADRASIAH") -> MADRASIAH | L1: =IFERROR(__xludf.DUMMYFUNCTION("""COMPUTED_VALUE"""),"HP") -> HP | M1: =IFERROR(__xludf.DUMMYFUNCTION("""COMPUTED_VALUE"""),"JARIYAH I") -> JARIYAH I | N1: =IFERROR(__xludf.DUMMYFUNCTION("""COMPUTED_VALUE"""),"DANA KEGIATAN") -> DANA KEGIATAN | O1: =IFERROR(__xludf.DUMMYFUNCTION("""COMPUTED_VALUE"""),7.0) -> 7 | P1: =IFERROR(__xludf.DUMMYFUNCTION("""COMPUTED_VALUE"""),8.0) -> 8 | Q1: =IFERROR(__xludf.DUMMYFUNCTION("""COMPUTED_VALUE"""),9.0) -> 9 | R1: =IFERROR(__xludf.DUMMYFUNCTION("""COMPUTED_VALUE"""),10.0) -> 10 | S1: =IFERROR(__xludf.DUMMYFUNCTION("""COMPUTED_VALUE"""),11.0) -> 11 | T1: =IFERROR(__xludf.DUMMYFUNCTION("""COMPUTED_VALUE"""),12.0) -> 12 | U1: =IFERROR(__xludf.DUMMYFUNCTION("""COMPUTED_VALUE"""),1.0) -> 1 | V1: =IFERROR(__xludf.DUMMYFUNCTION("""COMPUTED_VALUE"""),2.0) -> 2 | W1: =IFERROR(__xludf.DUMMYFUNCTION("""COMPUTED_VALUE"""),3.0) -> 3 | X1: =IFERROR(__xludf.DUMMYFUNCTION("""COMPUTED_VALUE"""),4.0) -> 4 | Y1: =IFERROR(__xludf.DUMMYFUNCTION("""COMPUTED_VALUE"""),5.0) -> 5 | Z1: =IFERROR(__xludf.DUMMYFUNCTION("""COMPUTED_VALUE"""),6.0) -> 6 | AA1: =IFERROR(__xludf.DUMMYFUNCTION("""COMPUTED_VALUE"""),"DAFTAR ULANG KELAS II") -> DAFTAR ULANG KELAS II | AB1: =IFERROR(__xludf.DUMMYFUNCTION("""COMPUTED_VALUE"""),"JARIYAH II") -> JARIYAH II | AC1: =IFERROR(__xludf.DUMMYFUNCTION("""COMPUTED_VALUE"""),7.0) -> 7 | AD1: =IFERROR(__xludf.DUMMYFUNCTION("""COMPUTED_VALUE"""),8.0) -> 8 | AE1: =IFERROR(__xludf.DUMMYFUNCTION("""COMPUTED_VALUE"""),9.0) -> 9 | AF1: =IFERROR(__xludf.DUMMYFUNCTION("""COMPUTED_VALUE"""),10.0) -> 10 | AG1: =IFERROR(__xludf.DUMMYFUNCTION("""COMPUTED_VALUE"""),11.0) -> 11 | AH1: =IFERROR(__xludf.DUMMYFUNCTION("""COMPUTED_VALUE"""),12.0) -> 12 | AI1: =IFERROR(__xludf.DUMMYFUNCTION("""COMPUTED_VALUE"""),1.0) -> 1 | AJ1: =IFERROR(__xludf.DUMMYFUNCTION("""COMPUTED_VALUE"""),2.0) -> 2 | AK1: =IFERROR(__xludf.DUMMYFUNCTION("""COMPUTED_VALUE"""),3.0) -> 3 | AL1: =IFERROR(__xludf.DUMMYFUNCTION("""COMPUTED_VALUE"""),4.0) -> 4 | AM1: =IFERROR(__xludf.DUMMYFUNCTION("""COMPUTED_VALUE"""),5.0) -> 5 | AN1: =IFERROR(__xludf.DUMMYFUNCTION("""COMPUTED_VALUE"""),6.0) -> 6 | AO1: =IFERROR(__xludf.DUMMYFUNCTION("""COMPUTED_VALUE"""),"DAFTAR ULANG KELAS III") -> DAFTAR ULANG KELAS III | AP1: =IFERROR(__xludf.DUMMYFUNCTION("""COMPUTED_VALUE"""),"JARIYAH III") -> JARIYAH III | AQ1: =IFERROR(__xludf.DUMMYFUNCTION("""COMPUTED_VALUE"""),7.0) -> 7 | AR1: =IFERROR(__xludf.DUMMYFUNCTION("""COMPUTED_VALUE"""),8.0) -> 8 | AS1: =IFERROR(__xludf.DUMMYFUNCTION("""COMPUTED_VALUE"""),9.0) -> 9 | AT1: =IFERROR(__xludf.DUMMYFUNCTION("""COMPUTED_VALUE"""),10.0) -> 10 | AU1: =IFERROR(__xludf.DUMMYFUNCTION("""COMPUTED_VALUE"""),11.0) -> 11 | AV1: =IFERROR(__xludf.DUMMYFUNCTION("""COMPUTED_VALUE"""),12.0) -> 12 | AW1: =IFERROR(__xludf.DUMMYFUNCTION("""COMPUTED_VALUE"""),1.0) -> 1 | AX1: =IFERROR(__xludf.DUMMYFUNCTION("""COMPUTED_VALUE"""),2.0) -> 2 | AY1: =IFERROR(__xludf.DUMMYFUNCTION("""COMPUTED_VALUE"""),3.0) -> 3 | AZ1: =IFERROR(__xludf.DUMMYFUNCTION("""COMPUTED_VALUE"""),4.0) -> 4 | BA1: =IFERROR(__xludf.DUMMYFUNCTION("""COMPUTED_VALUE"""),5.0) -> 5 | BB1: =IFERROR(__xludf.DUMMYFUNCTION("""COMPUTED_VALUE"""),6.0) -> 6 | BC1: =IFERROR(__xludf.DUMMYFUNCTION("""COMPUTED_VALUE"""),"JUMLAH SYAHRIYAH") -> JUMLAH SYAHRIYAH | BD1: =IFERROR(__xludf.DUMMYFUNCTION("""COMPUTED_VALUE"""),"JUMLAH JARIYAH") -> JUMLAH JARIYAH | BE1: =IFERROR(__xludf.DUMMYFUNCTION("""COMPUTED_VALUE"""),"JUMLAH DAFTAR ULANG") -> JUMLAH DAFTAR ULANG | BF1: =IFERROR(__xludf.DUMMYFUNCTION("""COMPUTED_VALUE"""),"JUMLAH TOTAL TUNGGAKAN") -> JUMLAH TOTAL TUNGGAKAN
A2: =IFERROR(__xludf.DUMMYFUNCTION("""COMPUTED_VALUE"""),"") | BC2: =IFERROR(__xludf.DUMMYFUNCTION("""COMPUTED_VALUE"""),0.0) -> 0 | BD2: =IFERROR(__xludf.DUMMYFUNCTION("""COMPUTED_VALUE"""),0.0) -> 0 | BE2: =IFERROR(__xludf.DUMMYFUNCTION("""COMPUTED_VALUE"""),0.0) -> 0 | BF2: =IFERROR(__xludf.DUMMYFUNCTION("""COMPUTED_VALUE"""),0.0) -> 0
A3: =IFERROR(__xludf.DUMMYFUNCTION("""COMPUTED_VALUE"""),"") | BC3: =IFERROR(__xludf.DUMMYFUNCTION("""COMPUTED_VALUE"""),0.0) -> 0 | BD3: =IFERROR(__xludf.DUMMYFUNCTION("""COMPUTED_VALUE"""),0.0) -> 0 | BE3: =IFERROR(__xludf.DUMMYFUNCTION("""COMPUTED_VALUE"""),0.0) -> 0 | BF3: =IFERROR(__xludf.DUMMYFUNCTION("""COMPUTED_VALUE"""),0.0) -> 0
A4: =IFERROR(__xludf.DUMMYFUNCTION("""COMPUTED_VALUE"""),"") | BC4: =IFERROR(__xludf.DUMMYFUNCTION("""COMPUTED_VALUE"""),0.0) -> 0 | BD4: =IFERROR(__xludf.DUMMYFUNCTION("""COMPUTED_VALUE"""),0.0) -> 0 | BE4: =IFERROR(__xludf.DUMMYFUNCTION("""COMPUTED_VALUE"""),0.0) -> 0 | BF4: =IFERROR(__xludf.DUMMYFUNCTION("""COMPUTED_VALUE"""),0.0) -> 0
A5: =IFERROR(__xludf.DUMMYFUNCTION("""COMPUTED_VALUE"""),"") | BC5: =IFERROR(__xludf.DUMMYFUNCTION("""COMPUTED_VALUE"""),0.0) -> 0 | BD5: =IFERROR(__xludf.DUMMYFUNCTION("""COMPUTED_VALUE"""),0.0) -> 0 | BE5: =IFERROR(__xludf.DUMMYFUNCTION("""COMPUTED_VALUE"""),0.0) -> 0 | BF5: =IFERROR(__xludf.DUMMYFUNCTION("""COMPUTED_VALUE"""),0.0) -> 0
A6: =IFERROR(__xludf.DUMMYFUNCTION("""COMPUTED_VALUE"""),"") | BC6: =IFERROR(__xludf.DUMMYFUNCTION("""COMPUTED_VALUE"""),0.0) -> 0 | BD6: =IFERROR(__xludf.DUMMYFUNCTION("""COMPUTED_VALUE"""),0.0) -> 0 | BE6: =IFERROR(__xludf.DUMMYFUNCTION("""COMPUTED_VALUE"""),0.0) -> 0 | BF6: =IFERROR(__xludf.DUMMYFUNCTION("""COMPUTED_VALUE"""),0.0) -> 0
A7: =IFERROR(__xludf.DUMMYFUNCTION("""COMPUTED_VALUE"""),"") | BC7: =IFERROR(__xludf.DUMMYFUNCTION("""COMPUTED_VALUE"""),0.0) -> 0 | BD7: =IFERROR(__xludf.DUMMYFUNCTION("""COMPUTED_VALUE"""),0.0) -> 0 | BE7: =IFERROR(__xludf.DUMMYFUNCTION("""COMPUTED_VALUE"""),0.0) -> 0 | BF7: =IFERROR(__xludf.DUMMYFUNCTION("""COMPUTED_VALUE"""),0.0) -> 0
A8: =IFERROR(__xludf.DUMMYFUNCTION("""COMPUTED_VALUE"""),"") | BC8: =IFERROR(__xludf.DUMMYFUNCTION("""COMPUTED_VALUE"""),0.0) -> 0 | BD8: =IFERROR(__xludf.DUMMYFUNCTION("""COMPUTED_VALUE"""),0.0) -> 0 | BE8: =IFERROR(__xludf.DUMMYFUNCTION("""COMPUTED_VALUE"""),0.0) -> 0 | BF8: =IFERROR(__xludf.DUMMYFUNCTION("""COMPUTED_VALUE"""),0.0) -> 0
A9: =IFERROR(__xludf.DUMMYFUNCTION("""COMPUTED_VALUE"""),"") | BC9: =IFERROR(__xludf.DUMMYFUNCTION("""COMPUTED_VALUE"""),0.0) -> 0 | BD9: =IFERROR(__xludf.DUMMYFUNCTION("""COMPUTED_VALUE"""),0.0) -> 0 | BE9: =IFERROR(__xludf.DUMMYFUNCTION("""COMPUTED_VALUE"""),0.0) -> 0 | BF9: =IFERROR(__xludf.DUMMYFUNCTION("""COMPUTED_VALUE"""),0.0) -> 0
A10: =IFERROR(__xludf.DUMMYFUNCTION("""COMPUTED_VALUE"""),"") | BC10: =IFERROR(__xludf.DUMMYFUNCTION("""COMPUTED_VALUE"""),0.0) -> 0 | BD10: =IFERROR(__xludf.DUMMYFUNCTION("""COMPUTED_VALUE"""),0.0) -> 0 | BE10: =IFERROR(__xludf.DUMMYFUNCTION("""COMPUTED_VALUE"""),0.0) -> 0 | BF10: =IFERROR(__xludf.DUMMYFUNCTION("""COMPUTED_VALUE"""),0.0) -> 0
A11: =IFERROR(__xludf.DUMMYFUNCTION("""COMPUTED_VALUE"""),"") | BC11: =IFERROR(__xludf.DUMMYFUNCTION("""COMPUTED_VALUE"""),0.0) -> 0 | BD11: =IFERROR(__xludf.DUMMYFUNCTION("""COMPUTED_VALUE"""),0.0) -> 0 | BE11: =IFERROR(__xludf.DUMMYFUNCTION("""COMPUTED_VALUE"""),0.0) -> 0 | BF11: =IFERROR(__xludf.DUMMYFUNCTION("""COMPUTED_VALUE"""),0.0) -> 0
A12: =IFERROR(__xludf.DUMMYFUNCTION("""COMPUTED_VALUE"""),"") | BC12: =IFERROR(__xludf.DUMMYFUNCTION("""COMPUTED_VALUE"""),0.0) -> 0 | BD12: =IFERROR(__xludf.DUMMYFUNCTION("""COMPUTED_VALUE"""),0.0) -> 0 | BE12: =IFERROR(__xludf.DUMMYFUNCTION("""COMPUTED_VALUE"""),0.0) -> 0 | BF12: =IFERROR(__xludf.DUMMYFUNCTION("""COMPUTED_VALUE"""),0.0) -> 0
A13: =IFERROR(__xludf.DUMMYFUNCTION("""COMPUTED_VALUE"""),"") | BC13: =IFERROR(__xludf.DUMMYFUNCTION("""COMPUTED_VALUE"""),0.0) -> 0 | BD13: =IFERROR(__xludf.DUMMYFUNCTION("""COMPUTED_VALUE"""),0.0) -> 0 | BE13: =IFERROR(__xludf.DUMMYFUNCTION("""COMPUTED_VALUE"""),0.0) -> 0 | BF13: =IFERROR(__xludf.DUMMYFUNCTION("""COMPUTED_VALUE"""),0.0) -> 0
... A370: =IFERROR(__xludf.DUMMYFUNCTION("""COMPUTED_VALUE"""),"") | BC370: =IFERROR(__xludf.DUMMYFUNCTION("""COMPUTED_VALUE"""),0.0) -> 0 | BD370: =IFERROR(__xludf.DUMMYFUNCTION("""COMPUTED_VALUE"""),0.0) -> 0 | BE370: =IFERROR(__xludf.DUMMYFUNCTION("""COMPUTED_VALUE"""),0.0) -> 0 | BF370: =IFERROR(__xludf.DUMMYFUNCTION("""COMPUTED_VALUE"""),0.0) -> 0
A371: =IFERROR(__xludf.DUMMYFUNCTION("""COMPUTED_VALUE"""),"")
A372: =IFERROR(__xludf.DUMMYFUNCTION("""COMPUTED_VALUE"""),"")
A373: =IFERROR(__xludf.DUMMYFUNCTION("""COMPUTED_VALUE"""),"")
A374: =IFERROR(__xludf.DUMMYFUNCTION("""COMPUTED_VALUE"""),"")
A375: =IFERROR(__xludf.DUMMYFUNCTION("""COMPUTED_VALUE"""),"")
A376: =IFERROR(__xludf.DUMMYFUNCTION("""COMPUTED_VALUE"""),"")
A377: =IFERROR(__xludf.DUMMYFUNCTION("""COMPUTED_VALUE"""),"")
A378: =IFERROR(__xludf.DUMMYFUNCTION("""COMPUTED_VALUE"""),"")
A379: =IFERROR(__xludf.DUMMYFUNCTION("""COMPUTED_VALUE"""),"")
A380: =IFERROR(__xludf.DUMMYFUNCTION("""COMPUTED_VALUE"""),"")
A381: =IFERROR(__xludf.DUMMYFUNCTION("""COMPUTED_VALUE"""),"")
A382: =IFERROR(__xludf.DUMMYFUNCTION("""COMPUTED_VALUE"""),"")
... A711: =IFERROR(__xludf.DUMMYFUNCTION("""COMPUTED_VALUE"""),"")
B757: 1 | C757: 2 | D757: 3 | E757: 4 | F757: 5 | G757: 6 | H757: 7 | I757: 8 | J757: 9 | K757: 10 | L757: 11 | M757: 12 | N757: 13 | O757: 14 | P757: 15 | Q757: 16 | R757: 17 | S757: 18 | T757: 19 | U757: 20 | V757: 21 | W757: 22 | X757: 23 | Y757: 24 | Z757: 25 | AA757: 26 | AB757: 27 | AC757: 28 | AD757: 29 | AE757: 30 | AF757: 31 | AG757: 32 | AH757: 33 | AI757: 34 | AJ757: 35 | AK757: 36 | AL757: 37 | AM757: 38 | AN757: 39 | AO757: 40 | AP757: 41 | AQ757: 42 | AR757: 43 | AS757: 44 | AT757: 45 | AU757: 46 | AV757: 47 | AW757: 48 | AX757: 49 | AY757: 50 | AZ757: 51 | BA757: 52 | BB757: 53 | BC757: 54 | BD757: 55 | BE757: 56

Sheet import2
A1: =IFERROR(__xludf.DUMMYFUNCTION("IMPORTRANGE(""1r--qa2i5jCx8YeQ_mLlUrqLRTQh7y-fik2wTdRKBimk/edit?gid=675166745#gid=675166745"",""KELAS II!A2:BF750"")"),"NO") -> NO | B1: =IFERROR(__xludf.DUMMYFUNCTION("""COMPUTED_VALUE"""),"NAMA") -> NAMA | C1: =IFERROR(__xludf.DUMMYFUNCTION("""COMPUTED_VALUE"""),"NIS") -> NIS | D1: =IFERROR(__xludf.DUMMYFUNCTION("""COMPUTED_VALUE"""),"AYAH") -> AYAH | E1: =IFERROR(__xludf.DUMMYFUNCTION("""COMPUTED_VALUE"""),"IBU") -> IBU | F1: =IFERROR(__xludf.DUMMYFUNCTION("""COMPUTED_VALUE"""),"ALAMAT") -> ALAMAT | G1: =IFERROR(__xludf.DUMMYFUNCTION("""COMPUTED_VALUE"""),"SEKOLAH") -> SEKOLAH | H1: =IFERROR(__xludf.DUMMYFUNCTION("""COMPUTED_VALUE"""),"ASRAMA") -> ASRAMA | I1: =IFERROR(__xludf.DUMMYFUNCTION("""COMPUTED_VALUE"""),"KAMAR") -> KAMAR | J1: =IFERROR(__xludf.DUMMYFUNCTION("""COMPUTED_VALUE"""),"TINGKAT") -> TINGKAT | K1: =IFERROR(__xludf.DUMMYFUNCTION("""COMPUTED_VALUE"""),"MADRASIAH") -> MADRASIAH | L1: =IFERROR(__xludf.DUMMYFUNCTION("""COMPUTED_VALUE"""),"HP") -> HP | M1: =IFERROR(__xludf.DUMMYFUNCTION("""COMPUTED_VALUE"""),"JARIYAH I") -> JARIYAH I | N1: =IFERROR(__xludf.DUMMYFUNCTION("""COMPUTED_VALUE"""),"DANA KEGIATAN") -> DANA KEGIATAN | O1: =IFERROR(__xludf.DUMMYFUNCTION("""COMPUTED_VALUE"""),7.0) -> 7 | P1: =IFERROR(__xludf.DUMMYFUNCTION("""COMPUTED_VALUE"""),8.0) -> 8 | Q1: =IFERROR(__xludf.DUMMYFUNCTION("""COMPUTED_VALUE"""),9.0) -> 9 | R1: =IFERROR(__xludf.DUMMYFUNCTION("""COMPUTED_VALUE"""),10.0) -> 10 | S1: =IFERROR(__xludf.DUMMYFUNCTION("""COMPUTED_VALUE"""),11.0) -> 11 | T1: =IFERROR(__xludf.DUMMYFUNCTION("""COMPUTED_VALUE"""),12.0) -> 12 | U1: =IFERROR(__xludf.DUMMYFUNCTION("""COMPUTED_VALUE"""),1.0) -> 1 | V1: =IFERROR(__xludf.DUMMYFUNCTION("""COMPUTED_VALUE"""),2.0) -> 2 | W1: =IFERROR(__xludf.DUMMYFUNCTION("""COMPUTED_VALUE"""),3.0) -> 3 | X1: =IFERROR(__xludf.DUMMYFUNCTION("""COMPUTED_VALUE"""),4.0) -> 4 | Y1: =IFERROR(__xludf.DUMMYFUNCTION("""COMPUTED_VALUE"""),5.0) -> 5 | Z1: =IFERROR(__xludf.DUMMYFUNCTION("""COMPUTED_VALUE"""),6.0) -> 6 | AA1: =IFERROR(__xludf.DUMMYFUNCTION("""COMPUTED_VALUE"""),"DAFTAR ULANG KELAS II") -> DAFTAR ULANG KELAS II | AB1: =IFERROR(__xludf.DUMMYFUNCTION("""COMPUTED_VALUE"""),"JARIYAH II") -> JARIYAH II | AC1: =IFERROR(__xludf.DUMMYFUNCTION("""COMPUTED_VALUE"""),7.0) -> 7 | AD1: =IFERROR(__xludf.DUMMYFUNCTION("""COMPUTED_VALUE"""),8.0) -> 8 | AE1: =IFERROR(__xludf.DUMMYFUNCTION("""COMPUTED_VALUE"""),9.0) -> 9 | AF1: =IFERROR(__xludf.DUMMYFUNCTION("""COMPUTED_VALUE"""),10.0) -> 10 | AG1: =IFERROR(__xludf.DUMMYFUNCTION("""COMPUTED_VALUE"""),11.0) -> 11 | AH1: =IFERROR(__xludf.DUMMYFUNCTION("""COMPUTED_VALUE"""),12.0) -> 12 | AI1: =IFERROR(__xludf.DUMMYFUNCTION("""COMPUTED_VALUE"""),1.0) -> 1 | AJ1: =IFERROR(__xludf.DUMMYFUNCTION("""COMPUTED_VALUE"""),2.0) -> 2 | AK1: =IFERROR(__xludf.DUMMYFUNCTION("""COMPUTED_VALUE"""),3.0) -> 3 | AL1: =IFERROR(__xludf.DUMMYFUNCTION("""COMPUTED_VALUE"""),4.0) -> 4 | AM1: =IFERROR(__xludf.DUMMYFUNCTION("""COMPUTED_VALUE"""),5.0) -> 5 | AN1: =IFERROR(__xludf.DUMMYFUNCTION("""COMPUTED_VALUE"""),6.0) -> 6 | AO1: =IFERROR(__xludf.DUMMYFUNCTION("""COMPUTED_VALUE"""),"DAFTAR ULANG KELAS III") -> DAFTAR ULANG KELAS III | AP1: =IFERROR(__xludf.DUMMYFUNCTION("""COMPUTED_VALUE"""),"JARIYAH III") -> JARIYAH III | AQ1: =IFERROR(__xludf.DUMMYFUNCTION("""COMPUTED_VALUE"""),7.0) -> 7 | AR1: =IFERROR(__xludf.DUMMYFUNCTION("""COMPUTED_VALUE"""),8.0) -> 8 | AS1: =IFERROR(__xludf.DUMMYFUNCTION("""COMPUTED_VALUE"""),9.0) -> 9 | AT1: =IFERROR(__xludf.DUMMYFUNCTION("""COMPUTED_VALUE"""),10.0) -> 10 | AU1: =IFERROR(__xludf.DUMMYFUNCTION("""COMPUTED_VALUE"""),11.0) -> 11 | AV1: =IFERROR(__xludf.DUMMYFUNCTION("""COMPUTED_VALUE"""),12.0) -> 12 | AW1: =IFERROR(__xludf.DUMMYFUNCTION("""COMPUTED_VALUE"""),1.0) -> 1 | AX1: =IFERROR(__xludf.DUMMYFUNCTION("""COMPUTED_VALUE"""),2.0) -> 2 | AY1: =IFERROR(__xludf.DUMMYFUNCTION("""COMPUTED_VALUE"""),3.0) -> 3 | AZ1: =IFERROR(__xludf.DUMMYFUNCTION("""COMPUTED_VALUE"""),4.0) -> 4 | BA1: =IFERROR(__xludf.DUMMYFUNCTION("""COMPUTED_VALUE"""),5.0) -> 5 | BB1: =IFERROR(__xludf.DUMMYFUNCTION("""COMPUTED_VALUE"""),6.0) -> 6 | BC1: =IFERROR(__xludf.DUMMYFUNCTION("""COMPUTED_VALUE"""),"JUMLAH SYAHRIYAH") -> JUMLAH SYAHRIYAH | BD1: =IFERROR(__xludf.DUMMYFUNCTION("""COMPUTED_VALUE"""),"JUMLAH JARIYAH") -> JUMLAH JARIYAH | BE1: =IFERROR(__xludf.DUMMYFUNCTION("""COMPUTED_VALUE"""),"JUMLAH DAFTAR ULANG") -> JUMLAH DAFTAR ULANG | BF1: =IFERROR(__xludf.DUMMYFUNCTION("""COMPUTED_VALUE"""),"JUMLAH TOTAL TUNGGAKAN") -> JUMLAH TOTAL TUNGGAKAN
A2: =IFERROR(__xludf.DUMMYFUNCTION("""COMPUTED_VALUE"""),1.0) -> 1 | B2: =IFERROR(__xludf.DUMMYFUNCTION("""COMPUTED_VALUE"""),"ABD. RO`UF WISNU WARDANA") -> ABD. RO`UF WISNU WARDANA | C2: =IFERROR(__xludf.DUMMYFUNCTION("""COMPUTED_VALUE"""),2.025070115E9) -> 2025070115 | D2: =IFERROR(__xludf.DUMMYFUNCTION("""COMPUTED_VALUE"""),"ABDUL MUKHIT") -> ABDUL MUKHIT | E2: =IFERROR(__xludf.DUMMYFUNCTION("""COMPUTED_VALUE"""),"NUR LAYLI ROHMAWATI") -> NUR LAYLI ROHMAWATI | F2: =IFERROR(__xludf.DUMMYFUNCTION("""COMPUTED_VALUE"""),"KLATING TAKERANKLATING RT 005 RW 001 TIKUNG LAMONGAN") -> KLATING TAKERANKLATING RT 005 RW 001 TIKUNG LAMONGAN | G2: =IFERROR(__xludf.DUMMYFUNCTION("""COMPUTED_VALUE"""),"MA-XI.13") -> MA-XI.13 | H2: =IFERROR(__xludf.DUMMYFUNCTION("""COMPUTED_VALUE"""),"A") -> A | I2: =IFERROR(__xludf.DUMMYFUNCTION("""COMPUTED_VALUE"""),"A-4") -> A-4 | J2: =IFERROR(__xludf.DUMMYFUNCTION("""COMPUTED_VALUE"""),2.0) -> 2 | K2: =IFERROR(__xludf.DUMMYFUNCTION("""COMPUTED_VALUE"""),"2 MAK PUTRA") -> 2 MAK PUTRA | L2: =IFERROR(__xludf.DUMMYFUNCTION("""COMPUTED_VALUE"""),"6285707284833") -> 6285707284833 | AB2: =IFERROR(__xludf.DUMMYFUNCTION("""COMPUTED_VALUE"""),500000.0) -> 500000 | AP2: =IFERROR(__xludf.DUMMYFUNCTION("""COMPUTED_VALUE"""),500000.0) -> 500000 | BC2: =IFERROR(__xludf.DUMMYFUNCTION("""COMPUTED_VALUE"""),0.0) -> 0 | BD2: =IFERROR(__xludf.DUMMYFUNCTION("""COMPUTED_VALUE"""),1000000.0) -> 1000000 | BE2: =IFERROR(__xludf.DUMMYFUNCTION("""COMPUTED_VALUE"""),0.0) -> 0 | BF2: =IFERROR(__xludf.DUMMYFUNCTION("""COMPUTED_VALUE"""),1000000.0) -> 1000000
A3: =IFERROR(__xludf.DUMMYFUNCTION("""COMPUTED_VALUE"""),2.0) -> 2 | B3: =IFERROR(__xludf.DUMMYFUNCTION("""COMPUTED_VALUE"""),"ABDUL AZIZ") -> ABDUL AZIZ | C3: =IFERROR(__xludf.DUMMYFUNCTION("""COMPUTED_VALUE"""),2.025070596E9) -> 2025070596 | D3: =IFERROR(__xludf.DUMMYFUNCTION("""COMPUTED_VALUE"""),"ABDUL ROHIM") -> ABDUL ROHIM | E3: =IFERROR(__xludf.DUMMYFUNCTION("""COMPUTED_VALUE"""),"MAHWIYAH") -> MAHWIYAH | F3: =IFERROR(__xludf.DUMMYFUNCTION("""COMPUTED_VALUE"""),"KALIREJO RT 003 RW 002 DUKUN GRESIK") -> KALIREJO RT 003 RW 002 DUKUN GRESIK | G3: =IFERROR(__xludf.DUMMYFUNCTION("""COMPUTED_VALUE"""),"MTS-8 C") -> MTS-8 C | H3: =IFERROR(__xludf.DUMMYFUNCTION("""COMPUTED_VALUE"""),"A") -> A | I3: =IFERROR(__xludf.DUMMYFUNCTION("""COMPUTED_VALUE"""),"A-1") -> A-1 | J3: =IFERROR(__xludf.DUMMYFUNCTION("""COMPUTED_VALUE"""),2.0) -> 2 | K3: =IFERROR(__xludf.DUMMYFUNCTION("""COMPUTED_VALUE"""),"2 ULA A PUTRA") -> 2 ULA A PUTRA | L3: =IFERROR(__xludf.DUMMYFUNCTION("""COMPUTED_VALUE"""),"6285784330109") -> 6285784330109 | AP3: =IFERROR(__xludf.DUMMYFUNCTION("""COMPUTED_VALUE"""),500000.0) -> 500000 | BC3: =IFERROR(__xludf.DUMMYFUNCTION("""COMPUTED_VALUE"""),0.0) -> 0 | BD3: =IFERROR(__xludf.DUMMYFUNCTION("""COMPUTED_VALUE"""),500000.0) -> 500000 | BE3: =IFERROR(__xludf.DUMMYFUNCTION("""COMPUTED_VALUE"""),0.0) -> 0 | BF3: =IFERROR(__xludf.DUMMYFUNCTION("""COMPUTED_VALUE"""),500000.0) -> 500000
A4: =IFERROR(__xludf.DUMMYFUNCTION("""COMPUTED_VALUE"""),3.0) -> 3 | B4: =IFERROR(__xludf.DUMMYFUNCTION("""COMPUTED_VALUE"""),"ABDUL MALIK ARIF DAULAY") -> ABDUL MALIK ARIF DAULAY | C4: =IFERROR(__xludf.DUMMYFUNCTION("""COMPUTED_VALUE"""),2.025070299E9) -> 2025070299 | D4: =IFERROR(__xludf.DUMMYFUNCTION("""COMPUTED_VALUE"""),"HARI MAULIADI DAULAY") -> HARI MAULIADI DAULAY | E4: =IFERROR(__xludf.DUMMYFUNCTION("""COMPUTED_VALUE"""),"SITI NURAFIYAH") -> SITI NURAFIYAH | F4: =IFERROR(__xludf.DUMMYFUNCTION("""COMPUTED_VALUE"""),"GENDONG RT 002 RW 004 LAREN LAMONGAN") -> GENDONG RT 002 RW 004 LAREN LAMONGAN | G4: =IFERROR(__xludf.DUMMYFUNCTION("""COMPUTED_VALUE"""),"MA-XI.13") -> MA-XI.13 | H4: =IFERROR(__xludf.DUMMYFUNCTION("""COMPUTED_VALUE"""),"A") -> A | I4: =IFERROR(__xludf.DUMMYFUNCTION("""COMPUTED_VALUE"""),"A-2") -> A-2 | J4: =IFERROR(__xludf.DUMMYFUNCTION("""COMPUTED_VALUE"""),2.0) -> 2 | K4: =IFERROR(__xludf.DUMMYFUNCTION("""COMPUTED_VALUE"""),"2 MAK PUTRA") -> 2 MAK PUTRA | L4: =IFERROR(__xludf.DUMMYFUNCTION("""COMPUTED_VALUE"""),"6285646321062") -> 6285646321062 | AP4: =IFERROR(__xludf.DUMMYFUNCTION("""COMPUTED_VALUE"""),500000.0) -> 500000 | BC4: =IFERROR(__xludf.DUMMYFUNCTION("""COMPUTED_VALUE"""),0.0) -> 0 | BD4: =IFERROR(__xludf.DUMMYFUNCTION("""COMPUTED_VALUE"""),500000.0) -> 500000 | BE4: =IFERROR(__xludf.DUMMYFUNCTION("""COMPUTED_VALUE"""),0.0) -> 0 | BF4: =IFERROR(__xludf.DUMMYFUNCTION("""COMPUTED_VALUE"""),500000.0) -> 500000
A5: =IFERROR(__xludf.DUMMYFUNCTION("""COMPUTED_VALUE"""),4.0) -> 4 | B5: =IFERROR(__xludf.DUMMYFUNCTION("""COMPUTED_VALUE"""),"ABDUL MUIZ SALAM") -> ABDUL MUIZ SALAM | C5: =IFERROR(__xludf.DUMMYFUNCTION("""COMPUTED_VALUE"""),2.025070224E9) -> 2025070224 | D5: =IFERROR(__xludf.DUMMYFUNCTION("""COMPUTED_VALUE"""),"SUHARTOYO") -> SUHARTOYO | E5: =IFERROR(__xludf.DUMMYFUNCTION("""COMPUTED_VALUE"""),"KASMUNTIK") -> KASMUNTIK | F5: =IFERROR(__xludf.DUMMYFUNCTION("""COMPUTED_VALUE"""),"KEPATIHAN SUKOREJO RT 007 RW 002 TURI LAMONGAN") -> KEPATIHAN SUKOREJO RT 007 RW 002 TURI LAMONGAN | G5: =IFERROR(__xludf.DUMMYFUNCTION("""COMPUTED_VALUE"""),"MA-XI.13") -> MA-XI.13 | H5: =IFERROR(__xludf.DUMMYFUNCTION("""COMPUTED_VALUE"""),"A") -> A | I5: =IFERROR(__xludf.DUMMYFUNCTION("""COMPUTED_VALUE"""),"A-4") -> A-4 | J5: =IFERROR(__xludf.DUMMYFUNCTION("""COMPUTED_VALUE"""),2.0) -> 2 | K5: =IFERROR(__xludf.DUMMYFUNCTION("""COMPUTED_VALUE"""),"2 MAK PUTRA") -> 2 MAK PUTRA | L5: =IFERROR(__xludf.DUMMYFUNCTION("""COMPUTED_VALUE"""),"6285731779996") -> 6285731779996 | AB5: =IFERROR(__xludf.DUMMYFUNCTION("""COMPUTED_VALUE"""),500000.0) -> 500000 | AP5: =IFERROR(__xludf.DUMMYFUNCTION("""COMPUTED_VALUE"""),500000.0) -> 500000 | BC5: =IFERROR(__xludf.DUMMYFUNCTION("""COMPUTED_VALUE"""),0.0) -> 0 | BD5: =IFERROR(__xludf.DUMMYFUNCTION("""COMPUTED_VALUE"""),1000000.0) -> 1000000 | BE5: =IFERROR(__xludf.DUMMYFUNCTION("""COMPUTED_VALUE"""),0.0) -> 0 | BF5: =IFERROR(__xludf.DUMMYFUNCTION("""COMPUTED_VALUE"""),1000000.0) -> 1000000
A6: =IFERROR(__xludf.DUMMYFUNCTION("""COMPUTED_VALUE"""),5.0) -> 5 | B6: =IFERROR(__xludf.DUMMYFUNCTION("""COMPUTED_VALUE"""),"ABDUL QODIR AL JAILANI") -> ABDUL QODIR AL JAILANI | C6: =IFERROR(__xludf.DUMMYFUNCTION("""COMPUTED_VALUE"""),2.025070418E9) -> 2025070418 | D6: =IFERROR(__xludf.DUMMYFUNCTION("""COMPUTED_VALUE"""),"SHOLEHODDIN") -> SHOLEHODDIN | E6: =IFERROR(__xludf.DUMMYFUNCTION("""COMPUTED_VALUE"""),"MUNIROH") -> MUNIROH | F6: =IFERROR(__xludf.DUMMYFUNCTION("""COMPUTED_VALUE"""),"BERLANTONG PANDIYANGAN RT 000 RW 000 ROBATAL SAMPANG") -> BERLANTONG PANDIYANGAN RT 000 RW 000 ROBATAL SAMPANG | G6: =IFERROR(__xludf.DUMMYFUNCTION("""COMPUTED_VALUE"""),"MA-XI.13") -> MA-XI.13 | H6: =IFERROR(__xludf.DUMMYFUNCTION("""COMPUTED_VALUE"""),"A") -> A | I6: =IFERROR(__xludf.DUMMYFUNCTION("""COMPUTED_VALUE"""),"A-2") -> A-2 | J6: =IFERROR(__xludf.DUMMYFUNCTION("""COMPUTED_VALUE"""),2.0) -> 2 | K6: =IFERROR(__xludf.DUMMYFUNCTION("""COMPUTED_VALUE"""),"2 MAK PUTRA") -> 2 MAK PUTRA | L6: =IFERROR(__xludf.DUMMYFUNCTION("""COMPUTED_VALUE"""),"6282334141174") -> 6282334141174 | N6: =IFERROR(__xludf.DUMMYFUNCTION("""COMPUTED_VALUE""")," ") | Z6: =IFERROR(__xludf.DUMMYFUNCTION("""COMPUTED_VALUE"""),450000.0) -> 450000 | BC6: =IFERROR(__xludf.DUMMYFUNCTION("""COMPUTED_VALUE"""),450000.0) -> 450000 | BD6: =IFERROR(__xludf.DUMMYFUNCTION("""COMPUTED_VALUE"""),0.0) -> 0 | BE6: =IFERROR(__xludf.DUMMYFUNCTION("""COMPUTED_VALUE"""),0.0) -> 0 | BF6: =IFERROR(__xludf.DUMMYFUNCTION("""COMPUTED_VALUE"""),450000.0) -> 450000
A7: =IFERROR(__xludf.DUMMYFUNCTION("""COMPUTED_VALUE"""),6.0) -> 6 | B7: =IFERROR(__xludf.DUMMYFUNCTION("""COMPUTED_VALUE"""),"ABI DZAR AL GHIFARI") -> ABI DZAR AL GHIFARI | C7: =IFERROR(__xludf.DUMMYFUNCTION("""COMPUTED_VALUE"""),2.025070493E9) -> 2025070493 | D7: =IFERROR(__xludf.DUMMYFUNCTION("""COMPUTED_VALUE"""),"MOH. ROHMAN") -> MOH. ROHMAN | E7: =IFERROR(__xludf.DUMMYFUNCTION("""COMPUTED_VALUE"""),"SITI WAHYUNI") -> SITI WAHYUNI | F7: =IFERROR(__xludf.DUMMYFUNCTION("""COMPUTED_VALUE"""),"GLUMO JELAKCATUR RT 001 RW 005 KALITENGAH LAMONGAN") -> GLUMO JELAKCATUR RT 001 RW 005 KALITENGAH LAMONGAN | G7: =IFERROR(__xludf.DUMMYFUNCTION("""COMPUTED_VALUE"""),"SMP-VIII C") -> SMP-VIII C | H7: =IFERROR(__xludf.DUMMYFUNCTION("""COMPUTED_VALUE"""),"A") -> A | I7: =IFERROR(__xludf.DUMMYFUNCTION("""COMPUTED_VALUE"""),"A-1") -> A-1 | J7: =IFERROR(__xludf.DUMMYFUNCTION("""COMPUTED_VALUE"""),2.0) -> 2 | K7: =IFERROR(__xludf.DUMMYFUNCTION("""COMPUTED_VALUE"""),"2 ULA A PUTRA") -> 2 ULA A PUTRA | L7: =IFERROR(__xludf.DUMMYFUNCTION("""COMPUTED_VALUE"""),"6285855722817") -> 6285855722817 | M7: =IFERROR(__xludf.DUMMYFUNCTION("""COMPUTED_VALUE"""),600000.0) -> 600000 | Q7: =IFERROR(__xludf.DUMMYFUNCTION("""COMPUTED_VALUE"""),450000.0) -> 450000 | R7: =IFERROR(__xludf.DUMMYFUNCTION("""COMPUTED_VALUE"""),450000.0) -> 450000 | S7: =IFERROR(__xludf.DUMMYFUNCTION("""COMPUTED_VALUE"""),450000.0) -> 450000 | T7: =IFERROR(__xludf.DUMMYFUNCTION("""COMPUTED_VALUE"""),450000.0) -> 450000 | U7: =IFERROR(__xludf.DUMMYFUNCTION("""COMPUTED_VALUE"""),450000.0) -> 450000 | V7: =IFERROR(__xludf.DUMMYFUNCTION("""COMPUTED_VALUE"""),450000.0) -> 450000 | W7: =IFERROR(__xludf.DUMMYFUNCTION("""COMPUTED_VALUE"""),450000.0) -> 450000 | X7: =IFERROR(__xludf.DUMMYFUNCTION("""COMPUTED_VALUE"""),450000.0) -> 450000 | ... Z7: =IFERROR(__xludf.DUMMYFUNCTION("""COMPUTED_VALUE"""),450000.0) -> 450000 | AB7: =IFERROR(__xludf.DUMMYFUNCTION("""COMPUTED_VALUE"""),500000.0) -> 500000 | AP7: =IFERROR(__xludf.DUMMYFUNCTION("""COMPUTED_VALUE"""),500000.0) -> 500000 | BC7: =IFERROR(__xludf.DUMMYFUNCTION("""COMPUTED_VALUE"""),4500000.0) -> 4500000 | BD7: =IFERROR(__xludf.DUMMYFUNCTION("""COMPUTED_VALUE"""),1600000.0) -> 1600000 | BE7: =IFERROR(__xludf.DUMMYFUNCTION("""COMPUTED_VALUE"""),0.0) -> 0 | BF7: =IFERROR(__xludf.DUMMYFUNCTION("""COMPUTED_VALUE"""),6100000.0) -> 6100000
A8: =IFERROR(__xludf.DUMMYFUNCTION("""COMPUTED_VALUE"""),7.0) -> 7 | B8: =IFERROR(__xludf.DUMMYFUNCTION("""COMPUTED_VALUE"""),"ACHMAD MIFTAHUL AN-NURIL HUDA") -> ACHMAD MIFTAHUL AN-NURIL HUDA | C8: =IFERROR(__xludf.DUMMYFUNCTION("""COMPUTED_VALUE"""),2.025070328E9) -> 2025070328 | D8: =IFERROR(__xludf.DUMMYFUNCTION("""COMPUTED_VALUE"""),"MUHAMMAD ROQIB") -> MUHAMMAD ROQIB | E8: =IFERROR(__xludf.DUMMYFUNCTION("""COMPUTED_VALUE"""),"QOMAI EFTIKA") -> QOMAI EFTIKA | F8: =IFERROR(__xludf.DUMMYFUNCTION("""COMPUTED_VALUE"""),"SUKOLILO RT 002 RW 003 SUKODADI LAMONGAN") -> SUKOLILO RT 002 RW 003 SUKODADI LAMONGAN | G8: =IFERROR(__xludf.DUMMYFUNCTION("""COMPUTED_VALUE"""),"MA-XI.13") -> MA-XI.13 | H8: =IFERROR(__xludf.DUMMYFUNCTION("""COMPUTED_VALUE"""),"A") -> A | I8: =IFERROR(__xludf.DUMMYFUNCTION("""COMPUTED_VALUE"""),"A-2") -> A-2 | J8: =IFERROR(__xludf.DUMMYFUNCTION("""COMPUTED_VALUE"""),2.0) -> 2 | K8: =IFERROR(__xludf.DUMMYFUNCTION("""COMPUTED_VALUE"""),"2 MAK PUTRA") -> 2 MAK PUTRA | L8: =IFERROR(__xludf.DUMMYFUNCTION("""COMPUTED_VALUE"""),"62895420477717") -> 62895420477717 | N8: =IFERROR(__xludf.DUMMYFUNCTION("""COMPUTED_VALUE"""),200000.0) -> 200000 | X8: =IFERROR(__xludf.DUMMYFUNCTION("""COMPUTED_VALUE"""),450000.0) -> 450000 | Y8: =IFERROR(__xludf.DUMMYFUNCTION("""COMPUTED_VALUE"""),450000.0) -> 450000 | Z8: =IFERROR(__xludf.DUMMYFUNCTION("""COMPUTED_VALUE"""),450000.0) -> 450000 | BC8: =IFERROR(__xludf.DUMMYFUNCTION("""COMPUTED_VALUE"""),1350000.0) -> 1350000 | BD8: =IFERROR(__xludf.DUMMYFUNCTION("""COMPUTED_VALUE"""),0.0) -> 0 | BE8: =IFERROR(__xludf.DUMMYFUNCTION("""COMPUTED_VALUE"""),0.0) -> 0 | BF8: =IFERROR(__xludf.DUMMYFUNCTION("""COMPUTED_VALUE"""),1350000.0) -> 1350000
A9: =IFERROR(__xludf.DUMMYFUNCTION("""COMPUTED_VALUE"""),8.0) -> 8 | B9: =IFERROR(__xludf.DUMMYFUNCTION("""COMPUTED_VALUE"""),"ACHMAD SIDDIQ") -> ACHMAD SIDDIQ | C9: =IFERROR(__xludf.DUMMYFUNCTION("""COMPUTED_VALUE"""),2.025070306E9) -> 2025070306 | D9: =IFERROR(__xludf.DUMMYFUNCTION("""COMPUTED_VALUE"""),"ZAENAL MUSTOFA") -> ZAENAL MUSTOFA | E9: =IFERROR(__xludf.DUMMYFUNCTION("""COMPUTED_VALUE"""),"KUSENAH") -> KUSENAH | F9: =IFERROR(__xludf.DUMMYFUNCTION("""COMPUTED_VALUE"""),"BANYUBANG RT 011 RW 003 SOLOKURO LAMONGAN") -> BANYUBANG RT 011 RW 003 SOLOKURO LAMONGAN | G9: =IFERROR(__xludf.DUMMYFUNCTION("""COMPUTED_VALUE"""),"MA-XI.13") -> MA-XI.13 | H9: =IFERROR(__xludf.DUMMYFUNCTION("""COMPUTED_VALUE"""),"A") -> A | I9: =IFERROR(__xludf.DUMMYFUNCTION("""COMPUTED_VALUE"""),"A-4") -> A-4 | J9: =IFERROR(__xludf.DUMMYFUNCTION("""COMPUTED_VALUE"""),2.0) -> 2 | K9: =IFERROR(__xludf.DUMMYFUNCTION("""COMPUTED_VALUE"""),"2 MAK PUTRA") -> 2 MAK PUTRA | L9: =IFERROR(__xludf.DUMMYFUNCTION("""COMPUTED_VALUE"""),"6282214993212") -> 6282214993212 | AB9: =IFERROR(__xludf.DUMMYFUNCTION("""COMPUTED_VALUE"""),500000.0) -> 500000 | AP9: =IFERROR(__xludf.DUMMYFUNCTION("""COMPUTED_VALUE"""),500000.0) -> 500000 | BC9: =IFERROR(__xludf.DUMMYFUNCTION("""COMPUTED_VALUE"""),0.0) -> 0 | BD9: =IFERROR(__xludf.DUMMYFUNCTION("""COMPUTED_VALUE"""),1000000.0) -> 1000000 | BE9: =IFERROR(__xludf.DUMMYFUNCTION("""COMPUTED_VALUE"""),0.0) -> 0 | BF9: =IFERROR(__xludf.DUMMYFUNCTION("""COMPUTED_VALUE"""),1000000.0) -> 1000000
A10: =IFERROR(__xludf.DUMMYFUNCTION("""COMPUTED_VALUE"""),9.0) -> 9 | B10: =IFERROR(__xludf.DUMMYFUNCTION("""COMPUTED_VALUE"""),"ACHMAD SYAHRUL DZAKIE AL KAUTSAR") -> ACHMAD SYAHRUL DZAKIE AL KAUTSAR | C10: =IFERROR(__xludf.DUMMYFUNCTION("""COMPUTED_VALUE"""),2.025070523E9) -> 2025070523 | D10: =IFERROR(__xludf.DUMMYFUNCTION("""COMPUTED_VALUE"""),"MOH. SYAIFUL ANSHOR") -> MOH. SYAIFUL ANSHOR | E10: =IFERROR(__xludf.DUMMYFUNCTION("""COMPUTED_VALUE"""),"SHOLIHATUL MUFIDAH") -> SHOLIHATUL MUFIDAH | F10: =IFERROR(__xludf.DUMMYFUNCTION("""COMPUTED_VALUE"""),"JL AMBARAWA PETUNG RT 010 RW 004 PANCENG BABAT") -> JL AMBARAWA PETUNG RT 010 RW 004 PANCENG BABAT | G10: =IFERROR(__xludf.DUMMYFUNCTION("""COMPUTED_VALUE"""),"MTS-8 F") -> MTS-8 F | H10: =IFERROR(__xludf.DUMMYFUNCTION("""COMPUTED_VALUE"""),"A") -> A | I10: =IFERROR(__xludf.DUMMYFUNCTION("""COMPUTED_VALUE"""),"A-3") -> A-3 | J10: =IFERROR(__xludf.DUMMYFUNCTION("""COMPUTED_VALUE"""),2.0) -> 2 | K10: =IFERROR(__xludf.DUMMYFUNCTION("""COMPUTED_VALUE"""),"2 ULA A PUTRA") -> 2 ULA A PUTRA | L10: =IFERROR(__xludf.DUMMYFUNCTION("""COMPUTED_VALUE"""),"62881027793394") -> 62881027793394 | AB10: =IFERROR(__xludf.DUMMYFUNCTION("""COMPUTED_VALUE"""),500000.0) -> 500000 | AP10: =IFERROR(__xludf.DUMMYFUNCTION("""COMPUTED_VALUE"""),500000.0) -> 500000 | BC10: =IFERROR(__xludf.DUMMYFUNCTION("""COMPUTED_VALUE"""),0.0) -> 0 | BD10: =IFERROR(__xludf.DUMMYFUNCTION("""COMPUTED_VALUE"""),1000000.0) -> 1000000 | BE10: =IFERROR(__xludf.DUMMYFUNCTION("""COMPUTED_VALUE"""),0.0) -> 0 | BF10: =IFERROR(__xludf.DUMMYFUNCTION("""COMPUTED_VALUE"""),1000000.0) -> 1000000
A11: =IFERROR(__xludf.DUMMYFUNCTION("""COMPUTED_VALUE"""),10.0) -> 10 | B11: =IFERROR(__xludf.DUMMYFUNCTION("""COMPUTED_VALUE"""),"ADHIAN SAKANI ZADDA") -> ADHIAN SAKANI ZADDA | C11: =IFERROR(__xludf.DUMMYFUNCTION("""COMPUTED_VALUE"""),2.025070582E9) -> 2025070582 | D11: =IFERROR(__xludf.DUMMYFUNCTION("""COMPUTED_VALUE"""),"KUSNUL SAKIN") -> KUSNUL SAKIN | E11: =IFERROR(__xludf.DUMMYFUNCTION("""COMPUTED_VALUE"""),"MARKUTIK") -> MARKUTIK | F11: =IFERROR(__xludf.DUMMYFUNCTION("""COMPUTED_VALUE"""),"SUGIHAN RT 012 RW 002 SOLOKURO LAMONGAN") -> SUGIHAN RT 012 RW 002 SOLOKURO LAMONGAN | G11: =IFERROR(__xludf.DUMMYFUNCTION("""COMPUTED_VALUE"""),"MTS-8 G") -> MTS-8 G | H11: =IFERROR(__xludf.DUMMYFUNCTION("""COMPUTED_VALUE"""),"A") -> A | I11: =IFERROR(__xludf.DUMMYFUNCTION("""COMPUTED_VALUE"""),"A-3") -> A-3 | J11: =IFERROR(__xludf.DUMMYFUNCTION("""COMPUTED_VALUE"""),2.0) -> 2 | K11: =IFERROR(__xludf.DUMMYFUNCTION("""COMPUTED_VALUE"""),"2 ULA A PUTRA") -> 2 ULA A PUTRA | L11: =IFERROR(__xludf.DUMMYFUNCTION("""COMPUTED_VALUE"""),"628563276002") -> 628563276002 | AB11: =IFERROR(__xludf.DUMMYFUNCTION("""COMPUTED_VALUE"""),500000.0) -> 500000 | AP11: =IFERROR(__xludf.DUMMYFUNCTION("""COMPUTED_VALUE"""),500000.0) -> 500000 | BC11: =IFERROR(__xludf.DUMMYFUNCTION("""COMPUTED_VALUE"""),0.0) -> 0 | BD11: =IFERROR(__xludf.DUMMYFUNCTION("""COMPUTED_VALUE"""),1000000.0) -> 1000000 | BE11: =IFERROR(__xludf.DUMMYFUNCTION("""COMPUTED_VALUE"""),0.0) -> 0 | BF11: =IFERROR(__xludf.DUMMYFUNCTION("""COMPUTED_VALUE"""),1000000.0) -> 1000000
A12: =IFERROR(__xludf.DUMMYFUNCTION("""COMPUTED_VALUE"""),11.0) -> 11 | B12: =IFERROR(__xludf.DUMMYFUNCTION("""COMPUTED_VALUE"""),"ADI FAJAR MUAYYAD") -> ADI FAJAR MUAYYAD | C12: =IFERROR(__xludf.DUMMYFUNCTION("""COMPUTED_VALUE"""),2.025070642E9) -> 2025070642 | D12: =IFERROR(__xludf.DUMMYFUNCTION("""COMPUTED_VALUE"""),"SRIMAT") -> SRIMAT | E12: =IFERROR(__xludf.DUMMYFUNCTION("""COMPUTED_VALUE"""),"UMMUL HASANAH") -> UMMUL HASANAH | F12: =IFERROR(__xludf.DUMMYFUNCTION("""COMPUTED_VALUE"""),"KARANGTAWAR RT 002 RW 001 LAREN LAMONGAN") -> KARANGTAWAR RT 002 RW 001 LAREN LAMONGAN | G12: =IFERROR(__xludf.DUMMYFUNCTION("""COMPUTED_VALUE"""),"MTS-8 B") -> MTS-8 B | H12: =IFERROR(__xludf.DUMMYFUNCTION("""COMPUTED_VALUE"""),"A") -> A | I12: =IFERROR(__xludf.DUMMYFUNCTION("""COMPUTED_VALUE"""),"A-1") -> A-1 | J12: =IFERROR(__xludf.DUMMYFUNCTION("""COMPUTED_VALUE"""),2.0) -> 2 | K12: =IFERROR(__xludf.DUMMYFUNCTION("""COMPUTED_VALUE"""),"2 ULA A PUTRA") -> 2 ULA A PUTRA | L12: =IFERROR(__xludf.DUMMYFUNCTION("""COMPUTED_VALUE"""),"6285739097145") -> 6285739097145 | BC12: =IFERROR(__xludf.DUMMYFUNCTION("""COMPUTED_VALUE"""),0.0) -> 0 | BD12: =IFERROR(__xludf.DUMMYFUNCTION("""COMPUTED_VALUE"""),0.0) -> 0 | BE12: =IFERROR(__xludf.DUMMYFUNCTION("""COMPUTED_VALUE"""),0.0) -> 0 | BF12: =IFERROR(__xludf.DUMMYFUNCTION("""COMPUTED_VALUE"""),0.0) -> 0
A13: =IFERROR(__xludf.DUMMYFUNCTION("""COMPUTED_VALUE"""),12.0) -> 12 | B13: =IFERROR(__xludf.DUMMYFUNCTION("""COMPUTED_VALUE"""),"ADITYA FERYANSYAH") -> ADITYA FERYANSYAH | C13: =IFERROR(__xludf.DUMMYFUNCTION("""COMPUTED_VALUE"""),2.02507046E9) -> 2025070460 | D13: =IFERROR(__xludf.DUMMYFUNCTION("""COMPUTED_VALUE"""),"ZAENAL ARIFIN W") -> ZAENAL ARIFIN W | E13: =IFERROR(__xludf.DUMMYFUNCTION("""COMPUTED_VALUE"""),"ASLAMIYAH") -> ASLAMIYAH | F13: =IFERROR(__xludf.DUMMYFUNCTION("""COMPUTED_VALUE"""),"JL. DEMAK JAYA GG 8 NO 9 TEMBOK DUKUH RT 012 RW 010 BUBUTAN SURABAYA") -> JL. DEMAK JAYA GG 8 NO 9 TEMBOK DUKUH RT 012 RW 010 BUBUTAN SURABAYA | G13: =IFERROR(__xludf.DUMMYFUNCTION("""COMPUTED_VALUE"""),"SMK-XI TSM") -> SMK-XI TSM | H13: =IFERROR(__xludf.DUMMYFUNCTION("""COMPUTED_VALUE"""),"A") -> A | I13: =IFERROR(__xludf.DUMMYFUNCTION("""COMPUTED_VALUE"""),"A-4") -> A-4 | J13: =IFERROR(__xludf.DUMMYFUNCTION("""COMPUTED_VALUE"""),2.0) -> 2 | K13: =IFERROR(__xludf.DUMMYFUNCTION("""COMPUTED_VALUE"""),"2 WUSTHO A PUTRA") -> 2 WUSTHO A PUTRA | L13: =IFERROR(__xludf.DUMMYFUNCTION("""COMPUTED_VALUE"""),"6283857988668") -> 6283857988668 | AB13: =IFERROR(__xludf.DUMMYFUNCTION("""COMPUTED_VALUE"""),500000.0) -> 500000 | AP13: =IFERROR(__xludf.DUMMYFUNCTION("""COMPUTED_VALUE"""),500000.0) -> 500000 | BC13: =IFERROR(__xludf.DUMMYFUNCTION("""COMPUTED_VALUE"""),0.0) -> 0 | BD13: =IFERROR(__xludf.DUMMYFUNCTION("""COMPUTED_VALUE"""),1000000.0) -> 1000000 | BE13: =IFERROR(__xludf.DUMMYFUNCTION("""COMPUTED_VALUE"""),0.0) -> 0 | BF13: =IFERROR(__xludf.DUMMYFUNCTION("""COMPUTED_VALUE"""),1000000.0) -> 1000000
A14: =IFERROR(__xludf.DUMMYFUNCTION("""COMPUTED_VALUE"""),13.0) -> 13 | B14: =IFERROR(__xludf.DUMMYFUNCTION("""COMPUTED_VALUE"""),"ADJIE PANGESTU NURZAINI") -> ADJIE PANGESTU NURZAINI | C14: =IFERROR(__xludf.DUMMYFUNCTION("""COMPUTED_VALUE"""),2.02507061E9) -> 2025070610 | D14: =IFERROR(__xludf.DUMMYFUNCTION("""COMPUTED_VALUE"""),"AHKMAD ZAINUDDIN") -> AHKMAD ZAINUDDIN | E14: =IFERROR(__xludf.DUMMYFUNCTION("""COMPUTED_VALUE"""),"YUNI HARIATI NINGSIH") -> YUNI HARIATI NINGSIH | F14: =IFERROR(__xludf.DUMMYFUNCTION("""COMPUTED_VALUE"""),"GERMAN RT 002 RW 004 SUGIO LAMONGAN") -> GERMAN RT 002 RW 004 SUGIO LAMONGAN | G14: =IFERROR(__xludf.DUMMYFUNCTION("""COMPUTED_VALUE"""),"MTS-8 C") -> MTS-8 C | H14: =IFERROR(__xludf.DUMMYFUNCTION("""COMPUTED_VALUE"""),"A") -> A | I14: =IFERROR(__xludf.DUMMYFUNCTION("""COMPUTED_VALUE"""),"A-1") -> A-1 | J14: =IFERROR(__xludf.DUMMYFUNCTION("""COMPUTED_VALUE"""),2.0) -> 2 | K14: =IFERROR(__xludf.DUMMYFUNCTION("""COMPUTED_VALUE"""),"2 ULA A PUTRA") -> 2 ULA A PUTRA | L14: =IFERROR(__xludf.DUMMYFUNCTION("""COMPUTED_VALUE"""),"6282132209162") -> 6282132209162 | Y14: =IFERROR(__xludf.DUMMYFUNCTION("""COMPUTED_VALUE"""),450000.0) -> 450000 | Z14: =IFERROR(__xludf.DUMMYFUNCTION("""COMPUTED_VALUE"""),450000.0) -> 450000 | AP14: =IFERROR(__xludf.DUMMYFUNCTION("""COMPUTED_VALUE"""),500000.0) -> 500000 | BC14: =IFERROR(__xludf.DUMMYFUNCTION("""COMPUTED_VALUE"""),900000.0) -> 900000 | BD14: =IFERROR(__xludf.DUMMYFUNCTION("""COMPUTED_VALUE"""),500000.0) -> 500000 | BE14: =IFERROR(__xludf.DUMMYFUNCTION("""COMPUTED_VALUE"""),0.0) -> 0 | BF14: =IFERROR(__xludf.DUMMYFUNCTION("""COMPUTED_VALUE"""),1400000.0) -> 1400000
A15: =IFERROR(__xludf.DUMMYFUNCTION("""COMPUTED_VALUE"""),14.0) -> 14 | B15: =IFERROR(__xludf.DUMMYFUNCTION("""COMPUTED_VALUE"""),"AFDHOL MUSYAFA") -> AFDHOL MUSYAFA | C15: =IFERROR(__xludf.DUMMYFUNCTION("""COMPUTED_VALUE"""),2.025070436E9) -> 2025070436 | D15: =IFERROR(__xludf.DUMMYFUNCTION("""COMPUTED_VALUE"""),"IRWAN") -> IRWAN | E15: =IFERROR(__xludf.DUMMYFUNCTION("""COMPUTED_VALUE"""),"MAISAROH") -> MAISAROH | F15: =IFERROR(__xludf.DUMMYFUNCTION("""COMPUTED_VALUE"""),"JL. KAPAL SELAM LOK TUAN RT 018 RW 000 BONTANG UTARA BONTANG") -> JL. KAPAL SELAM LOK TUAN RT 018 RW 000 BONTANG UTARA BONTANG | G15: =IFERROR(__xludf.DUMMYFUNCTION("""COMPUTED_VALUE"""),"SMK-XI TKJ 1") -> SMK-XI TKJ 1 | H15: =IFERROR(__xludf.DUMMYFUNCTION("""COMPUTED_VALUE"""),"A") -> A | I15: =IFERROR(__xludf.DUMMYFUNCTION("""COMPUTED_VALUE"""),"A-9") -> A-9 | J15: =IFERROR(__xludf.DUMMYFUNCTION("""COMPUTED_VALUE"""),2.0) -> 2 | K15: =IFERROR(__xludf.DUMMYFUNCTION("""COMPUTED_VALUE"""),"2 WUSTHO A PUTRA") -> 2 WUSTHO A PUTRA | L15: =IFERROR(__xludf.DUMMYFUNCTION("""COMPUTED_VALUE"""),"6282240716916") -> 6282240716916 | BC15: =IFERROR(__xludf.DUMMYFUNCTION("""COMPUTED_VALUE"""),0.0) -> 0 | BD15: =IFERROR(__xludf.DUMMYFUNCTION("""COMPUTED_VALUE"""),0.0) -> 0 | BE15: =IFERROR(__xludf.DUMMYFUNCTION("""COMPUTED_VALUE"""),0.0) -> 0 | BF15: =IFERROR(__xludf.DUMMYFUNCTION("""COMPUTED_VALUE"""),0.0) -> 0
A16: =IFERROR(__xludf.DUMMYFUNCTION("""COMPUTED_VALUE"""),15.0) -> 15 | B16: =IFERROR(__xludf.DUMMYFUNCTION("""COMPUTED_VALUE"""),"AHMAD AUFAR SHOLAHAN HIRZI") -> AHMAD AUFAR SHOLAHAN HIRZI | C16: =IFERROR(__xludf.DUMMYFUNCTION("""COMPUTED_VALUE"""),2.025070632E9) -> 2025070632 | D16: =IFERROR(__xludf.DUMMYFUNCTION("""COMPUTED_VALUE"""),"MOHAMAD NURUL IHSAN") -> MOHAMAD NURUL IHSAN | E16: =IFERROR(__xludf.DUMMYFUNCTION("""COMPUTED_VALUE"""),"SHOFIYATUN") -> SHOFIYATUN | F16: =IFERROR(__xludf.DUMMYFUNCTION("""COMPUTED_VALUE"""),"PUCANGRO RT 004 RW 001 KALITENGAH LAMONGAN") -> PUCANGRO RT 004 RW 001 KALITENGAH LAMONGAN | G16: =IFERROR(__xludf.DUMMYFUNCTION("""COMPUTED_VALUE"""),"MTS-8 C") -> MTS-8 C | H16: =IFERROR(__xludf.DUMMYFUNCTION("""COMPUTED_VALUE"""),"A") -> A | I16: =IFERROR(__xludf.DUMMYFUNCTION("""COMPUTED_VALUE"""),"A-3") -> A-3 | J16: =IFERROR(__xludf.DUMMYFUNCTION("""COMPUTED_VALUE"""),2.0) -> 2 | K16: =IFERROR(__xludf.DUMMYFUNCTION("""COMPUTED_VALUE"""),"2 ULA A PUTRA") -> 2 ULA A PUTRA | L16: =IFERROR(__xludf.DUMMYFUNCTION("""COMPUTED_VALUE"""),"6285707398701") -> 6285707398701 | AB16: =IFERROR(__xludf.DUMMYFUNCTION("""COMPUTED_VALUE"""),500000.0) -> 500000 | AP16: =IFERROR(__xludf.DUMMYFUNCTION("""COMPUTED_VALUE"""),500000.0) -> 500000 | BC16: =IFERROR(__xludf.DUMMYFUNCTION("""COMPUTED_VALUE"""),0.0) -> 0 | BD16: =IFERROR(__xludf.DUMMYFUNCTION("""COMPUTED_VALUE"""),1000000.0) -> 1000000 | BE16: =IFERROR(__xludf.DUMMYFUNCTION("""COMPUTED_VALUE"""),0.0) -> 0 | BF16: =IFERROR(__xludf.DUMMYFUNCTION("""COMPUTED_VALUE"""),1000000.0) -> 1000000
A17: =IFERROR(__xludf.DUMMYFUNCTION("""COMPUTED_VALUE"""),16.0) -> 16 | B17: =IFERROR(__xludf.DUMMYFUNCTION("""COMPUTED_VALUE"""),"AHMAD AVICENNA AHZA") -> AHMAD AVICENNA AHZA | C17: =IFERROR(__xludf.DUMMYFUNCTION("""COMPUTED_VALUE"""),2.025070625E9) -> 2025070625 | D17: =IFERROR(__xludf.DUMMYFUNCTION("""COMPUTED_VALUE"""),"ILHAM") -> ILHAM | E17: =IFERROR(__xludf.DUMMYFUNCTION("""COMPUTED_VALUE"""),"ARKANI") -> ARKANI | F17: =IFERROR(__xludf.DUMMYFUNCTION("""COMPUTED_VALUE"""),"PADENGANPLOSO RT 005 RW 001 PUCUK LAMONGAN") -> PADENGANPLOSO RT 005 RW 001 PUCUK LAMONGAN | G17: =IFERROR(__xludf.DUMMYFUNCTION("""COMPUTED_VALUE"""),"MTS-8 E") -> MTS-8 E | H17: =IFERROR(__xludf.DUMMYFUNCTION("""COMPUTED_VALUE"""),"A") -> A | I17: =IFERROR(__xludf.DUMMYFUNCTION("""COMPUTED_VALUE"""),"A-3") -> A-3 | J17: =IFERROR(__xludf.DUMMYFUNCTION("""COMPUTED_VALUE"""),2.0) -> 2 | K17: =IFERROR(__xludf.DUMMYFUNCTION("""COMPUTED_VALUE"""),"2 ULA A PUTRA") -> 2 ULA A PUTRA | L17: =IFERROR(__xludf.DUMMYFUNCTION("""COMPUTED_VALUE"""),"6285231952815") -> 6285231952815 | AB17: =IFERROR(__xludf.DUMMYFUNCTION("""COMPUTED_VALUE"""),500000.0) -> 500000 | AP17: =IFERROR(__xludf.DUMMYFUNCTION("""COMPUTED_VALUE"""),500000.0) -> 500000 | BC17: =IFERROR(__xludf.DUMMYFUNCTION("""COMPUTED_VALUE"""),0.0) -> 0 | BD17: =IFERROR(__xludf.DUMMYFUNCTION("""COMPUTED_VALUE"""),1000000.0) -> 1000000 | BE17: =IFERROR(__xludf.DUMMYFUNCTION("""COMPUTED_VALUE"""),0.0) -> 0 | BF17: =IFERROR(__xludf.DUMMYFUNCTION("""COMPUTED_VALUE"""),1000000.0) -> 1000000
A18: =IFERROR(__xludf.DUMMYFUNCTION("""COMPUTED_VALUE"""),17.0) -> 17 | B18: =IFERROR(__xludf.DUMMYFUNCTION("""COMPUTED_VALUE"""),"AHMAD AZMUL ARIF") -> AHMAD AZMUL ARIF | C18: =IFERROR(__xludf.DUMMYFUNCTION("""COMPUTED_VALUE"""),2.025070136E9) -> 2025070136 | D18: =IFERROR(__xludf.DUMMYFUNCTION("""COMPUTED_VALUE"""),"HUSNUN NADLIF") -> HUSNUN NADLIF | E18: =IFERROR(__xludf.DUMMYFUNCTION("""COMPUTED_VALUE"""),"KHOLIDATUL MA`RIFAH") -> KHOLIDATUL MA`RIFAH | F18: =IFERROR(__xludf.DUMMYFUNCTION("""COMPUTED_VALUE"""),"BANGERAN GENENG BANGERAN RT 005 RW 003 DUKUN GRESIK") -> BANGERAN GENENG BANGERAN RT 005 RW 003 DUKUN GRESIK | G18: =IFERROR(__xludf.DUMMYFUNCTION("""COMPUTED_VALUE"""),"MA-XI.13") -> MA-XI.13 | H18: =IFERROR(__xludf.DUMMYFUNCTION("""COMPUTED_VALUE"""),"A") -> A | I18: =IFERROR(__xludf.DUMMYFUNCTION("""COMPUTED_VALUE"""),"A-4") -> A-4 | J18: =IFERROR(__xludf.DUMMYFUNCTION("""COMPUTED_VALUE"""),2.0) -> 2 | K18: =IFERROR(__xludf.DUMMYFUNCTION("""COMPUTED_VALUE"""),"2 WUSTHO A PUTRA") -> 2 WUSTHO A PUTRA | L18: =IFERROR(__xludf.DUMMYFUNCTION("""COMPUTED_VALUE"""),"6287862214524") -> 6287862214524 | AB18: =IFERROR(__xludf.DUMMYFUNCTION("""COMPUTED_VALUE"""),500000.0) -> 500000 | AP18: =IFERROR(__xludf.DUMMYFUNCTION("""COMPUTED_VALUE"""),500000.0) -> 500000 | BC18: =IFERROR(__xludf.DUMMYFUNCTION("""COMPUTED_VALUE"""),0.0) -> 0 | BD18: =IFERROR(__xludf.DUMMYFUNCTION("""COMPUTED_VALUE"""),1000000.0) -> 1000000 | BE18: =IFERROR(__xludf.DUMMYFUNCTION("""COMPUTED_VALUE"""),0.0) -> 0 | BF18: =IFERROR(__xludf.DUMMYFUNCTION("""COMPUTED_VALUE"""),1000000.0) -> 1000000
A19: =IFERROR(__xludf.DUMMYFUNCTION("""COMPUTED_VALUE"""),18.0) -> 18 | B19: =IFERROR(__xludf.DUMMYFUNCTION("""COMPUTED_VALUE"""),"AHMAD BAHTIAR AL BUSTHOMY") -> AHMAD BAHTIAR AL BUSTHOMY | C19: =IFERROR(__xludf.DUMMYFUNCTION("""COMPUTED_VALUE"""),2.025070592E9) -> 2025070592 | D19: =IFERROR(__xludf.DUMMYFUNCTION("""COMPUTED_VALUE"""),"MOCH.IWAN PRIBADI") -> MOCH.IWAN PRIBADI | E19: =IFERROR(__xludf.DUMMYFUNCTION("""COMPUTED_VALUE"""),"NURUS SAIDATUL FUADAH") -> NURUS SAIDATUL FUADAH | F19: =IFERROR(__xludf.DUMMYFUNCTION("""COMPUTED_VALUE"""),"BALONGPANGGANG RT 004 RW 002 BALONGPANGGANG GRESIK") -> BALONGPANGGANG RT 004 RW 002 BALONGPANGGANG GRESIK | G19: =IFERROR(__xludf.DUMMYFUNCTION("""COMPUTED_VALUE"""),"MTS-8 B") -> MTS-8 B | H19: =IFERROR(__xludf.DUMMYFUNCTION("""COMPUTED_VALUE"""),"A") -> A | I19: =IFERROR(__xludf.DUMMYFUNCTION("""COMPUTED_VALUE"""),"A-1") -> A-1 | J19: =IFERROR(__xludf.DUMMYFUNCTION("""COMPUTED_VALUE"""),2.0) -> 2 | K19: =IFERROR(__xludf.DUMMYFUNCTION("""COMPUTED_VALUE"""),"2 ULA A PUTRA") -> 2 ULA A PUTRA | L19: =IFERROR(__xludf.DUMMYFUNCTION("""COMPUTED_VALUE"""),"6282231132034") -> 6282231132034 | BC19: =IFERROR(__xludf.DUMMYFUNCTION("""COMPUTED_VALUE"""),0.0) -> 0 | BD19: =IFERROR(__xludf.DUMMYFUNCTION("""COMPUTED_VALUE"""),0.0) -> 0 | BE19: =IFERROR(__xludf.DUMMYFUNCTION("""COMPUTED_VALUE"""),0.0) -> 0 | BF19: =IFERROR(__xludf.DUMMYFUNCTION("""COMPUTED_VALUE"""),0.0) -> 0
A20: =IFERROR(__xludf.DUMMYFUNCTION("""COMPUTED_VALUE"""),19.0) -> 19 | B20: =IFERROR(__xludf.DUMMYFUNCTION("""COMPUTED_VALUE"""),"AHMAD DANIEL IHSAN ADHITAMA") -> AHMAD DANIEL IHSAN ADHITAMA | C20: =IFERROR(__xludf.DUMMYFUNCTION("""COMPUTED_VALUE"""),2.025070607E9) -> 2025070607 | D20: =IFERROR(__xludf.DUMMYFUNCTION("""COMPUTED_VALUE"""),"MOH. IRSAN") -> MOH. IRSAN | E20: =IFERROR(__xludf.DUMMYFUNCTION("""COMPUTED_VALUE"""),"MUNJAROTUN") -> MUNJAROTUN | F20: =IFERROR(__xludf.DUMMYFUNCTION("""COMPUTED_VALUE"""),"KULURAN RT 004 RW 004 KALITENGAH LAMONGAN") -> KULURAN RT 004 RW 004 KALITENGAH LAMONGAN | G20: =IFERROR(__xludf.DUMMYFUNCTION("""COMPUTED_VALUE"""),"MTS-8 G") -> MTS-8 G | H20: =IFERROR(__xludf.DUMMYFUNCTION("""COMPUTED_VALUE"""),"A") -> A | I20: =IFERROR(__xludf.DUMMYFUNCTION("""COMPUTED_VALUE"""),"A-1") -> A-1 | J20: =IFERROR(__xludf.DUMMYFUNCTION("""COMPUTED_VALUE"""),2.0) -> 2 | K20: =IFERROR(__xludf.DUMMYFUNCTION("""COMPUTED_VALUE"""),"2 ULA A PUTRA") -> 2 ULA A PUTRA | L20: =IFERROR(__xludf.DUMMYFUNCTION("""COMPUTED_VALUE"""),"6285791936623") -> 6285791936623 | Z20: =IFERROR(__xludf.DUMMYFUNCTION("""COMPUTED_VALUE"""),450000.0) -> 450000 | AB20: =IFERROR(__xludf.DUMMYFUNCTION("""COMPUTED_VALUE"""),500000.0) -> 500000 | AP20: =IFERROR(__xludf.DUMMYFUNCTION("""COMPUTED_VALUE"""),500000.0) -> 500000 | BC20: =IFERROR(__xludf.DUMMYFUNCTION("""COMPUTED_VALUE"""),450000.0) -> 450000 | BD20: =IFERROR(__xludf.DUMMYFUNCTION("""COMPUTED_VALUE"""),1000000.0) -> 1000000 | BE20: =IFERROR(__xludf.DUMMYFUNCTION("""COMPUTED_VALUE"""),0.0) -> 0 | BF20: =IFERROR(__xludf.DUMMYFUNCTION("""COMPUTED_VALUE"""),1450000.0) -> 1450000
A21: =IFERROR(__xludf.DUMMYFUNCTION("""COMPUTED_VALUE"""),20.0) -> 20 | B21: =IFERROR(__xludf.DUMMYFUNCTION("""COMPUTED_VALUE"""),"AHMAD DANISH SYAHPUTRA") -> AHMAD DANISH SYAHPUTRA | C21: =IFERROR(__xludf.DUMMYFUNCTION("""COMPUTED_VALUE"""),2.025070602E9) -> 2025070602 | D21: =IFERROR(__xludf.DUMMYFUNCTION("""COMPUTED_VALUE"""),"ESNANTO HADI SAPUTRO") -> ESNANTO HADI SAPUTRO | E21: =IFERROR(__xludf.DUMMYFUNCTION("""COMPUTED_VALUE"""),"ZUNI ANISAH") -> ZUNI ANISAH | F21: =IFERROR(__xludf.DUMMYFUNCTION("""COMPUTED_VALUE"""),"GEGER RT 003 RW 003 TURI LAMONGAN") -> GEGER RT 003 RW 003 TURI LAMONGAN | G21: =IFERROR(__xludf.DUMMYFUNCTION("""COMPUTED_VALUE"""),"MTS-8 C") -> MTS-8 C | H21: =IFERROR(__xludf.DUMMYFUNCTION("""COMPUTED_VALUE"""),"A") -> A | I21: =IFERROR(__xludf.DUMMYFUNCTION("""COMPUTED_VALUE"""),"A-1") -> A-1 | J21: =IFERROR(__xludf.DUMMYFUNCTION("""COMPUTED_VALUE"""),2.0) -> 2 | K21: =IFERROR(__xludf.DUMMYFUNCTION("""COMPUTED_VALUE"""),"2 ULA A PUTRA") -> 2 ULA A PUTRA | L21: =IFERROR(__xludf.DUMMYFUNCTION("""COMPUTED_VALUE"""),"6285648764381") -> 6285648764381 | AB21: =IFERROR(__xludf.DUMMYFUNCTION("""COMPUTED_VALUE"""),500000.0) -> 500000 | AP21: =IFERROR(__xludf.DUMMYFUNCTION("""COMPUTED_VALUE"""),500000.0) -> 500000 | BC21: =IFERROR(__xludf.DUMMYFUNCTION("""COMPUTED_VALUE"""),0.0) -> 0 | BD21: =IFERROR(__xludf.DUMMYFUNCTION("""COMPUTED_VALUE"""),1000000.0) -> 1000000 | BE21: =IFERROR(__xludf.DUMMYFUNCTION("""COMPUTED_VALUE"""),0.0) -> 0 | BF21: =IFERROR(__xludf.DUMMYFUNCTION("""COMPUTED_VALUE"""),1000000.0) -> 1000000
A22: =IFERROR(__xludf.DUMMYFUNCTION("""COMPUTED_VALUE"""),21.0) -> 21 | B22: =IFERROR(__xludf.DUMMYFUNCTION("""COMPUTED_VALUE"""),"AHMAD FAIZIN") -> AHMAD FAIZIN | C22: =IFERROR(__xludf.DUMMYFUNCTION("""COMPUTED_VALUE"""),2.025070492E9) -> 2025070492 | D22: =IFERROR(__xludf.DUMMYFUNCTION("""COMPUTED_VALUE"""),"SUKAMTO") -> SUKAMTO | E22: =IFERROR(__xludf.DUMMYFUNCTION("""COMPUTED_VALUE"""),"SITI ROMLAH") -> SITI ROMLAH | F22: =IFERROR(__xludf.DUMMYFUNCTION("""COMPUTED_VALUE"""),"PELUK PENDOWOLIMO RT 001 RW 003 KARANGBINANGUN LAMONGAN") -> PELUK PENDOWOLIMO RT 001 RW 003 KARANGBINANGUN LAMONGAN | G22: =IFERROR(__xludf.DUMMYFUNCTION("""COMPUTED_VALUE"""),"MTS-8 A") -> MTS-8 A | H22: =IFERROR(__xludf.DUMMYFUNCTION("""COMPUTED_VALUE"""),"A") -> A | I22: =IFERROR(__xludf.DUMMYFUNCTION("""COMPUTED_VALUE"""),"A-13") -> A-13 | J22: =IFERROR(__xludf.DUMMYFUNCTION("""COMPUTED_VALUE"""),2.0) -> 2 | K22: =IFERROR(__xludf.DUMMYFUNCTION("""COMPUTED_VALUE"""),"2 ULA A PUTRA") -> 2 ULA A PUTRA | L22: =IFERROR(__xludf.DUMMYFUNCTION("""COMPUTED_VALUE"""),"6285730840655") -> 6285730840655 | Y22: =IFERROR(__xludf.DUMMYFUNCTION("""COMPUTED_VALUE"""),450000.0) -> 450000 | Z22: =IFERROR(__xludf.DUMMYFUNCTION("""COMPUTED_VALUE"""),450000.0) -> 450000 | AB22: =IFERROR(__xludf.DUMMYFUNCTION("""COMPUTED_VALUE"""),500000.0) -> 500000 | AP22: =IFERROR(__xludf.DUMMYFUNCTION("""COMPUTED_VALUE"""),500000.0) -> 500000 | BC22: =IFERROR(__xludf.DUMMYFUNCTION("""COMPUTED_VALUE"""),900000.0) -> 900000 | BD22: =IFERROR(__xludf.DUMMYFUNCTION("""COMPUTED_VALUE"""),1000000.0) -> 1000000 | BE22: =IFERROR(__xludf.DUMMYFUNCTION("""COMPUTED_VALUE"""),0.0) -> 0 | BF22: =IFERROR(__xludf.DUMMYFUNCTION("""COMPUTED_VALUE"""),1900000.0) -> 1900000
A23: =IFERROR(__xludf.DUMMYFUNCTION("""COMPUTED_VALUE"""),22.0) -> 22 | B23: =IFERROR(__xludf.DUMMYFUNCTION("""COMPUTED_VALUE"""),"AHMAD FAKHRI AFIF") -> AHMAD FAKHRI AFIF | C23: =IFERROR(__xludf.DUMMYFUNCTION("""COMPUTED_VALUE"""),2.025070393E9) -> 2025070393 | D23: =IFERROR(__xludf.DUMMYFUNCTION("""COMPUTED_VALUE"""),"SUPENDI") -> SUPENDI | E23: =IFERROR(__xludf.DUMMYFUNCTION("""COMPUTED_VALUE"""),"DWI ALFIAH LUTFIANINGSIH") -> DWI ALFIAH LUTFIANINGSIH | F23: =IFERROR(__xludf.DUMMYFUNCTION("""COMPUTED_VALUE"""),"BLOK C SUKA DAMAI RT 006 RW 002 MADANG SUKU III OKU TIMUR") -> BLOK C SUKA DAMAI RT 006 RW 002 MADANG SUKU III OKU TIMUR | G23: =IFERROR(__xludf.DUMMYFUNCTION("""COMPUTED_VALUE"""),"MA-XI.10") -> MA-XI.10 | H23: =IFERROR(__xludf.DUMMYFUNCTION("""COMPUTED_VALUE"""),"A") -> A | I23: =IFERROR(__xludf.DUMMYFUNCTION("""COMPUTED_VALUE"""),"A-4") -> A-4 | J23: =IFERROR(__xludf.DUMMYFUNCTION("""COMPUTED_VALUE"""),2.0) -> 2 | K23: =IFERROR(__xludf.DUMMYFUNCTION("""COMPUTED_VALUE"""),"2 WUSTHO A PUTRA") -> 2 WUSTHO A PUTRA | L23: =IFERROR(__xludf.DUMMYFUNCTION("""COMPUTED_VALUE"""),"6285664844095") -> 6285664844095 | T23: =IFERROR(__xludf.DUMMYFUNCTION("""COMPUTED_VALUE"""),450000.0) -> 450000 | U23: =IFERROR(__xludf.DUMMYFUNCTION("""COMPUTED_VALUE"""),450000.0) -> 450000 | V23: =IFERROR(__xludf.DUMMYFUNCTION("""COMPUTED_VALUE"""),450000.0) -> 450000 | W23: =IFERROR(__xludf.DUMMYFUNCTION("""COMPUTED_VALUE"""),450000.0) -> 450000 | X23: =IFERROR(__xludf.DUMMYFUNCTION("""COMPUTED_VALUE"""),450000.0) -> 450000 | Y23: =IFERROR(__xludf.DUMMYFUNCTION("""COMPUTED_VALUE"""),450000.0) -> 450000 | Z23: =IFERROR(__xludf.DUMMYFUNCTION("""COMPUTED_VALUE"""),450000.0) -> 450000 | AB23: =IFERROR(__xludf.DUMMYFUNCTION("""COMPUTED_VALUE"""),500000.0) -> 500000 | AP23: =IFERROR(__xludf.DUMMYFUNCTION("""COMPUTED_VALUE"""),500000.0) -> 500000 | BC23: =IFERROR(__xludf.DUMMYFUNCTION("""COMPUTED_VALUE"""),3150000.0) -> 3150000 | BD23: =IFERROR(__xludf.DUMMYFUNCTION("""COMPUTED_VALUE"""),1000000.0) -> 1000000 | BE23: =IFERROR(__xludf.DUMMYFUNCTION("""COMPUTED_VALUE"""),0.0) -> 0 | BF23: =IFERROR(__xludf.DUMMYFUNCTION("""COMPUTED_VALUE"""),4150000.0) -> 4150000
A24: =IFERROR(__xludf.DUMMYFUNCTION("""COMPUTED_VALUE"""),23.0) -> 23 | B24: =IFERROR(__xludf.DUMMYFUNCTION("""COMPUTED_VALUE"""),"AHMAD FATIH HASAN AL-FARROS") -> AHMAD FATIH HASAN AL-FARROS | C24: =IFERROR(__xludf.DUMMYFUNCTION("""COMPUTED_VALUE"""),2.025070375E9) -> 2025070375 | D24: =IFERROR(__xludf.DUMMYFUNCTION("""COMPUTED_VALUE"""),"ARIS TRYONO") -> ARIS TRYONO | E24: =IFERROR(__xludf.DUMMYFUNCTION("""COMPUTED_VALUE"""),"SYARIFATUL FARIDAH") -> SYARIFATUL FARIDAH | F24: =IFERROR(__xludf.DUMMYFUNCTION("""COMPUTED_VALUE"""),"BLAWI RT 002 RW 004 KARANGBINANGUN LAMONGAN") -> BLAWI RT 002 RW 004 KARANGBINANGUN LAMONGAN | G24: =IFERROR(__xludf.DUMMYFUNCTION("""COMPUTED_VALUE"""),"MA-XI.10") -> MA-XI.10 | H24: =IFERROR(__xludf.DUMMYFUNCTION("""COMPUTED_VALUE"""),"A") -> A | I24: =IFERROR(__xludf.DUMMYFUNCTION("""COMPUTED_VALUE"""),"A-4") -> A-4 | J24: =IFERROR(__xludf.DUMMYFUNCTION("""COMPUTED_VALUE"""),2.0) -> 2 | K24: =IFERROR(__xludf.DUMMYFUNCTION("""COMPUTED_VALUE"""),"2 WUSTHO A PUTRA") -> 2 WUSTHO A PUTRA | L24: =IFERROR(__xludf.DUMMYFUNCTION("""COMPUTED_VALUE"""),"6281234406503") -> 6281234406503 | BC24: =IFERROR(__xludf.DUMMYFUNCTION("""COMPUTED_VALUE"""),0.0) -> 0 | BD24: =IFERROR(__xludf.DUMMYFUNCTION("""COMPUTED_VALUE"""),0.0) -> 0 | BE24: =IFERROR(__xludf.DUMMYFUNCTION("""COMPUTED_VALUE"""),0.0) -> 0 | BF24: =IFERROR(__xludf.DUMMYFUNCTION("""COMPUTED_VALUE"""),0.0) -> 0
A25: =IFERROR(__xludf.DUMMYFUNCTION("""COMPUTED_VALUE"""),24.0) -> 24 | B25: =IFERROR(__xludf.DUMMYFUNCTION("""COMPUTED_VALUE"""),"AHMAD FIRDAUS") -> AHMAD FIRDAUS | C25: =IFERROR(__xludf.DUMMYFUNCTION("""COMPUTED_VALUE"""),2.025070151E9) -> 2025070151 | D25: =IFERROR(__xludf.DUMMYFUNCTION("""COMPUTED_VALUE"""),"ALAUDIN") -> ALAUDIN | E25: =IFERROR(__xludf.DUMMYFUNCTION("""COMPUTED_VALUE"""),"AFIDAH") -> AFIDAH | F25: =IFERROR(__xludf.DUMMYFUNCTION("""COMPUTED_VALUE"""),"TEJOASRI RT 001 RW 002 LAREN LAMONGAN") -> TEJOASRI RT 001 RW 002 LAREN LAMONGAN | G25: =IFERROR(__xludf.DUMMYFUNCTION("""COMPUTED_VALUE"""),"MA-XI.10") -> MA-XI.10 | H25: =IFERROR(__xludf.DUMMYFUNCTION("""COMPUTED_VALUE"""),"A") -> A | I25: =IFERROR(__xludf.DUMMYFUNCTION("""COMPUTED_VALUE"""),"A-4") -> A-4 | J25: =IFERROR(__xludf.DUMMYFUNCTION("""COMPUTED_VALUE"""),2.0) -> 2 | K25: =IFERROR(__xludf.DUMMYFUNCTION("""COMPUTED_VALUE"""),"2 WUSTHO A PUTRA") -> 2 WUSTHO A PUTRA | L25: =IFERROR(__xludf.DUMMYFUNCTION("""COMPUTED_VALUE"""),"6285777892081") -> 6285777892081 | U25: =IFERROR(__xludf.DUMMYFUNCTION("""COMPUTED_VALUE"""),450000.0) -> 450000 | V25: =IFERROR(__xludf.DUMMYFUNCTION("""COMPUTED_VALUE"""),450000.0) -> 450000 | W25: =IFERROR(__xludf.DUMMYFUNCTION("""COMPUTED_VALUE"""),450000.0) -> 450000 | X25: =IFERROR(__xludf.DUMMYFUNCTION("""COMPUTED_VALUE"""),450000.0) -> 450000 | Y25: =IFERROR(__xludf.DUMMYFUNCTION("""COMPUTED_VALUE"""),450000.0) -> 450000 | Z25: =IFERROR(__xludf.DUMMYFUNCTION("""COMPUTED_VALUE"""),450000.0) -> 450000 | AB25: =IFERROR(__xludf.DUMMYFUNCTION("""COMPUTED_VALUE"""),500000.0) -> 500000 | AP25: =IFERROR(__xludf.DUMMYFUNCTION("""COMPUTED_VALUE"""),500000.0) -> 500000 | BC25: =IFERROR(__xludf.DUMMYFUNCTION("""COMPUTED_VALUE"""),2700000.0) -> 2700000 | BD25: =IFERROR(__xludf.DUMMYFUNCTION("""COMPUTED_VALUE"""),1000000.0) -> 1000000 | BE25: =IFERROR(__xludf.DUMMYFUNCTION("""COMPUTED_VALUE"""),0.0) -> 0 | BF25: =IFERROR(__xludf.DUMMYFUNCTION("""COMPUTED_VALUE"""),3700000.0) -> 3700000
A26: =IFERROR(__xludf.DUMMYFUNCTION("""COMPUTED_VALUE"""),25.0) -> 25 | B26: =IFERROR(__xludf.DUMMYFUNCTION("""COMPUTED_VALUE"""),"AHMAD FIROS MUSADDAD") -> AHMAD FIROS MUSADDAD | C26: =IFERROR(__xludf.DUMMYFUNCTION("""COMPUTED_VALUE"""),2.025070197E9) -> 2025070197 | D26: =IFERROR(__xludf.DUMMYFUNCTION("""COMPUTED_VALUE"""),"MOH. ASYIKIN") -> MOH. ASYIKIN | E26: =IFERROR(__xludf.DUMMYFUNCTION("""COMPUTED_VALUE"""),"MUKAYAROH") -> MUKAYAROH | F26: =IFERROR(__xludf.DUMMYFUNCTION("""COMPUTED_VALUE"""),"KULURAN RT 003 RW 003 KALITENGAH LAMONGAN") -> KULURAN RT 003 RW 003 KALITENGAH LAMONGAN | G26: =IFERROR(__xludf.DUMMYFUNCTION("""COMPUTED_VALUE"""),"MA-XI.13") -> MA-XI.13 | H26: =IFERROR(__xludf.DUMMYFUNCTION("""COMPUTED_VALUE"""),"A") -> A | I26: =IFERROR(__xludf.DUMMYFUNCTION("""COMPUTED_VALUE"""),"A-2") -> A-2 | J26: =IFERROR(__xludf.DUMMYFUNCTION("""COMPUTED_VALUE"""),2.0) -> 2 | K26: =IFERROR(__xludf.DUMMYFUNCTION("""COMPUTED_VALUE"""),"2 MAK PUTRA") -> 2 MAK PUTRA | L26: =IFERROR(__xludf.DUMMYFUNCTION("""COMPUTED_VALUE"""),"6285606726357") -> 6285606726357 | Z26: =IFERROR(__xludf.DUMMYFUNCTION("""COMPUTED_VALUE"""),450000.0) -> 450000 | BC26: =IFERROR(__xludf.DUMMYFUNCTION("""COMPUTED_VALUE"""),450000.0) -> 450000 | BD26: =IFERROR(__xludf.DUMMYFUNCTION("""COMPUTED_VALUE"""),0.0) -> 0 | BE26: =IFERROR(__xludf.DUMMYFUNCTION("""COMPUTED_VALUE"""),0.0) -> 0 | BF26: =IFERROR(__xludf.DUMMYFUNCTION("""COMPUTED_VALUE"""),450000.0) -> 450000
A27: =IFERROR(__xludf.DUMMYFUNCTION("""COMPUTED_VALUE"""),26.0) -> 26 | B27: =IFERROR(__xludf.DUMMYFUNCTION("""COMPUTED_VALUE"""),"AHMAD HABIBUR RAHMAN") -> AHMAD HABIBUR RAHMAN | C27: =IFERROR(__xludf.DUMMYFUNCTION("""COMPUTED_VALUE"""),2.02507053E9) -> 2025070530 | D27: =IFERROR(__xludf.DUMMYFUNCTION("""COMPUTED_VALUE"""),"KARTAM") -> KARTAM | E27: =IFERROR(__xludf.DUMMYFUNCTION("""COMPUTED_VALUE"""),"JAYANTI") -> JAYANTI | F27: =IFERROR(__xludf.DUMMYFUNCTION("""COMPUTED_VALUE"""),"BADU BADURAME RT 002 RW 004 TURI LAMONGAN") -> BADU BADURAME RT 002 RW 004 TURI LAMONGAN | G27: =IFERROR(__xludf.DUMMYFUNCTION("""COMPUTED_VALUE"""),"MTS-8 G") -> MTS-8 G | H27: =IFERROR(__xludf.DUMMYFUNCTION("""COMPUTED_VALUE"""),"A") -> A | I27: =IFERROR(__xludf.DUMMYFUNCTION("""COMPUTED_VALUE"""),"A-3") -> A-3 | J27: =IFERROR(__xludf.DUMMYFUNCTION("""COMPUTED_VALUE"""),2.0) -> 2 | K27: =IFERROR(__xludf.DUMMYFUNCTION("""COMPUTED_VALUE"""),"2 ULA A PUTRA") -> 2 ULA A PUTRA | L27: =IFERROR(__xludf.DUMMYFUNCTION("""COMPUTED_VALUE"""),"6281649582028") -> 6281649582028 | M27: =IFERROR(__xludf.DUMMYFUNCTION("""COMPUTED_VALUE"""),600000.0) -> 600000 | R27: =IFERROR(__xludf.DUMMYFUNCTION("""COMPUTED_VALUE"""),450000.0) -> 450000 | S27: =IFERROR(__xludf.DUMMYFUNCTION("""COMPUTED_VALUE"""),450000.0) -> 450000 | T27: =IFERROR(__xludf.DUMMYFUNCTION("""COMPUTED_VALUE"""),450000.0) -> 450000 | U27: =IFERROR(__xludf.DUMMYFUNCTION("""COMPUTED_VALUE"""),450000.0) -> 450000 | V27: =IFERROR(__xludf.DUMMYFUNCTION("""COMPUTED_VALUE"""),450000.0) -> 450000 | W27: =IFERROR(__xludf.DUMMYFUNCTION("""COMPUTED_VALUE"""),450000.0) -> 450000 | X27: =IFERROR(__xludf.DUMMYFUNCTION("""COMPUTED_VALUE"""),450000.0) -> 450000 | Y27: =IFERROR(__xludf.DUMMYFUNCTION("""COMPUTED_VALUE"""),450000.0) -> 450000 | Z27: =IFERROR(__xludf.DUMMYFUNCTION("""COMPUTED_VALUE"""),450000.0) -> 450000 | AB27: =IFERROR(__xludf.DUMMYFUNCTION("""COMPUTED_VALUE"""),500000.0) -> 500000 | AP27: =IFERROR(__xludf.DUMMYFUNCTION("""COMPUTED_VALUE"""),500000.0) -> 500000 | BC27: =IFERROR(__xludf.DUMMYFUNCTION("""COMPUTED_VALUE"""),4050000.0) -> 4050000 | BD27: =IFERROR(__xludf.DUMMYFUNCTION("""COMPUTED_VALUE"""),1600000.0) -> 1600000 | BE27: =IFERROR(__xludf.DUMMYFUNCTION("""COMPUTED_VALUE"""),0.0) -> 0 | BF27: =IFERROR(__xludf.DUMMYFUNCTION("""COMPUTED_VALUE"""),5650000.0) -> 5650000
A28: =IFERROR(__xludf.DUMMYFUNCTION("""COMPUTED_VALUE"""),27.0) -> 27 | B28: =IFERROR(__xludf.DUMMYFUNCTION("""COMPUTED_VALUE"""),"AHMAD IRVAN SURYA MAHENDRA") -> AHMAD IRVAN SURYA MAHENDRA | C28: =IFERROR(__xludf.DUMMYFUNCTION("""COMPUTED_VALUE"""),2.025070397E9) -> 2025070397 | D28: =IFERROR(__xludf.DUMMYFUNCTION("""COMPUTED_VALUE"""),"SUYANTO") -> SUYANTO | E28: =IFERROR(__xludf.DUMMYFUNCTION("""COMPUTED_VALUE"""),"FATIMAH") -> FATIMAH | F28: =IFERROR(__xludf.DUMMYFUNCTION("""COMPUTED_VALUE"""),"TAMAN PRIJEG TAMAN PRIJEK RT 006 RW 002 LAREN LAMONGAN") -> TAMAN PRIJEG TAMAN PRIJEK RT 006 RW 002 LAREN LAMONGAN | G28: =IFERROR(__xludf.DUMMYFUNCTION("""COMPUTED_VALUE"""),"MA-XI.6") -> MA-XI.6 | H28: =IFERROR(__xludf.DUMMYFUNCTION("""COMPUTED_VALUE"""),"A") -> A | I28: =IFERROR(__xludf.DUMMYFUNCTION("""COMPUTED_VALUE"""),"A-4") -> A-4 | J28: =IFERROR(__xludf.DUMMYFUNCTION("""COMPUTED_VALUE"""),2.0) -> 2 | K28: =IFERROR(__xludf.DUMMYFUNCTION("""COMPUTED_VALUE"""),"2 WUSTHO A PUTRA") -> 2 WUSTHO A PUTRA | L28: =IFERROR(__xludf.DUMMYFUNCTION("""COMPUTED_VALUE"""),"6281331330878") -> 6281331330878 | AB28: =IFERROR(__xludf.DUMMYFUNCTION("""COMPUTED_VALUE"""),500000.0) -> 500000 | AP28: =IFERROR(__xludf.DUMMYFUNCTION("""COMPUTED_VALUE"""),500000.0) -> 500000 | BC28: =IFERROR(__xludf.DUMMYFUNCTION("""COMPUTED_VALUE"""),0.0) -> 0 | BD28: =IFERROR(__xludf.DUMMYFUNCTION("""COMPUTED_VALUE"""),1000000.0) -> 1000000 | BE28: =IFERROR(__xludf.DUMMYFUNCTION("""COMPUTED_VALUE"""),0.0) -> 0 | BF28: =IFERROR(__xludf.DUMMYFUNCTION("""COMPUTED_VALUE"""),1000000.0) -> 1000000
